Workbook
Name BD: 輸入頁!$E$7
Name BGP: OP!$C$30
Name CV: P_DATA!$V$273:$EC$539
Name DIE: P_DATA!$EI$2:$IP$268
Name EXP: P_DATA!$V$2:$EC$268
Name GP: P_DATA!$J:$K
Name IN: 輸入頁!$E$5
Name MGP: OP!$C$35
Name PA: P_DATA!$EI$273:$IP$539
Name PI: OP!$AK$4:$AL$90
Name PM: 輸入頁!$E$16
Name PVal: P_DATA!$O:$P
Name SEX: 輸入頁!$K$5
Name WORDING: OP!$P$2:$Q$20
Name WORDINGP: OP!$AD$2:$AE$41
Name YPN: 輸入頁!$D$24
Name 主約1: OP!$H$43:$H$45
Name 保額倍數: OP!$B$87:$C$197
Name 繳: OP!$H$17:$H$21
Name 繳別首: OP!$L$31:$L$35
Name 繳別續: OP!$M$31:$M$35

Sheet 揭露
B1: =OP!$C$56 -> CLX20 | C1: ←帶OP | D1: =IF(OP!$E$16=1,"足歲",IF(OP!$E$16=2,"保險年齡","錯誤")) -> 足歲 | E1: ←帶OP | Q1: 6 | R1: 7 | S1: 8 | T1: 9 | U1: 10 | V1: 11 | W1: 12
L2: 以下3欄要注意最下方要和右側揭露拉齊 | O2: 以下COPY-DB | Q2: 109
C3: 代表年齡第?小→ | D3: 1 | E3: 2 | F3: 3 | G3: 1 | H3: 2 | I3: 3 | K3: 年齡代號轉換 | L3: KEY | M3: 年齡 | N3: 年度 | O3: 險種大類 | P3: 年期險種 | Q3: 性別 | R3: 年齡 | S3: 繳費方式 | T3: 宣告利率 | U3: 繳費金額 | V3: 保單年度 | W3: 揭露利率
C4: 性別男=1，女=2→ | D4: 1 | E4: 1 | F4: 1 | G4: 2 | H4: 2 | I4: 2 | K4: =IF($D$1="足歲","15足歲","15") -> 15足歲 | L4: =IF(P4<>$B$1,"",P4&Q4&R4&V4) | M4: =IF(L4="","-",IF(ISERROR($R4*1),LEFT($R4,2)*1,$R4*1)) -> - | N4: =IF(L4="","",V4*1)
B5: 取第?欄→ | C5: 12 | D5: =IF(SMALL($M:$M,D$3)=15,$K$4,SMALL($M:$M,D$3)) -> #NUM! | E5: =IF(SMALL($M:$M,E$3)=15,$K$4,SMALL($M:$M,E$3)) -> #NUM! | F5: =IF(SMALL($M:$M,F$3)=15,$K$4,SMALL($M:$M,F$3)) -> #NUM! | G5: =IF(SMALL($M:$M,G$3)=15,$K$4,SMALL($M:$M,G$3)) -> #NUM! | H5: =IF(SMALL($M:$M,H$3)=15,$K$4,SMALL($M:$M,H$3)) -> #NUM! | I5: =IF(SMALL($M:$M,I$3)=15,$K$4,SMALL($M:$M,I$3)) -> #NUM! | L5: =IF(P5<>$B$1,"",P5&Q5&R5&V5) | M5: =IF(OR(L5="",COUNTIF($M$4:M4,IF(ISERROR($R5*1),LEFT($R5,2)*1,$R5*1))>=1),"-",IF(ISERROR($R5*1),LEFT($R5,2)*1,$R5*1)) -> - | N5: =IF(OR(L5="",COUNTIF($N$4:N4,V5*1)>=1),"-",V5*1) -> -
B6: 第?小↓ | C6: 保單年度 | D6: =IF(OR(ISERROR($D5)),"",IF(N(D$5)=0,D$5&"歲"&IF(D$4=1,"男性",IF(D$4=2,"女性","")),D$5&"歲"&IF(D$4=1,"男性",IF(D$4=2,"女性","")))) | E6: =IF(OR(ISERROR($D5)),"",IF(N(E$5)=0,E$5&"歲"&IF(E$4=1,"男性",IF(E$4=2,"女性","")),E$5&"歲"&IF(E$4=1,"男性",IF(E$4=2,"女性","")))) | F6: =IF(OR(ISERROR($D5)),"",IF(N(F$5)=0,F$5&"歲"&IF(F$4=1,"男性",IF(F$4=2,"女性","")),F$5&"歲"&IF(F$4=1,"男性",IF(F$4=2,"女性","")))) | G6: =IF(OR(ISERROR($D5)),"",IF(N(G$5)=0,G$5&"歲"&IF(G$4=1,"男性",IF(G$4=2,"女性","")),G$5&"歲"&IF(G$4=1,"男性",IF(G$4=2,"女性","")))) | H6: =IF(OR(ISERROR($D5)),"",IF(N(H$5)=0,H$5&"歲"&IF(H$4=1,"男性",IF(H$4=2,"女性","")),H$5&"歲"&IF(H$4=1,"男性",IF(H$4=2,"女性","")))) | I6: =IF(OR(ISERROR($D5)),"",IF(N(I$5)=0,I$5&"歲"&IF(I$4=1,"男性",IF(I$4=2,"女性","")),I$5&"歲"&IF(I$4=1,"男性",IF(I$4=2,"女性","")))) | L6: =IF(P6<>$B$1,"",P6&Q6&R6&V6) | M6: =IF(OR(L6="",COUNTIF($M$4:M5,IF(ISERROR($R6*1),LEFT($R6,2)*1,$R6*1))>=1),"-",IF(ISERROR($R6*1),LEFT($R6,2)*1,$R6*1)) -> - | N6: =IF(OR(L6="",COUNTIF($N$4:N5,V6*1)>=1),"-",V6*1) -> -
B7: 1 | C7: =IF(ISERROR(SMALL($N:$N,$B7)),"",SMALL($N:$N,$B7)) | D7: =IF(ISERROR(VLOOKUP($B$1&D$4&D$5&$C7,$L:$W,$C$5,0)),"",VLOOKUP($B$1&D$4&D$5&$C7,$L:$W,$C$5,0)) | E7: =IF(ISERROR(VLOOKUP($B$1&E$4&E$5&$C7,$L:$W,$C$5,0)),"",VLOOKUP($B$1&E$4&E$5&$C7,$L:$W,$C$5,0)) | F7: =IF(ISERROR(VLOOKUP($B$1&F$4&F$5&$C7,$L:$W,$C$5,0)),"",VLOOKUP($B$1&F$4&F$5&$C7,$L:$W,$C$5,0)) | G7: =IF(ISERROR(VLOOKUP($B$1&G$4&G$5&$C7,$L:$W,$C$5,0)),"",VLOOKUP($B$1&G$4&G$5&$C7,$L:$W,$C$5,0)) | H7: =IF(ISERROR(VLOOKUP($B$1&H$4&H$5&$C7,$L:$W,$C$5,0)),"",VLOOKUP($B$1&H$4&H$5&$C7,$L:$W,$C$5,0)) | I7: =IF(ISERROR(VLOOKUP($B$1&I$4&I$5&$C7,$L:$W,$C$5,0)),"",VLOOKUP($B$1&I$4&I$5&$C7,$L:$W,$C$5,0)) | L7: =IF(P7<>$B$1,"",P7&Q7&R7&V7) | M7: =IF(OR(L7="",COUNTIF($M$4:M6,IF(ISERROR($R7*1),LEFT($R7,2)*1,$R7*1))>=1),"-",IF(ISERROR($R7*1),LEFT($R7,2)*1,$R7*1)) -> - | N7: =IF(OR(L7="",COUNTIF($N$4:N6,V7*1)>=1),"-",V7*1) -> -
B8: 2 | C8: =IF(ISERROR(SMALL($N:$N,$B8)),"",SMALL($N:$N,$B8)) | D8: =IF(ISERROR(VLOOKUP($B$1&D$4&D$5&$C8,$L:$W,$C$5,0)),"",VLOOKUP($B$1&D$4&D$5&$C8,$L:$W,$C$5,0)) | E8: =IF(ISERROR(VLOOKUP($B$1&E$4&E$5&$C8,$L:$W,$C$5,0)),"",VLOOKUP($B$1&E$4&E$5&$C8,$L:$W,$C$5,0)) | F8: =IF(ISERROR(VLOOKUP($B$1&F$4&F$5&$C8,$L:$W,$C$5,0)),"",VLOOKUP($B$1&F$4&F$5&$C8,$L:$W,$C$5,0)) | G8: =IF(ISERROR(VLOOKUP($B$1&G$4&G$5&$C8,$L:$W,$C$5,0)),"",VLOOKUP($B$1&G$4&G$5&$C8,$L:$W,$C$5,0)) | H8: =IF(ISERROR(VLOOKUP($B$1&H$4&H$5&$C8,$L:$W,$C$5,0)),"",VLOOKUP($B$1&H$4&H$5&$C8,$L:$W,$C$5,0)) | I8: =IF(ISERROR(VLOOKUP($B$1&I$4&I$5&$C8,$L:$W,$C$5,0)),"",VLOOKUP($B$1&I$4&I$5&$C8,$L:$W,$C$5,0)) | L8: =IF(P8<>$B$1,"",P8&Q8&R8&V8) | M8: =IF(OR(L8="",COUNTIF($M$4:M7,IF(ISERROR($R8*1),LEFT($R8,2)*1,$R8*1))>=1),"-",IF(ISERROR($R8*1),LEFT($R8,2)*1,$R8*1)) -> - | N8: =IF(OR(L8="",COUNTIF($N$4:N7,V8*1)>=1),"-",V8*1) -> -
B9: 3 | C9: =IF(ISERROR(SMALL($N:$N,$B9)),"",SMALL($N:$N,$B9)) | D9: =IF(ISERROR(VLOOKUP($B$1&D$4&D$5&$C9,$L:$W,$C$5,0)),"",VLOOKUP($B$1&D$4&D$5&$C9,$L:$W,$C$5,0)) | E9: =IF(ISERROR(VLOOKUP($B$1&E$4&E$5&$C9,$L:$W,$C$5,0)),"",VLOOKUP($B$1&E$4&E$5&$C9,$L:$W,$C$5,0)) | F9: =IF(ISERROR(VLOOKUP($B$1&F$4&F$5&$C9,$L:$W,$C$5,0)),"",VLOOKUP($B$1&F$4&F$5&$C9,$L:$W,$C$5,0)) | G9: =IF(ISERROR(VLOOKUP($B$1&G$4&G$5&$C9,$L:$W,$C$5,0)),"",VLOOKUP($B$1&G$4&G$5&$C9,$L:$W,$C$5,0)) | H9: =IF(ISERROR(VLOOKUP($B$1&H$4&H$5&$C9,$L:$W,$C$5,0)),"",VLOOKUP($B$1&H$4&H$5&$C9,$L:$W,$C$5,0)) | I9: =IF(ISERROR(VLOOKUP($B$1&I$4&I$5&$C9,$L:$W,$C$5,0)),"",VLOOKUP($B$1&I$4&I$5&$C9,$L:$W,$C$5,0)) | L9: =IF(P9<>$B$1,"",P9&Q9&R9&V9) | M9: =IF(OR(L9="",COUNTIF($M$4:M8,IF(ISERROR($R9*1),LEFT($R9,2)*1,$R9*1))>=1),"-",IF(ISERROR($R9*1),LEFT($R9,2)*1,$R9*1)) -> - | N9: =IF(OR(L9="",COUNTIF($N$4:N8,V9*1)>=1),"-",V9*1) -> -
B10: 4 | C10: =IF(ISERROR(SMALL($N:$N,$B10)),"",SMALL($N:$N,$B10)) | D10: =IF(ISERROR(VLOOKUP($B$1&D$4&D$5&$C10,$L:$W,$C$5,0)),"",VLOOKUP($B$1&D$4&D$5&$C10,$L:$W,$C$5,0)) | E10: =IF(ISERROR(VLOOKUP($B$1&E$4&E$5&$C10,$L:$W,$C$5,0)),"",VLOOKUP($B$1&E$4&E$5&$C10,$L:$W,$C$5,0)) | F10: =IF(ISERROR(VLOOKUP($B$1&F$4&F$5&$C10,$L:$W,$C$5,0)),"",VLOOKUP($B$1&F$4&F$5&$C10,$L:$W,$C$5,0)) | G10: =IF(ISERROR(VLOOKUP($B$1&G$4&G$5&$C10,$L:$W,$C$5,0)),"",VLOOKUP($B$1&G$4&G$5&$C10,$L:$W,$C$5,0)) | H10: =IF(ISERROR(VLOOKUP($B$1&H$4&H$5&$C10,$L:$W,$C$5,0)),"",VLOOKUP($B$1&H$4&H$5&$C10,$L:$W,$C$5,0)) | I10: =IF(ISERROR(VLOOKUP($B$1&I$4&I$5&$C10,$L:$W,$C$5,0)),"",VLOOKUP($B$1&I$4&I$5&$C10,$L:$W,$C$5,0)) | L10: =IF(P10<>$B$1,"",P10&Q10&R10&V10) | M10: =IF(OR(L10="",COUNTIF($M$4:M9,IF(ISERROR($R10*1),LEFT($R10,2)*1,$R10*1))>=1),"-",IF(ISERROR($R10*1),LEFT($R10,2)*1,$R10*1)) -> - | N10: =IF(OR(L10="",COUNTIF($N$4:N9,V10*1)>=1),"-",V10*1) -> -
B11: 5 | C11: =IF(ISERROR(SMALL($N:$N,$B11)),"",SMALL($N:$N,$B11)) | D11: =IF(ISERROR(VLOOKUP($B$1&D$4&D$5&$C11,$L:$W,$C$5,0)),"",VLOOKUP($B$1&D$4&D$5&$C11,$L:$W,$C$5,0)) | E11: =IF(ISERROR(VLOOKUP($B$1&E$4&E$5&$C11,$L:$W,$C$5,0)),"",VLOOKUP($B$1&E$4&E$5&$C11,$L:$W,$C$5,0)) | F11: =IF(ISERROR(VLOOKUP($B$1&F$4&F$5&$C11,$L:$W,$C$5,0)),"",VLOOKUP($B$1&F$4&F$5&$C11,$L:$W,$C$5,0)) | G11: =IF(ISERROR(VLOOKUP($B$1&G$4&G$5&$C11,$L:$W,$C$5,0)),"",VLOOKUP($B$1&G$4&G$5&$C11,$L:$W,$C$5,0)) | H11: =IF(ISERROR(VLOOKUP($B$1&H$4&H$5&$C11,$L:$W,$C$5,0)),"",VLOOKUP($B$1&H$4&H$5&$C11,$L:$W,$C$5,0)) | I11: =IF(ISERROR(VLOOKUP($B$1&I$4&I$5&$C11,$L:$W,$C$5,0)),"",VLOOKUP($B$1&I$4&I$5&$C11,$L:$W,$C$5,0)) | L11: =IF(P11<>$B$1,"",P11&Q11&R11&V11) | M11: =IF(OR(L11="",COUNTIF($M$4:M10,IF(ISERROR($R11*1),LEFT($R11,2)*1,$R11*1))>=1),"-",IF(ISERROR($R11*1),LEFT($R11,2)*1,$R11*1)) -> - | N11: =IF(OR(L11="",COUNTIF($N$4:N10,V11*1)>=1),"-",V11*1) -> -
B12: 6 | C12: =IF(ISERROR(SMALL($N:$N,$B12)),"",SMALL($N:$N,$B12)) | D12: =IF(ISERROR(VLOOKUP($B$1&D$4&D$5&$C12,$L:$W,$C$5,0)),"",VLOOKUP($B$1&D$4&D$5&$C12,$L:$W,$C$5,0)) | E12: =IF(ISERROR(VLOOKUP($B$1&E$4&E$5&$C12,$L:$W,$C$5,0)),"",VLOOKUP($B$1&E$4&E$5&$C12,$L:$W,$C$5,0)) | F12: =IF(ISERROR(VLOOKUP($B$1&F$4&F$5&$C12,$L:$W,$C$5,0)),"",VLOOKUP($B$1&F$4&F$5&$C12,$L:$W,$C$5,0)) | G12: =IF(ISERROR(VLOOKUP($B$1&G$4&G$5&$C12,$L:$W,$C$5,0)),"",VLOOKUP($B$1&G$4&G$5&$C12,$L:$W,$C$5,0)) | H12: =IF(ISERROR(VLOOKUP($B$1&H$4&H$5&$C12,$L:$W,$C$5,0)),"",VLOOKUP($B$1&H$4&H$5&$C12,$L:$W,$C$5,0)) | I12: =IF(ISERROR(VLOOKUP($B$1&I$4&I$5&$C12,$L:$W,$C$5,0)),"",VLOOKUP($B$1&I$4&I$5&$C12,$L:$W,$C$5,0)) | L12: =IF(P12<>$B$1,"",P12&Q12&R12&V12) | M12: =IF(OR(L12="",COUNTIF($M$4:M11,IF(ISERROR($R12*1),LEFT($R12,2)*1,$R12*1))>=1),"-",IF(ISERROR($R12*1),LEFT($R12,2)*1,$R12*1)) -> - | N12: =IF(OR(L12="",COUNTIF($N$4:N11,V12*1)>=1),"-",V12*1) -> -
B13: 7 | C13: =IF(ISERROR(SMALL($N:$N,$B13)),"",SMALL($N:$N,$B13)) | D13: =IF(ISERROR(VLOOKUP($B$1&D$4&D$5&$C13,$L:$W,$C$5,0)),"",VLOOKUP($B$1&D$4&D$5&$C13,$L:$W,$C$5,0)) | E13: =IF(ISERROR(VLOOKUP($B$1&E$4&E$5&$C13,$L:$W,$C$5,0)),"",VLOOKUP($B$1&E$4&E$5&$C13,$L:$W,$C$5,0)) | F13: =IF(ISERROR(VLOOKUP($B$1&F$4&F$5&$C13,$L:$W,$C$5,0)),"",VLOOKUP($B$1&F$4&F$5&$C13,$L:$W,$C$5,0)) | G13: =IF(ISERROR(VLOOKUP($B$1&G$4&G$5&$C13,$L:$W,$C$5,0)),"",VLOOKUP($B$1&G$4&G$5&$C13,$L:$W,$C$5,0)) | H13: =IF(ISERROR(VLOOKUP($B$1&H$4&H$5&$C13,$L:$W,$C$5,0)),"",VLOOKUP($B$1&H$4&H$5&$C13,$L:$W,$C$5,0)) | I13: =IF(ISERROR(VLOOKUP($B$1&I$4&I$5&$C13,$L:$W,$C$5,0)),"",VLOOKUP($B$1&I$4&I$5&$C13,$L:$W,$C$5,0)) | L13: =IF(P13<>$B$1,"",P13&Q13&R13&V13) | M13: =IF(OR(L13="",COUNTIF($M$4:M12,IF(ISERROR($R13*1),LEFT($R13,2)*1,$R13*1))>=1),"-",IF(ISERROR($R13*1),LEFT($R13,2)*1,$R13*1)) -> - | N13: =IF(OR(L13="",COUNTIF($N$4:N12,V13*1)>=1),"-",V13*1) -> -
B14: 8 | C14: =IF(ISERROR(SMALL($N:$N,$B14)),"",SMALL($N:$N,$B14)) | D14: =IF(ISERROR(VLOOKUP($B$1&D$4&D$5&$C14,$L:$W,$C$5,0)),"",VLOOKUP($B$1&D$4&D$5&$C14,$L:$W,$C$5,0)) | E14: =IF(ISERROR(VLOOKUP($B$1&E$4&E$5&$C14,$L:$W,$C$5,0)),"",VLOOKUP($B$1&E$4&E$5&$C14,$L:$W,$C$5,0)) | F14: =IF(ISERROR(VLOOKUP($B$1&F$4&F$5&$C14,$L:$W,$C$5,0)),"",VLOOKUP($B$1&F$4&F$5&$C14,$L:$W,$C$5,0)) | G14: =IF(ISERROR(VLOOKUP($B$1&G$4&G$5&$C14,$L:$W,$C$5,0)),"",VLOOKUP($B$1&G$4&G$5&$C14,$L:$W,$C$5,0)) | H14: =IF(ISERROR(VLOOKUP($B$1&H$4&H$5&$C14,$L:$W,$C$5,0)),"",VLOOKUP($B$1&H$4&H$5&$C14,$L:$W,$C$5,0)) | I14: =IF(ISERROR(VLOOKUP($B$1&I$4&I$5&$C14,$L:$W,$C$5,0)),"",VLOOKUP($B$1&I$4&I$5&$C14,$L:$W,$C$5,0)) | L14: =IF(P14<>$B$1,"",P14&Q14&R14&V14) | M14: =IF(OR(L14="",COUNTIF($M$4:M13,IF(ISERROR($R14*1),LEFT($R14,2)*1,$R14*1))>=1),"-",IF(ISERROR($R14*1),LEFT($R14,2)*1,$R14*1)) -> - | N14: =IF(OR(L14="",COUNTIF($N$4:N13,V14*1)>=1),"-",V14*1) -> -
C15: 以上區域為帶入列印頁範圍 | L15: =IF(P15<>$B$1,"",P15&Q15&R15&V15) | M15: =IF(OR(L15="",COUNTIF($M$4:M14,IF(ISERROR($R15*1),LEFT($R15,2)*1,$R15*1))>=1),"-",IF(ISERROR($R15*1),LEFT($R15,2)*1,$R15*1)) -> - | N15: =IF(OR(L15="",COUNTIF($N$4:N14,V15*1)>=1),"-",V15*1) -> -
L16: =IF(P16<>$B$1,"",P16&Q16&R16&V16) | M16: =IF(OR(L16="",COUNTIF($M$4:M15,IF(ISERROR($R16*1),LEFT($R16,2)*1,$R16*1))>=1),"-",IF(ISERROR($R16*1),LEFT($R16,2)*1,$R16*1)) -> - | N16: =IF(OR(L16="",COUNTIF($N$4:N15,V16*1)>=1),"-",V16*1) -> -
L17: =IF(P17<>$B$1,"",P17&Q17&R17&V17) | M17: =IF(OR(L17="",COUNTIF($M$4:M16,IF(ISERROR($R17*1),LEFT($R17,2)*1,$R17*1))>=1),"-",IF(ISERROR($R17*1),LEFT($R17,2)*1,$R17*1)) -> - | N17: =IF(OR(L17="",COUNTIF($N$4:N16,V17*1)>=1),"-",V17*1) -> -
L18: =IF(P18<>$B$1,"",P18&Q18&R18&V18) | M18: =IF(OR(L18="",COUNTIF($M$4:M17,IF(ISERROR($R18*1),LEFT($R18,2)*1,$R18*1))>=1),"-",IF(ISERROR($R18*1),LEFT($R18,2)*1,$R18*1)) -> - | N18: =IF(OR(L18="",COUNTIF($N$4:N17,V18*1)>=1),"-",V18*1) -> -
L19: =IF(P19<>$B$1,"",P19&Q19&R19&V19) | M19: =IF(OR(L19="",COUNTIF($M$4:M18,IF(ISERROR($R19*1),LEFT($R19,2)*1,$R19*1))>=1),"-",IF(ISERROR($R19*1),LEFT($R19,2)*1,$R19*1)) -> - | N19: =IF(OR(L19="",COUNTIF($N$4:N18,V19*1)>=1),"-",V19*1) -> -
L20: =IF(P20<>$B$1,"",P20&Q20&R20&V20) | M20: =IF(OR(L20="",COUNTIF($M$4:M19,IF(ISERROR($R20*1),LEFT($R20,2)*1,$R20*1))>=1),"-",IF(ISERROR($R20*1),LEFT($R20,2)*1,$R20*1)) -> - | N20: =IF(OR(L20="",COUNTIF($N$4:N19,V20*1)>=1),"-",V20*1) -> -
L21: =IF(P21<>$B$1,"",P21&Q21&R21&V21) | M21: =IF(OR(L21="",COUNTIF($M$4:M20,IF(ISERROR($R21*1),LEFT($R21,2)*1,$R21*1))>=1),"-",IF(ISERROR($R21*1),LEFT($R21,2)*1,$R21*1)) -> - | N21: =IF(OR(L21="",COUNTIF($N$4:N20,V21*1)>=1),"-",V21*1) -> -
L22: =IF(P22<>$B$1,"",P22&Q22&R22&V22) | M22: =IF(OR(L22="",COUNTIF($M$4:M21,IF(ISERROR($R22*1),LEFT($R22,2)*1,$R22*1))>=1),"-",IF(ISERROR($R22*1),LEFT($R22,2)*1,$R22*1)) -> - | N22: =IF(OR(L22="",COUNTIF($N$4:N21,V22*1)>=1),"-",V22*1) -> -
L23: =IF(P23<>$B$1,"",P23&Q23&R23&V23) | M23: =IF(OR(L23="",COUNTIF($M$4:M22,IF(ISERROR($R23*1),LEFT($R23,2)*1,$R23*1))>=1),"-",IF(ISERROR($R23*1),LEFT($R23,2)*1,$R23*1)) -> - | N23: =IF(OR(L23="",COUNTIF($N$4:N22,V23*1)>=1),"-",V23*1) -> -
L24: =IF(P24<>$B$1,"",P24&Q24&R24&V24) | M24: =IF(OR(L24="",COUNTIF($M$4:M23,IF(ISERROR($R24*1),LEFT($R24,2)*1,$R24*1))>=1),"-",IF(ISERROR($R24*1),LEFT($R24,2)*1,$R24*1)) -> - | N24: =IF(OR(L24="",COUNTIF($N$4:N23,V24*1)>=1),"-",V24*1) -> -
L25: =IF(P25<>$B$1,"",P25&Q25&R25&V25) | M25: =IF(OR(L25="",COUNTIF($M$4:M24,IF(ISERROR($R25*1),LEFT($R25,2)*1,$R25*1))>=1),"-",IF(ISERROR($R25*1),LEFT($R25,2)*1,$R25*1)) -> - | N25: =IF(OR(L25="",COUNTIF($N$4:N24,V25*1)>=1),"-",V25*1) -> -
L26: =IF(P26<>$B$1,"",P26&Q26&R26&V26) | M26: =IF(OR(L26="",COUNTIF($M$4:M25,IF(ISERROR($R26*1),LEFT($R26,2)*1,$R26*1))>=1),"-",IF(ISERROR($R26*1),LEFT($R26,2)*1,$R26*1)) -> - | N26: =IF(OR(L26="",COUNTIF($N$4:N25,V26*1)>=1),"-",V26*1) -> -
L27: =IF(P27<>$B$1,"",P27&Q27&R27&V27) | M27: =IF(OR(L27="",COUNTIF($M$4:M26,IF(ISERROR($R27*1),LEFT($R27,2)*1,$R27*1))>=1),"-",IF(ISERROR($R27*1),LEFT($R27,2)*1,$R27*1)) -> - | N27: =IF(OR(L27="",COUNTIF($N$4:N26,V27*1)>=1),"-",V27*1) -> -
... L339: =IF(P339<>$B$1,"",P339&Q339&R339&V339) | M339: =IF(OR(L339="",COUNTIF($M$4:M338,IF(ISERROR($R339*1),LEFT($R339,2)*1,$R339*1))>=1),"-",IF(ISERROR($R339*1),LEFT($R339,2)*1,$R339*1)) -> - | N339: =IF(OR(L339="",COUNTIF($N$4:N338,V339*1)>=1),"-",V339*1) -> -

Sheet P_DATA
A1: GP | B1: CLX | C1: 1150109 | J1: =B1&TEXT(F1,"00")&TEXT(H1,"00") -> CLX0000 | O1: =M1&TEXT(N1,"00") -> 00 | R1: EXP | S1: 1150109 | V1: =S1&TEXT(T1,"00")&TEXT(U1,"00") -> 11501090000 | EE1: DIE | EF1: 1150109 | EI1: =EF1&TEXT(EG1,"00")&TEXT(EH1,"00") -> 11501090000
A2: 版次 | B2: 商品代號 | C2: 職業等級 | D2: 年期 | E2: 保額代碼 | F2: 性別 | G2: 投保金額 | H2: 年齡 | I2: 繳費年度 | J2: =B2&TEXT(F2,"00")&TEXT(H2,"00") -> 商品代號性別年齡 | K2: 保費 | M2: 商品代號 | N2: 累計給付年度 | O2: =M2&TEXT(N2,"00") -> 商品代號累計給付年度 | P2: 給付數值 | R2: 版次 | S2: 商品代號 | T2: 性別 | U2: 年齡 | V2: =S2&TEXT(T2,"00")&TEXT(U2,"00") -> 商品代號性別年齡 | W2: 第1年祝壽保險金 | X2: 第2年祝壽保險金 | Y2: 第3年祝壽保險金 | Z2: 第4年祝壽保險金 | AA2: 第5年祝壽保險金 | AB2: 第6年祝壽保險金 | AC2: 第7年祝壽保險金 | AD2: 第8年祝壽保險金 | AE2: 第9年祝壽保險金 | AF2: 第10年祝壽保險金 | AG2: 第11年祝壽保險金 | AH2: 第12年祝壽保險金 | AI2: 第13年祝壽保險金 | AJ2: 第14年祝壽保險金 | AK2: 第15年祝壽保險金 | AL2: 第16年祝壽保險金 | AM2: 第17年祝壽保險金 | AN2: 第18年祝壽保險金 | AO2: 第19年祝壽保險金 | AP2: 第20年祝壽保險金 | AQ2: 第21年祝壽保險金 | AR2: 第22年祝壽保險金 | AS2: 第23年祝壽保險金 | AT2: 第24年祝壽保險金 | AU2: 第25年祝壽保險金 | AV2: 第26年祝壽保險金 | AW2: 第27年祝壽保險金 | AX2: 第28年祝壽保險金 | AY2: 第29年祝壽保險金 | AZ2: 第30年祝壽保險金 | BA2: 第31年祝壽保險金 | BB2: 第32年祝壽保險金 | BC2: 第33年祝壽保險金 | BD2: 第34年祝壽保險金 | BE2: 第35年祝壽保險金 | BF2: 第36年祝壽保險金 | BG2: 第37年祝壽保險金 | BH2: 第38年祝壽保險金 | BI2: 第39年祝壽保險金 | BJ2: 第40年祝壽保險金 | BK2: 第41年祝壽保險金 | BL2: 第42年祝壽保險金 | BM2: 第43年祝壽保險金 | BN2: 第44年祝壽保險金 | BO2: 第45年祝壽保險金 | BP2: 第46年祝壽保險金 | BQ2: 第47年祝壽保險金 | BR2: 第48年祝壽保險金 | BS2: 第49年祝壽保險金 | BT2: 第50年祝壽保險金 | BU2: 第51年祝壽保險金 | BV2: 第52年祝壽保險金 | BW2: 第53年祝壽保險金 | BX2: 第54年祝壽保險金 | BY2: 第55年祝壽保險金 | BZ2: 第56年祝壽保險金 | CA2: 第57年祝壽保險金 | CB2: 第58年祝壽保險金 | CC2: 第59年祝壽保險金 | CD2: 第60年祝壽保險金 | CE2: 第61年祝壽保險金 | CF2: 第62年祝壽保險金 | CG2: 第63年祝壽保險金 | CH2: 第64年祝壽保險金 | CI2: 第65年祝壽保險金 | CJ2: 第66年祝壽保險金 | CK2: 第67年祝壽保險金 | CL2: 第68年祝壽保險金 | CM2: 第69年祝壽保險金 | CN2: 第70年祝壽保險金 | CO2: 第71年祝壽保險金 | CP2: 第72年祝壽保險金 | CQ2: 第73年祝壽保險金 | CR2: 第74年祝壽保險金 | CS2: 第75年祝壽保險金 | CT2: 第76年祝壽保險金 | CU2: 第77年祝壽保險金 | CV2: 第78年祝壽保險金 | CW2: 第79年祝壽保險金 | CX2: 第80年祝壽保險金 | CY2: 第81年祝壽保險金 | CZ2: 第82年祝壽保險金 | DA2: 第83年祝壽保險金 | DB2: 第84年祝壽保險金 | DC2: 第85年祝壽保險金 | DD2: 第86年祝壽保險金 | DE2: 第87年祝壽保險金 | DF2: 第88年祝壽保險金 | DG2: 第89年祝壽保險金 | DH2: 第90年祝壽保險金 | DI2: 第91年祝壽保險金 | DJ2: 第92年祝壽保險金 | DK2: 第93年祝壽保險金 | DL2: 第94年祝壽保險金 | DM2: 第95年祝壽保險金 | DN2: 第96年祝壽保險金 | DO2: 第97年祝壽保險金 | DP2: 第98年祝壽保險金 | DQ2: 第99年祝壽保險金 | DR2: 第100年祝壽保險金 | DS2: 第101年祝壽保險金 | DT2: 第102年祝壽保險金 | DU2: 第103年祝壽保險金 | DV2: 第104年祝壽保險金 | DW2: 第105年祝壽保險金 | DX2: 第106年祝壽保險金 | DY2: 第107年祝壽保險金 | DZ2: 第108年祝壽保險金 | EA2: 第109年祝壽保險金 | EB2: 第110年祝壽保險金 | EC2: 第111年祝壽保險金 | EE2: 版次 | EF2: 商品代號 | EG2: 性別 | EH2: 年齡 | EI2: =EF2&TEXT(EG2,"00")&TEXT(EH2,"00") -> 商品代號性別年齡 | EJ2: 第1年身故保險金 | EK2: 第2年身故保險金 | EL2: 第3年身故保險金 | EM2: 第4年身故保險金 | EN2: 第5年身故保險金 | EO2: 第6年身故保險金 | EP2: 第7年身故保險金 | EQ2: 第8年身故保險金 | ER2: 第9年身故保險金 | ES2: 第10年身故保險金 | ET2: 第11年身故保險金 | EU2: 第12年身故保險金 | EV2: 第13年身故保險金 | EW2: 第14年身故保險金 | EX2: 第15年身故保險金 | EY2: 第16年身故保險金 | EZ2: 第17年身故保險金 | FA2: 第18年身故保險金 | FB2: 第19年身故保險金 | FC2: 第20年身故保險金 | FD2: 第21年身故保險金 | FE2: 第22年身故保險金 | FF2: 第23年身故保險金 | FG2: 第24年身故保險金 | FH2: 第25年身故保險金 | FI2: 第26年身故保險金 | FJ2: 第27年身故保險金 | FK2: 第28年身故保險金 | FL2: 第29年身故保險金 | FM2: 第30年身故保險金 | FN2: 第31年身故保險金 | FO2: 第32年身故保險金 | FP2: 第33年身故保險金 | FQ2: 第34年身故保險金 | FR2: 第35年身故保險金 | FS2: 第36年身故保險金 | FT2: 第37年身故保險金 | FU2: 第38年身故保險金 | FV2: 第39年身故保險金 | FW2: 第40年身故保險金 | FX2: 第41年身故保險金 | FY2: 第42年身故保險金 | FZ2: 第43年身故保險金 | GA2: 第44年身故保險金 | GB2: 第45年身故保險金 | GC2: 第46年身故保險金 | GD2: 第47年身故保險金 | GE2: 第48年身故保險金 | GF2: 第49年身故保險金 | GG2: 第50年身故保險金 | GH2: 第51年身故保險金 | GI2: 第52年身故保險金 | GJ2: 第53年身故保險金 | GK2: 第54年身故保險金 | GL2: 第55年身故保險金 | GM2: 第56年身故保險金 | GN2: 第57年身故保險金 | GO2: 第58年身故保險金 | GP2: 第59年身故保險金 | GQ2: 第60年身故保險金 | GR2: 第61年身故保險金 | GS2: 第62年身故保險金 | GT2: 第63年身故保險金 | GU2: 第64年身故保險金 | GV2: 第65年身故保險金 | GW2: 第66年身故保險金 | GX2: 第67年身故保險金 | GY2: 第68年身故保險金 | GZ2: 第69年身故保險金 | HA2: 第70年身故保險金 | HB2: 第71年身故保險金 | HC2: 第72年身故保險金 | HD2: 第73年身故保險金 | HE2: 第74年身故保險金額 | HF2: 第75年身故保險金 | HG2: 第76年身故保險金 | HH2: 第77年身故保險金 | HI2: 第78年身故保險金 | HJ2: 第79年身故保險金 | HK2: 第80年身故保險金 | HL2: 第81年身故保險金 | HM2: 第82年身故保險金 | HN2: 第83年身故保險金 | HO2: 第84年身故保險金 | HP2: 第85年身故保險金 | HQ2: 第86年身故保險金 | HR2: 第87年身故保險金 | HS2: 第88年身故保險金 | HT2: 第89年身故保險金 | HU2: 第90年身故保險金 | HV2: 第91年身故保險金 | HW2: 第92年身故保險金 | HX2: 第93年身故保險金 | HY2: 第94年身故保險金 | HZ2: 第95年身故保險金 | IA2: 第96年身故保險金 | IB2: 第97年身故保險金 | IC2: 第98年身故保險金 | ID2: 第99年身故保險金 | IE2: 第100年身故保險金 | IF2: 第101年身故保險金 | IG2: 第102年身故保險金 | IH2: 第103年身故保險金 | II2: 第104年身故保險金 | IJ2: 第105年身故保險金 | IK2: 第106年身故保險金 | IL2: 第107年身故保險金 | IM2: 第108年身故保險金 | IN2: 第109年身故保險金 | IO2: 第110年身故保險金 | IP2: 第111年身故保險金
A3: 55 | B3: CLX10 | F3: 2 | H3: 18 | J3: =B3&TEXT(F3,"00")&TEXT(H3,"00") -> CLX100218 | K3: 435 | R3: 55 | S3: CLX10 | T3: 2 | U3: 18 | V3: =S3&TEXT(T3,"00")&TEXT(U3,"00") -> CLX100218 | W3: 0 | X3: 0 | Y3: 0 | Z3: 0 | AA3: 0 | AB3: 0 | AC3: 0 | AD3: 0 | AE3: 0 | AF3: 0 | AG3: 0 | AH3: 0 | AI3: 0 | AJ3: 0 | AK3: 0 | AL3: 0 | AM3: 0 | AN3: 0 | AO3: 0 | AP3: 0 | AQ3: 0 | AR3: 0 | AS3: 0 | AT3: 0 | AU3: 0 | AV3: 0 | AW3: 0 | AX3: 0 | AY3: 0 | AZ3: 0 | BA3: 0 | BB3: 0 | BC3: 0 | BD3: 0 | BE3: 0 | BF3: 0 | BG3: 0 | BH3: 0 | BI3: 0 | BJ3: 0 | BK3: 0 | BL3: 0 | BM3: 0 | BN3: 0 | BO3: 0 | BP3: 0 | BQ3: 0 | BR3: 0 | BS3: 0 | BT3: 0 | BU3: 0 | BV3: 0 | BW3: 0 | BX3: 0 | BY3: 0 | BZ3: 0 | CA3: 0 | CB3: 0 | CC3: 0 | CD3: 0 | CE3: 0 | CF3: 0 | CG3: 0 | CH3: 0 | CI3: 0 | CJ3: 0 | CK3: 0 | CL3: 0 | CM3: 0 | CN3: 0 | CO3: 0 | CP3: 4611 | CQ3: 0 | CR3: 0 | CS3: 0 | CT3: 0 | CU3: 0 | CV3: 0 | CW3: 0 | CX3: 0 | CY3: 0 | CZ3: 0 | DA3: 0 | DB3: 0 | DC3: 0 | DD3: 0 | DE3: 0 | DF3: 0 | DG3: 0 | DH3: 0 | DI3: 0 | DJ3: 0 | DK3: 0 | DL3: 0 | DM3: 0 | DN3: 0 | DO3: 0 | DP3: 0 | DQ3: 0 | DR3: 0 | DS3: 0 | DT3: 0 | DU3: 0 | DV3: 0 | EE3: 55 | EF3: CLX10 | EG3: 2 | EH3: 18 | EI3: =EF3&TEXT(EG3,"00")&TEXT(EH3,"00") -> CLX100218 | EJ3: 461.1 | EK3: 922.2 | EL3: 1383.3 | EM3: 1844.4 | EN3: 2305.5 | EO3: 2766.6 | EP3: 3227.7 | EQ3: 3688.8 | ER3: 4149.9 | ES3: 4611 | ET3: 4611 | EU3: 4611 | EV3: 4611 | EW3: 4611 | EX3: 4611 | EY3: 4611 | EZ3: 4611 | FA3: 4611 | FB3: 4611 | FC3: 4611 | FD3: 4611 | FE3: 4611 | FF3: 4611 | FG3: 4611 | FH3: 4611 | FI3: 4611 | FJ3: 4611 | FK3: 4611 | FL3: 4611 | FM3: 4611 | FN3: 4611 | FO3: 4611 | FP3: 4611 | FQ3: 4611 | FR3: 4611 | FS3: 4611 | FT3: 4611 | FU3: 4611 | FV3: 4611 | FW3: 4611 | FX3: 4611 | FY3: 4611 | FZ3: 4611 | GA3: 4611 | GB3: 4611 | GC3: 4611 | GD3: 4611 | GE3: 4611 | GF3: 4611 | GG3: 4611 | GH3: 4611 | GI3: 4611 | GJ3: 4611 | GK3: 4611 | GL3: 4611 | GM3: 4611 | GN3: 4611 | GO3: 4611 | GP3: 4611 | GQ3: 4611 | GR3: 4611 | GS3: 4611 | GT3: 4611 | GU3: 4611 | GV3: 4611 | GW3: 4611 | GX3: 4611 | GY3: 4611 | GZ3: 4611 | HA3: 4611 | HB3: 4611 | HC3: 4611 | HD3: 0 | HE3: 0 | HF3: 0 | HG3: 0 | HH3: 0 | HI3: 0 | HJ3: 0 | HK3: 0 | HL3: 0 | HM3: 0 | HN3: 0 | HO3: 0 | HP3: 0 | HQ3: 0 | HR3: 0 | HS3: 0 | HT3: 0 | HU3: 0 | HV3: 0 | HW3: 0 | HX3: 0 | HY3: 0 | HZ3: 0 | IA3: 0 | IB3: 0 | IC3: 0 | ID3: 0 | IE3: 0 | IF3: 0 | IG3: 0 | IH3: 0 | II3: 0 | IJ3: 0 | IK3: 0 | IL3: 0 | IM3: 0 | IN3: 0 | IO3: 0 | IP3: 0
A4: 55 | B4: CLX10 | F4: 2 | H4: 19 | J4: =B4&TEXT(F4,"00")&TEXT(H4,"00") -> CLX100219 | K4: 440 | R4: 55 | S4: CLX10 | T4: 2 | U4: 19 | V4: =S4&TEXT(T4,"00")&TEXT(U4,"00") -> CLX100219 | W4: 0 | X4: 0 | Y4: 0 | Z4: 0 | AA4: 0 | AB4: 0 | AC4: 0 | AD4: 0 | AE4: 0 | AF4: 0 | AG4: 0 | AH4: 0 | AI4: 0 | AJ4: 0 | AK4: 0 | AL4: 0 | AM4: 0 | AN4: 0 | AO4: 0 | AP4: 0 | AQ4: 0 | AR4: 0 | AS4: 0 | AT4: 0 | AU4: 0 | AV4: 0 | AW4: 0 | AX4: 0 | AY4: 0 | AZ4: 0 | BA4: 0 | BB4: 0 | BC4: 0 | BD4: 0 | BE4: 0 | BF4: 0 | BG4: 0 | BH4: 0 | BI4: 0 | BJ4: 0 | BK4: 0 | BL4: 0 | BM4: 0 | BN4: 0 | BO4: 0 | BP4: 0 | BQ4: 0 | BR4: 0 | BS4: 0 | BT4: 0 | BU4: 0 | BV4: 0 | BW4: 0 | BX4: 0 | BY4: 0 | BZ4: 0 | CA4: 0 | CB4: 0 | CC4: 0 | CD4: 0 | CE4: 0 | CF4: 0 | CG4: 0 | CH4: 0 | CI4: 0 | CJ4: 0 | CK4: 0 | CL4: 0 | CM4: 0 | CN4: 0 | CO4: 4664 | CP4: 0 | CQ4: 0 | CR4: 0 | CS4: 0 | CT4: 0 | CU4: 0 | CV4: 0 | CW4: 0 | CX4: 0 | CY4: 0 | CZ4: 0 | DA4: 0 | DB4: 0 | DC4: 0 | DD4: 0 | DE4: 0 | DF4: 0 | DG4: 0 | DH4: 0 | DI4: 0 | DJ4: 0 | DK4: 0 | DL4: 0 | DM4: 0 | DN4: 0 | DO4: 0 | DP4: 0 | DQ4: 0 | DR4: 0 | DS4: 0 | DT4: 0 | DU4: 0 | DV4: 0 | EE4: 55 | EF4: CLX10 | EG4: 2 | EH4: 19 | EI4: =EF4&TEXT(EG4,"00")&TEXT(EH4,"00") -> CLX100219 | EJ4: 466.4 | EK4: 932.8 | EL4: 1399.2 | EM4: 1865.6 | EN4: 2332 | EO4: 2798.4 | EP4: 3264.8 | EQ4: 3731.2 | ER4: 4197.6 | ES4: 4664 | ET4: 4664 | EU4: 4664 | EV4: 4664 | EW4: 4664 | EX4: 4664 | EY4: 4664 | EZ4: 4664 | FA4: 4664 | FB4: 4664 | FC4: 4664 | FD4: 4664 | FE4: 4664 | FF4: 4664 | FG4: 4664 | FH4: 4664 | FI4: 4664 | FJ4: 4664 | FK4: 4664 | FL4: 4664 | FM4: 4664 | FN4: 4664 | FO4: 4664 | FP4: 4664 | FQ4: 4664 | FR4: 4664 | FS4: 4664 | FT4: 4664 | FU4: 4664 | FV4: 4664 | FW4: 4664 | FX4: 4664 | FY4: 4664 | FZ4: 4664 | GA4: 4664 | GB4: 4664 | GC4: 4664 | GD4: 4664 | GE4: 4664 | GF4: 4664 | GG4: 4664 | GH4: 4664 | GI4: 4664 | GJ4: 4664 | GK4: 4664 | GL4: 4664 | GM4: 4664 | GN4: 4664 | GO4: 4664 | GP4: 4664 | GQ4: 4664 | GR4: 4664 | GS4: 4664 | GT4: 4664 | GU4: 4664 | GV4: 4664 | GW4: 4664 | GX4: 4664 | GY4: 4664 | GZ4: 4664 | HA4: 4664 | HB4: 4664 | HC4: 0 | HD4: 0 | HE4: 0 | HF4: 0 | HG4: 0 | HH4: 0 | HI4: 0 | HJ4: 0 | HK4: 0 | HL4: 0 | HM4: 0 | HN4: 0 | HO4: 0 | HP4: 0 | HQ4: 0 | HR4: 0 | HS4: 0 | HT4: 0 | HU4: 0 | HV4: 0 | HW4: 0 | HX4: 0 | HY4: 0 | HZ4: 0 | IA4: 0 | IB4: 0 | IC4: 0 | ID4: 0 | IE4: 0 | IF4: 0 | IG4: 0 | IH4: 0 | II4: 0 | IJ4: 0 | IK4: 0 | IL4: 0 | IM4: 0 | IN4: 0 | IO4: 0 | IP4: 0
A5: 55 | B5: CLX10 | F5: 2 | H5: 20 | J5: =B5&TEXT(F5,"00")&TEXT(H5,"00") -> CLX100220 | K5: 445 | R5: 55 | S5: CLX10 | T5: 2 | U5: 20 | V5: =S5&TEXT(T5,"00")&TEXT(U5,"00") -> CLX100220 | W5: 0 | X5: 0 | Y5: 0 | Z5: 0 | AA5: 0 | AB5: 0 | AC5: 0 | AD5: 0 | AE5: 0 | AF5: 0 | AG5: 0 | AH5: 0 | AI5: 0 | AJ5: 0 | AK5: 0 | AL5: 0 | AM5: 0 | AN5: 0 | AO5: 0 | AP5: 0 | AQ5: 0 | AR5: 0 | AS5: 0 | AT5: 0 | AU5: 0 | AV5: 0 | AW5: 0 | AX5: 0 | AY5: 0 | AZ5: 0 | BA5: 0 | BB5: 0 | BC5: 0 | BD5: 0 | BE5: 0 | BF5: 0 | BG5: 0 | BH5: 0 | BI5: 0 | BJ5: 0 | BK5: 0 | BL5: 0 | BM5: 0 | BN5: 0 | BO5: 0 | BP5: 0 | BQ5: 0 | BR5: 0 | BS5: 0 | BT5: 0 | BU5: 0 | BV5: 0 | BW5: 0 | BX5: 0 | BY5: 0 | BZ5: 0 | CA5: 0 | CB5: 0 | CC5: 0 | CD5: 0 | CE5: 0 | CF5: 0 | CG5: 0 | CH5: 0 | CI5: 0 | CJ5: 0 | CK5: 0 | CL5: 0 | CM5: 0 | CN5: 4717 | CO5: 0 | CP5: 0 | CQ5: 0 | CR5: 0 | CS5: 0 | CT5: 0 | CU5: 0 | CV5: 0 | CW5: 0 | CX5: 0 | CY5: 0 | CZ5: 0 | DA5: 0 | DB5: 0 | DC5: 0 | DD5: 0 | DE5: 0 | DF5: 0 | DG5: 0 | DH5: 0 | DI5: 0 | DJ5: 0 | DK5: 0 | DL5: 0 | DM5: 0 | DN5: 0 | DO5: 0 | DP5: 0 | DQ5: 0 | DR5: 0 | DS5: 0 | DT5: 0 | DU5: 0 | DV5: 0 | EE5: 55 | EF5: CLX10 | EG5: 2 | EH5: 20 | EI5: =EF5&TEXT(EG5,"00")&TEXT(EH5,"00") -> CLX100220 | EJ5: 471.7 | EK5: 943.4 | EL5: 1415.1 | EM5: 1886.8 | EN5: 2358.5 | EO5: 2830.2 | EP5: 3301.9 | EQ5: 3773.6 | ER5: 4245.3 | ES5: 4717 | ET5: 4717 | EU5: 4717 | EV5: 4717 | EW5: 4717 | EX5: 4717 | EY5: 4717 | EZ5: 4717 | FA5: 4717 | FB5: 4717 | FC5: 4717 | FD5: 4717 | FE5: 4717 | FF5: 4717 | FG5: 4717 | FH5: 4717 | FI5: 4717 | FJ5: 4717 | FK5: 4717 | FL5: 4717 | FM5: 4717 | FN5: 4717 | FO5: 4717 | FP5: 4717 | FQ5: 4717 | FR5: 4717 | FS5: 4717 | FT5: 4717 | FU5: 4717 | FV5: 4717 | FW5: 4717 | FX5: 4717 | FY5: 4717 | FZ5: 4717 | GA5: 4717 | GB5: 4717 | GC5: 4717 | GD5: 4717 | GE5: 4717 | GF5: 4717 | GG5: 4717 | GH5: 4717 | GI5: 4717 | GJ5: 4717 | GK5: 4717 | GL5: 4717 | GM5: 4717 | GN5: 4717 | GO5: 4717 | GP5: 4717 | GQ5: 4717 | GR5: 4717 | GS5: 4717 | GT5: 4717 | GU5: 4717 | GV5: 4717 | GW5: 4717 | GX5: 4717 | GY5: 4717 | GZ5: 4717 | HA5: 4717 | HB5: 0 | HC5: 0 | HD5: 0 | HE5: 0 | HF5: 0 | HG5: 0 | HH5: 0 | HI5: 0 | HJ5: 0 | HK5: 0 | HL5: 0 | HM5: 0 | HN5: 0 | HO5: 0 | HP5: 0 | HQ5: 0 | HR5: 0 | HS5: 0 | HT5: 0 | HU5: 0 | HV5: 0 | HW5: 0 | HX5: 0 | HY5: 0 | HZ5: 0 | IA5: 0 | IB5: 0 | IC5: 0 | ID5: 0 | IE5: 0 | IF5: 0 | IG5: 0 | IH5: 0 | II5: 0 | IJ5: 0 | IK5: 0 | IL5: 0 | IM5: 0 | IN5: 0 | IO5: 0 | IP5: 0
A6: 55 | B6: CLX10 | F6: 2 | H6: 21 | J6: =B6&TEXT(F6,"00")&TEXT(H6,"00") -> CLX100221 | K6: 450 | R6: 55 | S6: CLX10 | T6: 2 | U6: 21 | V6: =S6&TEXT(T6,"00")&TEXT(U6,"00") -> CLX100221 | W6: 0 | X6: 0 | Y6: 0 | Z6: 0 | AA6: 0 | AB6: 0 | AC6: 0 | AD6: 0 | AE6: 0 | AF6: 0 | AG6: 0 | AH6: 0 | AI6: 0 | AJ6: 0 | AK6: 0 | AL6: 0 | AM6: 0 | AN6: 0 | AO6: 0 | AP6: 0 | AQ6: 0 | AR6: 0 | AS6: 0 | AT6: 0 | AU6: 0 | AV6: 0 | AW6: 0 | AX6: 0 | AY6: 0 | AZ6: 0 | BA6: 0 | BB6: 0 | BC6: 0 | BD6: 0 | BE6: 0 | BF6: 0 | BG6: 0 | BH6: 0 | BI6: 0 | BJ6: 0 | BK6: 0 | BL6: 0 | BM6: 0 | BN6: 0 | BO6: 0 | BP6: 0 | BQ6: 0 | BR6: 0 | BS6: 0 | BT6: 0 | BU6: 0 | BV6: 0 | BW6: 0 | BX6: 0 | BY6: 0 | BZ6: 0 | CA6: 0 | CB6: 0 | CC6: 0 | CD6: 0 | CE6: 0 | CF6: 0 | CG6: 0 | CH6: 0 | CI6: 0 | CJ6: 0 | CK6: 0 | CL6: 0 | CM6: 4770 | CN6: 0 | CO6: 0 | CP6: 0 | CQ6: 0 | CR6: 0 | CS6: 0 | CT6: 0 | CU6: 0 | CV6: 0 | CW6: 0 | CX6: 0 | CY6: 0 | CZ6: 0 | DA6: 0 | DB6: 0 | DC6: 0 | DD6: 0 | DE6: 0 | DF6: 0 | DG6: 0 | DH6: 0 | DI6: 0 | DJ6: 0 | DK6: 0 | DL6: 0 | DM6: 0 | DN6: 0 | DO6: 0 | DP6: 0 | DQ6: 0 | DR6: 0 | DS6: 0 | DT6: 0 | DU6: 0 | DV6: 0 | EE6: 55 | EF6: CLX10 | EG6: 2 | EH6: 21 | EI6: =EF6&TEXT(EG6,"00")&TEXT(EH6,"00") -> CLX100221 | EJ6: 477 | EK6: 954 | EL6: 1431 | EM6: 1908 | EN6: 2385 | EO6: 2862 | EP6: 3339 | EQ6: 3816 | ER6: 4293 | ES6: 4770 | ET6: 4770 | EU6: 4770 | EV6: 4770 | EW6: 4770 | EX6: 4770 | EY6: 4770 | EZ6: 4770 | FA6: 4770 | FB6: 4770 | FC6: 4770 | FD6: 4770 | FE6: 4770 | FF6: 4770 | FG6: 4770 | FH6: 4770 | FI6: 4770 | FJ6: 4770 | FK6: 4770 | FL6: 4770 | FM6: 4770 | FN6: 4770 | FO6: 4770 | FP6: 4770 | FQ6: 4770 | FR6: 4770 | FS6: 4770 | FT6: 4770 | FU6: 4770 | FV6: 4770 | FW6: 4770 | FX6: 4770 | FY6: 4770 | FZ6: 4770 | GA6: 4770 | GB6: 4770 | GC6: 4770 | GD6: 4770 | GE6: 4770 | GF6: 4770 | GG6: 4770 | GH6: 4770 | GI6: 4770 | GJ6: 4770 | GK6: 4770 | GL6: 4770 | GM6: 4770 | GN6: 4770 | GO6: 4770 | GP6: 4770 | GQ6: 4770 | GR6: 4770 | GS6: 4770 | GT6: 4770 | GU6: 4770 | GV6: 4770 | GW6: 4770 | GX6: 4770 | GY6: 4770 | GZ6: 4770 | HA6: 0 | HB6: 0 | HC6: 0 | HD6: 0 | HE6: 0 | HF6: 0 | HG6: 0 | HH6: 0 | HI6: 0 | HJ6: 0 | HK6: 0 | HL6: 0 | HM6: 0 | HN6: 0 | HO6: 0 | HP6: 0 | HQ6: 0 | HR6: 0 | HS6: 0 | HT6: 0 | HU6: 0 | HV6: 0 | HW6: 0 | HX6: 0 | HY6: 0 | HZ6: 0 | IA6: 0 | IB6: 0 | IC6: 0 | ID6: 0 | IE6: 0 | IF6: 0 | IG6: 0 | IH6: 0 | II6: 0 | IJ6: 0 | IK6: 0 | IL6: 0 | IM6: 0 | IN6: 0 | IO6: 0 | IP6: 0
A7: 55 | B7: CLX10 | F7: 2 | H7: 22 | J7: =B7&TEXT(F7,"00")&TEXT(H7,"00") -> CLX100222 | K7: 455 | R7: 55 | S7: CLX10 | T7: 2 | U7: 22 | V7: =S7&TEXT(T7,"00")&TEXT(U7,"00") -> CLX100222 | W7: 0 | X7: 0 | Y7: 0 | Z7: 0 | AA7: 0 | AB7: 0 | AC7: 0 | AD7: 0 | AE7: 0 | AF7: 0 | AG7: 0 | AH7: 0 | AI7: 0 | AJ7: 0 | AK7: 0 | AL7: 0 | AM7: 0 | AN7: 0 | AO7: 0 | AP7: 0 | AQ7: 0 | AR7: 0 | AS7: 0 | AT7: 0 | AU7: 0 | AV7: 0 | AW7: 0 | AX7: 0 | AY7: 0 | AZ7: 0 | BA7: 0 | BB7: 0 | BC7: 0 | BD7: 0 | BE7: 0 | BF7: 0 | BG7: 0 | BH7: 0 | BI7: 0 | BJ7: 0 | BK7: 0 | BL7: 0 | BM7: 0 | BN7: 0 | BO7: 0 | BP7: 0 | BQ7: 0 | BR7: 0 | BS7: 0 | BT7: 0 | BU7: 0 | BV7: 0 | BW7: 0 | BX7: 0 | BY7: 0 | BZ7: 0 | CA7: 0 | CB7: 0 | CC7: 0 | CD7: 0 | CE7: 0 | CF7: 0 | CG7: 0 | CH7: 0 | CI7: 0 | CJ7: 0 | CK7: 0 | CL7: 4823 | CM7: 0 | CN7: 0 | CO7: 0 | CP7: 0 | CQ7: 0 | CR7: 0 | CS7: 0 | CT7: 0 | CU7: 0 | CV7: 0 | CW7: 0 | CX7: 0 | CY7: 0 | CZ7: 0 | DA7: 0 | DB7: 0 | DC7: 0 | DD7: 0 | DE7: 0 | DF7: 0 | DG7: 0 | DH7: 0 | DI7: 0 | DJ7: 0 | DK7: 0 | DL7: 0 | DM7: 0 | DN7: 0 | DO7: 0 | DP7: 0 | DQ7: 0 | DR7: 0 | DS7: 0 | DT7: 0 | DU7: 0 | DV7: 0 | EE7: 55 | EF7: CLX10 | EG7: 2 | EH7: 22 | EI7: =EF7&TEXT(EG7,"00")&TEXT(EH7,"00") -> CLX100222 | EJ7: 482.3 | EK7: 964.6 | EL7: 1446.9 | EM7: 1929.2 | EN7: 2411.5 | EO7: 2893.8 | EP7: 3376.1 | EQ7: 3858.4 | ER7: 4340.7 | ES7: 4823 | ET7: 4823 | EU7: 4823 | EV7: 4823 | EW7: 4823 | EX7: 4823 | EY7: 4823 | EZ7: 4823 | FA7: 4823 | FB7: 4823 | FC7: 4823 | FD7: 4823 | FE7: 4823 | FF7: 4823 | FG7: 4823 | FH7: 4823 | FI7: 4823 | FJ7: 4823 | FK7: 4823 | FL7: 4823 | FM7: 4823 | FN7: 4823 | FO7: 4823 | FP7: 4823 | FQ7: 4823 | FR7: 4823 | FS7: 4823 | FT7: 4823 | FU7: 4823 | FV7: 4823 | FW7: 4823 | FX7: 4823 | FY7: 4823 | FZ7: 4823 | GA7: 4823 | GB7: 4823 | GC7: 4823 | GD7: 4823 | GE7: 4823 | GF7: 4823 | GG7: 4823 | GH7: 4823 | GI7: 4823 | GJ7: 4823 | GK7: 4823 | GL7: 4823 | GM7: 4823 | GN7: 4823 | GO7: 4823 | GP7: 4823 | GQ7: 4823 | GR7: 4823 | GS7: 4823 | GT7: 4823 | GU7: 4823 | GV7: 4823 | GW7: 4823 | GX7: 4823 | GY7: 4823 | GZ7: 0 | HA7: 0 | HB7: 0 | HC7: 0 | HD7: 0 | HE7: 0 | HF7: 0 | HG7: 0 | HH7: 0 | HI7: 0 | HJ7: 0 | HK7: 0 | HL7: 0 | HM7: 0 | HN7: 0 | HO7: 0 | HP7: 0 | HQ7: 0 | HR7: 0 | HS7: 0 | HT7: 0 | HU7: 0 | HV7: 0 | HW7: 0 | HX7: 0 | HY7: 0 | HZ7: 0 | IA7: 0 | IB7: 0 | IC7: 0 | ID7: 0 | IE7: 0 | IF7: 0 | IG7: 0 | IH7: 0 | II7: 0 | IJ7: 0 | IK7: 0 | IL7: 0 | IM7: 0 | IN7: 0 | IO7: 0 | IP7: 0
A8: 55 | B8: CLX10 | F8: 2 | H8: 23 | J8: =B8&TEXT(F8,"00")&TEXT(H8,"00") -> CLX100223 | K8: 460 | R8: 55 | S8: CLX10 | T8: 2 | U8: 23 | V8: =S8&TEXT(T8,"00")&TEXT(U8,"00") -> CLX100223 | W8: 0 | X8: 0 | Y8: 0 | Z8: 0 | AA8: 0 | AB8: 0 | AC8: 0 | AD8: 0 | AE8: 0 | AF8: 0 | AG8: 0 | AH8: 0 | AI8: 0 | AJ8: 0 | AK8: 0 | AL8: 0 | AM8: 0 | AN8: 0 | AO8: 0 | AP8: 0 | AQ8: 0 | AR8: 0 | AS8: 0 | AT8: 0 | AU8: 0 | AV8: 0 | AW8: 0 | AX8: 0 | AY8: 0 | AZ8: 0 | BA8: 0 | BB8: 0 | BC8: 0 | BD8: 0 | BE8: 0 | BF8: 0 | BG8: 0 | BH8: 0 | BI8: 0 | BJ8: 0 | BK8: 0 | BL8: 0 | BM8: 0 | BN8: 0 | BO8: 0 | BP8: 0 | BQ8: 0 | BR8: 0 | BS8: 0 | BT8: 0 | BU8: 0 | BV8: 0 | BW8: 0 | BX8: 0 | BY8: 0 | BZ8: 0 | CA8: 0 | CB8: 0 | CC8: 0 | CD8: 0 | CE8: 0 | CF8: 0 | CG8: 0 | CH8: 0 | CI8: 0 | CJ8: 0 | CK8: 4876 | CL8: 0 | CM8: 0 | CN8: 0 | CO8: 0 | CP8: 0 | CQ8: 0 | CR8: 0 | CS8: 0 | CT8: 0 | CU8: 0 | CV8: 0 | CW8: 0 | CX8: 0 | CY8: 0 | CZ8: 0 | DA8: 0 | DB8: 0 | DC8: 0 | DD8: 0 | DE8: 0 | DF8: 0 | DG8: 0 | DH8: 0 | DI8: 0 | DJ8: 0 | DK8: 0 | DL8: 0 | DM8: 0 | DN8: 0 | DO8: 0 | DP8: 0 | DQ8: 0 | DR8: 0 | DS8: 0 | DT8: 0 | DU8: 0 | DV8: 0 | EE8: 55 | EF8: CLX10 | EG8: 2 | EH8: 23 | EI8: =EF8&TEXT(EG8,"00")&TEXT(EH8,"00") -> CLX100223 | EJ8: 487.6 | EK8: 975.2 | EL8: 1462.8 | EM8: 1950.4 | EN8: 2438 | EO8: 2925.6 | EP8: 3413.2 | EQ8: 3900.8 | ER8: 4388.4 | ES8: 4876 | ET8: 4876 | EU8: 4876 | EV8: 4876 | EW8: 4876 | EX8: 4876 | EY8: 4876 | EZ8: 4876 | FA8: 4876 | FB8: 4876 | FC8: 4876 | FD8: 4876 | FE8: 4876 | FF8: 4876 | FG8: 4876 | FH8: 4876 | FI8: 4876 | FJ8: 4876 | FK8: 4876 | FL8: 4876 | FM8: 4876 | FN8: 4876 | FO8: 4876 | FP8: 4876 | FQ8: 4876 | FR8: 4876 | FS8: 4876 | FT8: 4876 | FU8: 4876 | FV8: 4876 | FW8: 4876 | FX8: 4876 | FY8: 4876 | FZ8: 4876 | GA8: 4876 | GB8: 4876 | GC8: 4876 | GD8: 4876 | GE8: 4876 | GF8: 4876 | GG8: 4876 | GH8: 4876 | GI8: 4876 | GJ8: 4876 | GK8: 4876 | GL8: 4876 | GM8: 4876 | GN8: 4876 | GO8: 4876 | GP8: 4876 | GQ8: 4876 | GR8: 4876 | GS8: 4876 | GT8: 4876 | GU8: 4876 | GV8: 4876 | GW8: 4876 | GX8: 4876 | GY8: 0 | GZ8: 0 | HA8: 0 | HB8: 0 | HC8: 0 | HD8: 0 | HE8: 0 | HF8: 0 | HG8: 0 | HH8: 0 | HI8: 0 | HJ8: 0 | HK8: 0 | HL8: 0 | HM8: 0 | HN8: 0 | HO8: 0 | HP8: 0 | HQ8: 0 | HR8: 0 | HS8: 0 | HT8: 0 | HU8: 0 | HV8: 0 | HW8: 0 | HX8: 0 | HY8: 0 | HZ8: 0 | IA8: 0 | IB8: 0 | IC8: 0 | ID8: 0 | IE8: 0 | IF8: 0 | IG8: 0 | IH8: 0 | II8: 0 | IJ8: 0 | IK8: 0 | IL8: 0 | IM8: 0 | IN8: 0 | IO8: 0 | IP8: 0
A9: 55 | B9: CLX10 | F9: 2 | H9: 24 | J9: =B9&TEXT(F9,"00")&TEXT(H9,"00") -> CLX100224 | K9: 465 | R9: 55 | S9: CLX10 | T9: 2 | U9: 24 | V9: =S9&TEXT(T9,"00")&TEXT(U9,"00") -> CLX100224 | W9: 0 | X9: 0 | Y9: 0 | Z9: 0 | AA9: 0 | AB9: 0 | AC9: 0 | AD9: 0 | AE9: 0 | AF9: 0 | AG9: 0 | AH9: 0 | AI9: 0 | AJ9: 0 | AK9: 0 | AL9: 0 | AM9: 0 | AN9: 0 | AO9: 0 | AP9: 0 | AQ9: 0 | AR9: 0 | AS9: 0 | AT9: 0 | AU9: 0 | AV9: 0 | AW9: 0 | AX9: 0 | AY9: 0 | AZ9: 0 | BA9: 0 | BB9: 0 | BC9: 0 | BD9: 0 | BE9: 0 | BF9: 0 | BG9: 0 | BH9: 0 | BI9: 0 | BJ9: 0 | BK9: 0 | BL9: 0 | BM9: 0 | BN9: 0 | BO9: 0 | BP9: 0 | BQ9: 0 | BR9: 0 | BS9: 0 | BT9: 0 | BU9: 0 | BV9: 0 | BW9: 0 | BX9: 0 | BY9: 0 | BZ9: 0 | CA9: 0 | CB9: 0 | CC9: 0 | CD9: 0 | CE9: 0 | CF9: 0 | CG9: 0 | CH9: 0 | CI9: 0 | CJ9: 4929 | CK9: 0 | CL9: 0 | CM9: 0 | CN9: 0 | CO9: 0 | CP9: 0 | CQ9: 0 | CR9: 0 | CS9: 0 | CT9: 0 | CU9: 0 | CV9: 0 | CW9: 0 | CX9: 0 | CY9: 0 | CZ9: 0 | DA9: 0 | DB9: 0 | DC9: 0 | DD9: 0 | DE9: 0 | DF9: 0 | DG9: 0 | DH9: 0 | DI9: 0 | DJ9: 0 | DK9: 0 | DL9: 0 | DM9: 0 | DN9: 0 | DO9: 0 | DP9: 0 | DQ9: 0 | DR9: 0 | DS9: 0 | DT9: 0 | DU9: 0 | DV9: 0 | EE9: 55 | EF9: CLX10 | EG9: 2 | EH9: 24 | EI9: =EF9&TEXT(EG9,"00")&TEXT(EH9,"00") -> CLX100224 | EJ9: 492.9 | EK9: 985.8 | EL9: 1478.7 | EM9: 1971.6 | EN9: 2464.5 | EO9: 2957.4 | EP9: 3450.3 | EQ9: 3943.2 | ER9: 4436.1 | ES9: 4929 | ET9: 4929 | EU9: 4929 | EV9: 4929 | EW9: 4929 | EX9: 4929 | EY9: 4929 | EZ9: 4929 | FA9: 4929 | FB9: 4929 | FC9: 4929 | FD9: 4929 | FE9: 4929 | FF9: 4929 | FG9: 4929 | FH9: 4929 | FI9: 4929 | FJ9: 4929 | FK9: 4929 | FL9: 4929 | FM9: 4929 | FN9: 4929 | FO9: 4929 | FP9: 4929 | FQ9: 4929 | FR9: 4929 | FS9: 4929 | FT9: 4929 | FU9: 4929 | FV9: 4929 | FW9: 4929 | FX9: 4929 | FY9: 4929 | FZ9: 4929 | GA9: 4929 | GB9: 4929 | GC9: 4929 | GD9: 4929 | GE9: 4929 | GF9: 4929 | GG9: 4929 | GH9: 4929 | GI9: 4929 | GJ9: 4929 | GK9: 4929 | GL9: 4929 | GM9: 4929 | GN9: 4929 | GO9: 4929 | GP9: 4929 | GQ9: 4929 | GR9: 4929 | GS9: 4929 | GT9: 4929 | GU9: 4929 | GV9: 4929 | GW9: 4929 | GX9: 0 | GY9: 0 | GZ9: 0 | HA9: 0 | HB9: 0 | HC9: 0 | HD9: 0 | HE9: 0 | HF9: 0 | HG9: 0 | HH9: 0 | HI9: 0 | HJ9: 0 | HK9: 0 | HL9: 0 | HM9: 0 | HN9: 0 | HO9: 0 | HP9: 0 | HQ9: 0 | HR9: 0 | HS9: 0 | HT9: 0 | HU9: 0 | HV9: 0 | HW9: 0 | HX9: 0 | HY9: 0 | HZ9: 0 | IA9: 0 | IB9: 0 | IC9: 0 | ID9: 0 | IE9: 0 | IF9: 0 | IG9: 0 | IH9: 0 | II9: 0 | IJ9: 0 | IK9: 0 | IL9: 0 | IM9: 0 | IN9: 0 | IO9: 0 | IP9: 0
A10: 55 | B10: CLX10 | F10: 2 | H10: 25 | J10: =B10&TEXT(F10,"00")&TEXT(H10,"00") -> CLX100225 | K10: 470 | R10: 55 | S10: CLX10 | T10: 2 | U10: 25 | V10: =S10&TEXT(T10,"00")&TEXT(U10,"00") -> CLX100225 | W10: 0 | X10: 0 | Y10: 0 | Z10: 0 | AA10: 0 | AB10: 0 | AC10: 0 | AD10: 0 | AE10: 0 | AF10: 0 | AG10: 0 | AH10: 0 | AI10: 0 | AJ10: 0 | AK10: 0 | AL10: 0 | AM10: 0 | AN10: 0 | AO10: 0 | AP10: 0 | AQ10: 0 | AR10: 0 | AS10: 0 | AT10: 0 | AU10: 0 | AV10: 0 | AW10: 0 | AX10: 0 | AY10: 0 | AZ10: 0 | BA10: 0 | BB10: 0 | BC10: 0 | BD10: 0 | BE10: 0 | BF10: 0 | BG10: 0 | BH10: 0 | BI10: 0 | BJ10: 0 | BK10: 0 | BL10: 0 | BM10: 0 | BN10: 0 | BO10: 0 | BP10: 0 | BQ10: 0 | BR10: 0 | BS10: 0 | BT10: 0 | BU10: 0 | BV10: 0 | BW10: 0 | BX10: 0 | BY10: 0 | BZ10: 0 | CA10: 0 | CB10: 0 | CC10: 0 | CD10: 0 | CE10: 0 | CF10: 0 | CG10: 0 | CH10: 0 | CI10: 4982 | CJ10: 0 | CK10: 0 | CL10: 0 | CM10: 0 | CN10: 0 | CO10: 0 | CP10: 0 | CQ10: 0 | CR10: 0 | CS10: 0 | CT10: 0 | CU10: 0 | CV10: 0 | CW10: 0 | CX10: 0 | CY10: 0 | CZ10: 0 | DA10: 0 | DB10: 0 | DC10: 0 | DD10: 0 | DE10: 0 | DF10: 0 | DG10: 0 | DH10: 0 | DI10: 0 | DJ10: 0 | DK10: 0 | DL10: 0 | DM10: 0 | DN10: 0 | DO10: 0 | DP10: 0 | DQ10: 0 | DR10: 0 | DS10: 0 | DT10: 0 | DU10: 0 | DV10: 0 | EE10: 55 | EF10: CLX10 | EG10: 2 | EH10: 25 | EI10: =EF10&TEXT(EG10,"00")&TEXT(EH10,"00") -> CLX100225 | EJ10: 498.2 | EK10: 996.4 | EL10: 1494.6 | EM10: 1992.8 | EN10: 2491 | EO10: 2989.2 | EP10: 3487.4 | EQ10: 3985.6 | ER10: 4483.8 | ES10: 4982 | ET10: 4982 | EU10: 4982 | EV10: 4982 | EW10: 4982 | EX10: 4982 | EY10: 4982 | EZ10: 4982 | FA10: 4982 | FB10: 4982 | FC10: 4982 | FD10: 4982 | FE10: 4982 | FF10: 4982 | FG10: 4982 | FH10: 4982 | FI10: 4982 | FJ10: 4982 | FK10: 4982 | FL10: 4982 | FM10: 4982 | FN10: 4982 | FO10: 4982 | FP10: 4982 | FQ10: 4982 | FR10: 4982 | FS10: 4982 | FT10: 4982 | FU10: 4982 | FV10: 4982 | FW10: 4982 | FX10: 4982 | FY10: 4982 | FZ10: 4982 | GA10: 4982 | GB10: 4982 | GC10: 4982 | GD10: 4982 | GE10: 4982 | GF10: 4982 | GG10: 4982 | GH10: 4982 | GI10: 4982 | GJ10: 4982 | GK10: 4982 | GL10: 4982 | GM10: 4982 | GN10: 4982 | GO10: 4982 | GP10: 4982 | GQ10: 4982 | GR10: 4982 | GS10: 4982 | GT10: 4982 | GU10: 4982 | GV10: 4982 | GW10: 0 | GX10: 0 | GY10: 0 | GZ10: 0 | HA10: 0 | HB10: 0 | HC10: 0 | HD10: 0 | HE10: 0 | HF10: 0 | HG10: 0 | HH10: 0 | HI10: 0 | HJ10: 0 | HK10: 0 | HL10: 0 | HM10: 0 | HN10: 0 | HO10: 0 | HP10: 0 | HQ10: 0 | HR10: 0 | HS10: 0 | HT10: 0 | HU10: 0 | HV10: 0 | HW10: 0 | HX10: 0 | HY10: 0 | HZ10: 0 | IA10: 0 | IB10: 0 | IC10: 0 | ID10: 0 | IE10: 0 | IF10: 0 | IG10: 0 | IH10: 0 | II10: 0 | IJ10: 0 | IK10: 0 | IL10: 0 | IM10: 0 | IN10: 0 | IO10: 0 | IP10: 0
A11: 55 | B11: CLX10 | F11: 2 | H11: 26 | J11: =B11&TEXT(F11,"00")&TEXT(H11,"00") -> CLX100226 | K11: 480 | R11: 55 | S11: CLX10 | T11: 2 | U11: 26 | V11: =S11&TEXT(T11,"00")&TEXT(U11,"00") -> CLX100226 | W11: 0 | X11: 0 | Y11: 0 | Z11: 0 | AA11: 0 | AB11: 0 | AC11: 0 | AD11: 0 | AE11: 0 | AF11: 0 | AG11: 0 | AH11: 0 | AI11: 0 | AJ11: 0 | AK11: 0 | AL11: 0 | AM11: 0 | AN11: 0 | AO11: 0 | AP11: 0 | AQ11: 0 | AR11: 0 | AS11: 0 | AT11: 0 | AU11: 0 | AV11: 0 | AW11: 0 | AX11: 0 | AY11: 0 | AZ11: 0 | BA11: 0 | BB11: 0 | BC11: 0 | BD11: 0 | BE11: 0 | BF11: 0 | BG11: 0 | BH11: 0 | BI11: 0 | BJ11: 0 | BK11: 0 | BL11: 0 | BM11: 0 | BN11: 0 | BO11: 0 | BP11: 0 | BQ11: 0 | BR11: 0 | BS11: 0 | BT11: 0 | BU11: 0 | BV11: 0 | BW11: 0 | BX11: 0 | BY11: 0 | BZ11: 0 | CA11: 0 | CB11: 0 | CC11: 0 | CD11: 0 | CE11: 0 | CF11: 0 | CG11: 0 | CH11: 5088 | CI11: 0 | CJ11: 0 | CK11: 0 | CL11: 0 | CM11: 0 | CN11: 0 | CO11: 0 | CP11: 0 | CQ11: 0 | CR11: 0 | CS11: 0 | CT11: 0 | CU11: 0 | CV11: 0 | CW11: 0 | CX11: 0 | CY11: 0 | CZ11: 0 | DA11: 0 | DB11: 0 | DC11: 0 | DD11: 0 | DE11: 0 | DF11: 0 | DG11: 0 | DH11: 0 | DI11: 0 | DJ11: 0 | DK11: 0 | DL11: 0 | DM11: 0 | DN11: 0 | DO11: 0 | DP11: 0 | DQ11: 0 | DR11: 0 | DS11: 0 | DT11: 0 | DU11: 0 | DV11: 0 | EE11: 55 | EF11: CLX10 | EG11: 2 | EH11: 26 | EI11: =EF11&TEXT(EG11,"00")&TEXT(EH11,"00") -> CLX100226 | EJ11: 508.8 | EK11: 1017.6 | EL11: 1526.4 | EM11: 2035.2 | EN11: 2544 | EO11: 3052.8 | EP11: 3561.6 | EQ11: 4070.4 | ER11: 4579.2 | ES11: 5088 | ET11: 5088 | EU11: 5088 | EV11: 5088 | EW11: 5088 | EX11: 5088 | EY11: 5088 | EZ11: 5088 | FA11: 5088 | FB11: 5088 | FC11: 5088 | FD11: 5088 | FE11: 5088 | FF11: 5088 | FG11: 5088 | FH11: 5088 | FI11: 5088 | FJ11: 5088 | FK11: 5088 | FL11: 5088 | FM11: 5088 | FN11: 5088 | FO11: 5088 | FP11: 5088 | FQ11: 5088 | FR11: 5088 | FS11: 5088 | FT11: 5088 | FU11: 5088 | FV11: 5088 | FW11: 5088 | FX11: 5088 | FY11: 5088 | FZ11: 5088 | GA11: 5088 | GB11: 5088 | GC11: 5088 | GD11: 5088 | GE11: 5088 | GF11: 5088 | GG11: 5088 | GH11: 5088 | GI11: 5088 | GJ11: 5088 | GK11: 5088 | GL11: 5088 | GM11: 5088 | GN11: 5088 | GO11: 5088 | GP11: 5088 | GQ11: 5088 | GR11: 5088 | GS11: 5088 | GT11: 5088 | GU11: 5088 | GV11: 0 | GW11: 0 | GX11: 0 | GY11: 0 | GZ11: 0 | HA11: 0 | HB11: 0 | HC11: 0 | HD11: 0 | HE11: 0 | HF11: 0 | HG11: 0 | HH11: 0 | HI11: 0 | HJ11: 0 | HK11: 0 | HL11: 0 | HM11: 0 | HN11: 0 | HO11: 0 | HP11: 0 | HQ11: 0 | HR11: 0 | HS11: 0 | HT11: 0 | HU11: 0 | HV11: 0 | HW11: 0 | HX11: 0 | HY11: 0 | HZ11: 0 | IA11: 0 | IB11: 0 | IC11: 0 | ID11: 0 | IE11: 0 | IF11: 0 | IG11: 0 | IH11: 0 | II11: 0 | IJ11: 0 | IK11: 0 | IL11: 0 | IM11: 0 | IN11: 0 | IO11: 0 | IP11: 0
A12: 55 | B12: CLX10 | F12: 2 | H12: 27 | J12: =B12&TEXT(F12,"00")&TEXT(H12,"00") -> CLX100227 | K12: 490 | R12: 55 | S12: CLX10 | T12: 2 | U12: 27 | V12: =S12&TEXT(T12,"00")&TEXT(U12,"00") -> CLX100227 | W12: 0 | X12: 0 | Y12: 0 | Z12: 0 | AA12: 0 | AB12: 0 | AC12: 0 | AD12: 0 | AE12: 0 | AF12: 0 | AG12: 0 | AH12: 0 | AI12: 0 | AJ12: 0 | AK12: 0 | AL12: 0 | AM12: 0 | AN12: 0 | AO12: 0 | AP12: 0 | AQ12: 0 | AR12: 0 | AS12: 0 | AT12: 0 | AU12: 0 | AV12: 0 | AW12: 0 | AX12: 0 | AY12: 0 | AZ12: 0 | BA12: 0 | BB12: 0 | BC12: 0 | BD12: 0 | BE12: 0 | BF12: 0 | BG12: 0 | BH12: 0 | BI12: 0 | BJ12: 0 | BK12: 0 | BL12: 0 | BM12: 0 | BN12: 0 | BO12: 0 | BP12: 0 | BQ12: 0 | BR12: 0 | BS12: 0 | BT12: 0 | BU12: 0 | BV12: 0 | BW12: 0 | BX12: 0 | BY12: 0 | BZ12: 0 | CA12: 0 | CB12: 0 | CC12: 0 | CD12: 0 | CE12: 0 | CF12: 0 | CG12: 5194 | CH12: 0 | CI12: 0 | CJ12: 0 | CK12: 0 | CL12: 0 | CM12: 0 | CN12: 0 | CO12: 0 | CP12: 0 | CQ12: 0 | CR12: 0 | CS12: 0 | CT12: 0 | CU12: 0 | CV12: 0 | CW12: 0 | CX12: 0 | CY12: 0 | CZ12: 0 | DA12: 0 | DB12: 0 | DC12: 0 | DD12: 0 | DE12: 0 | DF12: 0 | DG12: 0 | DH12: 0 | DI12: 0 | DJ12: 0 | DK12: 0 | DL12: 0 | DM12: 0 | DN12: 0 | DO12: 0 | DP12: 0 | DQ12: 0 | DR12: 0 | DS12: 0 | DT12: 0 | DU12: 0 | DV12: 0 | EE12: 55 | EF12: CLX10 | EG12: 2 | EH12: 27 | EI12: =EF12&TEXT(EG12,"00")&TEXT(EH12,"00") -> CLX100227 | EJ12: 519.4 | EK12: 1038.8 | EL12: 1558.2 | EM12: 2077.6 | EN12: 2597 | EO12: 3116.4 | EP12: 3635.8 | EQ12: 4155.2 | ER12: 4674.6 | ES12: 5194 | ET12: 5194 | EU12: 5194 | EV12: 5194 | EW12: 5194 | EX12: 5194 | EY12: 5194 | EZ12: 5194 | FA12: 5194 | FB12: 5194 | FC12: 5194 | FD12: 5194 | FE12: 5194 | FF12: 5194 | FG12: 5194 | FH12: 5194 | FI12: 5194 | FJ12: 5194 | FK12: 5194 | FL12: 5194 | FM12: 5194 | FN12: 5194 | FO12: 5194 | FP12: 5194 | FQ12: 5194 | FR12: 5194 | FS12: 5194 | FT12: 5194 | FU12: 5194 | FV12: 5194 | FW12: 5194 | FX12: 5194 | FY12: 5194 | FZ12: 5194 | GA12: 5194 | GB12: 5194 | GC12: 5194 | GD12: 5194 | GE12: 5194 | GF12: 5194 | GG12: 5194 | GH12: 5194 | GI12: 5194 | GJ12: 5194 | GK12: 5194 | GL12: 5194 | GM12: 5194 | GN12: 5194 | GO12: 5194 | GP12: 5194 | GQ12: 5194 | GR12: 5194 | GS12: 5194 | GT12: 5194 | GU12: 0 | GV12: 0 | GW12: 0 | GX12: 0 | GY12: 0 | GZ12: 0 | HA12: 0 | HB12: 0 | HC12: 0 | HD12: 0 | HE12: 0 | HF12: 0 | HG12: 0 | HH12: 0 | HI12: 0 | HJ12: 0 | HK12: 0 | HL12: 0 | HM12: 0 | HN12: 0 | HO12: 0 | HP12: 0 | HQ12: 0 | HR12: 0 | HS12: 0 | HT12: 0 | HU12: 0 | HV12: 0 | HW12: 0 | HX12: 0 | HY12: 0 | HZ12: 0 | IA12: 0 | IB12: 0 | IC12: 0 | ID12: 0 | IE12: 0 | IF12: 0 | IG12: 0 | IH12: 0 | II12: 0 | IJ12: 0 | IK12: 0 | IL12: 0 | IM12: 0 | IN12: 0 | IO12: 0 | IP12: 0
A13: 55 | B13: CLX10 | F13: 2 | H13: 28 | J13: =B13&TEXT(F13,"00")&TEXT(H13,"00") -> CLX100228 | K13: 500 | R13: 55 | S13: CLX10 | T13: 2 | U13: 28 | V13: =S13&TEXT(T13,"00")&TEXT(U13,"00") -> CLX100228 | W13: 0 | X13: 0 | Y13: 0 | Z13: 0 | AA13: 0 | AB13: 0 | AC13: 0 | AD13: 0 | AE13: 0 | AF13: 0 | AG13: 0 | AH13: 0 | AI13: 0 | AJ13: 0 | AK13: 0 | AL13: 0 | AM13: 0 | AN13: 0 | AO13: 0 | AP13: 0 | AQ13: 0 | AR13: 0 | AS13: 0 | AT13: 0 | AU13: 0 | AV13: 0 | AW13: 0 | AX13: 0 | AY13: 0 | AZ13: 0 | BA13: 0 | BB13: 0 | BC13: 0 | BD13: 0 | BE13: 0 | BF13: 0 | BG13: 0 | BH13: 0 | BI13: 0 | BJ13: 0 | BK13: 0 | BL13: 0 | BM13: 0 | BN13: 0 | BO13: 0 | BP13: 0 | BQ13: 0 | BR13: 0 | BS13: 0 | BT13: 0 | BU13: 0 | BV13: 0 | BW13: 0 | BX13: 0 | BY13: 0 | BZ13: 0 | CA13: 0 | CB13: 0 | CC13: 0 | CD13: 0 | CE13: 0 | CF13: 5300 | CG13: 0 | CH13: 0 | CI13: 0 | CJ13: 0 | CK13: 0 | CL13: 0 | CM13: 0 | CN13: 0 | CO13: 0 | CP13: 0 | CQ13: 0 | CR13: 0 | CS13: 0 | CT13: 0 | CU13: 0 | CV13: 0 | CW13: 0 | CX13: 0 | CY13: 0 | CZ13: 0 | DA13: 0 | DB13: 0 | DC13: 0 | DD13: 0 | DE13: 0 | DF13: 0 | DG13: 0 | DH13: 0 | DI13: 0 | DJ13: 0 | DK13: 0 | DL13: 0 | DM13: 0 | DN13: 0 | DO13: 0 | DP13: 0 | DQ13: 0 | DR13: 0 | DS13: 0 | DT13: 0 | DU13: 0 | DV13: 0 | EE13: 55 | EF13: CLX10 | EG13: 2 | EH13: 28 | EI13: =EF13&TEXT(EG13,"00")&TEXT(EH13,"00") -> CLX100228 | EJ13: 530 | EK13: 1060 | EL13: 1590 | EM13: 2120 | EN13: 2650 | EO13: 3180 | EP13: 3710 | EQ13: 4240 | ER13: 4770 | ES13: 5300 | ET13: 5300 | EU13: 5300 | EV13: 5300 | EW13: 5300 | EX13: 5300 | EY13: 5300 | EZ13: 5300 | FA13: 5300 | FB13: 5300 | FC13: 5300 | FD13: 5300 | FE13: 5300 | FF13: 5300 | FG13: 5300 | FH13: 5300 | FI13: 5300 | FJ13: 5300 | FK13: 5300 | FL13: 5300 | FM13: 5300 | FN13: 5300 | FO13: 5300 | FP13: 5300 | FQ13: 5300 | FR13: 5300 | FS13: 5300 | FT13: 5300 | FU13: 5300 | FV13: 5300 | FW13: 5300 | FX13: 5300 | FY13: 5300 | FZ13: 5300 | GA13: 5300 | GB13: 5300 | GC13: 5300 | GD13: 5300 | GE13: 5300 | GF13: 5300 | GG13: 5300 | GH13: 5300 | GI13: 5300 | GJ13: 5300 | GK13: 5300 | GL13: 5300 | GM13: 5300 | GN13: 5300 | GO13: 5300 | GP13: 5300 | GQ13: 5300 | GR13: 5300 | GS13: 5300 | GT13: 0 | GU13: 0 | GV13: 0 | GW13: 0 | GX13: 0 | GY13: 0 | GZ13: 0 | HA13: 0 | HB13: 0 | HC13: 0 | HD13: 0 | HE13: 0 | HF13: 0 | HG13: 0 | HH13: 0 | HI13: 0 | HJ13: 0 | HK13: 0 | HL13: 0 | HM13: 0 | HN13: 0 | HO13: 0 | HP13: 0 | HQ13: 0 | HR13: 0 | HS13: 0 | HT13: 0 | HU13: 0 | HV13: 0 | HW13: 0 | HX13: 0 | HY13: 0 | HZ13: 0 | IA13: 0 | IB13: 0 | IC13: 0 | ID13: 0 | IE13: 0 | IF13: 0 | IG13: 0 | IH13: 0 | II13: 0 | IJ13: 0 | IK13: 0 | IL13: 0 | IM13: 0 | IN13: 0 | IO13: 0 | IP13: 0
A14: 55 | B14: CLX10 | F14: 2 | H14: 29 | J14: =B14&TEXT(F14,"00")&TEXT(H14,"00") -> CLX100229 | K14: 510 | R14: 55 | S14: CLX10 | T14: 2 | U14: 29 | V14: =S14&TEXT(T14,"00")&TEXT(U14,"00") -> CLX100229 | W14: 0 | X14: 0 | Y14: 0 | Z14: 0 | AA14: 0 | AB14: 0 | AC14: 0 | AD14: 0 | AE14: 0 | AF14: 0 | AG14: 0 | AH14: 0 | AI14: 0 | AJ14: 0 | AK14: 0 | AL14: 0 | AM14: 0 | AN14: 0 | AO14: 0 | AP14: 0 | AQ14: 0 | AR14: 0 | AS14: 0 | AT14: 0 | AU14: 0 | AV14: 0 | AW14: 0 | AX14: 0 | AY14: 0 | AZ14: 0 | BA14: 0 | BB14: 0 | BC14: 0 | BD14: 0 | BE14: 0 | BF14: 0 | BG14: 0 | BH14: 0 | BI14: 0 | BJ14: 0 | BK14: 0 | BL14: 0 | BM14: 0 | BN14: 0 | BO14: 0 | BP14: 0 | BQ14: 0 | BR14: 0 | BS14: 0 | BT14: 0 | BU14: 0 | BV14: 0 | BW14: 0 | BX14: 0 | BY14: 0 | BZ14: 0 | CA14: 0 | CB14: 0 | CC14: 0 | CD14: 0 | CE14: 5406 | CF14: 0 | CG14: 0 | CH14: 0 | CI14: 0 | CJ14: 0 | CK14: 0 | CL14: 0 | CM14: 0 | CN14: 0 | CO14: 0 | CP14: 0 | CQ14: 0 | CR14: 0 | CS14: 0 | CT14: 0 | CU14: 0 | CV14: 0 | CW14: 0 | CX14: 0 | CY14: 0 | CZ14: 0 | DA14: 0 | DB14: 0 | DC14: 0 | DD14: 0 | DE14: 0 | DF14: 0 | DG14: 0 | DH14: 0 | DI14: 0 | DJ14: 0 | DK14: 0 | DL14: 0 | DM14: 0 | DN14: 0 | DO14: 0 | DP14: 0 | DQ14: 0 | DR14: 0 | DS14: 0 | DT14: 0 | DU14: 0 | DV14: 0 | EE14: 55 | EF14: CLX10 | EG14: 2 | EH14: 29 | EI14: =EF14&TEXT(EG14,"00")&TEXT(EH14,"00") -> CLX100229 | EJ14: 540.6 | EK14: 1081.2 | EL14: 1621.8 | EM14: 2162.4 | EN14: 2703 | EO14: 3243.6 | EP14: 3784.2 | EQ14: 4324.8 | ER14: 4865.4 | ES14: 5406 | ET14: 5406 | EU14: 5406 | EV14: 5406 | EW14: 5406 | EX14: 5406 | EY14: 5406 | EZ14: 5406 | FA14: 5406 | FB14: 5406 | FC14: 5406 | FD14: 5406 | FE14: 5406 | FF14: 5406 | FG14: 5406 | FH14: 5406 | FI14: 5406 | FJ14: 5406 | FK14: 5406 | FL14: 5406 | FM14: 5406 | FN14: 5406 | FO14: 5406 | FP14: 5406 | FQ14: 5406 | FR14: 5406 | FS14: 5406 | FT14: 5406 | FU14: 5406 | FV14: 5406 | FW14: 5406 | FX14: 5406 | FY14: 5406 | FZ14: 5406 | GA14: 5406 | GB14: 5406 | GC14: 5406 | GD14: 5406 | GE14: 5406 | GF14: 5406 | GG14: 5406 | GH14: 5406 | GI14: 5406 | GJ14: 5406 | GK14: 5406 | GL14: 5406 | GM14: 5406 | GN14: 5406 | GO14: 5406 | GP14: 5406 | GQ14: 5406 | GR14: 5406 | GS14: 0 | GT14: 0 | GU14: 0 | GV14: 0 | GW14: 0 | GX14: 0 | GY14: 0 | GZ14: 0 | HA14: 0 | HB14: 0 | HC14: 0 | HD14: 0 | HE14: 0 | HF14: 0 | HG14: 0 | HH14: 0 | HI14: 0 | HJ14: 0 | HK14: 0 | HL14: 0 | HM14: 0 | HN14: 0 | HO14: 0 | HP14: 0 | HQ14: 0 | HR14: 0 | HS14: 0 | HT14: 0 | HU14: 0 | HV14: 0 | HW14: 0 | HX14: 0 | HY14: 0 | HZ14: 0 | IA14: 0 | IB14: 0 | IC14: 0 | ID14: 0 | IE14: 0 | IF14: 0 | IG14: 0 | IH14: 0 | II14: 0 | IJ14: 0 | IK14: 0 | IL14: 0 | IM14: 0 | IN14: 0 | IO14: 0 | IP14: 0
... A78: 55 | B78: CLX20 | F78: 2 | H78: 50 | J78: =B78&TEXT(F78,"00")&TEXT(H78,"00") -> CLX200250 | K78: 470 | R78: 55 | S78: CLX20 | T78: 2 | U78: 50 | V78: =S78&TEXT(T78,"00")&TEXT(U78,"00") -> CLX200250 | W78: 0 | X78: 0 | Y78: 0 | Z78: 0 | AA78: 0 | AB78: 0 | AC78: 0 | AD78: 0 | AE78: 0 | AF78: 0 | AG78: 0 | AH78: 0 | AI78: 0 | AJ78: 0 | AK78: 0 | AL78: 0 | AM78: 0 | AN78: 0 | AO78: 0 | AP78: 0 | AQ78: 0 | AR78: 0 | AS78: 0 | AT78: 0 | AU78: 0 | AV78: 0 | AW78: 0 | AX78: 0 | AY78: 0 | AZ78: 0 | BA78: 0 | BB78: 0 | BC78: 0 | BD78: 0 | BE78: 0 | BF78: 0 | BG78: 0 | BH78: 0 | BI78: 0 | BJ78: 9964 | BK78: 0 | BL78: 0 | BM78: 0 | BN78: 0 | BO78: 0 | BP78: 0 | BQ78: 0 | BR78: 0 | BS78: 0 | BT78: 0 | BU78: 0 | BV78: 0 | BW78: 0 | BX78: 0 | BY78: 0 | BZ78: 0 | CA78: 0 | CB78: 0 | CC78: 0 | CD78: 0 | CE78: 0 | CF78: 0 | CG78: 0 | CH78: 0 | CI78: 0 | CJ78: 0 | CK78: 0 | CL78: 0 | CM78: 0 | CN78: 0 | CO78: 0 | CP78: 0 | CQ78: 0 | CR78: 0 | CS78: 0 | CT78: 0 | CU78: 0 | CV78: 0 | CW78: 0 | CX78: 0 | CY78: 0 | CZ78: 0 | DA78: 0 | DB78: 0 | DC78: 0 | DD78: 0 | DE78: 0 | DF78: 0 | DG78: 0 | DH78: 0 | DI78: 0 | DJ78: 0 | DK78: 0 | DL78: 0 | DM78: 0 | DN78: 0 | DO78: 0 | DP78: 0 | DQ78: 0 | DR78: 0 | DS78: 0 | DT78: 0 | DU78: 0 | DV78: 0 | EE78: 55 | EF78: CLX20 | EG78: 2 | EH78: 50 | EI78: =EF78&TEXT(EG78,"00")&TEXT(EH78,"00") -> CLX200250 | EJ78: 498.2 | EK78: 996.4 | EL78: 1494.6 | EM78: 1992.8 | EN78: 2491 | EO78: 2989.2 | EP78: 3487.4 | EQ78: 3985.6 | ER78: 4483.8 | ES78: 4982 | ET78: 5480.2 | EU78: 5978.4 | EV78: 6476.6 | EW78: 6974.8 | EX78: 7473 | EY78: 7971.2 | EZ78: 8469.4 | FA78: 8967.6 | FB78: 9465.8 | FC78: 9964 | FD78: 9964 | FE78: 9964 | FF78: 9964 | FG78: 9964 | FH78: 9964 | FI78: 9964 | FJ78: 9964 | FK78: 9964 | FL78: 9964 | FM78: 9964 | FN78: 9964 | FO78: 9964 | FP78: 9964 | FQ78: 9964 | FR78: 9964 | FS78: 9964 | FT78: 9964 | FU78: 9964 | FV78: 9964 | FW78: 9964 | FX78: 0 | FY78: 0 | FZ78: 0 | GA78: 0 | GB78: 0 | GC78: 0 | GD78: 0 | GE78: 0 | GF78: 0 | GG78: 0 | GH78: 0 | GI78: 0 | GJ78: 0 | GK78: 0 | GL78: 0 | GM78: 0 | GN78: 0 | GO78: 0 | GP78: 0 | GQ78: 0 | GR78: 0 | GS78: 0 | GT78: 0 | GU78: 0 | GV78: 0 | GW78: 0 | GX78: 0 | GY78: 0 | GZ78: 0 | HA78: 0 | HB78: 0 | HC78: 0 | HD78: 0 | HE78: 0 | HF78: 0 | HG78: 0 | HH78: 0 | HI78: 0 | HJ78: 0 | HK78: 0 | HL78: 0 | HM78: 0 | HN78: 0 | HO78: 0 | HP78: 0 | HQ78: 0 | HR78: 0 | HS78: 0 | HT78: 0 | HU78: 0 | HV78: 0 | HW78: 0 | HX78: 0 | HY78: 0 | HZ78: 0 | IA78: 0 | IB78: 0 | IC78: 0 | ID78: 0 | IE78: 0 | IF78: 0 | IG78: 0 | IH78: 0 | II78: 0 | IJ78: 0 | IK78: 0 | IL78: 0 | IM78: 0 | IN78: 0 | IO78: 0 | IP78: 0
R272: CV | V272: =S272&TEXT(T272,"00")&TEXT(U272,"00") -> 0000 | EE272: PA | EI272: =EF272&TEXT(EG272,"00")&TEXT(EH272,"00") -> 0000
R273: 版次 | S273: 商品代號 | T273: 性別 | U273: 年齡 | V273: =S273&TEXT(T273,"00")&TEXT(U273,"00") -> 商品代號性別年齡 | W273: 第1年解約金 | X273: 第2年解約金 | Y273: 第3年解約金 | Z273: 第4年解約金 | AA273: 第5年解約金 | AB273: 第6年解約金 | AC273: 第7年解約金 | AD273: 第8年解約金 | AE273: 第9年解約金 | AF273: 第10年解約金 | AG273: 第11年解約金 | AH273: 第12年解約金 | AI273: 第13年解約金 | AJ273: 第14年解約金 | AK273: 第15年解約金 | AL273: 第16年解約金 | AM273: 第17年解約金 | AN273: 第18年解約金 | AO273: 第19年解約金 | AP273: 第20年解約金 | AQ273: 第21年解約金 | AR273: 第22年解約金 | AS273: 第23年解約金 | AT273: 第24年解約金 | AU273: 第25年解約金 | AV273: 第26年解約金 | AW273: 第27年解約金 | AX273: 第28年解約金 | AY273: 第29年解約金 | AZ273: 第30年解約金 | BA273: 第31年解約金 | BB273: 第32年解約金 | BC273: 第33年解約金 | BD273: 第34年解約金 | BE273: 第35年解約金 | BF273: 第36年解約金 | BG273: 第37年解約金 | BH273: 第38年解約金 | BI273: 第39年解約金 | BJ273: 第40年解約金 | BK273: 第41年解約金 | BL273: 第42年解約金 | BM273: 第43年解約金 | BN273: 第44年解約金 | BO273: 第45年解約金 | BP273: 第46年解約金 | BQ273: 第47年解約金 | BR273: 第48年解約金 | BS273: 第49年解約金 | BT273: 第50年解約金 | BU273: 第51年解約金 | BV273: 第52年解約金 | BW273: 第53年解約金 | BX273: 第54年解約金 | BY273: 第55年解約金 | BZ273: 第56年解約金 | CA273: 第57年解約金 | CB273: 第58年解約金 | CC273: 第59年解約金 | CD273: 第60年解約金 | CE273: 第61年解約金 | CF273: 第62年解約金 | CG273: 第63年解約金 | CH273: 第64年解約金 | CI273: 第65年解約金 | CJ273: 第66年解約金 | CK273: 第67年解約金 | CL273: 第68年解約金 | CM273: 第69年解約金 | CN273: 第70年解約金 | CO273: 第71年解約金 | CP273: 第72年解約金 | CQ273: 第73年解約金 | CR273: 第74年解約金 | CS273: 第75年解約金 | CT273: 第76年解約金 | CU273: 第77年解約金 | CV273: 第78年解約金 | CW273: 第79年解約金 | CX273: 第80年解約金 | CY273: 第81年解約金 | CZ273: 第82年解約金 | DA273: 第83年解約金 | DB273: 第84年解約金 | DC273: 第85年解約金 | DD273: 第86年解約金 | DE273: 第87年解約金 | DF273: 第88年解約金 | DG273: 第89年解約金 | DH273: 第90年解約金 | DI273: 第91年解約金 | DJ273: 第92年解約金 | DK273: 第93年解約金 | DL273: 第94年解約金 | DM273: 第95年解約金 | DN273: 第96年解約金 | DO273: 第97年解約金 | DP273: 第98年解約金 | DQ273: 第99年解約金 | DR273: 第100年解約金 | DS273: 第101年解約金 | DT273: 第102年解約金 | DU273: 第103年解約金 | DV273: 第104年解約金 | DW273: 第105年解約金 | DX273: 第106年解約金 | DY273: 第107年解約金 | DZ273: 第108年解約金 | EA273: 第109年解約金 | EB273: 第110年解約金 | EC273: 第111年解約金 | EE273: 版次 | EF273: 商品代號 | EG273: 性別 | EH273: 年齡 | EI273: =EF273&TEXT(EG273,"00")&TEXT(EH273,"00") -> 商品代號性別年齡 | EJ273: 第1年減額繳清保額 | EK273: 第2年減額繳清保額 | EL273: 第3年減額繳清保額 | EM273: 第4年減額繳清保額 | EN273: 第5年減額繳清保額 | EO273: 第6年減額繳清保額 | EP273: 第7年減額繳清保額 | EQ273: 第8年減額繳清保額 | ER273: 第9年減額繳清保額 | ES273: 第10年減額繳清保額 | ET273: 第11年減額繳清保額 | EU273: 第12年減額繳清保額 | EV273: 第13年減額繳清保額 | EW273: 第14年減額繳清保額 | EX273: 第15年減額繳清保額 | EY273: 第16年減額繳清保額 | EZ273: 第17年減額繳清保額 | FA273: 第18年減額繳清保額 | FB273: 第19年減額繳清保額B | FC273: 第20年減額繳清保額 | FD273: 第21年減額繳清保額B | FE273: 第22年減額繳清保額 | FF273: 第23年減額繳清保額 | FG273: 第24年減額繳清保額 | FH273: 第25年減額繳清保額 | FI273: 第26年減額繳清保額B | FJ273: 第27年減額繳清保額 | FK273: 第28年減額繳清保額B | FL273: 第29年減額繳清保額 | FM273: 第30年減額繳清保額B | FN273: 第31年減額繳清保額 | FO273: 第32年減額繳清保額 | FP273: 第33年減額繳清保額 | FQ273: 第34年減額繳清保額 | FR273: 第35年減額繳清保額 | FS273: 第36年減額繳清保額 | FT273: 第37年減額繳清保額 | FU273: 第38年減額繳清保額 | FV273: 第39年減額繳清保額 | FW273: 第40年減額繳清保額 | FX273: 第41年減額繳清保額 | FY273: 第42年減額繳清保額 | FZ273: 第43年減額繳清保額 | GA273: 第44年減額繳清保額 | GB273: 第45年減額繳清保額 | GC273: 第46年減額繳清保額 | GD273: 第47年減額繳清保額 | GE273: 第48年減額繳清保額 | GF273: 第49年減額繳清保額 | GG273: 第50年減額繳清保額 | GH273: 第51年減額繳清保額 | GI273: 第52年減額繳清保額 | GJ273: 第53年減額繳清保額 | GK273: 第54年減額繳清保額 | GL273: 第55年減額繳清保額 | GM273: 第56年減額繳清保額 | GN273: 第57年減額繳清保額 | GO273: 第58年減額繳清保額 | GP273: 第59年減額繳清保額 | GQ273: 第60年減額繳清保額 | GR273: 第61年減額繳清保額 | GS273: 第62年減額繳清保額 | GT273: 第63年減額繳清保額 | GU273: 第64年減額繳清保額 | GV273: 第65年減額繳清保額 | GW273: 第66年減額繳清保額 | GX273: 第67年減額繳清保額 | GY273: 第68年減額繳清保額 | GZ273: 第69年減額繳清保額 | HA273: 第70年減額繳清保額 | HB273: 第71年減額繳清保額 | HC273: 第72年減額繳清保額 | HD273: 第73年減額繳清保額 | HE273: 第74年減額繳清保額 | HF273: 第75年減額繳清保額 | HG273: 第76年減額繳清保額 | HH273: 第77年減額繳清保額 | HI273: 第78年減額繳清保額 | HJ273: 第79年減額繳清保額 | HK273: 第80年減額繳清保額 | HL273: 第81年減額繳清保額 | HM273: 第82年契遾B繳清保額 | HN273: 第83年減額繳清保額 | HO273: 第84年減額繳清保額 | HP273: 第85年減額繳清保額 | HQ273: 第86年減額繳清保額 | HR273: 第87年減額繳清保額 | HS273: 第88年減額繳清保額 | HT273: 第89年減額繳清保額 | HU273: 第90年減額繳清保額 | HV273: 第91年減額繳清保額 | HW273: 第92年減額繳清保額 | HX273: 第93年減額繳清保額 | HY273: 第94年減額繳清保額 | HZ273: 第95年減額繳清保額 | IA273: 第96年減額繳清保額 | IB273: 第97年減額繳清保額 | IC273: 第98年減額繳清保額 | ID273: 第99年減額繳清保額 | IE273: 第100年減額繳清保額 | IF273: 第101年減額繳清保額 | IG273: 第102年減額繳清保額 | IH273: 第103年減額繳清保額 | II273: 第104年減額繳清保額 | IJ273: 第105年減額繳清保額 | IK273: 第106年減額繳清保額 | IL273: 第107年減額繳清保額 | IM273: 第108年減額繳清保額 | IN273: 第109年減額繳清保額 | IO273: 第110年減額繳清保額 | IP273: 第111年減額繳清保額

Sheet OP
P1: 文字區域
B2: fubon | C2: 試算日 | D2: 生日 | E2: 驗證 | H2: 彈性繳 | I2: 1 | J2: 1 | K2: 1 | P2: 0 | Q2: 註： | AD2: =IF(AE2="","",MAX($AD$1:AD1)+1) | AL2: =$C$69 -> 業務、服展、北富銀
B3: =IF(C4=0,0,VALUE(MID(C4,IF(LEN(C4)=7,4,3),2))) -> 5 | C3: =IF(TODAY()<DATE(2026,4,9),DATE(2026,4,9),TODAY()) -> 46239 | D3: =IF(C4=0,0,DATE(LEFT(C4,IF(LEN(C4)=7,3,2))+1911,MID(C4,IF(LEN(C4)=7,4,3),2),RIGHT(C4,2))) -> 31927 | E3: =N(DAY(DATE(LEFT(C4,IF(LEN(C4)=7,3,2))+1911,MID(C4,IF(LEN(C4)=7,4,3),2)+1,0))) -> 31 | H3: 躉繳 | I3: 1 | J3: 1 | K3: 1 | P3: =IF(Q3="","",MAX($P$2:P2)+1) -> 1 | Q3: =IF(AND(C46=0,C47=0),"","‧上表年度實繳保費已扣除保費折扣，繳費期內如不符保費折扣條件，上表將不適用。") -> ‧上表年度實繳保費已扣除保費折扣，繳費期內如不符保費折扣條件，上表將不適用。 | AD3: =IF(AE3="","",MAX($AD$1:AD2)+1) | AL3: 業務、服展、北富銀 | AM3: 業務、服展 | AN3: 北富銀 | AO3: 整銷 | AP3: 多元
B4: 生日 | C4: =IF(C9=1,C10,IF(C9=2,VALUE(C11&TEXT(C12,"00")&TEXT(C13,"00")),"")) -> 760530 | D4: =DATE(YEAR(C3)-$C$15,MONTH(C3)-6,DAY(C3)) -> 27795 | E4: =IF(OR(B3<1,B3>12),1,"") | F4: =YEAR($D$4)-1911 -> 65 | H4: 年繳 | I4: 1 | J4: 1 | K4: 1 | P4: =IF(Q4="","",MAX($P$2:P3)+1) -> 2 | Q4: ‧上表所列之各項數值，係指各保單年度末之數值。本保險契約若辦理減額繳清保險時，上表將不適用。 | AD4: =IF(AE4="","",MAX($AD$1:AD3)+1) | AK4: =IF(OR($AL4="",COUNTIF($AL$3:$AR$3,$AL$2)=0),"",MAX($AK$3:AK3)+1) -> 1 | AL4: 富邦人壽保險股份有限公司履行個人資料保護法告知說明書
B5: 最高承保 | C5: 保險 | D5: =IF(SUM(E6,D10:D13)>=1,"生日格式錯誤",IF(D3>C3,"被保險人未出生",IF(MONTH(C3)<B3,IF(OR(MONTH(C3)+12-B3>6,AND(MONTH(C3)+12-B3=6,DAY(C3)>DAY(D3))),YEAR(C3)-1-YEAR(D3)+1,IF(OR(MONTH(C3)+12-B3<6,AND(MONTH(C3)+12-B3=6,DAY(C3)<=DAY(D3))),YEAR(C3)-1-YEAR(D3))),IF(OR(MONTH(C3)-B3>6,AND(MONTH(C3)-B3=6,DAY(C3)>DAY(D3))),YEAR(C3)-YEAR(D3)+1,IF(OR(MONTH(C3)-B3<=6,AND(MONTH(C3)-B3=6,DAY(C3)<=DAY(D3))),YEAR(C3)-YEAR(D3),))))) -> 39 | E5: =IF(OR(VALUE(RIGHT(C4,2))<1,VALUE(RIGHT(C4,2))>E3),1,"") | F5: =MONTH($D$4) -> 2 | H5: 半年繳 | I5: 0.52 | J5: 0.5 | K5: 2 | P5: =IF(Q5="","",MAX($P$2:P4)+1) -> 3 | Q5: ‧上表數值為從未申領老年住院醫療提前給付保險金之數值，如有申領過老年住院醫療提前給付保險金者上表將不適 | AD5: =IF(AE5="","",MAX($AD$1:AD4)+1) | AK5: =IF(OR($AL5="",COUNTIF($AL$3:$AR$3,$AL$2)=0),"",MAX($AK$3:AK4)+1) -> 2
C6: 足歲 | D6: =IF(SUM(E6,D10:D13)>=1,"生日格式錯誤",IF(D3>C3,"被保險人未出生",DATEDIF(D3,C3,"y"))) -> 39 | E6: =IF(OR(E4=1,E5=1),1,"") | F6: =DAY($D$4) -> 5 | H6: 季繳 | I6: 0.262 | J6: 0.25 | K6: 4 | P6: =IF(Q6="","",MAX($P$2:P5)+1) -> 4 | Q6: 用，老年住院醫療提前給付保險金申領之條件及限制請詳閱保單條款說明。 | AD6: =IF(AE6="","",MAX($AD$1:AD5)+1) | AK6: =IF(OR($AL6="",COUNTIF($AL$3:$AR$3,$AL$2)=0),"",MAX($AK$3:AK5)+1) -> 3 | AL6: 富邦人壽保險股份有限公司（下稱本公司）依據個人資料保護法（以下稱個資法）
F7: =F4&TEXT(F5,"00")&TEXT(F6,"00") -> 650205 | H7: 月繳 | I7: 0.088 | J7: 0.08333333 | K7: 12 | P7: =IF(Q7="","",MAX($P$2:P6)+1) -> 5 | Q7: ‧身故保險金若被保險人未滿十五足歲前身故者，將以「所繳保險費加計利息」退還予要保人。 | AD7: =IF(AE7="","",MAX($AD$1:AD6)+1) | AK7: =IF(OR($AL7="",COUNTIF($AL$3:$AR$3,$AL$2)=0),"",MAX($AK$3:AK6)+1) -> 4 | AL7: 規定，向 台端告知下列事項，請 台端詳閱：
K8: 第一頁說明↓ | L8: 警語↓ | M8: =COUNTA(L11:L12) -> 2 | P8: =IF(Q8="","",MAX($P$2:P7)+1) -> 6 | Q8: ‧上表保險年齡15歲以下(含15歲)之身故/完全失能保障數值，為按年繳計算之所繳保險費總和，不含加計利息的部分， | AD8: =IF(AE8="","",MAX($AD$1:AD7)+1) | AK8: =IF(OR($AL8="",COUNTIF($AL$3:$AR$3,$AL$2)=0),"",MAX($AK$3:AK7)+1) -> 5 | AL8: 一、蒐集之目的：
B9: 輸入格式選項 | C9: 1 | D9: 檢核欄位 | H9: 折扣使用 | I9: 首期 | J9: 續期 | K9: =K10&M10&K11&M11&K12&M12&K13&M13&D47 -> 繳費方式 1.0%折扣 | L9: ="保費折扣" -> 保費折扣 | M9: =L10&M10&L11&M11&L12&M12&L13&"折扣" -> 繳費方式折扣 | P9: =IF(Q9="","",MAX($P$2:P8)+1) -> 7 | Q9: 若有加計利息，則實際理賠金額依條款約定辦理。 | AD9: =IF(AE9="","",MAX($AD$1:AD8)+1) | AK9: =IF(OR($AL9="",COUNTIF($AL$3:$AR$3,$AL$2)=0),"",MAX($AK$3:AK8)+1) -> 6 | AL9: （一）人身保險（００一）
B10: 1.輸入格式1-6或7位數字輸入 | C10: =BD -> 760530 | D10: =IF(AND($C$9=1,OR(C10="",C10=0)),1,"") | G10: 1 | H10: 繳費方式 | I10: =$C$42 -> 0.01 | J10: =$C$44 -> 0.01 | K10: =IF(AND(I10>0,J10>0),""&H10&TEXT(I10," 0.0%")&"折扣",IF(AND(I10>0,J10=0),"首期"&H10&TEXT(I10," 0.0%")&"折扣",IF(AND(I10=0,J10>0),"續期"&H10&TEXT(J10," 0.0%")&"折扣",""))) -> 繳費方式 1.0%折扣 | L10: =IF(SUM(I10:J10)>0,H10,"") -> 繳費方式 | M10: =IF(L10="","",IF(SUM(N11:N13)>=2,"、",IF(SUM(N11:N13)=1,"及",""))) | N10: =IF(L10<>"",1,0) -> 1 | P10: =IF(Q10="","",MAX($P$2:P9)+1) | AD10: =IF(AE10="","",MAX($AD$1:AD9)+1) | AK10: =IF(OR($AL10="",COUNTIF($AL$3:$AR$3,$AL$2)=0),"",MAX($AK$3:AK9)+1) -> 7 | AL10: （二）其他經營合於營業登記項目或組織章程所定之業務（一八一）
