Workbook
Name CV: PDATA!$EI$282:$IP$548
Name DIE: PDATA!$V$552:$EC$828
Name En_BFM: OP!$W$4:$W$5
Name En_PayMF: OP!$U$3:$U$6
Name En_PayMR: OP!$V$3:$V$6
Name En_PayT: OP!$T$5:$T$8
Name En_Sex: OP!$S$3:$S$4
Name EXP: PDATA!$EI$552:$IP$828
Name GP: PDATA!$J:$K
Name HL_1: PDATA!$V$1164:$EC$1429
Name HL_2: PDATA!$EI$1164:$IP$1429
Name PA: PDATA!$V$2:$EC$278
Name PDN1_1: OP!$C$23
Name PDSN1: OP!$C$22
Name PDSN1_1: OP!$C$22
Name PI: OP!$AK$4:$AL$90
Name PV: PDATA!$EI$988:$IP$1150
Name PV0: PDATA!$V$988:$ED$1150
Name PVal: PDATA!$O:$P
Name PYO: PY!$D$4
Name PYR: PY!$C$11
Name PYY: PY!$C$4
Name SRV: PDATA!$EI$2:$IP$278
Name TOV: 總表!$B$3:$AI$114
Name 關係: OP!$B$182:$B$186

Sheet PDATA
A1: GP | B1: 1051130 | J1: =B1&TEXT(F1,"00")&TEXT(H1,"00") -> 10511300000 | O1: =M1&TEXT(N1,"00") -> 00 | R1: PA | V1: =S1&TEXT(T1,"00")&TEXT(U1,"00") -> 0000 | EE1: SRV | EI1: =EF1&TEXT(EG1,"00")&TEXT(EH1,"00") -> 0000
A2: 版次 | B2: 商品代號 | C2: 職業等級 | D2: 年期 | E2: 保額代碼 | F2: 性別 | G2: 投保金額 | H2: 年齡 | I2: 繳費年度 | J2: =B2&TEXT(F2,"00")&TEXT(H2,"00") -> 商品代號性別年齡 | K2: 保費 | M2: 商品代號 | N2: 累計給付年度 | O2: =M2&TEXT(N2,"00") -> 商品代號累計給付年度 | P2: 給付數值 | R2: 版次 | S2: 商品代號 | T2: 性別 | U2: 年齡 | V2: =S2&TEXT(T2,"00")&TEXT(U2,"00") -> 商品代號性別年齡 | W2: 第1年減額繳清保額 | X2: 第2年減額繳清保額 | Y2: 第3年減額繳清保額 | Z2: 第4年減額繳清保額 | AA2: 第5年減額繳清保額 | AB2: 第6年減額繳清保額 | AC2: 第7年減額繳清保額 | AD2: 第8年減額繳清保額 | AE2: 第9年減額繳清保額 | AF2: 第10年減額繳清保額 | AG2: 第11年減額繳清保額 | AH2: 第12年減額繳清保額 | AI2: 第13年減額繳清保額 | AJ2: 第14年減額繳清保額 | AK2: 第15年減額繳清保額 | AL2: 第16年減額繳清保額 | AM2: 第17年減額繳清保額 | AN2: 第18年減額繳清保額 | AO2: 第19年減額繳清保額B | AP2: 第20年減額繳清保額 | AQ2: 第21年減額繳清保額B | AR2: 第22年減額繳清保額 | AS2: 第23年減額繳清保額 | AT2: 第24年減額繳清保額 | AU2: 第25年減額繳清保額 | AV2: 第26年減額繳清保額B | AW2: 第27年減額繳清保額 | AX2: 第28年減額繳清保額B | AY2: 第29年減額繳清保額 | AZ2: 第30年減額繳清保額B | BA2: 第31年減額繳清保額 | BB2: 第32年減額繳清保額 | BC2: 第33年減額繳清保額 | BD2: 第34年減額繳清保額 | BE2: 第35年減額繳清保額 | BF2: 第36年減額繳清保額 | BG2: 第37年減額繳清保額 | BH2: 第38年減額繳清保額 | BI2: 第39年減額繳清保額 | BJ2: 第40年減額繳清保額 | BK2: 第41年減額繳清保額 | BL2: 第42年減額繳清保額 | BM2: 第43年減額繳清保額 | BN2: 第44年減額繳清保額 | BO2: 第45年減額繳清保額 | BP2: 第46年減額繳清保額 | BQ2: 第47年減額繳清保額 | BR2: 第48年減額繳清保額 | BS2: 第49年減額繳清保額 | BT2: 第50年減額繳清保額 | BU2: 第51年減額繳清保額 | BV2: 第52年減額繳清保額 | BW2: 第53年減額繳清保額 | BX2: 第54年減額繳清保額 | BY2: 第55年減額繳清保額 | BZ2: 第56年減額繳清保額 | CA2: 第57年減額繳清保額 | CB2: 第58年減額繳清保額 | CC2: 第59年減額繳清保額 | CD2: 第60年減額繳清保額 | CE2: 第61年減額繳清保額 | CF2: 第62年減額繳清保額 | CG2: 第63年減額繳清保額 | CH2: 第64年減額繳清保額 | CI2: 第65年減額繳清保額 | CJ2: 第66年減額繳清保額 | CK2: 第67年減額繳清保額 | CL2: 第68年減額繳清保額 | CM2: 第69年減額繳清保額 | CN2: 第70年減額繳清保額 | CO2: 第71年減額繳清保額 | CP2: 第72年減額繳清保額 | CQ2: 第73年減額繳清保額 | CR2: 第74年減額繳清保額 | CS2: 第75年減額繳清保額 | CT2: 第76年減額繳清保額 | CU2: 第77年減額繳清保額 | CV2: 第78年減額繳清保額 | CW2: 第79年減額繳清保額 | CX2: 第80年減額繳清保額 | CY2: 第81年減額繳清保額 | CZ2: 第82年契遾B繳清保額 | DA2: 第83年減額繳清保額 | DB2: 第84年減額繳清保額 | DC2: 第85年減額繳清保額 | DD2: 第86年減額繳清保額 | DE2: 第87年減額繳清保額 | DF2: 第88年減額繳清保額 | DG2: 第89年減額繳清保額 | DH2: 第90年減額繳清保額 | DI2: 第91年減額繳清保額 | DJ2: 第92年減額繳清保額 | DK2: 第93年減額繳清保額 | DL2: 第94年減額繳清保額 | DM2: 第95年減額繳清保額 | DN2: 第96年減額繳清保額 | DO2: 第97年減額繳清保額 | DP2: 第98年減額繳清保額 | DQ2: 第99年減額繳清保額 | DR2: 第100年減額繳清保額 | DS2: 第101年減額繳清保額 | DT2: 第102年減額繳清保額 | DU2: 第103年減額繳清保額 | DV2: 第104年減額繳清保額 | DW2: 第105年減額繳清保額 | DX2: 第106年減額繳清保額 | DY2: 第107年減額繳清保額 | DZ2: 第108年減額繳清保額 | EA2: 第109年減額繳清保額 | EB2: 第110年減額繳清保額 | EC2: 第111年減額繳清保額 | EE2: 版次 | EF2: 商品代號 | EG2: 性別 | EH2: 年齡
B3: LTQ30 | D3: 30 | F3: 1 | H3: 15 | J3: =B3&TEXT(F3,"00")&TEXT(H3,"00") -> LTQ300115 | K3: 12780 | M3: LTQ10 | N3: 1 | O3: =M3&TEXT(N3,"00") -> LTQ1001 | P3: 20000
B4: LTQ30 | D4: 30 | F4: 1 | H4: 16 | J4: =B4&TEXT(F4,"00")&TEXT(H4,"00") -> LTQ300116 | K4: 12980 | M4: LTQ10 | N4: 2 | O4: =M4&TEXT(N4,"00") -> LTQ1002 | P4: 20400
B5: LTQ30 | D5: 30 | F5: 1 | H5: 17 | J5: =B5&TEXT(F5,"00")&TEXT(H5,"00") -> LTQ300117 | K5: 13290 | M5: LTQ10 | N5: 3 | O5: =M5&TEXT(N5,"00") -> LTQ1003 | P5: 20800
B6: LTQ30 | D6: 30 | F6: 1 | H6: 18 | J6: =B6&TEXT(F6,"00")&TEXT(H6,"00") -> LTQ300118 | K6: 13600 | M6: LTQ10 | N6: 4 | O6: =M6&TEXT(N6,"00") -> LTQ1004 | P6: 21200
B7: LTQ30 | D7: 30 | F7: 1 | H7: 19 | J7: =B7&TEXT(F7,"00")&TEXT(H7,"00") -> LTQ300119 | K7: 13810 | M7: LTQ10 | N7: 5 | O7: =M7&TEXT(N7,"00") -> LTQ1005 | P7: 21600
B8: LTQ30 | D8: 30 | F8: 1 | H8: 20 | J8: =B8&TEXT(F8,"00")&TEXT(H8,"00") -> LTQ300120 | K8: 14320 | M8: LTQ10 | N8: 6 | O8: =M8&TEXT(N8,"00") -> LTQ1006 | P8: 22000
B9: LTQ30 | D9: 30 | F9: 1 | H9: 21 | J9: =B9&TEXT(F9,"00")&TEXT(H9,"00") -> LTQ300121 | K9: 14740 | M9: LTQ10 | N9: 7 | O9: =M9&TEXT(N9,"00") -> LTQ1007 | P9: 22400
B10: LTQ30 | D10: 30 | F10: 1 | H10: 22 | J10: =B10&TEXT(F10,"00")&TEXT(H10,"00") -> LTQ300122 | K10: 15150 | M10: LTQ10 | N10: 8 | O10: =M10&TEXT(N10,"00") -> LTQ1008 | P10: 22800
B11: LTQ30 | D11: 30 | F11: 1 | H11: 23 | J11: =B11&TEXT(F11,"00")&TEXT(H11,"00") -> LTQ300123 | K11: 15560 | M11: LTQ10 | N11: 9 | O11: =M11&TEXT(N11,"00") -> LTQ1009 | P11: 23200
B12: LTQ30 | D12: 30 | F12: 1 | H12: 24 | J12: =B12&TEXT(F12,"00")&TEXT(H12,"00") -> LTQ300124 | K12: 16070 | M12: LTQ10 | N12: 10 | O12: =M12&TEXT(N12,"00") -> LTQ1010 | P12: 23600
B13: LTQ30 | D13: 30 | F13: 1 | H13: 25 | J13: =B13&TEXT(F13,"00")&TEXT(H13,"00") -> LTQ300125 | K13: 16580 | M13: LTQ10 | N13: 11 | O13: =M13&TEXT(N13,"00") -> LTQ1011 | P13: 24000
B14: LTQ30 | D14: 30 | F14: 1 | H14: 26 | J14: =B14&TEXT(F14,"00")&TEXT(H14,"00") -> LTQ300126 | K14: 16990 | M14: LTQ10 | N14: 12 | O14: =M14&TEXT(N14,"00") -> LTQ1012 | P14: 24400
... B50: LTQ30 | D50: 30 | F50: 2 | H50: 26 | J50: =B50&TEXT(F50,"00")&TEXT(H50,"00") -> LTQ300226 | K50: 20970 | M50: LTQ30 | N50: 16 | O50: =M50&TEXT(N50,"00") -> LTQ3016 | P50: 26000
B51: LTQ30 | D51: 30 | F51: 2 | H51: 27 | J51: =B51&TEXT(F51,"00")&TEXT(H51,"00") -> LTQ300227 | K51: 21470
B52: LTQ30 | D52: 30 | F52: 2 | H52: 28 | J52: =B52&TEXT(F52,"00")&TEXT(H52,"00") -> LTQ300228 | K52: 21970
B53: LTQ30 | D53: 30 | F53: 2 | H53: 29 | J53: =B53&TEXT(F53,"00")&TEXT(H53,"00") -> LTQ300229 | K53: 22570
B54: LTQ30 | D54: 30 | F54: 2 | H54: 30 | J54: =B54&TEXT(F54,"00")&TEXT(H54,"00") -> LTQ300230 | K54: 23080
B55: LTQ30 | D55: 30 | F55: 2 | H55: 31 | J55: =B55&TEXT(F55,"00")&TEXT(H55,"00") -> LTQ300231 | K55: 23890
B56: LTQ30 | D56: 30 | F56: 2 | H56: 32 | J56: =B56&TEXT(F56,"00")&TEXT(H56,"00") -> LTQ300232 | K56: 24500
B57: LTQ30 | D57: 30 | F57: 2 | H57: 33 | J57: =B57&TEXT(F57,"00")&TEXT(H57,"00") -> LTQ300233 | K57: 25310
B58: LTQ30 | D58: 30 | F58: 2 | H58: 34 | J58: =B58&TEXT(F58,"00")&TEXT(H58,"00") -> LTQ300234 | K58: 26030
B59: LTQ30 | D59: 30 | F59: 2 | H59: 35 | J59: =B59&TEXT(F59,"00")&TEXT(H59,"00") -> LTQ300235 | K59: 26740
B60: LTQ30 | D60: 30 | F60: 2 | H60: 36 | J60: =B60&TEXT(F60,"00")&TEXT(H60,"00") -> LTQ300236 | K60: 27460
B61: LTQ30 | D61: 30 | F61: 2 | H61: 37 | J61: =B61&TEXT(F61,"00")&TEXT(H61,"00") -> LTQ300237 | K61: 28180
B62: LTQ30 | D62: 30 | F62: 2 | H62: 38 | J62: =B62&TEXT(F62,"00")&TEXT(H62,"00") -> LTQ300238 | K62: 29000
... B278: LTQ10 | D278: 10 | F278: 2 | H278: 70 | J278: =B278&TEXT(F278,"00")&TEXT(H278,"00") -> LTQ100270 | K278: 345100
R281: DIE2 | V281: =S281&TEXT(T281,"00")&TEXT(U281,"00") -> 0000 | EE281: CV | EI281: =EF281&TEXT(EG281,"00")&TEXT(EH281,"00") -> 0000
R282: 版次 | S282: 商品代號 | T282: 性別 | U282: 年齡 | EE282: 版次 | EF282: 商品代號 | EG282: 性別 | EH282: 年齡 | EI282: =EF282&TEXT(EG282,"00")&TEXT(EH282,"00") -> 商品代號性別年齡 | EJ282: 第1年解約金 | EK282: 第2年解約金 | EL282: 第3年解約金 | EM282: 第4年解約金 | EN282: 第5年解約金 | EO282: 第6年解約金 | EP282: 第7年解約金 | EQ282: 第8年解約金 | ER282: 第9年解約金 | ES282: 第10年解約金 | ET282: 第11年解約金 | EU282: 第12年解約金 | EV282: 第13年解約金 | EW282: 第14年解約金 | EX282: 第15年解約金 | EY282: 第16年解約金 | EZ282: 第17年解約金 | FA282: 第18年解約金 | FB282: 第19年解約金 | FC282: 第20年解約金 | FD282: 第21年解約金 | FE282: 第22年解約金 | FF282: 第23年解約金 | FG282: 第24年解約金 | FH282: 第25年解約金 | FI282: 第26年解約金 | FJ282: 第27年解約金 | FK282: 第28年解約金 | FL282: 第29年解約金 | FM282: 第30年解約金 | FN282: 第31年解約金 | FO282: 第32年解約金 | FP282: 第33年解約金 | FQ282: 第34年解約金 | FR282: 第35年解約金 | FS282: 第36年解約金 | FT282: 第37年解約金 | FU282: 第38年解約金 | FV282: 第39年解約金 | FW282: 第40年解約金 | FX282: 第41年解約金 | FY282: 第42年解約金 | FZ282: 第43年解約金 | GA282: 第44年解約金 | GB282: 第45年解約金 | GC282: 第46年解約金 | GD282: 第47年解約金 | GE282: 第48年解約金 | GF282: 第49年解約金 | GG282: 第50年解約金 | GH282: 第51年解約金 | GI282: 第52年解約金 | GJ282: 第53年解約金 | GK282: 第54年解約金 | GL282: 第55年解約金 | GM282: 第56年解約金 | GN282: 第57年解約金 | GO282: 第58年解約金 | GP282: 第59年解約金 | GQ282: 第60年解約金 | GR282: 第61年解約金 | GS282: 第62年解約金 | GT282: 第63年解約金 | GU282: 第64年解約金 | GV282: 第65年解約金 | GW282: 第66年解約金 | GX282: 第67年解約金 | GY282: 第68年解約金 | GZ282: 第69年解約金 | HA282: 第70年解約金 | HB282: 第71年解約金 | HC282: 第72年解約金 | HD282: 第73年解約金 | HE282: 第74年解約金 | HF282: 第75年解約金 | HG282: 第76年解約金 | HH282: 第77年解約金 | HI282: 第78年解約金 | HJ282: 第79年解約金 | HK282: 第80年解約金 | HL282: 第81年解約金 | HM282: 第82年解約金 | HN282: 第83年解約金 | HO282: 第84年解約金 | HP282: 第85年解約金 | HQ282: 第86年解約金 | HR282: 第87年解約金 | HS282: 第88年解約金 | HT282: 第89年解約金 | HU282: 第90年解約金 | HV282: 第91年解約金 | HW282: 第92年解約金 | HX282: 第93年解約金 | HY282: 第94年解約金 | HZ282: 第95年解約金 | IA282: 第96年解約金 | IB282: 第97年解約金 | IC282: 第98年解約金 | ID282: 第99年解約金 | IE282: 第100年解約金 | IF282: 第101年解約金 | IG282: 第102年解約金 | IH282: 第103年解約金 | II282: 第104年解約金 | IJ282: 第105年解約金 | IK282: 第106年解約金 | IL282: 第107年解約金 | IM282: 第108年解約金 | IN282: 第109年解約金 | IO282: 第110年解約金 | IP282: 第111年解約金
R551: DIE | V551: =S551&TEXT(T551,"00")&TEXT(U551,"00") -> 0000 | EE551: EXP | EI551: =EF551&TEXT(EG551,"00")&TEXT(EH551,"00") -> 0000
R552: 版次 | S552: 商品代號 | T552: 性別 | U552: 年齡 | V552: =S552&TEXT(T552,"00")&TEXT(U552,"00") -> 商品代號性別年齡 | W552: 第1年身故保險金 | X552: 第2年身故保險金 | Y552: 第3年身故保險金 | Z552: 第4年身故保險金 | AA552: 第5年身故保險金 | AB552: 第6年身故保險金 | AC552: 第7年身故保險金 | AD552: 第8年身故保險金 | AE552: 第9年身故保險金 | AF552: 第10年身故保險金 | AG552: 第11年身故保險金 | AH552: 第12年身故保險金 | AI552: 第13年身故保險金 | AJ552: 第14年身故保險金 | AK552: 第15年身故保險金 | AL552: 第16年身故保險金 | AM552: 第17年身故保險金 | AN552: 第18年身故保險金 | AO552: 第19年身故保險金 | AP552: 第20年身故保險金 | AQ552: 第21年身故保險金 | AR552: 第22年身故保險金 | AS552: 第23年身故保險金 | AT552: 第24年身故保險金 | AU552: 第25年身故保險金 | AV552: 第26年身故保險金 | AW552: 第27年身故保險金 | AX552: 第28年身故保險金 | AY552: 第29年身故保險金 | AZ552: 第30年身故保險金 | BA552: 第31年身故保險金 | BB552: 第32年身故保險金 | BC552: 第33年身故保險金 | BD552: 第34年身故保險金 | BE552: 第35年身故保險金 | BF552: 第36年身故保險金 | BG552: 第37年身故保險金 | BH552: 第38年身故保險金 | BI552: 第39年身故保險金 | BJ552: 第40年身故保險金 | BK552: 第41年身故保險金 | BL552: 第42年身故保險金 | BM552: 第43年身故保險金 | BN552: 第44年身故保險金 | BO552: 第45年身故保險金 | BP552: 第46年身故保險金 | BQ552: 第47年身故保險金 | BR552: 第48年身故保險金 | BS552: 第49年身故保險金 | BT552: 第50年身故保險金 | BU552: 第51年身故保險金 | BV552: 第52年身故保險金 | BW552: 第53年身故保險金 | BX552: 第54年身故保險金 | BY552: 第55年身故保險金 | BZ552: 第56年身故保險金 | CA552: 第57年身故保險金 | CB552: 第58年身故保險金 | CC552: 第59年身故保險金 | CD552: 第60年身故保險金 | CE552: 第61年身故保險金 | CF552: 第62年身故保險金 | CG552: 第63年身故保險金 | CH552: 第64年身故保險金 | CI552: 第65年身故保險金 | CJ552: 第66年身故保險金 | CK552: 第67年身故保險金 | CL552: 第68年身故保險金 | CM552: 第69年身故保險金 | CN552: 第70年身故保險金 | CO552: 第71年身故保險金 | CP552: 第72年身故保險金 | CQ552: 第73年身故保險金 | CR552: 第74年身故保險金額 | CS552: 第75年身故保險金 | CT552: 第76年身故保險金 | CU552: 第77年身故保險金 | CV552: 第78年身故保險金 | CW552: 第79年身故保險金 | CX552: 第80年身故保險金 | CY552: 第81年身故保險金 | CZ552: 第82年身故保險金 | DA552: 第83年身故保險金 | DB552: 第84年身故保險金 | DC552: 第85年身故保險金 | DD552: 第86年身故保險金 | DE552: 第87年身故保險金 | DF552: 第88年身故保險金 | DG552: 第89年身故保險金 | DH552: 第90年身故保險金 | DI552: 第91年身故保險金 | DJ552: 第92年身故保險金 | DK552: 第93年身故保險金 | DL552: 第94年身故保險金 | DM552: 第95年身故保險金 | DN552: 第96年身故保險金 | DO552: 第97年身故保險金 | DP552: 第98年身故保險金 | DQ552: 第99年身故保險金 | DR552: 第100年身故保險金 | DS552: 第101年身故保險金 | DT552: 第102年身故保險金 | DU552: 第103年身故保險金 | DV552: 第104年身故保險金 | DW552: 第105年身故保險金 | DX552: 第106年身故保險金 | DY552: 第107年身故保險金 | DZ552: 第108年身故保險金 | EA552: 第109年身故保險金 | EB552: 第110年身故保險金 | EC552: 第111年身故保險金 | EE552: 版次 | EF552: 商品代號 | EG552: 性別 | EH552: 年齡 | EI552: =EF552&TEXT(EG552,"00")&TEXT(EH552,"00") -> 商品代號性別年齡 | EJ552: 第1年祝壽保險金 | EK552: 第2年祝壽保險金 | EL552: 第3年祝壽保險金 | EM552: 第4年祝壽保險金 | EN552: 第5年祝壽保險金 | EO552: 第6年祝壽保險金 | EP552: 第7年祝壽保險金 | EQ552: 第8年祝壽保險金 | ER552: 第9年祝壽保險金 | ES552: 第10年祝壽保險金 | ET552: 第11年祝壽保險金 | EU552: 第12年祝壽保險金 | EV552: 第13年祝壽保險金 | EW552: 第14年祝壽保險金 | EX552: 第15年祝壽保險金 | EY552: 第16年祝壽保險金 | EZ552: 第17年祝壽保險金 | FA552: 第18年祝壽保險金 | FB552: 第19年祝壽保險金 | FC552: 第20年祝壽保險金 | FD552: 第21年祝壽保險金 | FE552: 第22年祝壽保險金 | FF552: 第23年祝壽保險金 | FG552: 第24年祝壽保險金 | FH552: 第25年祝壽保險金 | FI552: 第26年祝壽保險金 | FJ552: 第27年祝壽保險金 | FK552: 第28年祝壽保險金 | FL552: 第29年祝壽保險金 | FM552: 第30年祝壽保險金 | FN552: 第31年祝壽保險金 | FO552: 第32年祝壽保險金 | FP552: 第33年祝壽保險金 | FQ552: 第34年祝壽保險金 | FR552: 第35年祝壽保險金 | FS552: 第36年祝壽保險金 | FT552: 第37年祝壽保險金 | FU552: 第38年祝壽保險金 | FV552: 第39年祝壽保險金 | FW552: 第40年祝壽保險金 | FX552: 第41年祝壽保險金 | FY552: 第42年祝壽保險金 | FZ552: 第43年祝壽保險金 | GA552: 第44年祝壽保險金 | GB552: 第45年祝壽保險金 | GC552: 第46年祝壽保險金 | GD552: 第47年祝壽保險金 | GE552: 第48年祝壽保險金 | GF552: 第49年祝壽保險金 | GG552: 第50年祝壽保險金 | GH552: 第51年祝壽保險金 | GI552: 第52年祝壽保險金 | GJ552: 第53年祝壽保險金 | GK552: 第54年祝壽保險金 | GL552: 第55年祝壽保險金 | GM552: 第56年祝壽保險金 | GN552: 第57年祝壽保險金 | GO552: 第58年祝壽保險金 | GP552: 第59年祝壽保險金 | GQ552: 第60年祝壽保險金 | GR552: 第61年祝壽保險金 | GS552: 第62年祝壽保險金 | GT552: 第63年祝壽保險金 | GU552: 第64年祝壽保險金 | GV552: 第65年祝壽保險金 | GW552: 第66年祝壽保險金 | GX552: 第67年祝壽保險金 | GY552: 第68年祝壽保險金 | GZ552: 第69年祝壽保險金 | HA552: 第70年祝壽保險金 | HB552: 第71年祝壽保險金 | HC552: 第72年祝壽保險金 | HD552: 第73年祝壽保險金 | HE552: 第74年祝壽保險金 | HF552: 第75年祝壽保險金 | HG552: 第76年祝壽保險金 | HH552: 第77年祝壽保險金 | HI552: 第78年祝壽保險金 | HJ552: 第79年祝壽保險金 | HK552: 第80年祝壽保險金 | HL552: 第81年祝壽保險金 | HM552: 第82年祝壽保險金 | HN552: 第83年祝壽保險金 | HO552: 第84年祝壽保險金 | HP552: 第85年祝壽保險金 | HQ552: 第86年祝壽保險金 | HR552: 第87年祝壽保險金 | HS552: 第88年祝壽保險金 | HT552: 第89年祝壽保險金 | HU552: 第90年祝壽保險金 | HV552: 第91年祝壽保險金 | HW552: 第92年祝壽保險金 | HX552: 第93年祝壽保險金 | HY552: 第94年祝壽保險金 | HZ552: 第95年祝壽保險金 | IA552: 第96年祝壽保險金 | IB552: 第97年祝壽保險金 | IC552: 第98年祝壽保險金 | ID552: 第99年祝壽保險金 | IE552: 第100年祝壽保險金 | IF552: 第101年祝壽保險金 | IG552: 第102年祝壽保險金 | IH552: 第103年祝壽保險金 | II552: 第104年祝壽保險金 | IJ552: 第105年祝壽保險金 | IK552: 第106年祝壽保險金 | IL552: 第107年祝壽保險金 | IM552: 第108年祝壽保險金 | IN552: 第109年祝壽保險金 | IO552: 第110年祝壽保險金 | IP552: 第111年祝壽保險金
S553: LTQ30 | T553: 1 | U553: 15 | V553: =S553&TEXT(T553,"00")&TEXT(U553,"00") -> LTQ300115 | W553: 13035.6 | X553: 26071.2 | Y553: 39106.8 | Z553: 52142.4 | AA553: 65178 | AB553: 78213.6 | AC553: 91249.2 | AD553: 104284.8 | AE553: 117320.4 | AF553: 130356 | AG553: 143391.6 | AH553: 156427.2 | AI553: 169462.8 | AJ553: 182498.4 | AK553: 195534 | AL553: 208569.6 | AM553: 221605.2 | AN553: 234640.8 | AO553: 247676.4 | AP553: 260712 | AQ553: 273747.6 | AR553: 286783.2 | AS553: 299818.8 | AT553: 312854.4 | AU553: 325890 | AV553: 338925.6 | AW553: 351961.2 | AX553: 364996.8 | AY553: 378032.4 | AZ553: 391068 | BA553: 391068 | BB553: 391068 | BC553: 391068 | BD553: 391068 | BE553: 391068 | BF553: 391068 | BG553: 391068 | BH553: 391068 | BI553: 391068 | BJ553: 391068 | BK553: 391068 | BL553: 391068 | BM553: 391068 | BN553: 391068 | BO553: 391068 | BP553: 391068 | BQ553: 391068 | BR553: 391068 | BS553: 391068 | BT553: 391068 | BU553: 391068 | BV553: 391068 | BW553: 391068 | BX553: 391068 | BY553: 391068 | BZ553: 391068 | CA553: 391068 | CB553: 391068 | CC553: 391068 | CD553: 391068 | CE553: 391068 | CF553: 391068 | CG553: 391068 | CH553: 391068 | CI553: 391068 | CJ553: 391068 | CK553: 391068 | CL553: 391068 | CM553: 391068 | CN553: 391068 | CO553: 391068 | CP553: 391068 | CQ553: 391068 | CR553: 391068 | CS553: 391068 | CT553: 391068 | CU553: 391068 | CV553: 391068 | CW553: 391068 | CX553: 391068 | CY553: 391068 | CZ553: 391068 | DA553: 391068 | DB553: 391068 | DC553: 391068 | DD553: 0 | DE553: 0 | DF553: 0 | DG553: 0 | DH553: 0 | DI553: 0 | DJ553: 0 | DK553: 0 | DL553: 0 | DM553: 0 | DN553: 0 | DO553: 0 | DP553: 0 | DQ553: 0 | DR553: 0 | DS553: 0 | DT553: 0 | DU553: 0 | DV553: 0 | DW553: 0 | DX553: 0 | DY553: 0 | DZ553: 0 | EA553: 0 | EB553: 0 | EC553: 0 | EF553: LTQ30 | EG553: 1 | EH553: 15 | EI553: =EF553&TEXT(EG553,"00")&TEXT(EH553,"00") -> LTQ300115 | EJ553: 0 | EK553: 0 | EL553: 0 | EM553: 0 | EN553: 0 | EO553: 0 | EP553: 0 | EQ553: 0 | ER553: 0 | ES553: 0 | ET553: 0 | EU553: 0 | EV553: 0 | EW553: 0 | EX553: 0 | EY553: 0 | EZ553: 0 | FA553: 0 | FB553: 0 | FC553: 0 | FD553: 0 | FE553: 0 | FF553: 0 | FG553: 0 | FH553: 0 | FI553: 0 | FJ553: 0 | FK553: 0 | FL553: 0 | FM553: 0 | FN553: 0 | FO553: 0 | FP553: 0 | FQ553: 0 | FR553: 0 | FS553: 0 | FT553: 0 | FU553: 0 | FV553: 0 | FW553: 0 | FX553: 0 | FY553: 0 | FZ553: 0 | GA553: 0 | GB553: 0 | GC553: 0 | GD553: 0 | GE553: 0 | GF553: 0 | GG553: 0 | GH553: 0 | GI553: 0 | GJ553: 0 | GK553: 0 | GL553: 0 | GM553: 0 | GN553: 0 | GO553: 0 | GP553: 0 | GQ553: 0 | GR553: 0 | GS553: 0 | GT553: 0 | GU553: 0 | GV553: 0 | GW553: 0 | GX553: 0 | GY553: 0 | GZ553: 0 | HA553: 0 | HB553: 0 | HC553: 0 | HD553: 0 | HE553: 0 | HF553: 0 | HG553: 0 | HH553: 0 | HI553: 0 | HJ553: 0 | HK553: 0 | HL553: 0 | HM553: 0 | HN553: 0 | HO553: 0 | HP553: 391068 | HQ553: 0 | HR553: 0 | HS553: 0 | HT553: 0 | HU553: 0 | HV553: 0 | HW553: 0 | HX553: 0 | HY553: 0 | HZ553: 0 | IA553: 0 | IB553: 0 | IC553: 0 | ID553: 0 | IE553: 0 | IF553: 0 | IG553: 0 | IH553: 0 | II553: 0 | IJ553: 0 | IK553: 0 | IL553: 0 | IM553: 0 | IN553: 0 | IO553: 0 | IP553: 0
S554: LTQ30 | T554: 1 | U554: 16 | V554: =S554&TEXT(T554,"00")&TEXT(U554,"00") -> LTQ300116 | W554: 13239.6 | X554: 26479.2 | Y554: 39718.8 | Z554: 52958.4 | AA554: 66198 | AB554: 79437.6 | AC554: 92677.2 | AD554: 105916.8 | AE554: 119156.4 | AF554: 132396 | AG554: 145635.6 | AH554: 158875.2 | AI554: 172114.8 | AJ554: 185354.4 | AK554: 198594 | AL554: 211833.6 | AM554: 225073.2 | AN554: 238312.8 | AO554: 251552.4 | AP554: 264792 | AQ554: 278031.6 | AR554: 291271.2 | AS554: 304510.8 | AT554: 317750.4 | AU554: 330990 | AV554: 344229.6 | AW554: 357469.2 | AX554: 370708.8 | AY554: 383948.4 | AZ554: 397188 | BA554: 397188 | BB554: 397188 | BC554: 397188 | BD554: 397188 | BE554: 397188 | BF554: 397188 | BG554: 397188 | BH554: 397188 | BI554: 397188 | BJ554: 397188 | BK554: 397188 | BL554: 397188 | BM554: 397188 | BN554: 397188 | BO554: 397188 | BP554: 397188 | BQ554: 397188 | BR554: 397188 | BS554: 397188 | BT554: 397188 | BU554: 397188 | BV554: 397188 | BW554: 397188 | BX554: 397188 | BY554: 397188 | BZ554: 397188 | CA554: 397188 | CB554: 397188 | CC554: 397188 | CD554: 397188 | CE554: 397188 | CF554: 397188 | CG554: 397188 | CH554: 397188 | CI554: 397188 | CJ554: 397188 | CK554: 397188 | CL554: 397188 | CM554: 397188 | CN554: 397188 | CO554: 397188 | CP554: 397188 | CQ554: 397188 | CR554: 397188 | CS554: 397188 | CT554: 397188 | CU554: 397188 | CV554: 397188 | CW554: 397188 | CX554: 397188 | CY554: 397188 | CZ554: 397188 | DA554: 397188 | DB554: 397188 | DC554: 0 | DD554: 0 | DE554: 0 | DF554: 0 | DG554: 0 | DH554: 0 | DI554: 0 | DJ554: 0 | DK554: 0 | DL554: 0 | DM554: 0 | DN554: 0 | DO554: 0 | DP554: 0 | DQ554: 0 | DR554: 0 | DS554: 0 | DT554: 0 | DU554: 0 | DV554: 0 | DW554: 0 | DX554: 0 | DY554: 0 | DZ554: 0 | EA554: 0 | EB554: 0 | EC554: 0 | EF554: LTQ30 | EG554: 1 | EH554: 16 | EI554: =EF554&TEXT(EG554,"00")&TEXT(EH554,"00") -> LTQ300116 | EJ554: 0 | EK554: 0 | EL554: 0 | EM554: 0 | EN554: 0 | EO554: 0 | EP554: 0 | EQ554: 0 | ER554: 0 | ES554: 0 | ET554: 0 | EU554: 0 | EV554: 0 | EW554: 0 | EX554: 0 | EY554: 0 | EZ554: 0 | FA554: 0 | FB554: 0 | FC554: 0 | FD554: 0 | FE554: 0 | FF554: 0 | FG554: 0 | FH554: 0 | FI554: 0 | FJ554: 0 | FK554: 0 | FL554: 0 | FM554: 0 | FN554: 0 | FO554: 0 | FP554: 0 | FQ554: 0 | FR554: 0 | FS554: 0 | FT554: 0 | FU554: 0 | FV554: 0 | FW554: 0 | FX554: 0 | FY554: 0 | FZ554: 0 | GA554: 0 | GB554: 0 | GC554: 0 | GD554: 0 | GE554: 0 | GF554: 0 | GG554: 0 | GH554: 0 | GI554: 0 | GJ554: 0 | GK554: 0 | GL554: 0 | GM554: 0 | GN554: 0 | GO554: 0 | GP554: 0 | GQ554: 0 | GR554: 0 | GS554: 0 | GT554: 0 | GU554: 0 | GV554: 0 | GW554: 0 | GX554: 0 | GY554: 0 | GZ554: 0 | HA554: 0 | HB554: 0 | HC554: 0 | HD554: 0 | HE554: 0 | HF554: 0 | HG554: 0 | HH554: 0 | HI554: 0 | HJ554: 0 | HK554: 0 | HL554: 0 | HM554: 0 | HN554: 0 | HO554: 397188 | HP554: 0 | HQ554: 0 | HR554: 0 | HS554: 0 | HT554: 0 | HU554: 0 | HV554: 0 | HW554: 0 | HX554: 0 | HY554: 0 | HZ554: 0 | IA554: 0 | IB554: 0 | IC554: 0 | ID554: 0 | IE554: 0 | IF554: 0 | IG554: 0 | IH554: 0 | II554: 0 | IJ554: 0 | IK554: 0 | IL554: 0 | IM554: 0 | IN554: 0 | IO554: 0 | IP554: 0
S555: LTQ30 | T555: 1 | U555: 17 | V555: =S555&TEXT(T555,"00")&TEXT(U555,"00") -> LTQ300117 | W555: 13555.8 | X555: 27111.6 | Y555: 40667.4 | Z555: 54223.2 | AA555: 67779 | AB555: 81334.8 | AC555: 94890.6 | AD555: 108446.4 | AE555: 122002.2 | AF555: 135558 | AG555: 149113.8 | AH555: 162669.6 | AI555: 176225.4 | AJ555: 189781.2 | AK555: 203337 | AL555: 216892.8 | AM555: 230448.6 | AN555: 244004.4 | AO555: 257560.2 | AP555: 271116 | AQ555: 284671.8 | AR555: 298227.6 | AS555: 311783.4 | AT555: 325339.2 | AU555: 338895 | AV555: 352450.8 | AW555: 366006.6 | AX555: 379562.4 | AY555: 393118.2 | AZ555: 406674 | BA555: 406674 | BB555: 406674 | BC555: 406674 | BD555: 406674 | BE555: 406674 | BF555: 406674 | BG555: 406674 | BH555: 406674 | BI555: 406674 | BJ555: 406674 | BK555: 406674 | BL555: 406674 | BM555: 406674 | BN555: 406674 | BO555: 406674 | BP555: 406674 | BQ555: 406674 | BR555: 406674 | BS555: 406674 | BT555: 406674 | BU555: 406674 | BV555: 406674 | BW555: 406674 | BX555: 406674 | BY555: 406674 | BZ555: 406674 | CA555: 406674 | CB555: 406674 | CC555: 406674 | CD555: 406674 | CE555: 406674 | CF555: 406674 | CG555: 406674 | CH555: 406674 | CI555: 406674 | CJ555: 406674 | CK555: 406674 | CL555: 406674 | CM555: 406674 | CN555: 406674 | CO555: 406674 | CP555: 406674 | CQ555: 406674 | CR555: 406674 | CS555: 406674 | CT555: 406674 | CU555: 406674 | CV555: 406674 | CW555: 406674 | CX555: 406674 | CY555: 406674 | CZ555: 406674 | DA555: 406674 | DB555: 0 | DC555: 0 | DD555: 0 | DE555: 0 | DF555: 0 | DG555: 0 | DH555: 0 | DI555: 0 | DJ555: 0 | DK555: 0 | DL555: 0 | DM555: 0 | DN555: 0 | DO555: 0 | DP555: 0 | DQ555: 0 | DR555: 0 | DS555: 0 | DT555: 0 | DU555: 0 | DV555: 0 | DW555: 0 | DX555: 0 | DY555: 0 | DZ555: 0 | EA555: 0 | EB555: 0 | EC555: 0 | EF555: LTQ30 | EG555: 1 | EH555: 17 | EI555: =EF555&TEXT(EG555,"00")&TEXT(EH555,"00") -> LTQ300117 | EJ555: 0 | EK555: 0 | EL555: 0 | EM555: 0 | EN555: 0 | EO555: 0 | EP555: 0 | EQ555: 0 | ER555: 0 | ES555: 0 | ET555: 0 | EU555: 0 | EV555: 0 | EW555: 0 | EX555: 0 | EY555: 0 | EZ555: 0 | FA555: 0 | FB555: 0 | FC555: 0 | FD555: 0 | FE555: 0 | FF555: 0 | FG555: 0 | FH555: 0 | FI555: 0 | FJ555: 0 | FK555: 0 | FL555: 0 | FM555: 0 | FN555: 0 | FO555: 0 | FP555: 0 | FQ555: 0 | FR555: 0 | FS555: 0 | FT555: 0 | FU555: 0 | FV555: 0 | FW555: 0 | FX555: 0 | FY555: 0 | FZ555: 0 | GA555: 0 | GB555: 0 | GC555: 0 | GD555: 0 | GE555: 0 | GF555: 0 | GG555: 0 | GH555: 0 | GI555: 0 | GJ555: 0 | GK555: 0 | GL555: 0 | GM555: 0 | GN555: 0 | GO555: 0 | GP555: 0 | GQ555: 0 | GR555: 0 | GS555: 0 | GT555: 0 | GU555: 0 | GV555: 0 | GW555: 0 | GX555: 0 | GY555: 0 | GZ555: 0 | HA555: 0 | HB555: 0 | HC555: 0 | HD555: 0 | HE555: 0 | HF555: 0 | HG555: 0 | HH555: 0 | HI555: 0 | HJ555: 0 | HK555: 0 | HL555: 0 | HM555: 0 | HN555: 406674 | HO555: 0 | HP555: 0 | HQ555: 0 | HR555: 0 | HS555: 0 | HT555: 0 | HU555: 0 | HV555: 0 | HW555: 0 | HX555: 0 | HY555: 0 | HZ555: 0 | IA555: 0 | IB555: 0 | IC555: 0 | ID555: 0 | IE555: 0 | IF555: 0 | IG555: 0 | IH555: 0 | II555: 0 | IJ555: 0 | IK555: 0 | IL555: 0 | IM555: 0 | IN555: 0 | IO555: 0 | IP555: 0
S556: LTQ30 | T556: 1 | U556: 18 | V556: =S556&TEXT(T556,"00")&TEXT(U556,"00") -> LTQ300118 | W556: 13872 | X556: 27744 | Y556: 41616 | Z556: 55488 | AA556: 69360 | AB556: 83232 | AC556: 97104 | AD556: 110976 | AE556: 124848 | AF556: 138720 | AG556: 152592 | AH556: 166464 | AI556: 180336 | AJ556: 194208 | AK556: 208080 | AL556: 221952 | AM556: 235824 | AN556: 249696 | AO556: 263568 | AP556: 277440 | AQ556: 291312 | AR556: 305184 | AS556: 319056 | AT556: 332928 | AU556: 346800 | AV556: 360672 | AW556: 374544 | AX556: 388416 | AY556: 402288 | AZ556: 416160 | BA556: 416160 | BB556: 416160 | BC556: 416160 | BD556: 416160 | BE556: 416160 | BF556: 416160 | BG556: 416160 | BH556: 416160 | BI556: 416160 | BJ556: 416160 | BK556: 416160 | BL556: 416160 | BM556: 416160 | BN556: 416160 | BO556: 416160 | BP556: 416160 | BQ556: 416160 | BR556: 416160 | BS556: 416160 | BT556: 416160 | BU556: 416160 | BV556: 416160 | BW556: 416160 | BX556: 416160 | BY556: 416160 | BZ556: 416160 | CA556: 416160 | CB556: 416160 | CC556: 416160 | CD556: 416160 | CE556: 416160 | CF556: 416160 | CG556: 416160 | CH556: 416160 | CI556: 416160 | CJ556: 416160 | CK556: 416160 | CL556: 416160 | CM556: 416160 | CN556: 416160 | CO556: 416160 | CP556: 416160 | CQ556: 416160 | CR556: 416160 | CS556: 416160 | CT556: 416160 | CU556: 416160 | CV556: 416160 | CW556: 416160 | CX556: 416160 | CY556: 416160 | CZ556: 416160 | DA556: 0 | DB556: 0 | DC556: 0 | DD556: 0 | DE556: 0 | DF556: 0 | DG556: 0 | DH556: 0 | DI556: 0 | DJ556: 0 | DK556: 0 | DL556: 0 | DM556: 0 | DN556: 0 | DO556: 0 | DP556: 0 | DQ556: 0 | DR556: 0 | DS556: 0 | DT556: 0 | DU556: 0 | DV556: 0 | DW556: 0 | DX556: 0 | DY556: 0 | DZ556: 0 | EA556: 0 | EB556: 0 | EC556: 0 | EF556: LTQ30 | EG556: 1 | EH556: 18 | EI556: =EF556&TEXT(EG556,"00")&TEXT(EH556,"00") -> LTQ300118 | EJ556: 0 | EK556: 0 | EL556: 0 | EM556: 0 | EN556: 0 | EO556: 0 | EP556: 0 | EQ556: 0 | ER556: 0 | ES556: 0 | ET556: 0 | EU556: 0 | EV556: 0 | EW556: 0 | EX556: 0 | EY556: 0 | EZ556: 0 | FA556: 0 | FB556: 0 | FC556: 0 | FD556: 0 | FE556: 0 | FF556: 0 | FG556: 0 | FH556: 0 | FI556: 0 | FJ556: 0 | FK556: 0 | FL556: 0 | FM556: 0 | FN556: 0 | FO556: 0 | FP556: 0 | FQ556: 0 | FR556: 0 | FS556: 0 | FT556: 0 | FU556: 0 | FV556: 0 | FW556: 0 | FX556: 0 | FY556: 0 | FZ556: 0 | GA556: 0 | GB556: 0 | GC556: 0 | GD556: 0 | GE556: 0 | GF556: 0 | GG556: 0 | GH556: 0 | GI556: 0 | GJ556: 0 | GK556: 0 | GL556: 0 | GM556: 0 | GN556: 0 | GO556: 0 | GP556: 0 | GQ556: 0 | GR556: 0 | GS556: 0 | GT556: 0 | GU556: 0 | GV556: 0 | GW556: 0 | GX556: 0 | GY556: 0 | GZ556: 0 | HA556: 0 | HB556: 0 | HC556: 0 | HD556: 0 | HE556: 0 | HF556: 0 | HG556: 0 | HH556: 0 | HI556: 0 | HJ556: 0 | HK556: 0 | HL556: 0 | HM556: 416160 | HN556: 0 | HO556: 0 | HP556: 0 | HQ556: 0 | HR556: 0 | HS556: 0 | HT556: 0 | HU556: 0 | HV556: 0 | HW556: 0 | HX556: 0 | HY556: 0 | HZ556: 0 | IA556: 0 | IB556: 0 | IC556: 0 | ID556: 0 | IE556: 0 | IF556: 0 | IG556: 0 | IH556: 0 | II556: 0 | IJ556: 0 | IK556: 0 | IL556: 0 | IM556: 0 | IN556: 0 | IO556: 0 | IP556: 0
S557: LTQ30 | T557: 1 | U557: 19 | V557: =S557&TEXT(T557,"00")&TEXT(U557,"00") -> LTQ300119 | W557: 14086.2 | X557: 28172.4 | Y557: 42258.6 | Z557: 56344.8 | AA557: 70431 | AB557: 84517.2 | AC557: 98603.4 | AD557: 112689.6 | AE557: 126775.8 | AF557: 140862 | AG557: 154948.2 | AH557: 169034.4 | AI557: 183120.6 | AJ557: 197206.8 | AK557: 211293 | AL557: 225379.2 | AM557: 239465.4 | AN557: 253551.6 | AO557: 267637.8 | AP557: 281724 | AQ557: 295810.2 | AR557: 309896.4 | AS557: 323982.6 | AT557: 338068.8 | AU557: 352155 | AV557: 366241.2 | AW557: 380327.4 | AX557: 394413.6 | AY557: 408499.8 | AZ557: 422586 | BA557: 422586 | BB557: 422586 | BC557: 422586 | BD557: 422586 | BE557: 422586 | BF557: 422586 | BG557: 422586 | BH557: 422586 | BI557: 422586 | BJ557: 422586 | BK557: 422586 | BL557: 422586 | BM557: 422586 | BN557: 422586 | BO557: 422586 | BP557: 422586 | BQ557: 422586 | BR557: 422586 | BS557: 422586 | BT557: 422586 | BU557: 422586 | BV557: 422586 | BW557: 422586 | BX557: 422586 | BY557: 422586 | BZ557: 422586 | CA557: 422586 | CB557: 422586 | CC557: 422586 | CD557: 422586 | CE557: 422586 | CF557: 422586 | CG557: 422586 | CH557: 422586 | CI557: 422586 | CJ557: 422586 | CK557: 422586 | CL557: 422586 | CM557: 422586 | CN557: 422586 | CO557: 422586 | CP557: 422586 | CQ557: 422586 | CR557: 422586 | CS557: 422586 | CT557: 422586 | CU557: 422586 | CV557: 422586 | CW557: 422586 | CX557: 422586 | CY557: 422586 | CZ557: 0 | DA557: 0 | DB557: 0 | DC557: 0 | DD557: 0 | DE557: 0 | DF557: 0 | DG557: 0 | DH557: 0 | DI557: 0 | DJ557: 0 | DK557: 0 | DL557: 0 | DM557: 0 | DN557: 0 | DO557: 0 | DP557: 0 | DQ557: 0 | DR557: 0 | DS557: 0 | DT557: 0 | DU557: 0 | DV557: 0 | DW557: 0 | DX557: 0 | DY557: 0 | DZ557: 0 | EA557: 0 | EB557: 0 | EC557: 0 | EF557: LTQ30 | EG557: 1 | EH557: 19 | EI557: =EF557&TEXT(EG557,"00")&TEXT(EH557,"00") -> LTQ300119 | EJ557: 0 | EK557: 0 | EL557: 0 | EM557: 0 | EN557: 0 | EO557: 0 | EP557: 0 | EQ557: 0 | ER557: 0 | ES557: 0 | ET557: 0 | EU557: 0 | EV557: 0 | EW557: 0 | EX557: 0 | EY557: 0 | EZ557: 0 | FA557: 0 | FB557: 0 | FC557: 0 | FD557: 0 | FE557: 0 | FF557: 0 | FG557: 0 | FH557: 0 | FI557: 0 | FJ557: 0 | FK557: 0 | FL557: 0 | FM557: 0 | FN557: 0 | FO557: 0 | FP557: 0 | FQ557: 0 | FR557: 0 | FS557: 0 | FT557: 0 | FU557: 0 | FV557: 0 | FW557: 0 | FX557: 0 | FY557: 0 | FZ557: 0 | GA557: 0 | GB557: 0 | GC557: 0 | GD557: 0 | GE557: 0 | GF557: 0 | GG557: 0 | GH557: 0 | GI557: 0 | GJ557: 0 | GK557: 0 | GL557: 0 | GM557: 0 | GN557: 0 | GO557: 0 | GP557: 0 | GQ557: 0 | GR557: 0 | GS557: 0 | GT557: 0 | GU557: 0 | GV557: 0 | GW557: 0 | GX557: 0 | GY557: 0 | GZ557: 0 | HA557: 0 | HB557: 0 | HC557: 0 | HD557: 0 | HE557: 0 | HF557: 0 | HG557: 0 | HH557: 0 | HI557: 0 | HJ557: 0 | HK557: 0 | HL557: 422586 | HM557: 0 | HN557: 0 | HO557: 0 | HP557: 0 | HQ557: 0 | HR557: 0 | HS557: 0 | HT557: 0 | HU557: 0 | HV557: 0 | HW557: 0 | HX557: 0 | HY557: 0 | HZ557: 0 | IA557: 0 | IB557: 0 | IC557: 0 | ID557: 0 | IE557: 0 | IF557: 0 | IG557: 0 | IH557: 0 | II557: 0 | IJ557: 0 | IK557: 0 | IL557: 0 | IM557: 0 | IN557: 0 | IO557: 0 | IP557: 0
S558: LTQ30 | T558: 1 | U558: 20 | V558: =S558&TEXT(T558,"00")&TEXT(U558,"00") -> LTQ300120 | W558: 14606.4 | X558: 29212.8 | Y558: 43819.2 | Z558: 58425.6 | AA558: 73032 | AB558: 87638.4 | AC558: 102244.8 | AD558: 116851.2 | AE558: 131457.6 | AF558: 146064 | AG558: 160670.4 | AH558: 175276.8 | AI558: 189883.2 | AJ558: 204489.6 | AK558: 219096 | AL558: 233702.4 | AM558: 248308.8 | AN558: 262915.2 | AO558: 277521.6 | AP558: 292128 | AQ558: 306734.4 | AR558: 321340.8 | AS558: 335947.2 | AT558: 350553.6 | AU558: 365160 | AV558: 379766.4 | AW558: 394372.8 | AX558: 408979.2 | AY558: 423585.6 | AZ558: 438192 | BA558: 438192 | BB558: 438192 | BC558: 438192 | BD558: 438192 | BE558: 438192 | BF558: 438192 | BG558: 438192 | BH558: 438192 | BI558: 438192 | BJ558: 438192 | BK558: 438192 | BL558: 438192 | BM558: 438192 | BN558: 438192 | BO558: 438192 | BP558: 438192 | BQ558: 438192 | BR558: 438192 | BS558: 438192 | BT558: 438192 | BU558: 438192 | BV558: 438192 | BW558: 438192 | BX558: 438192 | BY558: 438192 | BZ558: 438192 | CA558: 438192 | CB558: 438192 | CC558: 438192 | CD558: 438192 | CE558: 438192 | CF558: 438192 | CG558: 438192 | CH558: 438192 | CI558: 438192 | CJ558: 438192 | CK558: 438192 | CL558: 438192 | CM558: 438192 | CN558: 438192 | CO558: 438192 | CP558: 438192 | CQ558: 438192 | CR558: 438192 | CS558: 438192 | CT558: 438192 | CU558: 438192 | CV558: 438192 | CW558: 438192 | CX558: 438192 | CY558: 0 | CZ558: 0 | DA558: 0 | DB558: 0 | DC558: 0 | DD558: 0 | DE558: 0 | DF558: 0 | DG558: 0 | DH558: 0 | DI558: 0 | DJ558: 0 | DK558: 0 | DL558: 0 | DM558: 0 | DN558: 0 | DO558: 0 | DP558: 0 | DQ558: 0 | DR558: 0 | DS558: 0 | DT558: 0 | DU558: 0 | DV558: 0 | DW558: 0 | DX558: 0 | DY558: 0 | DZ558: 0 | EA558: 0 | EB558: 0 | EC558: 0 | EF558: LTQ30 | EG558: 1 | EH558: 20 | EI558: =EF558&TEXT(EG558,"00")&TEXT(EH558,"00") -> LTQ300120 | EJ558: 0 | EK558: 0 | EL558: 0 | EM558: 0 | EN558: 0 | EO558: 0 | EP558: 0 | EQ558: 0 | ER558: 0 | ES558: 0 | ET558: 0 | EU558: 0 | EV558: 0 | EW558: 0 | EX558: 0 | EY558: 0 | EZ558: 0 | FA558: 0 | FB558: 0 | FC558: 0 | FD558: 0 | FE558: 0 | FF558: 0 | FG558: 0 | FH558: 0 | FI558: 0 | FJ558: 0 | FK558: 0 | FL558: 0 | FM558: 0 | FN558: 0 | FO558: 0 | FP558: 0 | FQ558: 0 | FR558: 0 | FS558: 0 | FT558: 0 | FU558: 0 | FV558: 0 | FW558: 0 | FX558: 0 | FY558: 0 | FZ558: 0 | GA558: 0 | GB558: 0 | GC558: 0 | GD558: 0 | GE558: 0 | GF558: 0 | GG558: 0 | GH558: 0 | GI558: 0 | GJ558: 0 | GK558: 0 | GL558: 0 | GM558: 0 | GN558: 0 | GO558: 0 | GP558: 0 | GQ558: 0 | GR558: 0 | GS558: 0 | GT558: 0 | GU558: 0 | GV558: 0 | GW558: 0 | GX558: 0 | GY558: 0 | GZ558: 0 | HA558: 0 | HB558: 0 | HC558: 0 | HD558: 0 | HE558: 0 | HF558: 0 | HG558: 0 | HH558: 0 | HI558: 0 | HJ558: 0 | HK558: 438192 | HL558: 0 | HM558: 0 | HN558: 0 | HO558: 0 | HP558: 0 | HQ558: 0 | HR558: 0 | HS558: 0 | HT558: 0 | HU558: 0 | HV558: 0 | HW558: 0 | HX558: 0 | HY558: 0 | HZ558: 0 | IA558: 0 | IB558: 0 | IC558: 0 | ID558: 0 | IE558: 0 | IF558: 0 | IG558: 0 | IH558: 0 | II558: 0 | IJ558: 0 | IK558: 0 | IL558: 0 | IM558: 0 | IN558: 0 | IO558: 0 | IP558: 0
S559: LTQ30 | T559: 1 | U559: 21 | V559: =S559&TEXT(T559,"00")&TEXT(U559,"00") -> LTQ300121 | W559: 15034.8 | X559: 30069.6 | Y559: 45104.4 | Z559: 60139.2 | AA559: 75174 | AB559: 90208.8 | AC559: 105243.6 | AD559: 120278.4 | AE559: 135313.2 | AF559: 150348 | AG559: 165382.8 | AH559: 180417.6 | AI559: 195452.4 | AJ559: 210487.2 | AK559: 225522 | AL559: 240556.8 | AM559: 255591.6 | AN559: 270626.4 | AO559: 285661.2 | AP559: 300696 | AQ559: 315730.8 | AR559: 330765.6 | AS559: 345800.4 | AT559: 360835.2 | AU559: 375870 | AV559: 390904.8 | AW559: 405939.6 | AX559: 420974.4 | AY559: 436009.2 | AZ559: 451044 | BA559: 451044 | BB559: 451044 | BC559: 451044 | BD559: 451044 | BE559: 451044 | BF559: 451044 | BG559: 451044 | BH559: 451044 | BI559: 451044 | BJ559: 451044 | BK559: 451044 | BL559: 451044 | BM559: 451044 | BN559: 451044 | BO559: 451044 | BP559: 451044 | BQ559: 451044 | BR559: 451044 | BS559: 451044 | BT559: 451044 | BU559: 451044 | BV559: 451044 | BW559: 451044 | BX559: 451044 | BY559: 451044 | BZ559: 451044 | CA559: 451044 | CB559: 451044 | CC559: 451044 | CD559: 451044 | CE559: 451044 | CF559: 451044 | CG559: 451044 | CH559: 451044 | CI559: 451044 | CJ559: 451044 | CK559: 451044 | CL559: 451044 | CM559: 451044 | CN559: 451044 | CO559: 451044 | CP559: 451044 | CQ559: 451044 | CR559: 451044 | CS559: 451044 | CT559: 451044 | CU559: 451044 | CV559: 451044 | CW559: 451044 | CX559: 0 | CY559: 0 | CZ559: 0 | DA559: 0 | DB559: 0 | DC559: 0 | DD559: 0 | DE559: 0 | DF559: 0 | DG559: 0 | DH559: 0 | DI559: 0 | DJ559: 0 | DK559: 0 | DL559: 0 | DM559: 0 | DN559: 0 | DO559: 0 | DP559: 0 | DQ559: 0 | DR559: 0 | DS559: 0 | DT559: 0 | DU559: 0 | DV559: 0 | DW559: 0 | DX559: 0 | DY559: 0 | DZ559: 0 | EA559: 0 | EB559: 0 | EC559: 0 | EF559: LTQ30 | EG559: 1 | EH559: 21 | EI559: =EF559&TEXT(EG559,"00")&TEXT(EH559,"00") -> LTQ300121 | EJ559: 0 | EK559: 0 | EL559: 0 | EM559: 0 | EN559: 0 | EO559: 0 | EP559: 0 | EQ559: 0 | ER559: 0 | ES559: 0 | ET559: 0 | EU559: 0 | EV559: 0 | EW559: 0 | EX559: 0 | EY559: 0 | EZ559: 0 | FA559: 0 | FB559: 0 | FC559: 0 | FD559: 0 | FE559: 0 | FF559: 0 | FG559: 0 | FH559: 0 | FI559: 0 | FJ559: 0 | FK559: 0 | FL559: 0 | FM559: 0 | FN559: 0 | FO559: 0 | FP559: 0 | FQ559: 0 | FR559: 0 | FS559: 0 | FT559: 0 | FU559: 0 | FV559: 0 | FW559: 0 | FX559: 0 | FY559: 0 | FZ559: 0 | GA559: 0 | GB559: 0 | GC559: 0 | GD559: 0 | GE559: 0 | GF559: 0 | GG559: 0 | GH559: 0 | GI559: 0 | GJ559: 0 | GK559: 0 | GL559: 0 | GM559: 0 | GN559: 0 | GO559: 0 | GP559: 0 | GQ559: 0 | GR559: 0 | GS559: 0 | GT559: 0 | GU559: 0 | GV559: 0 | GW559: 0 | GX559: 0 | GY559: 0 | GZ559: 0 | HA559: 0 | HB559: 0 | HC559: 0 | HD559: 0 | HE559: 0 | HF559: 0 | HG559: 0 | HH559: 0 | HI559: 0 | HJ559: 451044 | HK559: 0 | HL559: 0 | HM559: 0 | HN559: 0 | HO559: 0 | HP559: 0 | HQ559: 0 | HR559: 0 | HS559: 0 | HT559: 0 | HU559: 0 | HV559: 0 | HW559: 0 | HX559: 0 | HY559: 0 | HZ559: 0 | IA559: 0 | IB559: 0 | IC559: 0 | ID559: 0 | IE559: 0 | IF559: 0 | IG559: 0 | IH559: 0 | II559: 0 | IJ559: 0 | IK559: 0 | IL559: 0 | IM559: 0 | IN559: 0 | IO559: 0 | IP559: 0
S560: LTQ30 | T560: 1 | U560: 22 | V560: =S560&TEXT(T560,"00")&TEXT(U560,"00") -> LTQ300122 | W560: 15453 | X560: 30906 | Y560: 46359 | Z560: 61812 | AA560: 77265 | AB560: 92718 | AC560: 108171 | AD560: 123624 | AE560: 139077 | AF560: 154530 | AG560: 169983 | AH560: 185436 | AI560: 200889 | AJ560: 216342 | AK560: 231795 | AL560: 247248 | AM560: 262701 | AN560: 278154 | AO560: 293607 | AP560: 309060 | AQ560: 324513 | AR560: 339966 | AS560: 355419 | AT560: 370872 | AU560: 386325 | AV560: 401778 | AW560: 417231 | AX560: 432684 | AY560: 448137 | AZ560: 463590 | BA560: 463590 | BB560: 463590 | BC560: 463590 | BD560: 463590 | BE560: 463590 | BF560: 463590 | BG560: 463590 | BH560: 463590 | BI560: 463590 | BJ560: 463590 | BK560: 463590 | BL560: 463590 | BM560: 463590 | BN560: 463590 | BO560: 463590 | BP560: 463590 | BQ560: 463590 | BR560: 463590 | BS560: 463590 | BT560: 463590 | BU560: 463590 | BV560: 463590 | BW560: 463590 | BX560: 463590 | BY560: 463590 | BZ560: 463590 | CA560: 463590 | CB560: 463590 | CC560: 463590 | CD560: 463590 | CE560: 463590 | CF560: 463590 | CG560: 463590 | CH560: 463590 | CI560: 463590 | CJ560: 463590 | CK560: 463590 | CL560: 463590 | CM560: 463590 | CN560: 463590 | CO560: 463590 | CP560: 463590 | CQ560: 463590 | CR560: 463590 | CS560: 463590 | CT560: 463590 | CU560: 463590 | CV560: 463590 | CW560: 0 | CX560: 0 | CY560: 0 | CZ560: 0 | DA560: 0 | DB560: 0 | DC560: 0 | DD560: 0 | DE560: 0 | DF560: 0 | DG560: 0 | DH560: 0 | DI560: 0 | DJ560: 0 | DK560: 0 | DL560: 0 | DM560: 0 | DN560: 0 | DO560: 0 | DP560: 0 | DQ560: 0 | DR560: 0 | DS560: 0 | DT560: 0 | DU560: 0 | DV560: 0 | DW560: 0 | DX560: 0 | DY560: 0 | DZ560: 0 | EA560: 0 | EB560: 0 | EC560: 0 | EF560: LTQ30 | EG560: 1 | EH560: 22 | EI560: =EF560&TEXT(EG560,"00")&TEXT(EH560,"00") -> LTQ300122 | EJ560: 0 | EK560: 0 | EL560: 0 | EM560: 0 | EN560: 0 | EO560: 0 | EP560: 0 | EQ560: 0 | ER560: 0 | ES560: 0 | ET560: 0 | EU560: 0 | EV560: 0 | EW560: 0 | EX560: 0 | EY560: 0 | EZ560: 0 | FA560: 0 | FB560: 0 | FC560: 0 | FD560: 0 | FE560: 0 | FF560: 0 | FG560: 0 | FH560: 0 | FI560: 0 | FJ560: 0 | FK560: 0 | FL560: 0 | FM560: 0 | FN560: 0 | FO560: 0 | FP560: 0 | FQ560: 0 | FR560: 0 | FS560: 0 | FT560: 0 | FU560: 0 | FV560: 0 | FW560: 0 | FX560: 0 | FY560: 0 | FZ560: 0 | GA560: 0 | GB560: 0 | GC560: 0 | GD560: 0 | GE560: 0 | GF560: 0 | GG560: 0 | GH560: 0 | GI560: 0 | GJ560: 0 | GK560: 0 | GL560: 0 | GM560: 0 | GN560: 0 | GO560: 0 | GP560: 0 | GQ560: 0 | GR560: 0 | GS560: 0 | GT560: 0 | GU560: 0 | GV560: 0 | GW560: 0 | GX560: 0 | GY560: 0 | GZ560: 0 | HA560: 0 | HB560: 0 | HC560: 0 | HD560: 0 | HE560: 0 | HF560: 0 | HG560: 0 | HH560: 0 | HI560: 463590 | HJ560: 0 | HK560: 0 | HL560: 0 | HM560: 0 | HN560: 0 | HO560: 0 | HP560: 0 | HQ560: 0 | HR560: 0 | HS560: 0 | HT560: 0 | HU560: 0 | HV560: 0 | HW560: 0 | HX560: 0 | HY560: 0 | HZ560: 0 | IA560: 0 | IB560: 0 | IC560: 0 | ID560: 0 | IE560: 0 | IF560: 0 | IG560: 0 | IH560: 0 | II560: 0 | IJ560: 0 | IK560: 0 | IL560: 0 | IM560: 0 | IN560: 0 | IO560: 0 | IP560: 0
...

Sheet RDATA
A1: =OP!$C$22 -> LTQ | B1: =IF($F$2>0,1,"") | G1: 1 | H1: =IF(H2<>A2&A1,"富邦人壽官網尚未公告"&A2&"宣告利率，目前使用"&LEFT($H$2,8)&"宣告利率，試算當月宣告利率以富邦人壽官網公告為準。","") -> 富邦人壽官網尚未公告115 / 8 宣告利率，目前使用宣告利率，試算當月宣告利率以富邦人壽官網公告為準。 | I1: =IF(H1="",1,"")
A2: =YEAR(TODAY())-1911&" / "&MONTH(TODAY())&" " -> 115 / 8 | D2: key | E2: 宣告利率 | F2: =SUM($F$3:$F$200) -> 0 | G2: 1 | I2: =IF(OP!$C$3<J2,K2,L2) -> 0.0175 | J2: 46023 | K2: 0.0175 | L2: 0.0175
B3: =IF(OR(D3="",D3=0,RIGHT(D3,LEN($A$1))<>$A$1),,(LEFT($D3,3)*100)+MID($D3,7,IF(OR(AND(LEN($A$1)=3,LEN($D3)=12),AND(LEN($A$1)=4,LEN($D3)=13)),2,1))*1) -> 0 | C3: =IF($B3=0,,RANK($B3,$B$3:$B$78)) -> 0 | F3: =IF(AND(RIGHT($D3,LEN($A$1))<>$A$1,$D3<>""),1,0) -> 0 | G3: 2 | H3: =IF(ISNA(VLOOKUP($G3,$C:$E,2,0)),"",VLOOKUP($G3,$C:$E,2,0)) | I3: =IF(ISNA(VLOOKUP($G3,$C:$E,3,0)),"",VLOOKUP($G3,$C:$E,3,0)) | J3: 45658 | K3: 0.0162 | L3: 0.0175
A4: =COUNTIF($D:$D,$A$3) -> 0 | B4: =IF(OR(D4="",D4=0,RIGHT(D4,LEN($A$1))<>$A$1),,(LEFT($D4,3)*100)+MID($D4,7,IF(OR(AND(LEN($A$1)=3,LEN($D4)=12),AND(LEN($A$1)=4,LEN($D4)=13)),2,1))*1) -> 0 | C4: =IF($B4=0,,RANK($B4,$B$3:$B$78)) -> 0 | F4: =IF(AND(RIGHT($D4,LEN($A$1))<>$A$1,$D4<>""),1,0) -> 0 | G4: 3 | H4: =IF(ISNA(VLOOKUP($G4,$C:$E,2,0)),"",VLOOKUP($G4,$C:$E,2,0)) | I4: =IF(ISNA(VLOOKUP($G4,$C:$E,3,0)),"",VLOOKUP($G4,$C:$E,3,0)) | J4: 45292 | K4: 0.015 | L4: 0.0162
B5: =IF(OR(D5="",D5=0,RIGHT(D5,LEN($A$1))<>$A$1),,(LEFT($D5,3)*100)+MID($D5,7,IF(OR(AND(LEN($A$1)=3,LEN($D5)=12),AND(LEN($A$1)=4,LEN($D5)=13)),2,1))*1) -> 0 | C5: =IF($B5=0,,RANK($B5,$B$3:$B$78)) -> 0 | F5: =IF(AND(RIGHT($D5,LEN($A$1))<>$A$1,$D5<>""),1,0) -> 0 | G5: 4 | H5: =IF(ISNA(VLOOKUP($G5,$C:$E,2,0)),"",VLOOKUP($G5,$C:$E,2,0)) | I5: =IF(ISNA(VLOOKUP($G5,$C:$E,3,0)),"",VLOOKUP($G5,$C:$E,3,0))
B6: =IF(OR(D6="",D6=0,RIGHT(D6,LEN($A$1))<>$A$1),,(LEFT($D6,3)*100)+MID($D6,7,IF(OR(AND(LEN($A$1)=3,LEN($D6)=12),AND(LEN($A$1)=4,LEN($D6)=13)),2,1))*1) -> 0 | C6: =IF($B6=0,,RANK($B6,$B$3:$B$78)) -> 0 | F6: =IF(AND(RIGHT($D6,LEN($A$1))<>$A$1,$D6<>""),1,0) -> 0 | G6: 5 | H6: =IF(ISNA(VLOOKUP($G6,$C:$E,2,0)),"",VLOOKUP($G6,$C:$E,2,0)) | I6: =IF(ISNA(VLOOKUP($G6,$C:$E,3,0)),"",VLOOKUP($G6,$C:$E,3,0))
B7: =IF(OR(D7="",D7=0,RIGHT(D7,LEN($A$1))<>$A$1),,(LEFT($D7,3)*100)+MID($D7,7,IF(OR(AND(LEN($A$1)=3,LEN($D7)=12),AND(LEN($A$1)=4,LEN($D7)=13)),2,1))*1) -> 0 | C7: =IF($B7=0,,RANK($B7,$B$3:$B$78)) -> 0 | F7: =IF(AND(RIGHT($D7,LEN($A$1))<>$A$1,$D7<>""),1,0) -> 0 | G7: 6 | H7: =IF(ISNA(VLOOKUP($G7,$C:$E,2,0)),"",VLOOKUP($G7,$C:$E,2,0)) | I7: =IF(ISNA(VLOOKUP($G7,$C:$E,3,0)),"",VLOOKUP($G7,$C:$E,3,0))
B8: =IF(OR(D8="",D8=0,RIGHT(D8,LEN($A$1))<>$A$1),,(LEFT($D8,3)*100)+MID($D8,7,IF(OR(AND(LEN($A$1)=3,LEN($D8)=12),AND(LEN($A$1)=4,LEN($D8)=13)),2,1))*1) -> 0 | C8: =IF($B8=0,,RANK($B8,$B$3:$B$78)) -> 0 | F8: =IF(AND(RIGHT($D8,LEN($A$1))<>$A$1,$D8<>""),1,0) -> 0 | G8: 7 | H8: =IF(ISNA(VLOOKUP($G8,$C:$E,2,0)),"",VLOOKUP($G8,$C:$E,2,0)) | I8: =IF(ISNA(VLOOKUP($G8,$C:$E,3,0)),"",VLOOKUP($G8,$C:$E,3,0))
B9: =IF(OR(D9="",D9=0,RIGHT(D9,LEN($A$1))<>$A$1),,(LEFT($D9,3)*100)+MID($D9,7,IF(OR(AND(LEN($A$1)=3,LEN($D9)=12),AND(LEN($A$1)=4,LEN($D9)=13)),2,1))*1) -> 0 | C9: =IF($B9=0,,RANK($B9,$B$3:$B$78)) -> 0 | F9: =IF(AND(RIGHT($D9,LEN($A$1))<>$A$1,$D9<>""),1,0) -> 0 | G9: 8 | H9: =IF(ISNA(VLOOKUP($G9,$C:$E,2,0)),"",VLOOKUP($G9,$C:$E,2,0)) | I9: =IF(ISNA(VLOOKUP($G9,$C:$E,3,0)),"",VLOOKUP($G9,$C:$E,3,0))
B10: =IF(OR(D10="",D10=0,RIGHT(D10,LEN($A$1))<>$A$1),,(LEFT($D10,3)*100)+MID($D10,7,IF(OR(AND(LEN($A$1)=3,LEN($D10)=12),AND(LEN($A$1)=4,LEN($D10)=13)),2,1))*1) -> 0 | C10: =IF($B10=0,,RANK($B10,$B$3:$B$78)) -> 0 | F10: =IF(AND(RIGHT($D10,LEN($A$1))<>$A$1,$D10<>""),1,0) -> 0 | G10: 9 | H10: =IF(ISNA(VLOOKUP($G10,$C:$E,2,0)),"",VLOOKUP($G10,$C:$E,2,0)) | I10: =IF(ISNA(VLOOKUP($G10,$C:$E,3,0)),"",VLOOKUP($G10,$C:$E,3,0))
B11: =IF(OR(D11="",D11=0,RIGHT(D11,LEN($A$1))<>$A$1),,(LEFT($D11,3)*100)+MID($D11,7,IF(OR(AND(LEN($A$1)=3,LEN($D11)=12),AND(LEN($A$1)=4,LEN($D11)=13)),2,1))*1) -> 0 | C11: =IF($B11=0,,RANK($B11,$B$3:$B$78)) -> 0 | F11: =IF(AND(RIGHT($D11,LEN($A$1))<>$A$1,$D11<>""),1,0) -> 0 | G11: 10 | H11: =IF(ISNA(VLOOKUP($G11,$C:$E,2,0)),"",VLOOKUP($G11,$C:$E,2,0)) | I11: =IF(ISNA(VLOOKUP($G11,$C:$E,3,0)),"",VLOOKUP($G11,$C:$E,3,0))
B12: =IF(OR(D12="",D12=0,RIGHT(D12,LEN($A$1))<>$A$1),,(LEFT($D12,3)*100)+MID($D12,7,IF(OR(AND(LEN($A$1)=3,LEN($D12)=12),AND(LEN($A$1)=4,LEN($D12)=13)),2,1))*1) -> 0 | C12: =IF($B12=0,,RANK($B12,$B$3:$B$78)) -> 0 | F12: =IF(AND(RIGHT($D12,LEN($A$1))<>$A$1,$D12<>""),1,0) -> 0 | G12: 11 | H12: =IF(ISNA(VLOOKUP($G12,$C:$E,2,0)),"",VLOOKUP($G12,$C:$E,2,0)) | I12: =IF(ISNA(VLOOKUP($G12,$C:$E,3,0)),"",VLOOKUP($G12,$C:$E,3,0))
B13: =IF(OR(D13="",D13=0,RIGHT(D13,LEN($A$1))<>$A$1),,(LEFT($D13,3)*100)+MID($D13,7,IF(OR(AND(LEN($A$1)=3,LEN($D13)=12),AND(LEN($A$1)=4,LEN($D13)=13)),2,1))*1) -> 0 | C13: =IF($B13=0,,RANK($B13,$B$3:$B$78)) -> 0 | F13: =IF(AND(RIGHT($D13,LEN($A$1))<>$A$1,$D13<>""),1,0) -> 0 | G13: 12 | H13: =IF(ISNA(VLOOKUP($G13,$C:$E,2,0)),"",VLOOKUP($G13,$C:$E,2,0)) | I13: =IF(ISNA(VLOOKUP($G13,$C:$E,3,0)),"",VLOOKUP($G13,$C:$E,3,0))
B14: =IF(OR(D14="",D14=0,RIGHT(D14,LEN($A$1))<>$A$1),,(LEFT($D14,3)*100)+MID($D14,7,IF(OR(AND(LEN($A$1)=3,LEN($D14)=12),AND(LEN($A$1)=4,LEN($D14)=13)),2,1))*1) -> 0 | C14: =IF($B14=0,,RANK($B14,$B$3:$B$78)) -> 0 | F14: =IF(AND(RIGHT($D14,LEN($A$1))<>$A$1,$D14<>""),1,0) -> 0 | G14: 13 | H14: =IF(ISNA(VLOOKUP($G14,$C:$E,2,0)),"",VLOOKUP($G14,$C:$E,2,0)) | I14: =IF(ISNA(VLOOKUP($G14,$C:$E,3,0)),"",VLOOKUP($G14,$C:$E,3,0))
B15: =IF(OR(D15="",D15=0,RIGHT(D15,LEN($A$1))<>$A$1),,(LEFT($D15,3)*100)+MID($D15,7,IF(OR(AND(LEN($A$1)=3,LEN($D15)=12),AND(LEN($A$1)=4,LEN($D15)=13)),2,1))*1) -> 0 | C15: =IF($B15=0,,RANK($B15,$B$3:$B$78)) -> 0 | F15: =IF(AND(RIGHT($D15,LEN($A$1))<>$A$1,$D15<>""),1,0) -> 0 | G15: 14 | H15: =IF(ISNA(VLOOKUP($G15,$C:$E,2,0)),"",VLOOKUP($G15,$C:$E,2,0)) | I15: =IF(ISNA(VLOOKUP($G15,$C:$E,3,0)),"",VLOOKUP($G15,$C:$E,3,0))
B16: =IF(OR(D16="",D16=0,RIGHT(D16,LEN($A$1))<>$A$1),,(LEFT($D16,3)*100)+MID($D16,7,IF(OR(AND(LEN($A$1)=3,LEN($D16)=12),AND(LEN($A$1)=4,LEN($D16)=13)),2,1))*1) -> 0 | C16: =IF($B16=0,,RANK($B16,$B$3:$B$78)) -> 0 | F16: =IF(AND(RIGHT($D16,LEN($A$1))<>$A$1,$D16<>""),1,0) -> 0 | G16: 15 | H16: =IF(ISNA(VLOOKUP($G16,$C:$E,2,0)),"",VLOOKUP($G16,$C:$E,2,0)) | I16: =IF(ISNA(VLOOKUP($G16,$C:$E,3,0)),"",VLOOKUP($G16,$C:$E,3,0))
... B25: =IF(OR(D25="",D25=0,RIGHT(D25,LEN($A$1))<>$A$1),,(LEFT($D25,3)*100)+MID($D25,7,IF(OR(AND(LEN($A$1)=3,LEN($D25)=12),AND(LEN($A$1)=4,LEN($D25)=13)),2,1))*1) -> 0 | C25: =IF($B25=0,,RANK($B25,$B$3:$B$78)) -> 0 | F25: =IF(AND(RIGHT($D25,LEN($A$1))<>$A$1,$D25<>""),1,0) -> 0 | G25: 24 | H25: =IF(ISNA(VLOOKUP($G25,$C:$E,2,0)),"",VLOOKUP($G25,$C:$E,2,0)) | I25: =IF(ISNA(VLOOKUP($G25,$C:$E,3,0)),"",VLOOKUP($G25,$C:$E,3,0))
B26: =IF(OR(D26="",D26=0,RIGHT(D26,LEN($A$1))<>$A$1),,(LEFT($D26,3)*100)+MID($D26,7,IF(OR(AND(LEN($A$1)=3,LEN($D26)=12),AND(LEN($A$1)=4,LEN($D26)=13)),2,1))*1) -> 0 | C26: =IF($B26=0,,RANK($B26,$B$3:$B$78)) -> 0 | F26: =IF(AND(RIGHT($D26,LEN($A$1))<>$A$1,$D26<>""),1,0) -> 0
B27: =IF(OR(D27="",D27=0,RIGHT(D27,LEN($A$1))<>$A$1),,(LEFT($D27,3)*100)+MID($D27,7,IF(OR(AND(LEN($A$1)=3,LEN($D27)=12),AND(LEN($A$1)=4,LEN($D27)=13)),2,1))*1) -> 0 | C27: =IF($B27=0,,RANK($B27,$B$3:$B$78)) -> 0 | F27: =IF(AND(RIGHT($D27,LEN($A$1))<>$A$1,$D27<>""),1,0) -> 0 | H27: MAX | I27: =MAX(I2:I26) -> 0.0175
B28: =IF(OR(D28="",D28=0,RIGHT(D28,LEN($A$1))<>$A$1),,(LEFT($D28,3)*100)+MID($D28,7,IF(OR(AND(LEN($A$1)=3,LEN($D28)=12),AND(LEN($A$1)=4,LEN($D28)=13)),2,1))*1) -> 0 | C28: =IF($B28=0,,RANK($B28,$B$3:$B$78)) -> 0 | F28: =IF(AND(RIGHT($D28,LEN($A$1))<>$A$1,$D28<>""),1,0) -> 0
B29: =IF(OR(D29="",D29=0,RIGHT(D29,LEN($A$1))<>$A$1),,(LEFT($D29,3)*100)+MID($D29,7,IF(OR(AND(LEN($A$1)=3,LEN($D29)=12),AND(LEN($A$1)=4,LEN($D29)=13)),2,1))*1) -> 0 | C29: =IF($B29=0,,RANK($B29,$B$3:$B$78)) -> 0 | F29: =IF(AND(RIGHT($D29,LEN($A$1))<>$A$1,$D29<>""),1,0) -> 0
B30: =IF(OR(D30="",D30=0,RIGHT(D30,LEN($A$1))<>$A$1),,(LEFT($D30,3)*100)+MID($D30,7,IF(OR(AND(LEN($A$1)=3,LEN($D30)=12),AND(LEN($A$1)=4,LEN($D30)=13)),2,1))*1) -> 0 | C30: =IF($B30=0,,RANK($B30,$B$3:$B$78)) -> 0 | F30: =IF(AND(RIGHT($D30,LEN($A$1))<>$A$1,$D30<>""),1,0) -> 0
B31: =IF(OR(D31="",D31=0,RIGHT(D31,LEN($A$1))<>$A$1),,(LEFT($D31,3)*100)+MID($D31,7,IF(OR(AND(LEN($A$1)=3,LEN($D31)=12),AND(LEN($A$1)=4,LEN($D31)=13)),2,1))*1) -> 0 | C31: =IF($B31=0,,RANK($B31,$B$3:$B$78)) -> 0 | F31: =IF(AND(RIGHT($D31,LEN($A$1))<>$A$1,$D31<>""),1,0) -> 0
B32: =IF(OR(D32="",D32=0,RIGHT(D32,LEN($A$1))<>$A$1),,(LEFT($D32,3)*100)+MID($D32,7,IF(OR(AND(LEN($A$1)=3,LEN($D32)=12),AND(LEN($A$1)=4,LEN($D32)=13)),2,1))*1) -> 0 | C32: =IF($B32=0,,RANK($B32,$B$3:$B$78)) -> 0 | F32: =IF(AND(RIGHT($D32,LEN($A$1))<>$A$1,$D32<>""),1,0) -> 0
B33: =IF(OR(D33="",D33=0,RIGHT(D33,LEN($A$1))<>$A$1),,(LEFT($D33,3)*100)+MID($D33,7,IF(OR(AND(LEN($A$1)=3,LEN($D33)=12),AND(LEN($A$1)=4,LEN($D33)=13)),2,1))*1) -> 0 | C33: =IF($B33=0,,RANK($B33,$B$3:$B$78)) -> 0 | F33: =IF(AND(RIGHT($D33,LEN($A$1))<>$A$1,$D33<>""),1,0) -> 0
B34: =IF(OR(D34="",D34=0,RIGHT(D34,LEN($A$1))<>$A$1),,(LEFT($D34,3)*100)+MID($D34,7,IF(OR(AND(LEN($A$1)=3,LEN($D34)=12),AND(LEN($A$1)=4,LEN($D34)=13)),2,1))*1) -> 0 | C34: =IF($B34=0,,RANK($B34,$B$3:$B$78)) -> 0 | F34: =IF(AND(RIGHT($D34,LEN($A$1))<>$A$1,$D34<>""),1,0) -> 0
B35: =IF(OR(D35="",D35=0,RIGHT(D35,LEN($A$1))<>$A$1),,(LEFT($D35,3)*100)+MID($D35,7,IF(OR(AND(LEN($A$1)=3,LEN($D35)=12),AND(LEN($A$1)=4,LEN($D35)=13)),2,1))*1) -> 0 | C35: =IF($B35=0,,RANK($B35,$B$3:$B$78)) -> 0 | F35: =IF(AND(RIGHT($D35,LEN($A$1))<>$A$1,$D35<>""),1,0) -> 0
B36: =IF(OR(D36="",D36=0,RIGHT(D36,LEN($A$1))<>$A$1),,(LEFT($D36,3)*100)+MID($D36,7,IF(OR(AND(LEN($A$1)=3,LEN($D36)=12),AND(LEN($A$1)=4,LEN($D36)=13)),2,1))*1) -> 0 | C36: =IF($B36=0,,RANK($B36,$B$3:$B$78)) -> 0 | F36: =IF(AND(RIGHT($D36,LEN($A$1))<>$A$1,$D36<>""),1,0) -> 0
B37: =IF(OR(D37="",D37=0,RIGHT(D37,LEN($A$1))<>$A$1),,(LEFT($D37,3)*100)+MID($D37,7,IF(OR(AND(LEN($A$1)=3,LEN($D37)=12),AND(LEN($A$1)=4,LEN($D37)=13)),2,1))*1) -> 0 | C37: =IF($B37=0,,RANK($B37,$B$3:$B$78)) -> 0 | F37: =IF(AND(RIGHT($D37,LEN($A$1))<>$A$1,$D37<>""),1,0) -> 0
B38: =IF(OR(D38="",D38=0,RIGHT(D38,LEN($A$1))<>$A$1),,(LEFT($D38,3)*100)+MID($D38,7,IF(OR(AND(LEN($A$1)=3,LEN($D38)=12),AND(LEN($A$1)=4,LEN($D38)=13)),2,1))*1) -> 0 | C38: =IF($B38=0,,RANK($B38,$B$3:$B$78)) -> 0 | F38: =IF(AND(RIGHT($D38,LEN($A$1))<>$A$1,$D38<>""),1,0) -> 0
B39: =IF(OR(D39="",D39=0,RIGHT(D39,LEN($A$1))<>$A$1),,(LEFT($D39,3)*100)+MID($D39,7,IF(OR(AND(LEN($A$1)=3,LEN($D39)=12),AND(LEN($A$1)=4,LEN($D39)=13)),2,1))*1) -> 0 | C39: =IF($B39=0,,RANK($B39,$B$3:$B$78)) -> 0 | F39: =IF(AND(RIGHT($D39,LEN($A$1))<>$A$1,$D39<>""),1,0) -> 0
... B200: =IF(OR(D200="",D200=0,RIGHT(D200,LEN($A$1))<>$A$1),,(LEFT($D200,3)*100)+MID($D200,7,IF(OR(AND(LEN($A$1)=3,LEN($D200)=12),AND(LEN($A$1)=4,LEN($D200)=13)),2,1))*1) -> 0 | C200: =IF($B200=0,,RANK($B200,$B$3:$B$78)) -> 0 | F200: =IF(AND(RIGHT($D200,LEN($A$1))<>$A$1,$D200<>""),1,0) -> 0

Sheet PY
B2: 轉換金額 | C2: 10000
C3: 分期 | D3: ㄧ次
B4: 指定保險金比例： | C4: =MIN(1,ROUND(OP!$C$141,2)) -> 0 | D4: =1-C4 -> 1 | F4: 年 | G4: 1
B5: 分期最低金額 | C5: =$C$38 -> 20000 | D5: =$D$38 -> 200000 | F5: 半年 | G5: 2
B6: 分期定期保險金給付期間： | C6: =OP!$C$142 -> 10 | F6: 季 | G6: 4
B7: 假設分期定期保險金預定利率： | C7: =$B$30 -> 0.02 | F7: 月 | G7: 12
B8: 期別 | C8: 年 | D8: =VLOOKUP($C$8,$F$4:$G$7,2,0) -> 1
B10: 精算公式→ | C10: =IF(C6=0,,C2*(C7*(1/(1+C7)))/(1-(1/(1+C7))^C6)) -> 1091.4365 | D10: ←精算換算比例(每萬元)
C11: =C10/10000 -> 0.10914365 | D11: ←帶入換算比例(每元)
B15: 定期定額-本利攤還
B16: 給付金額/每期 | C16: =ROUND(PMT($C$7/$D$8,$C$6*$D$8,-$C$2*$C$4,,1),0) -> 0
B17: 給付總額 | C17: =C16*C6*D8 -> 0
B18: 給付比例 | C18: =PMT($C$7/$D$8,$C$6*$D$8,-$C$2,,1)/C2 -> 0.10914365 | D18: ←自行計算換算比例
B20: 定額不定期
B21: 給付金額/每期 | C21: 550 | D21: ←帶入期付金額
B22: 給付總額 | C22: =C21*(($C$26*$D$8)+$C$27) -> 12100
B23: 給付比例 | C23: =$C$21/($C$2/$C$4) -> #DIV/0!
B24: 給付次數 | C24: =NPER($C$7/$D$8,$C$21,-$C$2,0,1) -> 22.261841
B25: 剩餘金額 | C25: =ROUND(C21*($C$24-ROUNDDOWN($C$24,0)),0) -> 144
B26: 給付年次 | C26: =ROUNDDOWN(ROUNDDOWN($C$24,0)/$D$8,0) -> 22 | D26: ←自行計算給付年月數
B27: ="給付"&C8&"次" -> 給付年次 | C27: =ROUNDDOWN($C$24,0)-($C$26*$D$8) -> 0 | D27: ="EX："&$C$26&" 年 "&IF($C$27=0,"",C27&" "&$C$8) -> EX：22 年
B29: 台幣=1，美元=2，澳幣=3 | C29: =OP!$C$21 -> 1 | D29: 新臺幣 | E29: ←設定幣別
B30: =IF($C$29=1,$C$31,IF($C$29=2,$D$31,$E$31)) -> 0.02 | C30: 台幣(1) | D30: 美元(2) | E30: 澳幣(3)
C31: 0.02 | D31: 0.025 | E31: 0.0275
B37: 分期低額 | C37: 每期 | D37: 指定
B38: =$C$29 -> 1 | C38: =VLOOKUP(B38,$B$39:$D$40,2,0) -> 20000 | D38: =VLOOKUP(B38,$B$39:$D$40,3,0) -> 200000
B39: 2 | C39: 3000 | D39: 30000 | E39: =NUMBERSTRING(IF(C39/10000<1,C39/1000,C39/10000),3)&RIGHT(NUMBERSTRING(C39,1),1) -> 三千 | F39: =NUMBERSTRING(IF(D39/10000<1,D39/1000,D39/10000),1)&RIGHT(NUMBERSTRING(D39,2),1) -> 三萬
B40: 1 | C40: 20000 | D40: 200000 | E40: =NUMBERSTRING(IF(C40/10000<1,C40/1000,C40/10000),3)&RIGHT(NUMBERSTRING(C40,2),1) -> 二萬 | F40: =NUMBERSTRING(IF(D40/10000<1,D40/1000,D40/10000),1)&RIGHT(NUMBERSTRING(D40,2),1) -> 二十萬
B41: 3 | C41: 3000 | D41: 30000 | E41: =NUMBERSTRING(IF(C41/10000<1,C41/1000,C41/10000),3)&RIGHT(NUMBERSTRING(C41,1),1) -> 三千 | F41: =NUMBERSTRING(IF(D41/10000<1,D41/1000,D41/10000),1)&RIGHT(NUMBERSTRING(D41,2),1) -> 三萬
B42: 4 | E42: =NUMBERSTRING(IF(C42/10000<1,C42/1000,C42/10000),3)&RIGHT(NUMBERSTRING(C42,2),1) -> ○零 | F42: =NUMBERSTRING(IF(D42/10000<1,D42/1000,D42/10000),1)&RIGHT(NUMBERSTRING(D42,2),1) -> ○零
B43: =IF(OR(AND($D$29=$B$45,$C$29<>1),ISERROR(VLOOKUP($D$29,$B$45:$D$48,3,0))),"商品幣別設定錯誤",VLOOKUP($D$29,$B$45:$D$48,3,0)) -> 二十萬元或每年給付之分期定期保險金低於二萬元者， | C43: =IF(OR(AND($D$29=$B$45,$C$29<>1),ISERROR(VLOOKUP($D$29,$B$45:$D$48,3,0))),1,0) -> 0
B45: 新臺幣 | C45: 1 | D45: =VLOOKUP($C$45,$B$39:$F$42,5,0)&"元"&"或每年給付之分期定期保險金低於"&VLOOKUP($C$45,$B$39:$F$42,4,0)&"元"&"者，" -> 二十萬元或每年給付之分期定期保險金低於二萬元者，
B46: 美元 | C46: 2 | D46: =VLOOKUP($C$46,$B$39:$F$42,5,0)&$B$46&"或每年給付之分期定期保險金低於"&VLOOKUP($C$46,$B$39:$F$42,4,0)&$B$46&"者，" -> 三萬美元或每年給付之分期定期保險金低於三千美元者，
B47: 澳幣 | C47: 3 | D47: =VLOOKUP($C$47,$B$39:$F$42,5,0)&$B$47&"或每年給付之分期定期保險金低於"&VLOOKUP($C$47,$B$39:$F$42,4,0)&$B$47&"者，" -> 三萬澳幣或每年給付之分期定期保險金低於三千澳幣者，
B48: 人民幣 | C48: 4 | D48: =VLOOKUP($C$48,$B$39:$F$42,5,0)&$B$48&"或每年給付之分期定期保險金低於"&VLOOKUP($C$48,$B$39:$F$42,4,0)&$B$48&"者，" -> ○零人民幣或每年給付之分期定期保險金低於○零人民幣者，

Sheet 揭露
B1: =OP!$C$56 -> LTQ30 | C1: ←帶OP | D1: =IF(OP!$E$16=1,"足歲",IF(OP!$E$16=2,"保險年齡","錯誤")) -> 保險年齡 | E1: ←帶OP | Q1: 6 | R1: 7 | S1: 8 | T1: 9 | U1: 10 | V1: 11 | W1: 12
L2: 以下3欄要注意最下方要和右側揭露拉齊 | O2: 以下COPY-DB | Q2: 1120911
C3: 代表年齡第?小→ | D3: 1 | E3: 2 | F3: 3 | G3: 1 | H3: 2 | I3: 3 | K3: 年齡代號轉換 | L3: KEY | M3: 年齡 | N3: 年度 | O3: 險種大類 | P3: 年期險種 | Q3: 性別 | R3: 年齡 | S3: 繳費方式 | T3: 宣告利率 | U3: 繳費金額 | V3: 保單年度 | W3: 揭露利率
C4: 性別男=1，女=2→ | D4: 1 | E4: 1 | F4: 1 | G4: 2 | H4: 2 | I4: 2 | K4: =IF($D$1="足歲","15足","") | L4: =IF(P4<>$B$1,"",P4&Q4&R4&V4) | M4: =IF(L4="","-",IF(ISERROR($R4*1),LEFT($R4,2)*1,$R4*1)) -> - | N4: =IF(L4="","",V4*1)
B5: 取第?欄→ | C5: 12 | D5: =IF(SMALL($M:$M,D$3)=15,$K$4,SMALL($M:$M,D$3)) -> #NUM! | E5: =IF(SMALL($M:$M,E$3)=15,$K$4,SMALL($M:$M,E$3)) -> #NUM! | F5: =IF(SMALL($M:$M,F$3)=15,$K$4,SMALL($M:$M,F$3)) -> #NUM! | G5: =IF(SMALL($M:$M,G$3)=15,$K$4,SMALL($M:$M,G$3)) -> #NUM! | H5: =IF(SMALL($M:$M,H$3)=15,$K$4,SMALL($M:$M,H$3)) -> #NUM! | I5: =IF(SMALL($M:$M,I$3)=15,$K$4,SMALL($M:$M,I$3)) -> #NUM! | L5: =IF(P5<>$B$1,"",P5&Q5&R5&V5) | M5: =IF(OR(L5="",COUNTIF($M$4:M4,IF(ISERROR($R5*1),LEFT($R5,2)*1,$R5*1))>=1),"-",IF(ISERROR($R5*1),LEFT($R5,2)*1,$R5*1)) -> - | N5: =IF(OR(L5="",COUNTIF($N$4:N4,V5*1)>=1),"-",V5*1) -> -
B6: 第?小↓ | C6: 保單年度 | D6: =IF(OR(ISERROR($D5)),"",IF((D$5)=0,D$5&IF(D$4=1,"男性",IF(D$4=2,"女性","")),D$5&"歲"&IF(D$4=1,"男性",IF(D$4=2,"女性","")))) | E6: =IF(OR(ISERROR($D5)),"",IF((E$5)=0,E$5&IF(E$4=1,"男性",IF(E$4=2,"女性","")),E$5&"歲"&IF(E$4=1,"男性",IF(E$4=2,"女性","")))) | F6: =IF(OR(ISERROR($D5)),"",IF((F$5)=0,F$5&IF(F$4=1,"男性",IF(F$4=2,"女性","")),F$5&"歲"&IF(F$4=1,"男性",IF(F$4=2,"女性","")))) | G6: =IF(OR(ISERROR($D5)),"",IF((G$5)=0,G$5&IF(G$4=1,"男性",IF(G$4=2,"女性","")),G$5&"歲"&IF(G$4=1,"男性",IF(G$4=2,"女性","")))) | H6: =IF(OR(ISERROR($D5)),"",IF((H$5)=0,H$5&IF(H$4=1,"男性",IF(H$4=2,"女性","")),H$5&"歲"&IF(H$4=1,"男性",IF(H$4=2,"女性","")))) | I6: =IF(OR(ISERROR($D5)),"",IF((I$5)=0,I$5&IF(I$4=1,"男性",IF(I$4=2,"女性","")),I$5&"歲"&IF(I$4=1,"男性",IF(I$4=2,"女性","")))) | L6: =IF(P6<>$B$1,"",P6&Q6&R6&V6) | M6: =IF(OR(L6="",COUNTIF($M$4:M5,IF(ISERROR($R6*1),LEFT($R6,2)*1,$R6*1))>=1),"-",IF(ISERROR($R6*1),LEFT($R6,2)*1,$R6*1)) -> - | N6: =IF(OR(L6="",COUNTIF($N$4:N5,V6*1)>=1),"-",V6*1) -> -
B7: 1 | C7: =IF(ISERROR(SMALL($N:$N,$B7)),"",SMALL($N:$N,$B7)) | D7: =IF(ISERROR(VLOOKUP($B$1&D$4&D$5&$C7,$L:$W,$C$5,0)),"",VLOOKUP($B$1&D$4&D$5&$C7,$L:$W,$C$5,0)) | E7: =IF(ISERROR(VLOOKUP($B$1&E$4&E$5&$C7,$L:$W,$C$5,0)),"",VLOOKUP($B$1&E$4&E$5&$C7,$L:$W,$C$5,0)) | F7: =IF(ISERROR(VLOOKUP($B$1&F$4&F$5&$C7,$L:$W,$C$5,0)),"",VLOOKUP($B$1&F$4&F$5&$C7,$L:$W,$C$5,0)) | G7: =IF(ISERROR(VLOOKUP($B$1&G$4&G$5&$C7,$L:$W,$C$5,0)),"",VLOOKUP($B$1&G$4&G$5&$C7,$L:$W,$C$5,0)) | H7: =IF(ISERROR(VLOOKUP($B$1&H$4&H$5&$C7,$L:$W,$C$5,0)),"",VLOOKUP($B$1&H$4&H$5&$C7,$L:$W,$C$5,0)) | I7: =IF(ISERROR(VLOOKUP($B$1&I$4&I$5&$C7,$L:$W,$C$5,0)),"",VLOOKUP($B$1&I$4&I$5&$C7,$L:$W,$C$5,0)) | L7: =IF(P7<>$B$1,"",P7&Q7&R7&V7) | M7: =IF(OR(L7="",COUNTIF($M$4:M6,IF(ISERROR($R7*1),LEFT($R7,2)*1,$R7*1))>=1),"-",IF(ISERROR($R7*1),LEFT($R7,2)*1,$R7*1)) -> - | N7: =IF(OR(L7="",COUNTIF($N$4:N6,V7*1)>=1),"-",V7*1) -> -
B8: 2 | C8: =IF(ISERROR(SMALL($N:$N,$B8)),"",SMALL($N:$N,$B8)) | D8: =IF(ISERROR(VLOOKUP($B$1&D$4&D$5&$C8,$L:$W,$C$5,0)),"",VLOOKUP($B$1&D$4&D$5&$C8,$L:$W,$C$5,0)) | E8: =IF(ISERROR(VLOOKUP($B$1&E$4&E$5&$C8,$L:$W,$C$5,0)),"",VLOOKUP($B$1&E$4&E$5&$C8,$L:$W,$C$5,0)) | F8: =IF(ISERROR(VLOOKUP($B$1&F$4&F$5&$C8,$L:$W,$C$5,0)),"",VLOOKUP($B$1&F$4&F$5&$C8,$L:$W,$C$5,0)) | G8: =IF(ISERROR(VLOOKUP($B$1&G$4&G$5&$C8,$L:$W,$C$5,0)),"",VLOOKUP($B$1&G$4&G$5&$C8,$L:$W,$C$5,0)) | H8: =IF(ISERROR(VLOOKUP($B$1&H$4&H$5&$C8,$L:$W,$C$5,0)),"",VLOOKUP($B$1&H$4&H$5&$C8,$L:$W,$C$5,0)) | I8: =IF(ISERROR(VLOOKUP($B$1&I$4&I$5&$C8,$L:$W,$C$5,0)),"",VLOOKUP($B$1&I$4&I$5&$C8,$L:$W,$C$5,0)) | L8: =IF(P8<>$B$1,"",P8&Q8&R8&V8) | M8: =IF(OR(L8="",COUNTIF($M$4:M7,IF(ISERROR($R8*1),LEFT($R8,2)*1,$R8*1))>=1),"-",IF(ISERROR($R8*1),LEFT($R8,2)*1,$R8*1)) -> - | N8: =IF(OR(L8="",COUNTIF($N$4:N7,V8*1)>=1),"-",V8*1) -> -
B9: 3 | C9: =IF(ISERROR(SMALL($N:$N,$B9)),"",SMALL($N:$N,$B9)) | D9: =IF(ISERROR(VLOOKUP($B$1&D$4&D$5&$C9,$L:$W,$C$5,0)),"",VLOOKUP($B$1&D$4&D$5&$C9,$L:$W,$C$5,0)) | E9: =IF(ISERROR(VLOOKUP($B$1&E$4&E$5&$C9,$L:$W,$C$5,0)),"",VLOOKUP($B$1&E$4&E$5&$C9,$L:$W,$C$5,0)) | F9: =IF(ISERROR(VLOOKUP($B$1&F$4&F$5&$C9,$L:$W,$C$5,0)),"",VLOOKUP($B$1&F$4&F$5&$C9,$L:$W,$C$5,0)) | G9: =IF(ISERROR(VLOOKUP($B$1&G$4&G$5&$C9,$L:$W,$C$5,0)),"",VLOOKUP($B$1&G$4&G$5&$C9,$L:$W,$C$5,0)) | H9: =IF(ISERROR(VLOOKUP($B$1&H$4&H$5&$C9,$L:$W,$C$5,0)),"",VLOOKUP($B$1&H$4&H$5&$C9,$L:$W,$C$5,0)) | I9: =IF(ISERROR(VLOOKUP($B$1&I$4&I$5&$C9,$L:$W,$C$5,0)),"",VLOOKUP($B$1&I$4&I$5&$C9,$L:$W,$C$5,0)) | L9: =IF(P9<>$B$1,"",P9&Q9&R9&V9) | M9: =IF(OR(L9="",COUNTIF($M$4:M8,IF(ISERROR($R9*1),LEFT($R9,2)*1,$R9*1))>=1),"-",IF(ISERROR($R9*1),LEFT($R9,2)*1,$R9*1)) -> - | N9: =IF(OR(L9="",COUNTIF($N$4:N8,V9*1)>=1),"-",V9*1) -> -
B10: 4 | C10: =IF(ISERROR(SMALL($N:$N,$B10)),"",SMALL($N:$N,$B10)) | D10: =IF(ISERROR(VLOOKUP($B$1&D$4&D$5&$C10,$L:$W,$C$5,0)),"",VLOOKUP($B$1&D$4&D$5&$C10,$L:$W,$C$5,0)) | E10: =IF(ISERROR(VLOOKUP($B$1&E$4&E$5&$C10,$L:$W,$C$5,0)),"",VLOOKUP($B$1&E$4&E$5&$C10,$L:$W,$C$5,0)) | F10: =IF(ISERROR(VLOOKUP($B$1&F$4&F$5&$C10,$L:$W,$C$5,0)),"",VLOOKUP($B$1&F$4&F$5&$C10,$L:$W,$C$5,0)) | G10: =IF(ISERROR(VLOOKUP($B$1&G$4&G$5&$C10,$L:$W,$C$5,0)),"",VLOOKUP($B$1&G$4&G$5&$C10,$L:$W,$C$5,0)) | H10: =IF(ISERROR(VLOOKUP($B$1&H$4&H$5&$C10,$L:$W,$C$5,0)),"",VLOOKUP($B$1&H$4&H$5&$C10,$L:$W,$C$5,0)) | I10: =IF(ISERROR(VLOOKUP($B$1&I$4&I$5&$C10,$L:$W,$C$5,0)),"",VLOOKUP($B$1&I$4&I$5&$C10,$L:$W,$C$5,0)) | L10: =IF(P10<>$B$1,"",P10&Q10&R10&V10) | M10: =IF(OR(L10="",COUNTIF($M$4:M9,IF(ISERROR($R10*1),LEFT($R10,2)*1,$R10*1))>=1),"-",IF(ISERROR($R10*1),LEFT($R10,2)*1,$R10*1)) -> - | N10: =IF(OR(L10="",COUNTIF($N$4:N9,V10*1)>=1),"-",V10*1) -> -
B11: 5 | C11: =IF(ISERROR(SMALL($N:$N,$B11)),"",SMALL($N:$N,$B11)) | D11: =IF(ISERROR(VLOOKUP($B$1&D$4&D$5&$C11,$L:$W,$C$5,0)),"",VLOOKUP($B$1&D$4&D$5&$C11,$L:$W,$C$5,0)) | E11: =IF(ISERROR(VLOOKUP($B$1&E$4&E$5&$C11,$L:$W,$C$5,0)),"",VLOOKUP($B$1&E$4&E$5&$C11,$L:$W,$C$5,0)) | F11: =IF(ISERROR(VLOOKUP($B$1&F$4&F$5&$C11,$L:$W,$C$5,0)),"",VLOOKUP($B$1&F$4&F$5&$C11,$L:$W,$C$5,0)) | G11: =IF(ISERROR(VLOOKUP($B$1&G$4&G$5&$C11,$L:$W,$C$5,0)),"",VLOOKUP($B$1&G$4&G$5&$C11,$L:$W,$C$5,0)) | H11: =IF(ISERROR(VLOOKUP($B$1&H$4&H$5&$C11,$L:$W,$C$5,0)),"",VLOOKUP($B$1&H$4&H$5&$C11,$L:$W,$C$5,0)) | I11: =IF(ISERROR(VLOOKUP($B$1&I$4&I$5&$C11,$L:$W,$C$5,0)),"",VLOOKUP($B$1&I$4&I$5&$C11,$L:$W,$C$5,0)) | L11: =IF(P11<>$B$1,"",P11&Q11&R11&V11) | M11: =IF(OR(L11="",COUNTIF($M$4:M10,IF(ISERROR($R11*1),LEFT($R11,2)*1,$R11*1))>=1),"-",IF(ISERROR($R11*1),LEFT($R11,2)*1,$R11*1)) -> - | N11: =IF(OR(L11="",COUNTIF($N$4:N10,V11*1)>=1),"-",V11*1) -> -
