Workbook
Name CV: PDATA!$EI$252:$IP$518
Name DIE: PDATA!$V$522:$EC$798
Name En_BFM: OP!$W$4:$W$5
Name En_PayMF: OP!$U$3:$U$6
Name En_PayMR: OP!$V$3:$V$6
Name En_PayT: OP!$T$5:$T$8
Name En_Sex: OP!$S$3:$S$4
Name EXP: PDATA!$EI$522:$IP$798
Name GP: PDATA!$J:$K
Name HL_1: PDATA!$V$1134:$EC$1399
Name HL_2: PDATA!$EI$1134:$IP$1399
Name PA: PDATA!$V$2:$EC$248
Name PDN1_1: OP!$C$23
Name PDSN1: OP!$C$22
Name PDSN1_1: OP!$C$22
Name PI: OP!$AK$4:$AL$90
Name PV: PDATA!$EI$958:$IP$1120
Name PV0: PDATA!$V$958:$ED$1120
Name PVal: PDATA!$O:$P
Name PYO: PY!$D$4
Name PYR: PY!$C$11
Name PYY: PY!$C$4
Name SRV: PDATA!$EI$2:$IP$248
Name TOV: 總表!$B$3:$AI$114
Name 關係: OP!$B$182:$B$186

Sheet PDATA
A1: GP | B1: 1051130 | J1: =B1&TEXT(F1,"00")&TEXT(H1,"00") -> 10511300000 | O1: =M1&TEXT(N1,"00") -> 00 | R1: PA | V1: =S1&TEXT(T1,"00")&TEXT(U1,"00") -> 0000 | EE1: SRV | EI1: =EF1&TEXT(EG1,"00")&TEXT(EH1,"00") -> 0000
A2: 版次 | B2: 商品代號 | C2: 職業等級 | D2: 年期 | E2: 保額代碼 | F2: 性別 | G2: 投保金額 | H2: 年齡 | I2: 繳費年度 | J2: =B2&TEXT(F2,"00")&TEXT(H2,"00") -> 商品代號性別年齡 | K2: 保費 | M2: 商品代號 | N2: 累計給付年度 | O2: =M2&TEXT(N2,"00") -> 商品代號累計給付年度 | P2: 給付數值 | R2: 版次 | S2: 商品代號 | T2: 性別 | U2: 年齡 | V2: =S2&TEXT(T2,"00")&TEXT(U2,"00") -> 商品代號性別年齡 | W2: 第1年減額繳清保額 | X2: 第2年減額繳清保額 | Y2: 第3年減額繳清保額 | Z2: 第4年減額繳清保額 | AA2: 第5年減額繳清保額 | AB2: 第6年減額繳清保額 | AC2: 第7年減額繳清保額 | AD2: 第8年減額繳清保額 | AE2: 第9年減額繳清保額 | AF2: 第10年減額繳清保額 | AG2: 第11年減額繳清保額 | AH2: 第12年減額繳清保額 | AI2: 第13年減額繳清保額 | AJ2: 第14年減額繳清保額 | AK2: 第15年減額繳清保額 | AL2: 第16年減額繳清保額 | AM2: 第17年減額繳清保額 | AN2: 第18年減額繳清保額 | AO2: 第19年減額繳清保額B | AP2: 第20年減額繳清保額 | AQ2: 第21年減額繳清保額B | AR2: 第22年減額繳清保額 | AS2: 第23年減額繳清保額 | AT2: 第24年減額繳清保額 | AU2: 第25年減額繳清保額 | AV2: 第26年減額繳清保額B | AW2: 第27年減額繳清保額 | AX2: 第28年減額繳清保額B | AY2: 第29年減額繳清保額 | AZ2: 第30年減額繳清保額B | BA2: 第31年減額繳清保額 | BB2: 第32年減額繳清保額 | BC2: 第33年減額繳清保額 | BD2: 第34年減額繳清保額 | BE2: 第35年減額繳清保額 | BF2: 第36年減額繳清保額 | BG2: 第37年減額繳清保額 | BH2: 第38年減額繳清保額 | BI2: 第39年減額繳清保額 | BJ2: 第40年減額繳清保額 | BK2: 第41年減額繳清保額 | BL2: 第42年減額繳清保額 | BM2: 第43年減額繳清保額 | BN2: 第44年減額繳清保額 | BO2: 第45年減額繳清保額 | BP2: 第46年減額繳清保額 | BQ2: 第47年減額繳清保額 | BR2: 第48年減額繳清保額 | BS2: 第49年減額繳清保額 | BT2: 第50年減額繳清保額 | BU2: 第51年減額繳清保額 | BV2: 第52年減額繳清保額 | BW2: 第53年減額繳清保額 | BX2: 第54年減額繳清保額 | BY2: 第55年減額繳清保額 | BZ2: 第56年減額繳清保額 | CA2: 第57年減額繳清保額 | CB2: 第58年減額繳清保額 | CC2: 第59年減額繳清保額 | CD2: 第60年減額繳清保額 | CE2: 第61年減額繳清保額 | CF2: 第62年減額繳清保額 | CG2: 第63年減額繳清保額 | CH2: 第64年減額繳清保額 | CI2: 第65年減額繳清保額 | CJ2: 第66年減額繳清保額 | CK2: 第67年減額繳清保額 | CL2: 第68年減額繳清保額 | CM2: 第69年減額繳清保額 | CN2: 第70年減額繳清保額 | CO2: 第71年減額繳清保額 | CP2: 第72年減額繳清保額 | CQ2: 第73年減額繳清保額 | CR2: 第74年減額繳清保額 | CS2: 第75年減額繳清保額 | CT2: 第76年減額繳清保額 | CU2: 第77年減額繳清保額 | CV2: 第78年減額繳清保額 | CW2: 第79年減額繳清保額 | CX2: 第80年減額繳清保額 | CY2: 第81年減額繳清保額 | CZ2: 第82年契遾B繳清保額 | DA2: 第83年減額繳清保額 | DB2: 第84年減額繳清保額 | DC2: 第85年減額繳清保額 | DD2: 第86年減額繳清保額 | DE2: 第87年減額繳清保額 | DF2: 第88年減額繳清保額 | DG2: 第89年減額繳清保額 | DH2: 第90年減額繳清保額 | DI2: 第91年減額繳清保額 | DJ2: 第92年減額繳清保額 | DK2: 第93年減額繳清保額 | DL2: 第94年減額繳清保額 | DM2: 第95年減額繳清保額 | DN2: 第96年減額繳清保額 | DO2: 第97年減額繳清保額 | DP2: 第98年減額繳清保額 | DQ2: 第99年減額繳清保額 | DR2: 第100年減額繳清保額 | DS2: 第101年減額繳清保額 | DT2: 第102年減額繳清保額 | DU2: 第103年減額繳清保額 | DV2: 第104年減額繳清保額 | DW2: 第105年減額繳清保額 | DX2: 第106年減額繳清保額 | DY2: 第107年減額繳清保額 | DZ2: 第108年減額繳清保額 | EA2: 第109年減額繳清保額 | EB2: 第110年減額繳清保額 | EC2: 第111年減額繳清保額 | EE2: 版次 | EF2: 商品代號 | EG2: 性別 | EH2: 年齡
B3: LTT10 | F3: 1 | H3: 15 | J3: =B3&TEXT(F3,"00")&TEXT(H3,"00") -> LTT100115 | K3: 22030 | M3: LTT10 | N3: 1 | O3: =M3&TEXT(N3,"00") -> LTT1001 | P3: 20000
B4: LTT10 | F4: 1 | H4: 16 | J4: =B4&TEXT(F4,"00")&TEXT(H4,"00") -> LTT100116 | K4: 22330 | M4: LTT10 | N4: 2 | O4: =M4&TEXT(N4,"00") -> LTT1002 | P4: 20400
B5: LTT10 | F5: 1 | H5: 17 | J5: =B5&TEXT(F5,"00")&TEXT(H5,"00") -> LTT100117 | K5: 22690 | M5: LTT10 | N5: 3 | O5: =M5&TEXT(N5,"00") -> LTT1003 | P5: 20800
B6: LTT10 | F6: 1 | H6: 18 | J6: =B6&TEXT(F6,"00")&TEXT(H6,"00") -> LTT100118 | K6: 23030 | M6: LTT10 | N6: 4 | O6: =M6&TEXT(N6,"00") -> LTT1004 | P6: 21200
B7: LTT10 | F7: 1 | H7: 19 | J7: =B7&TEXT(F7,"00")&TEXT(H7,"00") -> LTT100119 | K7: 23410 | M7: LTT10 | N7: 5 | O7: =M7&TEXT(N7,"00") -> LTT1005 | P7: 21600
B8: LTT10 | F8: 1 | H8: 20 | J8: =B8&TEXT(F8,"00")&TEXT(H8,"00") -> LTT100120 | K8: 23800 | M8: LTT10 | N8: 6 | O8: =M8&TEXT(N8,"00") -> LTT1006 | P8: 22000
B9: LTT10 | F9: 1 | H9: 21 | J9: =B9&TEXT(F9,"00")&TEXT(H9,"00") -> LTT100121 | K9: 24160 | M9: LTT10 | N9: 7 | O9: =M9&TEXT(N9,"00") -> LTT1007 | P9: 22400
B10: LTT10 | F10: 1 | H10: 22 | J10: =B10&TEXT(F10,"00")&TEXT(H10,"00") -> LTT100122 | K10: 24560 | M10: LTT10 | N10: 8 | O10: =M10&TEXT(N10,"00") -> LTT1008 | P10: 22800
B11: LTT10 | F11: 1 | H11: 23 | J11: =B11&TEXT(F11,"00")&TEXT(H11,"00") -> LTT100123 | K11: 24940 | M11: LTT10 | N11: 9 | O11: =M11&TEXT(N11,"00") -> LTT1009 | P11: 23200
B12: LTT10 | F12: 1 | H12: 24 | J12: =B12&TEXT(F12,"00")&TEXT(H12,"00") -> LTT100124 | K12: 25320 | M12: LTT10 | N12: 10 | O12: =M12&TEXT(N12,"00") -> LTT1010 | P12: 23600
B13: LTT10 | F13: 1 | H13: 25 | J13: =B13&TEXT(F13,"00")&TEXT(H13,"00") -> LTT100125 | K13: 25750 | M13: LTT10 | N13: 11 | O13: =M13&TEXT(N13,"00") -> LTT1011 | P13: 24000
B14: LTT10 | F14: 1 | H14: 26 | J14: =B14&TEXT(F14,"00")&TEXT(H14,"00") -> LTT100126 | K14: 26150 | M14: LTT10 | N14: 12 | O14: =M14&TEXT(N14,"00") -> LTT1012 | P14: 24400
... B47: LTT10 | F47: 1 | H47: 59 | J47: =B47&TEXT(F47,"00")&TEXT(H47,"00") -> LTT100159 | K47: 48180 | M47: LTT30 | N47: 15 | O47: =M47&TEXT(N47,"00") -> LTT3015 | P47: 25600
B48: LTT10 | F48: 1 | H48: 60 | J48: =B48&TEXT(F48,"00")&TEXT(H48,"00") -> LTT100160 | K48: 49210
B49: LTT10 | F49: 1 | H49: 61 | J49: =B49&TEXT(F49,"00")&TEXT(H49,"00") -> LTT100161 | K49: 50250
B50: LTT10 | F50: 1 | H50: 62 | J50: =B50&TEXT(F50,"00")&TEXT(H50,"00") -> LTT100162 | K50: 51390
B51: LTT10 | F51: 1 | H51: 63 | J51: =B51&TEXT(F51,"00")&TEXT(H51,"00") -> LTT100163 | K51: 52640
B52: LTT10 | F52: 1 | H52: 64 | J52: =B52&TEXT(F52,"00")&TEXT(H52,"00") -> LTT100164 | K52: 53910
B53: LTT10 | F53: 1 | H53: 65 | J53: =B53&TEXT(F53,"00")&TEXT(H53,"00") -> LTT100165 | K53: 55220
B54: LTT10 | F54: 2 | H54: 15 | J54: =B54&TEXT(F54,"00")&TEXT(H54,"00") -> LTT100215 | K54: 30890
B55: LTT10 | F55: 2 | H55: 16 | J55: =B55&TEXT(F55,"00")&TEXT(H55,"00") -> LTT100216 | K55: 31430
B56: LTT10 | F56: 2 | H56: 17 | J56: =B56&TEXT(F56,"00")&TEXT(H56,"00") -> LTT100217 | K56: 31910
B57: LTT10 | F57: 2 | H57: 18 | J57: =B57&TEXT(F57,"00")&TEXT(H57,"00") -> LTT100218 | K57: 32430
B58: LTT10 | F58: 2 | H58: 19 | J58: =B58&TEXT(F58,"00")&TEXT(H58,"00") -> LTT100219 | K58: 32920
B59: LTT10 | F59: 2 | H59: 20 | J59: =B59&TEXT(F59,"00")&TEXT(H59,"00") -> LTT100220 | K59: 33420
... B248: LTT30 | F248: 2 | H248: 45 | J248: =B248&TEXT(F248,"00")&TEXT(H248,"00") -> LTT300245 | K248: 20610
R251: DIE2 | V251: =S251&TEXT(T251,"00")&TEXT(U251,"00") -> 0000 | EE251: CV | EI251: =EF251&TEXT(EG251,"00")&TEXT(EH251,"00") -> 0000
R252: 版次 | S252: 商品代號 | T252: 性別 | U252: 年齡 | EE252: 版次 | EF252: 商品代號 | EG252: 性別 | EH252: 年齡 | EI252: =EF252&TEXT(EG252,"00")&TEXT(EH252,"00") -> 商品代號性別年齡 | EJ252: 第1年解約金 | EK252: 第2年解約金 | EL252: 第3年解約金 | EM252: 第4年解約金 | EN252: 第5年解約金 | EO252: 第6年解約金 | EP252: 第7年解約金 | EQ252: 第8年解約金 | ER252: 第9年解約金 | ES252: 第10年解約金 | ET252: 第11年解約金 | EU252: 第12年解約金 | EV252: 第13年解約金 | EW252: 第14年解約金 | EX252: 第15年解約金 | EY252: 第16年解約金 | EZ252: 第17年解約金 | FA252: 第18年解約金 | FB252: 第19年解約金 | FC252: 第20年解約金 | FD252: 第21年解約金 | FE252: 第22年解約金 | FF252: 第23年解約金 | FG252: 第24年解約金 | FH252: 第25年解約金 | FI252: 第26年解約金 | FJ252: 第27年解約金 | FK252: 第28年解約金 | FL252: 第29年解約金 | FM252: 第30年解約金 | FN252: 第31年解約金 | FO252: 第32年解約金 | FP252: 第33年解約金 | FQ252: 第34年解約金 | FR252: 第35年解約金 | FS252: 第36年解約金 | FT252: 第37年解約金 | FU252: 第38年解約金 | FV252: 第39年解約金 | FW252: 第40年解約金 | FX252: 第41年解約金 | FY252: 第42年解約金 | FZ252: 第43年解約金 | GA252: 第44年解約金 | GB252: 第45年解約金 | GC252: 第46年解約金 | GD252: 第47年解約金 | GE252: 第48年解約金 | GF252: 第49年解約金 | GG252: 第50年解約金 | GH252: 第51年解約金 | GI252: 第52年解約金 | GJ252: 第53年解約金 | GK252: 第54年解約金 | GL252: 第55年解約金 | GM252: 第56年解約金 | GN252: 第57年解約金 | GO252: 第58年解約金 | GP252: 第59年解約金 | GQ252: 第60年解約金 | GR252: 第61年解約金 | GS252: 第62年解約金 | GT252: 第63年解約金 | GU252: 第64年解約金 | GV252: 第65年解約金 | GW252: 第66年解約金 | GX252: 第67年解約金 | GY252: 第68年解約金 | GZ252: 第69年解約金 | HA252: 第70年解約金 | HB252: 第71年解約金 | HC252: 第72年解約金 | HD252: 第73年解約金 | HE252: 第74年解約金 | HF252: 第75年解約金 | HG252: 第76年解約金 | HH252: 第77年解約金 | HI252: 第78年解約金 | HJ252: 第79年解約金 | HK252: 第80年解約金 | HL252: 第81年解約金 | HM252: 第82年解約金 | HN252: 第83年解約金 | HO252: 第84年解約金 | HP252: 第85年解約金 | HQ252: 第86年解約金 | HR252: 第87年解約金 | HS252: 第88年解約金 | HT252: 第89年解約金 | HU252: 第90年解約金 | HV252: 第91年解約金 | HW252: 第92年解約金 | HX252: 第93年解約金 | HY252: 第94年解約金 | HZ252: 第95年解約金 | IA252: 第96年解約金 | IB252: 第97年解約金 | IC252: 第98年解約金 | ID252: 第99年解約金 | IE252: 第100年解約金 | IF252: 第101年解約金 | IG252: 第102年解約金 | IH252: 第103年解約金 | II252: 第104年解約金 | IJ252: 第105年解約金 | IK252: 第106年解約金 | IL252: 第107年解約金 | IM252: 第108年解約金 | IN252: 第109年解約金 | IO252: 第110年解約金 | IP252: 第111年解約金
R521: DIE | V521: =S521&TEXT(T521,"00")&TEXT(U521,"00") -> 0000 | EE521: EXP | EI521: =EF521&TEXT(EG521,"00")&TEXT(EH521,"00") -> 0000
R522: 版次 | S522: 商品代號 | T522: 性別 | U522: 年齡 | V522: =S522&TEXT(T522,"00")&TEXT(U522,"00") -> 商品代號性別年齡 | W522: 第1年身故保險金 | X522: 第2年身故保險金 | Y522: 第3年身故保險金 | Z522: 第4年身故保險金 | AA522: 第5年身故保險金 | AB522: 第6年身故保險金 | AC522: 第7年身故保險金 | AD522: 第8年身故保險金 | AE522: 第9年身故保險金 | AF522: 第10年身故保險金 | AG522: 第11年身故保險金 | AH522: 第12年身故保險金 | AI522: 第13年身故保險金 | AJ522: 第14年身故保險金 | AK522: 第15年身故保險金 | AL522: 第16年身故保險金 | AM522: 第17年身故保險金 | AN522: 第18年身故保險金 | AO522: 第19年身故保險金 | AP522: 第20年身故保險金 | AQ522: 第21年身故保險金 | AR522: 第22年身故保險金 | AS522: 第23年身故保險金 | AT522: 第24年身故保險金 | AU522: 第25年身故保險金 | AV522: 第26年身故保險金 | AW522: 第27年身故保險金 | AX522: 第28年身故保險金 | AY522: 第29年身故保險金 | AZ522: 第30年身故保險金 | BA522: 第31年身故保險金 | BB522: 第32年身故保險金 | BC522: 第33年身故保險金 | BD522: 第34年身故保險金 | BE522: 第35年身故保險金 | BF522: 第36年身故保險金 | BG522: 第37年身故保險金 | BH522: 第38年身故保險金 | BI522: 第39年身故保險金 | BJ522: 第40年身故保險金 | BK522: 第41年身故保險金 | BL522: 第42年身故保險金 | BM522: 第43年身故保險金 | BN522: 第44年身故保險金 | BO522: 第45年身故保險金 | BP522: 第46年身故保險金 | BQ522: 第47年身故保險金 | BR522: 第48年身故保險金 | BS522: 第49年身故保險金 | BT522: 第50年身故保險金 | BU522: 第51年身故保險金 | BV522: 第52年身故保險金 | BW522: 第53年身故保險金 | BX522: 第54年身故保險金 | BY522: 第55年身故保險金 | BZ522: 第56年身故保險金 | CA522: 第57年身故保險金 | CB522: 第58年身故保險金 | CC522: 第59年身故保險金 | CD522: 第60年身故保險金 | CE522: 第61年身故保險金 | CF522: 第62年身故保險金 | CG522: 第63年身故保險金 | CH522: 第64年身故保險金 | CI522: 第65年身故保險金 | CJ522: 第66年身故保險金 | CK522: 第67年身故保險金 | CL522: 第68年身故保險金 | CM522: 第69年身故保險金 | CN522: 第70年身故保險金 | CO522: 第71年身故保險金 | CP522: 第72年身故保險金 | CQ522: 第73年身故保險金 | CR522: 第74年身故保險金額 | CS522: 第75年身故保險金 | CT522: 第76年身故保險金 | CU522: 第77年身故保險金 | CV522: 第78年身故保險金 | CW522: 第79年身故保險金 | CX522: 第80年身故保險金 | CY522: 第81年身故保險金 | CZ522: 第82年身故保險金 | DA522: 第83年身故保險金 | DB522: 第84年身故保險金 | DC522: 第85年身故保險金 | DD522: 第86年身故保險金 | DE522: 第87年身故保險金 | DF522: 第88年身故保險金 | DG522: 第89年身故保險金 | DH522: 第90年身故保險金 | DI522: 第91年身故保險金 | DJ522: 第92年身故保險金 | DK522: 第93年身故保險金 | DL522: 第94年身故保險金 | DM522: 第95年身故保險金 | DN522: 第96年身故保險金 | DO522: 第97年身故保險金 | DP522: 第98年身故保險金 | DQ522: 第99年身故保險金 | DR522: 第100年身故保險金 | DS522: 第101年身故保險金 | DT522: 第102年身故保險金 | DU522: 第103年身故保險金 | DV522: 第104年身故保險金 | DW522: 第105年身故保險金 | DX522: 第106年身故保險金 | DY522: 第107年身故保險金 | DZ522: 第108年身故保險金 | EA522: 第109年身故保險金 | EB522: 第110年身故保險金 | EC522: 第111年身故保險金 | EE522: 版次 | EF522: 商品代號 | EG522: 性別 | EH522: 年齡 | EI522: =EF522&TEXT(EG522,"00")&TEXT(EH522,"00") -> 商品代號性別年齡 | EJ522: 第1年祝壽保險金 | EK522: 第2年祝壽保險金 | EL522: 第3年祝壽保險金 | EM522: 第4年祝壽保險金 | EN522: 第5年祝壽保險金 | EO522: 第6年祝壽保險金 | EP522: 第7年祝壽保險金 | EQ522: 第8年祝壽保險金 | ER522: 第9年祝壽保險金 | ES522: 第10年祝壽保險金 | ET522: 第11年祝壽保險金 | EU522: 第12年祝壽保險金 | EV522: 第13年祝壽保險金 | EW522: 第14年祝壽保險金 | EX522: 第15年祝壽保險金 | EY522: 第16年祝壽保險金 | EZ522: 第17年祝壽保險金 | FA522: 第18年祝壽保險金 | FB522: 第19年祝壽保險金 | FC522: 第20年祝壽保險金 | FD522: 第21年祝壽保險金 | FE522: 第22年祝壽保險金 | FF522: 第23年祝壽保險金 | FG522: 第24年祝壽保險金 | FH522: 第25年祝壽保險金 | FI522: 第26年祝壽保險金 | FJ522: 第27年祝壽保險金 | FK522: 第28年祝壽保險金 | FL522: 第29年祝壽保險金 | FM522: 第30年祝壽保險金 | FN522: 第31年祝壽保險金 | FO522: 第32年祝壽保險金 | FP522: 第33年祝壽保險金 | FQ522: 第34年祝壽保險金 | FR522: 第35年祝壽保險金 | FS522: 第36年祝壽保險金 | FT522: 第37年祝壽保險金 | FU522: 第38年祝壽保險金 | FV522: 第39年祝壽保險金 | FW522: 第40年祝壽保險金 | FX522: 第41年祝壽保險金 | FY522: 第42年祝壽保險金 | FZ522: 第43年祝壽保險金 | GA522: 第44年祝壽保險金 | GB522: 第45年祝壽保險金 | GC522: 第46年祝壽保險金 | GD522: 第47年祝壽保險金 | GE522: 第48年祝壽保險金 | GF522: 第49年祝壽保險金 | GG522: 第50年祝壽保險金 | GH522: 第51年祝壽保險金 | GI522: 第52年祝壽保險金 | GJ522: 第53年祝壽保險金 | GK522: 第54年祝壽保險金 | GL522: 第55年祝壽保險金 | GM522: 第56年祝壽保險金 | GN522: 第57年祝壽保險金 | GO522: 第58年祝壽保險金 | GP522: 第59年祝壽保險金 | GQ522: 第60年祝壽保險金 | GR522: 第61年祝壽保險金 | GS522: 第62年祝壽保險金 | GT522: 第63年祝壽保險金 | GU522: 第64年祝壽保險金 | GV522: 第65年祝壽保險金 | GW522: 第66年祝壽保險金 | GX522: 第67年祝壽保險金 | GY522: 第68年祝壽保險金 | GZ522: 第69年祝壽保險金 | HA522: 第70年祝壽保險金 | HB522: 第71年祝壽保險金 | HC522: 第72年祝壽保險金 | HD522: 第73年祝壽保險金 | HE522: 第74年祝壽保險金 | HF522: 第75年祝壽保險金 | HG522: 第76年祝壽保險金 | HH522: 第77年祝壽保險金 | HI522: 第78年祝壽保險金 | HJ522: 第79年祝壽保險金 | HK522: 第80年祝壽保險金 | HL522: 第81年祝壽保險金 | HM522: 第82年祝壽保險金 | HN522: 第83年祝壽保險金 | HO522: 第84年祝壽保險金 | HP522: 第85年祝壽保險金 | HQ522: 第86年祝壽保險金 | HR522: 第87年祝壽保險金 | HS522: 第88年祝壽保險金 | HT522: 第89年祝壽保險金 | HU522: 第90年祝壽保險金 | HV522: 第91年祝壽保險金 | HW522: 第92年祝壽保險金 | HX522: 第93年祝壽保險金 | HY522: 第94年祝壽保險金 | HZ522: 第95年祝壽保險金 | IA522: 第96年祝壽保險金 | IB522: 第97年祝壽保險金 | IC522: 第98年祝壽保險金 | ID522: 第99年祝壽保險金 | IE522: 第100年祝壽保險金 | IF522: 第101年祝壽保險金 | IG522: 第102年祝壽保險金 | IH522: 第103年祝壽保險金 | II522: 第104年祝壽保險金 | IJ522: 第105年祝壽保險金 | IK522: 第106年祝壽保險金 | IL522: 第107年祝壽保險金 | IM522: 第108年祝壽保險金 | IN522: 第109年祝壽保險金 | IO522: 第110年祝壽保險金 | IP522: 第111年祝壽保險金
R801: PVFB | S801: 含 | T801: 1051130 | V801: =S801&TEXT(T801,"00")&TEXT(U801,"00") -> 含105113000 | EE801: PVFB0 | EF801: 領後 | EG801: 1051128 | EI801: =EF801&TEXT(EG801,"00")&TEXT(EH801,"00") -> 領後105112800
R802: 版次 | S802: 商品代號 | T802: 性別 | U802: 年齡 | EE802: 版次 | EF802: 商品代號 | EG802: 性別 | EH802: 年齡
R957: tbPV0(期初保價金)_領後(不含生存金) | V957: =S957&TEXT(T957,"00")&TEXT(U957,"00") -> 0000 | EE957: PV | EI957: =EF957&TEXT(EG957,"00")&TEXT(EH957,"00") -> 0000
EE958: 版次 | EF958: 商品代號 | EG958: 性別 | EH958: 年齡
R1132: tbHEALTH1 | V1132: =S1132&TEXT(T1132,"00")&TEXT(U1132,"00") -> 0000 | EE1132: tbHEALTH2 | EI1132: =EF1132&TEXT(EG1132,"00")&TEXT(EH1132,"00") -> 0000
R1133: 版次 | S1133: InsuranceReverseName | T1133: Gender | U1133: Age | V1133: =S1133&TEXT(T1133,"00")&TEXT(U1133,"00") -> InsuranceReverseNameGenderAge | W1133: HEALTH1 | X1133: HEALTH2 | Y1133: HEALTH3 | Z1133: HEALTH4 | AA1133: HEALTH5 | AB1133: HEALTH6 | AC1133: HEALTH7 | AD1133: HEALTH8 | AE1133: HEALTH9 | AF1133: HEALTH10 | AG1133: HEALTH11 | AH1133: HEALTH12 | AI1133: HEALTH13 | AJ1133: HEALTH14 | AK1133: HEALTH15 | AL1133: HEALTH16 | AM1133: HEALTH17 | AN1133: HEALTH18 | AO1133: HEALTH19 | AP1133: HEALTH20 | AQ1133: HEALTH21 | AR1133: HEALTH22 | AS1133: HEALTH23 | AT1133: HEALTH24 | AU1133: HEALTH25 | AV1133: HEALTH26 | AW1133: HEALTH27 | AX1133: HEALTH28 | AY1133: HEALTH29 | AZ1133: HEALTH30 | BA1133: HEALTH31 | BB1133: HEALTH32 | BC1133: HEALTH33 | BD1133: HEALTH34 | BE1133: HEALTH35 | BF1133: HEALTH36 | BG1133: HEALTH37 | BH1133: HEALTH38 | BI1133: HEALTH39 | BJ1133: HEALTH40 | BK1133: HEALTH41 | BL1133: HEALTH42 | BM1133: HEALTH43 | BN1133: HEALTH44 | BO1133: HEALTH45 | BP1133: HEALTH46 | BQ1133: HEALTH47 | BR1133: HEALTH48 | BS1133: HEALTH49 | BT1133: HEALTH50 | BU1133: HEALTH51 | BV1133: HEALTH52 | BW1133: HEALTH53 | BX1133: HEALTH54 | BY1133: HEALTH55 | BZ1133: HEALTH56 | CA1133: HEALTH57 | CB1133: HEALTH58 | CC1133: HEALTH59 | CD1133: HEALTH60 | CE1133: HEALTH61 | CF1133: HEALTH62 | CG1133: HEALTH63 | CH1133: HEALTH64 | CI1133: HEALTH65 | CJ1133: HEALTH66 | CK1133: HEALTH67 | CL1133: HEALTH68 | CM1133: HEALTH69 | CN1133: HEALTH70 | CO1133: HEALTH71 | CP1133: HEALTH72 | CQ1133: HEALTH73 | CR1133: HEALTH74 | CS1133: HEALTH75 | CT1133: HEALTH76 | CU1133: HEALTH77 | CV1133: HEALTH78 | CW1133: HEALTH79 | CX1133: HEALTH80 | CY1133: HEALTH81 | CZ1133: HEALTH82 | DA1133: HEALTH83 | DB1133: HEALTH84 | DC1133: HEALTH85 | DD1133: HEALTH86 | DE1133: HEALTH87 | DF1133: HEALTH88 | DG1133: HEALTH89 | DH1133: HEALTH90 | DI1133: HEALTH91 | DJ1133: HEALTH92 | DK1133: HEALTH93 | DL1133: HEALTH94 | DM1133: HEALTH95 | DN1133: HEALTH96 | DO1133: HEALTH97 | DP1133: HEALTH98 | DQ1133: HEALTH99 | DR1133: HEALTH100 | DS1133: HEALTH101 | DT1133: HEALTH102 | DU1133: HEALTH103 | DV1133: HEALTH104 | DW1133: HEALTH105 | DX1133: HEALTH106 | DY1133: HEALTH107 | DZ1133: HEALTH108 | EA1133: HEALTH109 | EB1133: HEALTH110 | EC1133: HEALTH111 | EE1133: 版次 | EF1133: InsuranceReverseName | EG1133: Gender | EH1133: Age | EI1133: =EF1133&TEXT(EG1133,"00")&TEXT(EH1133,"00") -> InsuranceReverseNameGenderAge | EJ1133: HEALTH1 | EK1133: HEALTH2 | EL1133: HEALTH3 | EM1133: HEALTH4 | EN1133: HEALTH5 | EO1133: HEALTH6 | EP1133: HEALTH7 | EQ1133: HEALTH8 | ER1133: HEALTH9 | ES1133: HEALTH10 | ET1133: HEALTH11 | EU1133: HEALTH12 | EV1133: HEALTH13 | EW1133: HEALTH14 | EX1133: HEALTH15 | EY1133: HEALTH16 | EZ1133: HEALTH17 | FA1133: HEALTH18 | FB1133: HEALTH19 | FC1133: HEALTH20 | FD1133: HEALTH21 | FE1133: HEALTH22 | FF1133: HEALTH23 | FG1133: HEALTH24 | FH1133: HEALTH25 | FI1133: HEALTH26 | FJ1133: HEALTH27 | FK1133: HEALTH28 | FL1133: HEALTH29 | FM1133: HEALTH30 | FN1133: HEALTH31 | FO1133: HEALTH32 | FP1133: HEALTH33 | FQ1133: HEALTH34 | FR1133: HEALTH35 | FS1133: HEALTH36 | FT1133: HEALTH37 | FU1133: HEALTH38 | FV1133: HEALTH39 | FW1133: HEALTH40 | FX1133: HEALTH41 | FY1133: HEALTH42 | FZ1133: HEALTH43 | GA1133: HEALTH44 | GB1133: HEALTH45 | GC1133: HEALTH46 | GD1133: HEALTH47 | GE1133: HEALTH48 | GF1133: HEALTH49 | GG1133: HEALTH50 | GH1133: HEALTH51 | GI1133: HEALTH52 | GJ1133: HEALTH53 | GK1133: HEALTH54 | GL1133: HEALTH55 | GM1133: HEALTH56 | GN1133: HEALTH57 | GO1133: HEALTH58 | GP1133: HEALTH59 | GQ1133: HEALTH60 | GR1133: HEALTH61 | GS1133: HEALTH62 | GT1133: HEALTH63 | GU1133: HEALTH64 | GV1133: HEALTH65 | GW1133: HEALTH66 | GX1133: HEALTH67 | GY1133: HEALTH68 | GZ1133: HEALTH69 | HA1133: HEALTH70 | HB1133: HEALTH71 | HC1133: HEALTH72 | HD1133: HEALTH73 | HE1133: HEALTH74 | HF1133: HEALTH75 | HG1133: HEALTH76 | HH1133: HEALTH77 | HI1133: HEALTH78 | HJ1133: HEALTH79 | HK1133: HEALTH80 | HL1133: HEALTH81 | HM1133: HEALTH82 | HN1133: HEALTH83 | HO1133: HEALTH84 | HP1133: HEALTH85 | HQ1133: HEALTH86 | HR1133: HEALTH87 | HS1133: HEALTH88 | HT1133: HEALTH89 | HU1133: HEALTH90 | HV1133: HEALTH91 | HW1133: HEALTH92 | HX1133: HEALTH93 | HY1133: HEALTH94 | HZ1133: HEALTH95 | IA1133: HEALTH96 | IB1133: HEALTH97 | IC1133: HEALTH98 | ID1133: HEALTH99 | IE1133: HEALTH100 | IF1133: HEALTH101 | IG1133: HEALTH102 | IH1133: HEALTH103 | II1133: HEALTH104 | IJ1133: HEALTH105 | IK1133: HEALTH106 | IL1133: HEALTH107 | IM1133: HEALTH108 | IN1133: HEALTH109 | IO1133: HEALTH110 | IP1133: HEALTH111

Sheet RDATA
A1: =OP!$C$22 -> LTT | B1: =IF($F$2>0,1,"") | G1: 1 | H1: =IF(H2<>A2&A1,"富邦人壽官網尚未公告"&A2&"宣告利率，目前使用"&LEFT($H$2,8)&"宣告利率，試算當月宣告利率以富邦人壽官網公告為準。","") -> 富邦人壽官網尚未公告115 / 8 宣告利率，目前使用宣告利率，試算當月宣告利率以富邦人壽官網公告為準。 | I1: =IF(H1="",1,"")
A2: =YEAR(TODAY())-1911&" / "&MONTH(TODAY())&" " -> 115 / 8 | D2: key | E2: 宣告利率 | F2: =SUM($F$3:$F$200) -> 0 | G2: 1 | I2: =IF(OP!$C$3<J2,K2,L2) -> 0.0175 | J2: 46023 | K2: 0.0175 | L2: 0.0175
B3: =IF(OR(D3="",D3=0,RIGHT(D3,LEN($A$1))<>$A$1),,(LEFT($D3,3)*100)+MID($D3,7,IF(OR(AND(LEN($A$1)=3,LEN($D3)=12),AND(LEN($A$1)=4,LEN($D3)=13)),2,1))*1) -> 0 | C3: =IF($B3=0,,RANK($B3,$B$3:$B$78)) -> 0 | F3: =IF(AND(RIGHT($D3,LEN($A$1))<>$A$1,$D3<>""),1,0) -> 0 | G3: 2 | H3: =IF(ISNA(VLOOKUP($G3,$C:$E,2,0)),"",VLOOKUP($G3,$C:$E,2,0)) | I3: =IF(ISNA(VLOOKUP($G3,$C:$E,3,0)),"",VLOOKUP($G3,$C:$E,3,0)) | J3: 45658 | K3: 0.0162 | L3: 0.0175
A4: =COUNTIF($D:$D,$A$3) -> 0 | B4: =IF(OR(D4="",D4=0,RIGHT(D4,LEN($A$1))<>$A$1),,(LEFT($D4,3)*100)+MID($D4,7,IF(OR(AND(LEN($A$1)=3,LEN($D4)=12),AND(LEN($A$1)=4,LEN($D4)=13)),2,1))*1) -> 0 | C4: =IF($B4=0,,RANK($B4,$B$3:$B$78)) -> 0 | F4: =IF(AND(RIGHT($D4,LEN($A$1))<>$A$1,$D4<>""),1,0) -> 0 | G4: 3 | H4: =IF(ISNA(VLOOKUP($G4,$C:$E,2,0)),"",VLOOKUP($G4,$C:$E,2,0)) | I4: =IF(ISNA(VLOOKUP($G4,$C:$E,3,0)),"",VLOOKUP($G4,$C:$E,3,0)) | J4: 45292 | K4: 0.015 | L4: 0.0162
B5: =IF(OR(D5="",D5=0,RIGHT(D5,LEN($A$1))<>$A$1),,(LEFT($D5,3)*100)+MID($D5,7,IF(OR(AND(LEN($A$1)=3,LEN($D5)=12),AND(LEN($A$1)=4,LEN($D5)=13)),2,1))*1) -> 0 | C5: =IF($B5=0,,RANK($B5,$B$3:$B$78)) -> 0 | F5: =IF(AND(RIGHT($D5,LEN($A$1))<>$A$1,$D5<>""),1,0) -> 0 | G5: 4 | H5: =IF(ISNA(VLOOKUP($G5,$C:$E,2,0)),"",VLOOKUP($G5,$C:$E,2,0)) | I5: =IF(ISNA(VLOOKUP($G5,$C:$E,3,0)),"",VLOOKUP($G5,$C:$E,3,0))
B6: =IF(OR(D6="",D6=0,RIGHT(D6,LEN($A$1))<>$A$1),,(LEFT($D6,3)*100)+MID($D6,7,IF(OR(AND(LEN($A$1)=3,LEN($D6)=12),AND(LEN($A$1)=4,LEN($D6)=13)),2,1))*1) -> 0 | C6: =IF($B6=0,,RANK($B6,$B$3:$B$78)) -> 0 | F6: =IF(AND(RIGHT($D6,LEN($A$1))<>$A$1,$D6<>""),1,0) -> 0 | G6: 5 | H6: =IF(ISNA(VLOOKUP($G6,$C:$E,2,0)),"",VLOOKUP($G6,$C:$E,2,0)) | I6: =IF(ISNA(VLOOKUP($G6,$C:$E,3,0)),"",VLOOKUP($G6,$C:$E,3,0))
B7: =IF(OR(D7="",D7=0,RIGHT(D7,LEN($A$1))<>$A$1),,(LEFT($D7,3)*100)+MID($D7,7,IF(OR(AND(LEN($A$1)=3,LEN($D7)=12),AND(LEN($A$1)=4,LEN($D7)=13)),2,1))*1) -> 0 | C7: =IF($B7=0,,RANK($B7,$B$3:$B$78)) -> 0 | F7: =IF(AND(RIGHT($D7,LEN($A$1))<>$A$1,$D7<>""),1,0) -> 0 | G7: 6 | H7: =IF(ISNA(VLOOKUP($G7,$C:$E,2,0)),"",VLOOKUP($G7,$C:$E,2,0)) | I7: =IF(ISNA(VLOOKUP($G7,$C:$E,3,0)),"",VLOOKUP($G7,$C:$E,3,0))
B8: =IF(OR(D8="",D8=0,RIGHT(D8,LEN($A$1))<>$A$1),,(LEFT($D8,3)*100)+MID($D8,7,IF(OR(AND(LEN($A$1)=3,LEN($D8)=12),AND(LEN($A$1)=4,LEN($D8)=13)),2,1))*1) -> 0 | C8: =IF($B8=0,,RANK($B8,$B$3:$B$78)) -> 0 | F8: =IF(AND(RIGHT($D8,LEN($A$1))<>$A$1,$D8<>""),1,0) -> 0 | G8: 7 | H8: =IF(ISNA(VLOOKUP($G8,$C:$E,2,0)),"",VLOOKUP($G8,$C:$E,2,0)) | I8: =IF(ISNA(VLOOKUP($G8,$C:$E,3,0)),"",VLOOKUP($G8,$C:$E,3,0))
B9: =IF(OR(D9="",D9=0,RIGHT(D9,LEN($A$1))<>$A$1),,(LEFT($D9,3)*100)+MID($D9,7,IF(OR(AND(LEN($A$1)=3,LEN($D9)=12),AND(LEN($A$1)=4,LEN($D9)=13)),2,1))*1) -> 0 | C9: =IF($B9=0,,RANK($B9,$B$3:$B$78)) -> 0 | F9: =IF(AND(RIGHT($D9,LEN($A$1))<>$A$1,$D9<>""),1,0) -> 0 | G9: 8 | H9: =IF(ISNA(VLOOKUP($G9,$C:$E,2,0)),"",VLOOKUP($G9,$C:$E,2,0)) | I9: =IF(ISNA(VLOOKUP($G9,$C:$E,3,0)),"",VLOOKUP($G9,$C:$E,3,0))
B10: =IF(OR(D10="",D10=0,RIGHT(D10,LEN($A$1))<>$A$1),,(LEFT($D10,3)*100)+MID($D10,7,IF(OR(AND(LEN($A$1)=3,LEN($D10)=12),AND(LEN($A$1)=4,LEN($D10)=13)),2,1))*1) -> 0 | C10: =IF($B10=0,,RANK($B10,$B$3:$B$78)) -> 0 | F10: =IF(AND(RIGHT($D10,LEN($A$1))<>$A$1,$D10<>""),1,0) -> 0 | G10: 9 | H10: =IF(ISNA(VLOOKUP($G10,$C:$E,2,0)),"",VLOOKUP($G10,$C:$E,2,0)) | I10: =IF(ISNA(VLOOKUP($G10,$C:$E,3,0)),"",VLOOKUP($G10,$C:$E,3,0))
B11: =IF(OR(D11="",D11=0,RIGHT(D11,LEN($A$1))<>$A$1),,(LEFT($D11,3)*100)+MID($D11,7,IF(OR(AND(LEN($A$1)=3,LEN($D11)=12),AND(LEN($A$1)=4,LEN($D11)=13)),2,1))*1) -> 0 | C11: =IF($B11=0,,RANK($B11,$B$3:$B$78)) -> 0 | F11: =IF(AND(RIGHT($D11,LEN($A$1))<>$A$1,$D11<>""),1,0) -> 0 | G11: 10 | H11: =IF(ISNA(VLOOKUP($G11,$C:$E,2,0)),"",VLOOKUP($G11,$C:$E,2,0)) | I11: =IF(ISNA(VLOOKUP($G11,$C:$E,3,0)),"",VLOOKUP($G11,$C:$E,3,0))
B12: =IF(OR(D12="",D12=0,RIGHT(D12,LEN($A$1))<>$A$1),,(LEFT($D12,3)*100)+MID($D12,7,IF(OR(AND(LEN($A$1)=3,LEN($D12)=12),AND(LEN($A$1)=4,LEN($D12)=13)),2,1))*1) -> 0 | C12: =IF($B12=0,,RANK($B12,$B$3:$B$78)) -> 0 | F12: =IF(AND(RIGHT($D12,LEN($A$1))<>$A$1,$D12<>""),1,0) -> 0 | G12: 11 | H12: =IF(ISNA(VLOOKUP($G12,$C:$E,2,0)),"",VLOOKUP($G12,$C:$E,2,0)) | I12: =IF(ISNA(VLOOKUP($G12,$C:$E,3,0)),"",VLOOKUP($G12,$C:$E,3,0))
B13: =IF(OR(D13="",D13=0,RIGHT(D13,LEN($A$1))<>$A$1),,(LEFT($D13,3)*100)+MID($D13,7,IF(OR(AND(LEN($A$1)=3,LEN($D13)=12),AND(LEN($A$1)=4,LEN($D13)=13)),2,1))*1) -> 0 | C13: =IF($B13=0,,RANK($B13,$B$3:$B$78)) -> 0 | F13: =IF(AND(RIGHT($D13,LEN($A$1))<>$A$1,$D13<>""),1,0) -> 0 | G13: 12 | H13: =IF(ISNA(VLOOKUP($G13,$C:$E,2,0)),"",VLOOKUP($G13,$C:$E,2,0)) | I13: =IF(ISNA(VLOOKUP($G13,$C:$E,3,0)),"",VLOOKUP($G13,$C:$E,3,0))
B14: =IF(OR(D14="",D14=0,RIGHT(D14,LEN($A$1))<>$A$1),,(LEFT($D14,3)*100)+MID($D14,7,IF(OR(AND(LEN($A$1)=3,LEN($D14)=12),AND(LEN($A$1)=4,LEN($D14)=13)),2,1))*1) -> 0 | C14: =IF($B14=0,,RANK($B14,$B$3:$B$78)) -> 0 | F14: =IF(AND(RIGHT($D14,LEN($A$1))<>$A$1,$D14<>""),1,0) -> 0 | G14: 13 | H14: =IF(ISNA(VLOOKUP($G14,$C:$E,2,0)),"",VLOOKUP($G14,$C:$E,2,0)) | I14: =IF(ISNA(VLOOKUP($G14,$C:$E,3,0)),"",VLOOKUP($G14,$C:$E,3,0))
B15: =IF(OR(D15="",D15=0,RIGHT(D15,LEN($A$1))<>$A$1),,(LEFT($D15,3)*100)+MID($D15,7,IF(OR(AND(LEN($A$1)=3,LEN($D15)=12),AND(LEN($A$1)=4,LEN($D15)=13)),2,1))*1) -> 0 | C15: =IF($B15=0,,RANK($B15,$B$3:$B$78)) -> 0 | F15: =IF(AND(RIGHT($D15,LEN($A$1))<>$A$1,$D15<>""),1,0) -> 0 | G15: 14 | H15: =IF(ISNA(VLOOKUP($G15,$C:$E,2,0)),"",VLOOKUP($G15,$C:$E,2,0)) | I15: =IF(ISNA(VLOOKUP($G15,$C:$E,3,0)),"",VLOOKUP($G15,$C:$E,3,0))
B16: =IF(OR(D16="",D16=0,RIGHT(D16,LEN($A$1))<>$A$1),,(LEFT($D16,3)*100)+MID($D16,7,IF(OR(AND(LEN($A$1)=3,LEN($D16)=12),AND(LEN($A$1)=4,LEN($D16)=13)),2,1))*1) -> 0 | C16: =IF($B16=0,,RANK($B16,$B$3:$B$78)) -> 0 | F16: =IF(AND(RIGHT($D16,LEN($A$1))<>$A$1,$D16<>""),1,0) -> 0 | G16: 15 | H16: =IF(ISNA(VLOOKUP($G16,$C:$E,2,0)),"",VLOOKUP($G16,$C:$E,2,0)) | I16: =IF(ISNA(VLOOKUP($G16,$C:$E,3,0)),"",VLOOKUP($G16,$C:$E,3,0))
... B25: =IF(OR(D25="",D25=0,RIGHT(D25,LEN($A$1))<>$A$1),,(LEFT($D25,3)*100)+MID($D25,7,IF(OR(AND(LEN($A$1)=3,LEN($D25)=12),AND(LEN($A$1)=4,LEN($D25)=13)),2,1))*1) -> 0 | C25: =IF($B25=0,,RANK($B25,$B$3:$B$78)) -> 0 | F25: =IF(AND(RIGHT($D25,LEN($A$1))<>$A$1,$D25<>""),1,0) -> 0 | G25: 24 | H25: =IF(ISNA(VLOOKUP($G25,$C:$E,2,0)),"",VLOOKUP($G25,$C:$E,2,0)) | I25: =IF(ISNA(VLOOKUP($G25,$C:$E,3,0)),"",VLOOKUP($G25,$C:$E,3,0))
B26: =IF(OR(D26="",D26=0,RIGHT(D26,LEN($A$1))<>$A$1),,(LEFT($D26,3)*100)+MID($D26,7,IF(OR(AND(LEN($A$1)=3,LEN($D26)=12),AND(LEN($A$1)=4,LEN($D26)=13)),2,1))*1) -> 0 | C26: =IF($B26=0,,RANK($B26,$B$3:$B$78)) -> 0 | F26: =IF(AND(RIGHT($D26,LEN($A$1))<>$A$1,$D26<>""),1,0) -> 0
B27: =IF(OR(D27="",D27=0,RIGHT(D27,LEN($A$1))<>$A$1),,(LEFT($D27,3)*100)+MID($D27,7,IF(OR(AND(LEN($A$1)=3,LEN($D27)=12),AND(LEN($A$1)=4,LEN($D27)=13)),2,1))*1) -> 0 | C27: =IF($B27=0,,RANK($B27,$B$3:$B$78)) -> 0 | F27: =IF(AND(RIGHT($D27,LEN($A$1))<>$A$1,$D27<>""),1,0) -> 0 | H27: MAX | I27: =MAX(I2:I26) -> 0.0175
B28: =IF(OR(D28="",D28=0,RIGHT(D28,LEN($A$1))<>$A$1),,(LEFT($D28,3)*100)+MID($D28,7,IF(OR(AND(LEN($A$1)=3,LEN($D28)=12),AND(LEN($A$1)=4,LEN($D28)=13)),2,1))*1) -> 0 | C28: =IF($B28=0,,RANK($B28,$B$3:$B$78)) -> 0 | F28: =IF(AND(RIGHT($D28,LEN($A$1))<>$A$1,$D28<>""),1,0) -> 0
B29: =IF(OR(D29="",D29=0,RIGHT(D29,LEN($A$1))<>$A$1),,(LEFT($D29,3)*100)+MID($D29,7,IF(OR(AND(LEN($A$1)=3,LEN($D29)=12),AND(LEN($A$1)=4,LEN($D29)=13)),2,1))*1) -> 0 | C29: =IF($B29=0,,RANK($B29,$B$3:$B$78)) -> 0 | F29: =IF(AND(RIGHT($D29,LEN($A$1))<>$A$1,$D29<>""),1,0) -> 0
B30: =IF(OR(D30="",D30=0,RIGHT(D30,LEN($A$1))<>$A$1),,(LEFT($D30,3)*100)+MID($D30,7,IF(OR(AND(LEN($A$1)=3,LEN($D30)=12),AND(LEN($A$1)=4,LEN($D30)=13)),2,1))*1) -> 0 | C30: =IF($B30=0,,RANK($B30,$B$3:$B$78)) -> 0 | F30: =IF(AND(RIGHT($D30,LEN($A$1))<>$A$1,$D30<>""),1,0) -> 0
B31: =IF(OR(D31="",D31=0,RIGHT(D31,LEN($A$1))<>$A$1),,(LEFT($D31,3)*100)+MID($D31,7,IF(OR(AND(LEN($A$1)=3,LEN($D31)=12),AND(LEN($A$1)=4,LEN($D31)=13)),2,1))*1) -> 0 | C31: =IF($B31=0,,RANK($B31,$B$3:$B$78)) -> 0 | F31: =IF(AND(RIGHT($D31,LEN($A$1))<>$A$1,$D31<>""),1,0) -> 0
B32: =IF(OR(D32="",D32=0,RIGHT(D32,LEN($A$1))<>$A$1),,(LEFT($D32,3)*100)+MID($D32,7,IF(OR(AND(LEN($A$1)=3,LEN($D32)=12),AND(LEN($A$1)=4,LEN($D32)=13)),2,1))*1) -> 0 | C32: =IF($B32=0,,RANK($B32,$B$3:$B$78)) -> 0 | F32: =IF(AND(RIGHT($D32,LEN($A$1))<>$A$1,$D32<>""),1,0) -> 0
B33: =IF(OR(D33="",D33=0,RIGHT(D33,LEN($A$1))<>$A$1),,(LEFT($D33,3)*100)+MID($D33,7,IF(OR(AND(LEN($A$1)=3,LEN($D33)=12),AND(LEN($A$1)=4,LEN($D33)=13)),2,1))*1) -> 0 | C33: =IF($B33=0,,RANK($B33,$B$3:$B$78)) -> 0 | F33: =IF(AND(RIGHT($D33,LEN($A$1))<>$A$1,$D33<>""),1,0) -> 0
B34: =IF(OR(D34="",D34=0,RIGHT(D34,LEN($A$1))<>$A$1),,(LEFT($D34,3)*100)+MID($D34,7,IF(OR(AND(LEN($A$1)=3,LEN($D34)=12),AND(LEN($A$1)=4,LEN($D34)=13)),2,1))*1) -> 0 | C34: =IF($B34=0,,RANK($B34,$B$3:$B$78)) -> 0 | F34: =IF(AND(RIGHT($D34,LEN($A$1))<>$A$1,$D34<>""),1,0) -> 0
B35: =IF(OR(D35="",D35=0,RIGHT(D35,LEN($A$1))<>$A$1),,(LEFT($D35,3)*100)+MID($D35,7,IF(OR(AND(LEN($A$1)=3,LEN($D35)=12),AND(LEN($A$1)=4,LEN($D35)=13)),2,1))*1) -> 0 | C35: =IF($B35=0,,RANK($B35,$B$3:$B$78)) -> 0 | F35: =IF(AND(RIGHT($D35,LEN($A$1))<>$A$1,$D35<>""),1,0) -> 0
B36: =IF(OR(D36="",D36=0,RIGHT(D36,LEN($A$1))<>$A$1),,(LEFT($D36,3)*100)+MID($D36,7,IF(OR(AND(LEN($A$1)=3,LEN($D36)=12),AND(LEN($A$1)=4,LEN($D36)=13)),2,1))*1) -> 0 | C36: =IF($B36=0,,RANK($B36,$B$3:$B$78)) -> 0 | F36: =IF(AND(RIGHT($D36,LEN($A$1))<>$A$1,$D36<>""),1,0) -> 0
B37: =IF(OR(D37="",D37=0,RIGHT(D37,LEN($A$1))<>$A$1),,(LEFT($D37,3)*100)+MID($D37,7,IF(OR(AND(LEN($A$1)=3,LEN($D37)=12),AND(LEN($A$1)=4,LEN($D37)=13)),2,1))*1) -> 0 | C37: =IF($B37=0,,RANK($B37,$B$3:$B$78)) -> 0 | F37: =IF(AND(RIGHT($D37,LEN($A$1))<>$A$1,$D37<>""),1,0) -> 0
B38: =IF(OR(D38="",D38=0,RIGHT(D38,LEN($A$1))<>$A$1),,(LEFT($D38,3)*100)+MID($D38,7,IF(OR(AND(LEN($A$1)=3,LEN($D38)=12),AND(LEN($A$1)=4,LEN($D38)=13)),2,1))*1) -> 0 | C38: =IF($B38=0,,RANK($B38,$B$3:$B$78)) -> 0 | F38: =IF(AND(RIGHT($D38,LEN($A$1))<>$A$1,$D38<>""),1,0) -> 0
B39: =IF(OR(D39="",D39=0,RIGHT(D39,LEN($A$1))<>$A$1),,(LEFT($D39,3)*100)+MID($D39,7,IF(OR(AND(LEN($A$1)=3,LEN($D39)=12),AND(LEN($A$1)=4,LEN($D39)=13)),2,1))*1) -> 0 | C39: =IF($B39=0,,RANK($B39,$B$3:$B$78)) -> 0 | F39: =IF(AND(RIGHT($D39,LEN($A$1))<>$A$1,$D39<>""),1,0) -> 0
... B200: =IF(OR(D200="",D200=0,RIGHT(D200,LEN($A$1))<>$A$1),,(LEFT($D200,3)*100)+MID($D200,7,IF(OR(AND(LEN($A$1)=3,LEN($D200)=12),AND(LEN($A$1)=4,LEN($D200)=13)),2,1))*1) -> 0 | C200: =IF($B200=0,,RANK($B200,$B$3:$B$78)) -> 0 | F200: =IF(AND(RIGHT($D200,LEN($A$1))<>$A$1,$D200<>""),1,0) -> 0

Sheet PY
B2: 轉換金額 | C2: 10000
C3: 分期 | D3: ㄧ次
B4: 指定保險金比例： | C4: =MIN(1,ROUND(OP!$C$141,2)) -> 0 | D4: =1-C4 -> 1 | F4: 年 | G4: 1
B5: 分期最低金額 | C5: =$C$38 -> 20000 | D5: =$D$38 -> 200000 | F5: 半年 | G5: 2
B6: 分期定期保險金給付期間： | C6: =OP!$C$142 -> 10 | F6: 季 | G6: 4
B7: 假設分期定期保險金預定利率： | C7: =$B$30 -> 0.02 | F7: 月 | G7: 12
B8: 期別 | C8: 年 | D8: =VLOOKUP($C$8,$F$4:$G$7,2,0) -> 1
B10: 精算公式→ | C10: =IF(C6=0,,C2*(C7*(1/(1+C7)))/(1-(1/(1+C7))^C6)) -> 1091.4365 | D10: ←精算換算比例(每萬元)
C11: =C10/10000 -> 0.10914365 | D11: ←帶入換算比例(每元)
B15: 定期定額-本利攤還
B16: 給付金額/每期 | C16: =ROUND(PMT($C$7/$D$8,$C$6*$D$8,-$C$2*$C$4,,1),0) -> 0
B17: 給付總額 | C17: =C16*C6*D8 -> 0
B18: 給付比例 | C18: =PMT($C$7/$D$8,$C$6*$D$8,-$C$2,,1)/C2 -> 0.10914365 | D18: ←自行計算換算比例
B20: 定額不定期
B21: 給付金額/每期 | C21: 550 | D21: ←帶入期付金額
B22: 給付總額 | C22: =C21*(($C$26*$D$8)+$C$27) -> 12100
B23: 給付比例 | C23: =$C$21/($C$2/$C$4) -> #DIV/0!
B24: 給付次數 | C24: =NPER($C$7/$D$8,$C$21,-$C$2,0,1) -> 22.261841
B25: 剩餘金額 | C25: =ROUND(C21*($C$24-ROUNDDOWN($C$24,0)),0) -> 144
B26: 給付年次 | C26: =ROUNDDOWN(ROUNDDOWN($C$24,0)/$D$8,0) -> 22 | D26: ←自行計算給付年月數
B27: ="給付"&C8&"次" -> 給付年次 | C27: =ROUNDDOWN($C$24,0)-($C$26*$D$8) -> 0 | D27: ="EX："&$C$26&" 年 "&IF($C$27=0,"",C27&" "&$C$8) -> EX：22 年
B29: 台幣=1，美元=2，澳幣=3 | C29: =OP!$C$21 -> 1 | D29: 新臺幣 | E29: ←設定幣別
B30: =IF($C$29=1,$C$31,IF($C$29=2,$D$31,$E$31)) -> 0.02 | C30: 台幣(1) | D30: 美元(2) | E30: 澳幣(3)
C31: 0.02 | D31: 0.025 | E31: 0.0275
B37: 分期低額 | C37: 每期 | D37: 指定
B38: =$C$29 -> 1 | C38: =VLOOKUP(B38,$B$39:$D$40,2,0) -> 20000 | D38: =VLOOKUP(B38,$B$39:$D$40,3,0) -> 200000
B39: 2 | C39: 3000 | D39: 30000 | E39: =NUMBERSTRING(IF(C39/10000<1,C39/1000,C39/10000),3)&RIGHT(NUMBERSTRING(C39,1),1) -> 三千 | F39: =NUMBERSTRING(IF(D39/10000<1,D39/1000,D39/10000),1)&RIGHT(NUMBERSTRING(D39,2),1) -> 三萬
B40: 1 | C40: 20000 | D40: 200000 | E40: =NUMBERSTRING(IF(C40/10000<1,C40/1000,C40/10000),3)&RIGHT(NUMBERSTRING(C40,2),1) -> 二萬 | F40: =NUMBERSTRING(IF(D40/10000<1,D40/1000,D40/10000),1)&RIGHT(NUMBERSTRING(D40,2),1) -> 二十萬
B41: 3 | C41: 3000 | D41: 30000 | E41: =NUMBERSTRING(IF(C41/10000<1,C41/1000,C41/10000),3)&RIGHT(NUMBERSTRING(C41,1),1) -> 三千 | F41: =NUMBERSTRING(IF(D41/10000<1,D41/1000,D41/10000),1)&RIGHT(NUMBERSTRING(D41,2),1) -> 三萬
B42: 4 | E42: =NUMBERSTRING(IF(C42/10000<1,C42/1000,C42/10000),3)&RIGHT(NUMBERSTRING(C42,2),1) -> ○零 | F42: =NUMBERSTRING(IF(D42/10000<1,D42/1000,D42/10000),1)&RIGHT(NUMBERSTRING(D42,2),1) -> ○零
B43: =IF(OR(AND($D$29=$B$45,$C$29<>1),ISERROR(VLOOKUP($D$29,$B$45:$D$48,3,0))),"商品幣別設定錯誤",VLOOKUP($D$29,$B$45:$D$48,3,0)) -> 二十萬元或每年給付之分期定期保險金低於二萬元者， | C43: =IF(OR(AND($D$29=$B$45,$C$29<>1),ISERROR(VLOOKUP($D$29,$B$45:$D$48,3,0))),1,0) -> 0
B45: 新臺幣 | C45: 1 | D45: =VLOOKUP($C$45,$B$39:$F$42,5,0)&"元"&"或每年給付之分期定期保險金低於"&VLOOKUP($C$45,$B$39:$F$42,4,0)&"元"&"者，" -> 二十萬元或每年給付之分期定期保險金低於二萬元者，
B46: 美元 | C46: 2 | D46: =VLOOKUP($C$46,$B$39:$F$42,5,0)&$B$46&"或每年給付之分期定期保險金低於"&VLOOKUP($C$46,$B$39:$F$42,4,0)&$B$46&"者，" -> 三萬美元或每年給付之分期定期保險金低於三千美元者，
B47: 澳幣 | C47: 3 | D47: =VLOOKUP($C$47,$B$39:$F$42,5,0)&$B$47&"或每年給付之分期定期保險金低於"&VLOOKUP($C$47,$B$39:$F$42,4,0)&$B$47&"者，" -> 三萬澳幣或每年給付之分期定期保險金低於三千澳幣者，
B48: 人民幣 | C48: 4 | D48: =VLOOKUP($C$48,$B$39:$F$42,5,0)&$B$48&"或每年給付之分期定期保險金低於"&VLOOKUP($C$48,$B$39:$F$42,4,0)&$B$48&"者，" -> ○零人民幣或每年給付之分期定期保險金低於○零人民幣者，

Sheet 揭露
B1: =OP!$C$56 -> LTT30 | C1: ←帶OP | D1: =IF(OP!$E$16=1,"足歲",IF(OP!$E$16=2,"保險年齡","錯誤")) -> 保險年齡 | E1: ←帶OP | Q1: 6 | R1: 7 | S1: 8 | T1: 9 | U1: 10 | V1: 11 | W1: 12
L2: 以下3欄要注意最下方要和右側揭露拉齊 | O2: 以下COPY-DB | Q2: 1120911
C3: 代表年齡第?小→ | D3: 1 | E3: 2 | F3: 3 | G3: 1 | H3: 2 | I3: 3 | K3: 年齡代號轉換 | L3: KEY | M3: 年齡 | N3: 年度 | O3: 險種大類 | P3: 年期險種 | Q3: 性別 | R3: 年齡 | S3: 繳費方式 | T3: 宣告利率 | U3: 繳費金額 | V3: 保單年度 | W3: 揭露利率
C4: 性別男=1，女=2→ | D4: 1 | E4: 1 | F4: 1 | G4: 2 | H4: 2 | I4: 2 | K4: =IF($D$1="足歲","15足","") | L4: =IF(P4<>$B$1,"",P4&Q4&R4&V4) | M4: =IF(L4="","-",IF(ISERROR($R4*1),LEFT($R4,2)*1,$R4*1)) -> - | N4: =IF(L4="","",V4*1)
B5: 取第?欄→ | C5: 12 | D5: =IF(SMALL($M:$M,D$3)=15,$K$4,SMALL($M:$M,D$3)) -> #NUM! | E5: =IF(SMALL($M:$M,E$3)=15,$K$4,SMALL($M:$M,E$3)) -> #NUM! | F5: =IF(SMALL($M:$M,F$3)=15,$K$4,SMALL($M:$M,F$3)) -> #NUM! | G5: =IF(SMALL($M:$M,G$3)=15,$K$4,SMALL($M:$M,G$3)) -> #NUM! | H5: =IF(SMALL($M:$M,H$3)=15,$K$4,SMALL($M:$M,H$3)) -> #NUM! | I5: =IF(SMALL($M:$M,I$3)=15,$K$4,SMALL($M:$M,I$3)) -> #NUM! | L5: =IF(P5<>$B$1,"",P5&Q5&R5&V5) | M5: =IF(OR(L5="",COUNTIF($M$4:M4,IF(ISERROR($R5*1),LEFT($R5,2)*1,$R5*1))>=1),"-",IF(ISERROR($R5*1),LEFT($R5,2)*1,$R5*1)) -> - | N5: =IF(OR(L5="",COUNTIF($N$4:N4,V5*1)>=1),"-",V5*1) -> -
B6: 第?小↓ | C6: 保單年度 | D6: =IF(OR(ISERROR($D5)),"",IF((D$5)=0,D$5&IF(D$4=1,"男性",IF(D$4=2,"女性","")),D$5&"歲"&IF(D$4=1,"男性",IF(D$4=2,"女性","")))) | E6: =IF(OR(ISERROR($D5)),"",IF((E$5)=0,E$5&IF(E$4=1,"男性",IF(E$4=2,"女性","")),E$5&"歲"&IF(E$4=1,"男性",IF(E$4=2,"女性","")))) | F6: =IF(OR(ISERROR($D5)),"",IF((F$5)=0,F$5&IF(F$4=1,"男性",IF(F$4=2,"女性","")),F$5&"歲"&IF(F$4=1,"男性",IF(F$4=2,"女性","")))) | G6: =IF(OR(ISERROR($D5)),"",IF((G$5)=0,G$5&IF(G$4=1,"男性",IF(G$4=2,"女性","")),G$5&"歲"&IF(G$4=1,"男性",IF(G$4=2,"女性","")))) | H6: =IF(OR(ISERROR($D5)),"",IF((H$5)=0,H$5&IF(H$4=1,"男性",IF(H$4=2,"女性","")),H$5&"歲"&IF(H$4=1,"男性",IF(H$4=2,"女性","")))) | I6: =IF(OR(ISERROR($D5)),"",IF((I$5)=0,I$5&IF(I$4=1,"男性",IF(I$4=2,"女性","")),I$5&"歲"&IF(I$4=1,"男性",IF(I$4=2,"女性","")))) | L6: =IF(P6<>$B$1,"",P6&Q6&R6&V6) | M6: =IF(OR(L6="",COUNTIF($M$4:M5,IF(ISERROR($R6*1),LEFT($R6,2)*1,$R6*1))>=1),"-",IF(ISERROR($R6*1),LEFT($R6,2)*1,$R6*1)) -> - | N6: =IF(OR(L6="",COUNTIF($N$4:N5,V6*1)>=1),"-",V6*1) -> -
B7: 1 | C7: =IF(ISERROR(SMALL($N:$N,$B7)),"",SMALL($N:$N,$B7)) | D7: =IF(ISERROR(VLOOKUP($B$1&D$4&D$5&$C7,$L:$W,$C$5,0)),"",VLOOKUP($B$1&D$4&D$5&$C7,$L:$W,$C$5,0)) | E7: =IF(ISERROR(VLOOKUP($B$1&E$4&E$5&$C7,$L:$W,$C$5,0)),"",VLOOKUP($B$1&E$4&E$5&$C7,$L:$W,$C$5,0)) | F7: =IF(ISERROR(VLOOKUP($B$1&F$4&F$5&$C7,$L:$W,$C$5,0)),"",VLOOKUP($B$1&F$4&F$5&$C7,$L:$W,$C$5,0)) | G7: =IF(ISERROR(VLOOKUP($B$1&G$4&G$5&$C7,$L:$W,$C$5,0)),"",VLOOKUP($B$1&G$4&G$5&$C7,$L:$W,$C$5,0)) | H7: =IF(ISERROR(VLOOKUP($B$1&H$4&H$5&$C7,$L:$W,$C$5,0)),"",VLOOKUP($B$1&H$4&H$5&$C7,$L:$W,$C$5,0)) | I7: =IF(ISERROR(VLOOKUP($B$1&I$4&I$5&$C7,$L:$W,$C$5,0)),"",VLOOKUP($B$1&I$4&I$5&$C7,$L:$W,$C$5,0)) | L7: =IF(P7<>$B$1,"",P7&Q7&R7&V7) | M7: =IF(OR(L7="",COUNTIF($M$4:M6,IF(ISERROR($R7*1),LEFT($R7,2)*1,$R7*1))>=1),"-",IF(ISERROR($R7*1),LEFT($R7,2)*1,$R7*1)) -> - | N7: =IF(OR(L7="",COUNTIF($N$4:N6,V7*1)>=1),"-",V7*1) -> -
B8: 2 | C8: =IF(ISERROR(SMALL($N:$N,$B8)),"",SMALL($N:$N,$B8)) | D8: =IF(ISERROR(VLOOKUP($B$1&D$4&D$5&$C8,$L:$W,$C$5,0)),"",VLOOKUP($B$1&D$4&D$5&$C8,$L:$W,$C$5,0)) | E8: =IF(ISERROR(VLOOKUP($B$1&E$4&E$5&$C8,$L:$W,$C$5,0)),"",VLOOKUP($B$1&E$4&E$5&$C8,$L:$W,$C$5,0)) | F8: =IF(ISERROR(VLOOKUP($B$1&F$4&F$5&$C8,$L:$W,$C$5,0)),"",VLOOKUP($B$1&F$4&F$5&$C8,$L:$W,$C$5,0)) | G8: =IF(ISERROR(VLOOKUP($B$1&G$4&G$5&$C8,$L:$W,$C$5,0)),"",VLOOKUP($B$1&G$4&G$5&$C8,$L:$W,$C$5,0)) | H8: =IF(ISERROR(VLOOKUP($B$1&H$4&H$5&$C8,$L:$W,$C$5,0)),"",VLOOKUP($B$1&H$4&H$5&$C8,$L:$W,$C$5,0)) | I8: =IF(ISERROR(VLOOKUP($B$1&I$4&I$5&$C8,$L:$W,$C$5,0)),"",VLOOKUP($B$1&I$4&I$5&$C8,$L:$W,$C$5,0)) | L8: =IF(P8<>$B$1,"",P8&Q8&R8&V8) | M8: =IF(OR(L8="",COUNTIF($M$4:M7,IF(ISERROR($R8*1),LEFT($R8,2)*1,$R8*1))>=1),"-",IF(ISERROR($R8*1),LEFT($R8,2)*1,$R8*1)) -> - | N8: =IF(OR(L8="",COUNTIF($N$4:N7,V8*1)>=1),"-",V8*1) -> -
B9: 3 | C9: =IF(ISERROR(SMALL($N:$N,$B9)),"",SMALL($N:$N,$B9)) | D9: =IF(ISERROR(VLOOKUP($B$1&D$4&D$5&$C9,$L:$W,$C$5,0)),"",VLOOKUP($B$1&D$4&D$5&$C9,$L:$W,$C$5,0)) | E9: =IF(ISERROR(VLOOKUP($B$1&E$4&E$5&$C9,$L:$W,$C$5,0)),"",VLOOKUP($B$1&E$4&E$5&$C9,$L:$W,$C$5,0)) | F9: =IF(ISERROR(VLOOKUP($B$1&F$4&F$5&$C9,$L:$W,$C$5,0)),"",VLOOKUP($B$1&F$4&F$5&$C9,$L:$W,$C$5,0)) | G9: =IF(ISERROR(VLOOKUP($B$1&G$4&G$5&$C9,$L:$W,$C$5,0)),"",VLOOKUP($B$1&G$4&G$5&$C9,$L:$W,$C$5,0)) | H9: =IF(ISERROR(VLOOKUP($B$1&H$4&H$5&$C9,$L:$W,$C$5,0)),"",VLOOKUP($B$1&H$4&H$5&$C9,$L:$W,$C$5,0)) | I9: =IF(ISERROR(VLOOKUP($B$1&I$4&I$5&$C9,$L:$W,$C$5,0)),"",VLOOKUP($B$1&I$4&I$5&$C9,$L:$W,$C$5,0)) | L9: =IF(P9<>$B$1,"",P9&Q9&R9&V9) | M9: =IF(OR(L9="",COUNTIF($M$4:M8,IF(ISERROR($R9*1),LEFT($R9,2)*1,$R9*1))>=1),"-",IF(ISERROR($R9*1),LEFT($R9,2)*1,$R9*1)) -> - | N9: =IF(OR(L9="",COUNTIF($N$4:N8,V9*1)>=1),"-",V9*1) -> -
B10: 4 | C10: =IF(ISERROR(SMALL($N:$N,$B10)),"",SMALL($N:$N,$B10)) | D10: =IF(ISERROR(VLOOKUP($B$1&D$4&D$5&$C10,$L:$W,$C$5,0)),"",VLOOKUP($B$1&D$4&D$5&$C10,$L:$W,$C$5,0)) | E10: =IF(ISERROR(VLOOKUP($B$1&E$4&E$5&$C10,$L:$W,$C$5,0)),"",VLOOKUP($B$1&E$4&E$5&$C10,$L:$W,$C$5,0)) | F10: =IF(ISERROR(VLOOKUP($B$1&F$4&F$5&$C10,$L:$W,$C$5,0)),"",VLOOKUP($B$1&F$4&F$5&$C10,$L:$W,$C$5,0)) | G10: =IF(ISERROR(VLOOKUP($B$1&G$4&G$5&$C10,$L:$W,$C$5,0)),"",VLOOKUP($B$1&G$4&G$5&$C10,$L:$W,$C$5,0)) | H10: =IF(ISERROR(VLOOKUP($B$1&H$4&H$5&$C10,$L:$W,$C$5,0)),"",VLOOKUP($B$1&H$4&H$5&$C10,$L:$W,$C$5,0)) | I10: =IF(ISERROR(VLOOKUP($B$1&I$4&I$5&$C10,$L:$W,$C$5,0)),"",VLOOKUP($B$1&I$4&I$5&$C10,$L:$W,$C$5,0)) | L10: =IF(P10<>$B$1,"",P10&Q10&R10&V10) | M10: =IF(OR(L10="",COUNTIF($M$4:M9,IF(ISERROR($R10*1),LEFT($R10,2)*1,$R10*1))>=1),"-",IF(ISERROR($R10*1),LEFT($R10,2)*1,$R10*1)) -> - | N10: =IF(OR(L10="",COUNTIF($N$4:N9,V10*1)>=1),"-",V10*1) -> -
B11: 5 | C11: =IF(ISERROR(SMALL($N:$N,$B11)),"",SMALL($N:$N,$B11)) | D11: =IF(ISERROR(VLOOKUP($B$1&D$4&D$5&$C11,$L:$W,$C$5,0)),"",VLOOKUP($B$1&D$4&D$5&$C11,$L:$W,$C$5,0)) | E11: =IF(ISERROR(VLOOKUP($B$1&E$4&E$5&$C11,$L:$W,$C$5,0)),"",VLOOKUP($B$1&E$4&E$5&$C11,$L:$W,$C$5,0)) | F11: =IF(ISERROR(VLOOKUP($B$1&F$4&F$5&$C11,$L:$W,$C$5,0)),"",VLOOKUP($B$1&F$4&F$5&$C11,$L:$W,$C$5,0)) | G11: =IF(ISERROR(VLOOKUP($B$1&G$4&G$5&$C11,$L:$W,$C$5,0)),"",VLOOKUP($B$1&G$4&G$5&$C11,$L:$W,$C$5,0)) | H11: =IF(ISERROR(VLOOKUP($B$1&H$4&H$5&$C11,$L:$W,$C$5,0)),"",VLOOKUP($B$1&H$4&H$5&$C11,$L:$W,$C$5,0)) | I11: =IF(ISERROR(VLOOKUP($B$1&I$4&I$5&$C11,$L:$W,$C$5,0)),"",VLOOKUP($B$1&I$4&I$5&$C11,$L:$W,$C$5,0)) | L11: =IF(P11<>$B$1,"",P11&Q11&R11&V11) | M11: =IF(OR(L11="",COUNTIF($M$4:M10,IF(ISERROR($R11*1),LEFT($R11,2)*1,$R11*1))>=1),"-",IF(ISERROR($R11*1),LEFT($R11,2)*1,$R11*1)) -> - | N11: =IF(OR(L11="",COUNTIF($N$4:N10,V11*1)>=1),"-",V11*1) -> -
B12: 6 | C12: =IF(ISERROR(SMALL($N:$N,$B12)),"",SMALL($N:$N,$B12)) | D12: =IF(ISERROR(VLOOKUP($B$1&D$4&D$5&$C12,$L:$W,$C$5,0)),"",VLOOKUP($B$1&D$4&D$5&$C12,$L:$W,$C$5,0)) | E12: =IF(ISERROR(VLOOKUP($B$1&E$4&E$5&$C12,$L:$W,$C$5,0)),"",VLOOKUP($B$1&E$4&E$5&$C12,$L:$W,$C$5,0)) | F12: =IF(ISERROR(VLOOKUP($B$1&F$4&F$5&$C12,$L:$W,$C$5,0)),"",VLOOKUP($B$1&F$4&F$5&$C12,$L:$W,$C$5,0)) | G12: =IF(ISERROR(VLOOKUP($B$1&G$4&G$5&$C12,$L:$W,$C$5,0)),"",VLOOKUP($B$1&G$4&G$5&$C12,$L:$W,$C$5,0)) | H12: =IF(ISERROR(VLOOKUP($B$1&H$4&H$5&$C12,$L:$W,$C$5,0)),"",VLOOKUP($B$1&H$4&H$5&$C12,$L:$W,$C$5,0)) | I12: =IF(ISERROR(VLOOKUP($B$1&I$4&I$5&$C12,$L:$W,$C$5,0)),"",VLOOKUP($B$1&I$4&I$5&$C12,$L:$W,$C$5,0)) | L12: =IF(P12<>$B$1,"",P12&Q12&R12&V12) | M12: =IF(OR(L12="",COUNTIF($M$4:M11,IF(ISERROR($R12*1),LEFT($R12,2)*1,$R12*1))>=1),"-",IF(ISERROR($R12*1),LEFT($R12,2)*1,$R12*1)) -> - | N12: =IF(OR(L12="",COUNTIF($N$4:N11,V12*1)>=1),"-",V12*1) -> -
B13: 7 | C13: =IF(ISERROR(SMALL($N:$N,$B13)),"",SMALL($N:$N,$B13)) | D13: =IF(ISERROR(VLOOKUP($B$1&D$4&D$5&$C13,$L:$W,$C$5,0)),"",VLOOKUP($B$1&D$4&D$5&$C13,$L:$W,$C$5,0)) | E13: =IF(ISERROR(VLOOKUP($B$1&E$4&E$5&$C13,$L:$W,$C$5,0)),"",VLOOKUP($B$1&E$4&E$5&$C13,$L:$W,$C$5,0)) | F13: =IF(ISERROR(VLOOKUP($B$1&F$4&F$5&$C13,$L:$W,$C$5,0)),"",VLOOKUP($B$1&F$4&F$5&$C13,$L:$W,$C$5,0)) | G13: =IF(ISERROR(VLOOKUP($B$1&G$4&G$5&$C13,$L:$W,$C$5,0)),"",VLOOKUP($B$1&G$4&G$5&$C13,$L:$W,$C$5,0)) | H13: =IF(ISERROR(VLOOKUP($B$1&H$4&H$5&$C13,$L:$W,$C$5,0)),"",VLOOKUP($B$1&H$4&H$5&$C13,$L:$W,$C$5,0)) | I13: =IF(ISERROR(VLOOKUP($B$1&I$4&I$5&$C13,$L:$W,$C$5,0)),"",VLOOKUP($B$1&I$4&I$5&$C13,$L:$W,$C$5,0)) | L13: =IF(P13<>$B$1,"",P13&Q13&R13&V13) | M13: =IF(OR(L13="",COUNTIF($M$4:M12,IF(ISERROR($R13*1),LEFT($R13,2)*1,$R13*1))>=1),"-",IF(ISERROR($R13*1),LEFT($R13,2)*1,$R13*1)) -> - | N13: =IF(OR(L13="",COUNTIF($N$4:N12,V13*1)>=1),"-",V13*1) -> -
B14: 8 | C14: =IF(ISERROR(SMALL($N:$N,$B14)),"",SMALL($N:$N,$B14)) | D14: =IF(ISERROR(VLOOKUP($B$1&D$4&D$5&$C14,$L:$W,$C$5,0)),"",VLOOKUP($B$1&D$4&D$5&$C14,$L:$W,$C$5,0)) | E14: =IF(ISERROR(VLOOKUP($B$1&E$4&E$5&$C14,$L:$W,$C$5,0)),"",VLOOKUP($B$1&E$4&E$5&$C14,$L:$W,$C$5,0)) | F14: =IF(ISERROR(VLOOKUP($B$1&F$4&F$5&$C14,$L:$W,$C$5,0)),"",VLOOKUP($B$1&F$4&F$5&$C14,$L:$W,$C$5,0)) | G14: =IF(ISERROR(VLOOKUP($B$1&G$4&G$5&$C14,$L:$W,$C$5,0)),"",VLOOKUP($B$1&G$4&G$5&$C14,$L:$W,$C$5,0)) | H14: =IF(ISERROR(VLOOKUP($B$1&H$4&H$5&$C14,$L:$W,$C$5,0)),"",VLOOKUP($B$1&H$4&H$5&$C14,$L:$W,$C$5,0)) | I14: =IF(ISERROR(VLOOKUP($B$1&I$4&I$5&$C14,$L:$W,$C$5,0)),"",VLOOKUP($B$1&I$4&I$5&$C14,$L:$W,$C$5,0)) | L14: =IF(P14<>$B$1,"",P14&Q14&R14&V14) | M14: =IF(OR(L14="",COUNTIF($M$4:M13,IF(ISERROR($R14*1),LEFT($R14,2)*1,$R14*1))>=1),"-",IF(ISERROR($R14*1),LEFT($R14,2)*1,$R14*1)) -> - | N14: =IF(OR(L14="",COUNTIF($N$4:N13,V14*1)>=1),"-",V14*1) -> -
C15: 以上區域為帶入列印頁範圍 | L15: =IF(P15<>$B$1,"",P15&Q15&R15&V15) | M15: =IF(OR(L15="",COUNTIF($M$4:M14,IF(ISERROR($R15*1),LEFT($R15,2)*1,$R15*1))>=1),"-",IF(ISERROR($R15*1),LEFT($R15,2)*1,$R15*1)) -> - | N15: =IF(OR(L15="",COUNTIF($N$4:N14,V15*1)>=1),"-",V15*1) -> -
L16: =IF(P16<>$B$1,"",P16&Q16&R16&V16) | M16: =IF(OR(L16="",COUNTIF($M$4:M15,IF(ISERROR($R16*1),LEFT($R16,2)*1,$R16*1))>=1),"-",IF(ISERROR($R16*1),LEFT($R16,2)*1,$R16*1)) -> - | N16: =IF(OR(L16="",COUNTIF($N$4:N15,V16*1)>=1),"-",V16*1) -> -
L17: =IF(P17<>$B$1,"",P17&Q17&R17&V17) | M17: =IF(OR(L17="",COUNTIF($M$4:M16,IF(ISERROR($R17*1),LEFT($R17,2)*1,$R17*1))>=1),"-",IF(ISERROR($R17*1),LEFT($R17,2)*1,$R17*1)) -> - | N17: =IF(OR(L17="",COUNTIF($N$4:N16,V17*1)>=1),"-",V17*1) -> -
L18: =IF(P18<>$B$1,"",P18&Q18&R18&V18) | M18: =IF(OR(L18="",COUNTIF($M$4:M17,IF(ISERROR($R18*1),LEFT($R18,2)*1,$R18*1))>=1),"-",IF(ISERROR($R18*1),LEFT($R18,2)*1,$R18*1)) -> - | N18: =IF(OR(L18="",COUNTIF($N$4:N17,V18*1)>=1),"-",V18*1) -> -
L19: =IF(P19<>$B$1,"",P19&Q19&R19&V19) | M19: =IF(OR(L19="",COUNTIF($M$4:M18,IF(ISERROR($R19*1),LEFT($R19,2)*1,$R19*1))>=1),"-",IF(ISERROR($R19*1),LEFT($R19,2)*1,$R19*1)) -> - | N19: =IF(OR(L19="",COUNTIF($N$4:N18,V19*1)>=1),"-",V19*1) -> -
L20: =IF(P20<>$B$1,"",P20&Q20&R20&V20) | M20: =IF(OR(L20="",COUNTIF($M$4:M19,IF(ISERROR($R20*1),LEFT($R20,2)*1,$R20*1))>=1),"-",IF(ISERROR($R20*1),LEFT($R20,2)*1,$R20*1)) -> - | N20: =IF(OR(L20="",COUNTIF($N$4:N19,V20*1)>=1),"-",V20*1) -> -
L21: =IF(P21<>$B$1,"",P21&Q21&R21&V21) | M21: =IF(OR(L21="",COUNTIF($M$4:M20,IF(ISERROR($R21*1),LEFT($R21,2)*1,$R21*1))>=1),"-",IF(ISERROR($R21*1),LEFT($R21,2)*1,$R21*1)) -> - | N21: =IF(OR(L21="",COUNTIF($N$4:N20,V21*1)>=1),"-",V21*1) -> -
L22: =IF(P22<>$B$1,"",P22&Q22&R22&V22) | M22: =IF(OR(L22="",COUNTIF($M$4:M21,IF(ISERROR($R22*1),LEFT($R22,2)*1,$R22*1))>=1),"-",IF(ISERROR($R22*1),LEFT($R22,2)*1,$R22*1)) -> - | N22: =IF(OR(L22="",COUNTIF($N$4:N21,V22*1)>=1),"-",V22*1) -> -
L23: =IF(P23<>$B$1,"",P23&Q23&R23&V23) | M23: =IF(OR(L23="",COUNTIF($M$4:M22,IF(ISERROR($R23*1),LEFT($R23,2)*1,$R23*1))>=1),"-",IF(ISERROR($R23*1),LEFT($R23,2)*1,$R23*1)) -> - | N23: =IF(OR(L23="",COUNTIF($N$4:N22,V23*1)>=1),"-",V23*1) -> -
L24: =IF(P24<>$B$1,"",P24&Q24&R24&V24) | M24: =IF(OR(L24="",COUNTIF($M$4:M23,IF(ISERROR($R24*1),LEFT($R24,2)*1,$R24*1))>=1),"-",IF(ISERROR($R24*1),LEFT($R24,2)*1,$R24*1)) -> - | N24: =IF(OR(L24="",COUNTIF($N$4:N23,V24*1)>=1),"-",V24*1) -> -
L25: =IF(P25<>$B$1,"",P25&Q25&R25&V25) | M25: =IF(OR(L25="",COUNTIF($M$4:M24,IF(ISERROR($R25*1),LEFT($R25,2)*1,$R25*1))>=1),"-",IF(ISERROR($R25*1),LEFT($R25,2)*1,$R25*1)) -> - | N25: =IF(OR(L25="",COUNTIF($N$4:N24,V25*1)>=1),"-",V25*1) -> -
L26: =IF(P26<>$B$1,"",P26&Q26&R26&V26) | M26: =IF(OR(L26="",COUNTIF($M$4:M25,IF(ISERROR($R26*1),LEFT($R26,2)*1,$R26*1))>=1),"-",IF(ISERROR($R26*1),LEFT($R26,2)*1,$R26*1)) -> - | N26: =IF(OR(L26="",COUNTIF($N$4:N25,V26*1)>=1),"-",V26*1) -> -
L27: =IF(P27<>$B$1,"",P27&Q27&R27&V27) | M27: =IF(OR(L27="",COUNTIF($M$4:M26,IF(ISERROR($R27*1),LEFT($R27,2)*1,$R27*1))>=1),"-",IF(ISERROR($R27*1),LEFT($R27,2)*1,$R27*1)) -> - | N27: =IF(OR(L27="",COUNTIF($N$4:N26,V27*1)>=1),"-",V27*1) -> -
... L147: =IF(P147<>$B$1,"",P147&Q147&R147&V147) | M147: =IF(OR(L147="",COUNTIF($M$4:M146,IF(ISERROR($R147*1),LEFT($R147,2)*1,$R147*1))>=1),"-",IF(ISERROR($R147*1),LEFT($R147,2)*1,$R147*1)) -> - | N147: =IF(OR(L147="",COUNTIF($N$4:N146,V147*1)>=1),"-",V147*1) -> -

Sheet input_s
A1: 回傳資訊
A2: 保費：首期 | B2: =IF($H$8=0,"",IF(ISERROR(OP!$D$53),"資料錯誤_首期保費",OP!$C$48))
A3: 保費：續期 | B3: =IF($H$8=0,"",IF(ISERROR(OP!$D$53),"資料錯誤_續期保費",IF(OP!$C$24=1,0,OP!$C$49)))
A4: 錯誤訊息： | B4: =IF($H$8=0,"",IF(ISERROR(OP!$D$53),"資料錯誤",I15&J15&I16&J16&I17&J17&I19&J19&I20&J20&I21&J21&I22&J22&I24&J24&I26&J26&I27&J27&I32&J32&I34&J34&I35&J35&I40&J40&I45&J45&I53&J53&I59&J59&I61&J61&I62&J62&I63&J63&I64&J64&I71&J71&I79&J79&I81&J81&I82&J82&I84&J84&I86&J86&I92&J92&I93&J93&I94&J94&I95&J95&I106&J106))
A5: 原始保費： | B5: =IF($H$8=0,"",IF(ISERROR(OP!$D$53),"資料錯誤_原始保費",OP!$C$35)) | C5: 1090428新增 | H5: 目前未使用，預留
A6: 保險年齡： | B6: =IF($H$8=0,"",IF(ISERROR(OP!$D$53),"資料錯誤_保險年齡",OP!$D$5)) | C6: 1090428新增 | H6: EXCEL使用
H7: 是否使用：1=系統帶入,0=輸入頁帶入 | I7: 利變：1、分紅：2、其他：3
H8: 0 | I8: 3
A9: 欄位名 | B9: 中文名 | C9: 說明 | D9: 是否必填 | E9: 試算表使用欄位 | H9: excel套用欄位內容 | I9: 錯誤訊息 | J9: 間隔 | L9: 性別
A10: ProposalRequest | L10: 1 | M10: 男
A11: TrnNum | B11: 交易序號 | C11: 系統代號+yyyymmddhhMMssmis(建議保險公司可以接收該欄位並記錄於log中, 到時候追查資料時比較方便) | D11: V | E11: X | J11: =IF(I11="","",IF(COUNTA(I12:$I$138)>0,"|","")) | L11: 2 | M11: 女
A12: data_type | B12: 資料類別 | C12: 1.產生建議書 | D12: V | J12: =IF(I12="","",IF(COUNTA(I13:$I$138)>0,"|",""))
C13: 2.要保書檢核 | J13: =IF(I13="","",IF(COUNTA(I14:$I$138)>0,"|",""))
A14: insco_no | B14: 保險公司代碼 | C14: 018安聯 | D14: V | E14: X | J14: =IF(I14="","",IF(COUNTA(I15:$I$138)>0,"|",""))
A15: proposal_seq | B15: 建議書序號 | C15: data_type為2(要保書檢核)時不傳 | E15: 中信規則 | H15: =IF($H$8=1,$G15,"") | I15: =IF(G15="","","") | J15: =IF(I15="","",IF(COUNTA(I16:$I$138)>0,"|","")) | L15: 被保人身分別 | N15: 1090721-建議書序號不需檢核 | O15: =IF(G15="","無傳入建議書序號","") -> 無傳入建議書序號
A16: owner_name | B16: 要保人姓名 | D16: V | F16: 目前無要保人欄位，預留 | H16: =IF($H$8=1,$G16,"") | J16: =IF(I16="","",IF(COUNTA(I17:$I$138)>0,"|","")) | L16: 1 | M16: 一般
A17: owner_sex | B17: 要保人性別 | C17: 1男 | D17: V | H17: =IF($H$8=1,IF(ISERROR(VLOOKUP($G17,$L$10:$M$13,2,0)),"",VLOOKUP($G17,$L$10:$M$13,2,0)),"") | J17: =IF(I17="","",IF(COUNTA(I18:$I$138)>0,"|","")) | L17: 2 | M17: 學生
C18: 2女 | J18: =IF(I18="","",IF(COUNTA(I19:$I$138)>0,"|","")) | L18: 3 | M18: 家管
A19: owner_birth | B19: 要保人出生年月日 | C19: yyyymmdd | D19: V | H19: =IF($H$8=1,IF(OR($G$19="",LEN($G$19)<>8),"",LEFT($G$19,4)-1911&TEXT(MID($G$19,5,2),"00")&TEXT(RIGHT($G$19,2),"00")),輸入頁!$E$14) -> 0 | J19: =IF(I19="","",IF(COUNTA(I20:$I$138)>0,"|","")) | L19: 4 | M19: 退休人士
A20: is_owner | B20: 要被保人同一人 | C20: Y/N | D20: V | H20: =IF($H$8=1,$G20,"") | J20: =IF(I20="","",IF(COUNTA(I21:$I$138)>0,"|",""))
A21: insure_name | B21: 被保人姓名 | D21: V | H21: =IF($H$8=1,IF($G$21="","",$G21),輸入頁!$E$5) -> 客戶 | I21: =IF($H$21="",$I$10&"被保險人姓名未填寫","") | J21: =IF(I21="","",IF(COUNTA(I22:$I$138)>0,"|",""))
A22: insure_sex | B22: 被保險人性別 | C22: 1男 | D22: V | H22: =IF($H$8=1,IF(ISERROR(VLOOKUP($G22,$L$10:$M$13,2,0)),"",VLOOKUP($G22,$L$10:$M$13,2,0)),輸入頁!$K$5) -> 女 | I22: =IF(OR($H$22="",OP!$D$18=1),$I$10&"被保險人性別錯誤","") | J22: =IF(I22="","",IF(COUNTA(I23:$I$138)>0,"|",""))
C23: 2女 | J23: =IF(I23="","",IF(COUNTA(I24:$I$138)>0,"|","")) | L23: 繳別
A24: insure_birthday | B24: 被保險人出生年月日 | C24: yyyymmdd | D24: V | H24: =IF($H$8=1,IF(OR($G$24="",LEN($G$24)<>8),"",LEFT($G$24,4)-1911&TEXT(MID($G$24,5,2),"00")&TEXT(RIGHT($G$24,2),"00")),輸入頁!$N$5) -> 1010101 | I24: =IF(H24="",$I$10&"被保險人生日錯誤",IF(OP!$E$6=1,"生日日期錯誤",""))&IF(OR(OP!$D$15=1,OP!$D$16=1),"＊年齡不符專案投保區間，請先確認年齡後 重新試算，其他欄位檢核訊息請先忽略＊","") | J24: =IF(I24="","",IF(COUNTA(I25:$I$138)>0,"|","")) | K24: 1150126調整 | L24: 01 | M24: 月繳
J25: =IF(I25="","",IF(COUNTA(I26:$I$138)>0,"|","")) | L25: 03 | M25: 季繳
A26: insure_prof_kind | B26: 被保險人職業等級 | C26: 1~6 | D26: V | F26: 與被保人兼業等級取大 | H26: =IF($H$8=1,MAX($G26,$G32),"") | J26: =IF(I26="","",IF(COUNTA(I27:$I$138)>0,"|","")) | L26: 06 | M26: 半年繳
A27: insure_prof_type | B27: 被保險人職業身分別 | C27: 1.一般 | F27: 試算表無身分判別，預留 | H27: =IF($H$8=1,IF(ISERROR(VLOOKUP($G27,$L$16:$M$21,2,0)),"",VLOOKUP($G27,$L$16:$M$21,2,0)),"") | J27: =IF(I27="","",IF(COUNTA(I28:$I$138)>0,"|","")) | L27: 12 | M27: 年繳
C28: 2.學生 | J28: =IF(I28="","",IF(COUNTA(I29:$I$138)>0,"|","")) | L28: P | M28: 躉繳
C29: 3.家管 | J29: =IF(I29="","",IF(COUNTA(I30:$I$138)>0,"|",""))
C30: 4.退休人士 | J30: =IF(I30="","",IF(COUNTA(I31:$I$138)>0,"|",""))
A31: insure_job_code | B31: 被保險人職業代碼 | E31: X | J31: =IF(I31="","",IF(COUNTA(I32:$I$138)>0,"|","")) | L31: 繳費方式 | M31: 首期 | N31: 續期 | O31: 中信
A32: insure_part_time_prof_kind | B32: 被保險人兼職職業等級 | C32: 1~6 | D32: V | H32: 於H26取大 | J32: =IF(I32="","",IF(COUNTA(I33:$I$138)>0,"|","")) | L32: 1 | M32: =IF(OP!$C$21=1,"匯款","外幣匯款") -> 匯款 | N32: - | O32: 1.帳戶圈存(匯款)
A33: insure_part_time_job_code | B33: 被保險人兼職職業代碼 | E33: X | J33: =IF(I33="","",IF(COUNTA(I34:$I$138)>0,"|","")) | L33: 2 | M33: =IF(OP!$C$21=1,"匯款","外幣匯款") -> 匯款 | N33: - | O33: 2.現金圈存(匯款)
A34: plan_code | B34: 險種代號 | D34: V | H34: =IF($H$8=1,UPPER($G34),輸入頁!$E$39) -> LTT | I34: =IF(ISERROR(VLOOKUP($H$34,OP!$H$43:$H$62,1,0)),$I$10&"險種錯誤","") | J34: =IF(I34="","",IF(COUNTA(I35:$I$138)>0,"|","")) | L34: 3 | M34: 一般信用卡 | N34: 一般信用卡 | O34: 3.信用卡
A35: paid_period_year | B35: 繳費年期 | D35: V | H35: =IF($H$8=1,$G35,輸入頁!$E$37) -> 30 | I35: =IF(COUNTIF(OP!$J$43:$J$62,$H$35&$H$34)<>1,$I$10&"年期錯誤","") | J35: =IF(I35="","",IF(COUNTA(I36:$I$138)>0,"|","")) | L35: 4 | M35: 金融機構轉帳 | N35: 金融機構轉帳 | O35: 4.本行自扣(轉帳)
A36: coverage_type | B36: 保障類別單位 | C36: 1.保額 2單位 3計畫 | D36: V | E36: X | F36: 試算表無須判別 | J36: =IF(I36="","",IF(COUNTA(I37:$I$138)>0,"|","")) | L36: 5 | M36: =IF(OP!$C$21=1,"匯款","外幣匯款") -> 匯款 | N36: 自行繳費 | O36: 5.臨櫃轉帳(匯款)
A37: cuy_cpo | B37: 保額幣別 | C37: 台幣為TWD | D37: V | E37: X | F37: 試算表無須判別 | J37: =IF(I37="","",IF(COUNTA(I38:$I$138)>0,"|","")) | L37: 6 | M37: =IF(OP!$C$21=1,"匯款","外幣匯款") -> 匯款 | N37: 自行繳費 | O37: 6.臨櫃存入(匯款)
A38: cuy_prem | B38: 保費幣別 | C38: OIU商品時, | D38: V | E38: X | F38: 試算表無須判別 | J38: =IF(I38="","",IF(COUNTA(I39:$I$138)>0,"|","")) | L38: 7 | M38: - | N38: - | O38: 9.其他
C39: 可能保額與保費幣別不同 | J39: =IF(I39="","",IF(COUNTA(I40:$I$138)>0,"|","")) | L39: A | M39: 金融機構轉帳 | N39: 金融機構轉帳 | O39: A.他行自扣(轉帳)
A40: Modx | B40: 繳別 | C40: 01 月繳 | D40: V | H40: =IF($H$8=1,IF(ISERROR(VLOOKUP($G40,$L$24:$M$29,2,0)),"",VLOOKUP($G40,$L$24:$M$29,2,0)),輸入頁!$E$17) -> 年繳 | I40: =IF(OP!$D$32=1,$I$10&"繳別錯誤","") | J40: =IF(I40="","",IF(COUNTA(I41:$I$138)>0,"|",""))
...

Sheet 總表
B1: 1 | C1: 2 | D1: 3 | E1: 4 | F1: 5 | G1: 6 | H1: 7 | I1: 8 | J1: 9 | K1: 10 | L1: 11 | M1: 12 | N1: 13 | O1: 14 | P1: 15 | Q1: 16 | R1: 17 | S1: 18 | T1: 19 | U1: 20 | V1: 21 | W1: 22 | X1: 23 | Y1: 24 | Z1: 25 | AA1: 26 | AB1: 27 | AC1: 28 | AD1: 29 | AE1: 30 | AF1: 31 | AG1: 32 | AH1: 33 | AI1: 34
D2: 列印頁-簡/銀保/彙總 | F2: 基本保額 | N2: 累計增額繳清保險金額 | S2: 生存保險金 F+O | T2: 累計生存保險金 | U2: 生存保險金(月) round(S/12,0) | V2: 累計生存保險金(月) (U*12)+上期總額 | Y2: 年度末身故/完全失能時可領總金額 | Z2: 身故保障=基本保額+增購保額-最後一年回饋金(增購保額) ㄧ次給付身故=身故保障*比例PYO+紅利+最後一年紅利(增購保額) 分期給付=身故保障*比例PYY | AA2: 列印頁 未扣除增值回饋分享金 | AB2: 列印頁 未扣除增值回饋分享金 | AC2: 保險金額- 大眾運輸工具意外身故保障-28 (不含年度末身故/完全失能時可領總金額) | AD2: 重大燒燙傷保險金-29 | AE2: 保險金額- 大眾運輸工具 意外身故保障-30 (含年度末身故/完全失能保障) | AF2: 意外身故保險金(含身故可領總金額)-31
B3: 保 單 年 度 | C3: 保 險 年 齡 | D3: ="年度實繳保費"&IF(OP!$F$55<15," 已扣除增值回饋分享金 ","") -> 年度實繳保費 | E3: ="累計實繳保費"&IF(OP!$F$55<15," 已扣除增值回饋分享金 ","") -> 累計實繳保費 | F3: 生存保險金 | G3: 累計已領 生存保險金 | H3: 年度末 身故/完全 失能保障 | I3: 年度末 解約金 | J3: 年度末 減額繳清 保險金額 | N3: 年度末 保險金額 ( Z ) | O3: 生存保險金 | P3: 累計已領生存保險金 | Q3: ="年度末 身故/完全失能保障 ( D ) "&OP!$D$114 -> 年度末 身故/完全失能保障 ( D ) | R3: ="年度末 解約金 ( E ) "&OP!$D$115 -> 年度末 解約金 ( E ) | Y3: ㄧ次給付 | Z3: =IF(OR(PYY=0,PY!$C$6=0),"","分期給付(年) 給付"&PY!$C$6&"年") | AA3: 年度 實繳保費 | AB3: 累計 實繳保費 | AE3: 年度末 大眾運輸 交通工具 意外身故保障 | AF3: 年度末 大眾運輸交通工具 意外身故時可領總金額 | AG3: 重大疾病暨 特定傷病保險金 | AH3: 輕度失智 保險金 | AI3: 中重度失智 保險金 (免責期間屆滿 時之保單年度)
B4: 1 | C4: =IF(OP!$D$53=1,"",OP!$F$55) -> 15 | D4: =IF(OR(OP!$D$53=1,AND($B4>OP!$C$24)),"",OP!$C$51) -> 11326 | E4: =IF(OR(OP!$D$53=1,$B4=""),"",N(D4)) -> 11326 | F4: =IF(OR(OP!$D$53=1,$B4="",ISERROR(VLOOKUP(OP!$C$55,SRV,$B4+1,0))),"",ROUND(VLOOKUP(OP!$C$55,SRV,$B4+1,0)*OP!$C$28,0)) | G4: =IF(OR(OP!$D$53=1,$B4="",ISERROR(VLOOKUP(OP!$C$55,SRV,$B4+1,0))),"",N($F4)) | H4: =IF(OR(OP!$D$53=1,$B4=""),"",ROUND(VLOOKUP(OP!$C$55,DIE,$B4+1,0)*OP!$C$28,0)) -> #N/A | I4: =IF(OR(OP!$D$53=1,$B4=""),"",ROUND(VLOOKUP(OP!$C$55,CV,$B4+1,0)*OP!$C$28,0)) -> #N/A | J4: =IF(OR(OP!$D$53=1,$B4=""),"",ROUND(VLOOKUP(OP!$C$55,PA,$B4+1,0)*OP!$C$28,0)) -> #N/A | S4: =IF(OR(OP!$D$53=1,$B4=""),"",N($F4)+N($O4)) -> 0 | T4: =IF(OR(OP!$D$53=1,$B4=""),0,N($S4)) -> 0 | U4: =IF(OR(OP!$D$53=1,$B4=""),"",ROUND($S4/12,0)) -> 0 | V4: =IF(OR(OP!$D$53=1,$B4=""),0,N($U4)*12) -> 0 | Y4: =IF(OR(OP!$D$53=1,$B4=""),"",ROUND(($H4+$Q4)*IF(OR($C4<16,$Z4=0,$Z4=""),1,PYO),0)) -> #N/A | Z4: =IF(OR(OP!$D$53=1,$B4=""),"",ROUND(($H4+Q4)*IF(OR($C4<16,($H4+$Q4)*PY!$C$4<PY!$D$5,($H4+$Q4)*PY!$C$4*PYR<PY!$C$5),0,PYY)*PYR,0)) -> #N/A | AA4: =IF(OR(OP!$D$53=1,AND(B4>OP!$C$24)),"",OP!$C$51) -> 11326 | AB4: =IF(OR(OP!$D$53=1,$B4=""),"",N($AA4)) -> 11326 | AH4: =IF(OR(OP!$D$53=1,$B4=""),"",ROUND(VLOOKUP(OP!$C$55,HL_1,$B4+1,0)*OP!$C$28,0)) -> #N/A | AI4: =IF(OR(OP!$D$53=1,$B4=""),"",ROUND(VLOOKUP(OP!$C$55,HL_2,$B4+1,0)*OP!$C$28,0)) -> #N/A
B5: =IF(OR(C4>=OP!$F$57,C4=""),"",IF(C4+1>OP!$F$57,OP!$F$57+1-$C$4,B4+1)) -> 2 | C5: =IF(OR(OP!$D$53=1,MAX($C4:C$4)>=OP!$F$57),"",C4+(B5-B4)) -> 16 | D5: =IF(OR(OP!$D$53=1,AND($B5>OP!$C$24)),"",OP!$C$52-IF($C5<16,$K4,0)) -> 11326 | E5: =IF(OR(OP!$D$53=1,$B5=""),"",N($E4)+N($D5)) -> 22652 | F5: =IF(OR(OP!$D$53=1,$B5="",ISERROR(VLOOKUP(OP!$C$55,SRV,$B5+1,0))),"",ROUND(VLOOKUP(OP!$C$55,SRV,$B5+1,0)*OP!$C$28,0)) | G5: =IF(OR(OP!$D$53=1,$B5="",ISERROR(VLOOKUP(OP!$C$55,SRV,$B5+1,0))),"",N($G4)+N($F5)) | H5: =IF(OR(OP!$D$53=1,$B5=""),"",ROUND(VLOOKUP(OP!$C$55,DIE,$B5+1,0)*OP!$C$28,0)) -> #N/A | I5: =IF(OR(OP!$D$53=1,$B5=""),"",ROUND(VLOOKUP(OP!$C$55,CV,$B5+1,0)*OP!$C$28,0)) -> #N/A | J5: =IF(OR(OP!$D$53=1,$B5=""),"",ROUND(VLOOKUP(OP!$C$55,PA,$B5+1,0)*OP!$C$28,0)) -> #N/A | S5: =IF(OR(OP!$D$53=1,$B5=""),"",N($F5)+N($O5)) -> 0 | T5: =IF(OR(OP!$D$53=1,$B5=""),0,N($T4)+N($S5)) -> 0 | U5: =IF(OR(OP!$D$53=1,$B5=""),"",ROUND($S5/12,0)) -> 0 | V5: =IF(OR(OP!$D$53=1,$B5=""),0,N($V4)+(N($U5)*12)) -> 0 | Y5: =IF(OR(OP!$D$53=1,$B5=""),"",ROUND(($H5+$Q5)*IF(OR($C5<16,$Z5=0,$Z5=""),1,PYO),0)) -> #N/A | Z5: =IF(OR(OP!$D$53=1,$B5=""),"",ROUND(($H5+Q5)*IF(OR($C5<16,($H5+$Q5)*PY!$C$4<PY!$D$5,($H5+$Q5)*PY!$C$4*PYR<PY!$C$5),0,PYY)*PYR,0)) -> #N/A | AA5: =IF(OR(OP!$D$53=1,AND(B5>OP!$C$24)),"",OP!$C$52) -> 11326 | AB5: =IF(OR(OP!$D$53=1,$B5=""),"",N($AB4)+N($AA5)) -> 22652 | AH5: =IF(OR(OP!$D$53=1,$B5=""),"",ROUND(VLOOKUP(OP!$C$55,HL_1,$B5+1,0)*OP!$C$28,0)) -> #N/A | AI5: =IF(OR(OP!$D$53=1,$B5=""),"",ROUND(VLOOKUP(OP!$C$55,HL_2,$B5+1,0)*OP!$C$28,0)) -> #N/A
B6: =IF(OR(C5>=OP!$F$57,C5=""),"",IF(C5+1>OP!$F$57,OP!$F$57+1-$C$4,B5+1)) -> 3 | C6: =IF(OR(OP!$D$53=1,MAX($C$4:C5)>=OP!$F$57),"",C5+(B6-B5)) -> 17 | D6: =IF(OR(OP!$D$53=1,AND($B6>OP!$C$24)),"",OP!$C$52-IF($C6<16,$K5,0)) -> 11326 | E6: =IF(OR(OP!$D$53=1,$B6=""),"",N($E5)+N($D6)) -> 33978 | F6: =IF(OR(OP!$D$53=1,$B6="",ISERROR(VLOOKUP(OP!$C$55,SRV,$B6+1,0))),"",ROUND(VLOOKUP(OP!$C$55,SRV,$B6+1,0)*OP!$C$28,0)) | G6: =IF(OR(OP!$D$53=1,$B6="",ISERROR(VLOOKUP(OP!$C$55,SRV,$B6+1,0))),"",N($G5)+N($F6)) | H6: =IF(OR(OP!$D$53=1,$B6=""),"",ROUND(VLOOKUP(OP!$C$55,DIE,$B6+1,0)*OP!$C$28,0)) -> #N/A | I6: =IF(OR(OP!$D$53=1,$B6=""),"",ROUND(VLOOKUP(OP!$C$55,CV,$B6+1,0)*OP!$C$28,0)) -> #N/A | J6: =IF(OR(OP!$D$53=1,$B6=""),"",ROUND(VLOOKUP(OP!$C$55,PA,$B6+1,0)*OP!$C$28,0)) -> #N/A | S6: =IF(OR(OP!$D$53=1,$B6=""),"",N($F6)+N($O6)) -> 0 | T6: =IF(OR(OP!$D$53=1,$B6=""),0,N($T5)+N($S6)) -> 0 | U6: =IF(OR(OP!$D$53=1,$B6=""),"",ROUND($S6/12,0)) -> 0 | V6: =IF(OR(OP!$D$53=1,$B6=""),0,N($V5)+(N($U6)*12)) -> 0 | Y6: =IF(OR(OP!$D$53=1,$B6=""),"",ROUND(($H6+$Q6)*IF(OR($C6<16,$Z6=0,$Z6=""),1,PYO),0)) -> #N/A | Z6: =IF(OR(OP!$D$53=1,$B6=""),"",ROUND(($H6+Q6)*IF(OR($C6<16,($H6+$Q6)*PY!$C$4<PY!$D$5,($H6+$Q6)*PY!$C$4*PYR<PY!$C$5),0,PYY)*PYR,0)) -> #N/A | AA6: =IF(OR(OP!$D$53=1,AND(B6>OP!$C$24)),"",OP!$C$52) -> 11326 | AB6: =IF(OR(OP!$D$53=1,$B6=""),"",N($AB5)+N($AA6)) -> 33978 | AH6: =IF(OR(OP!$D$53=1,$B6=""),"",ROUND(VLOOKUP(OP!$C$55,HL_1,$B6+1,0)*OP!$C$28,0)) -> #N/A | AI6: =IF(OR(OP!$D$53=1,$B6=""),"",ROUND(VLOOKUP(OP!$C$55,HL_2,$B6+1,0)*OP!$C$28,0)) -> #N/A
B7: =IF(OR(C6>=OP!$F$57,C6=""),"",IF(C6+1>OP!$F$57,OP!$F$57+1-$C$4,B6+1)) -> 4 | C7: =IF(OR(OP!$D$53=1,MAX($C$4:C6)>=OP!$F$57),"",C6+(B7-B6)) -> 18 | D7: =IF(OR(OP!$D$53=1,AND($B7>OP!$C$24)),"",OP!$C$52-IF($C7<16,$K6,0)) -> 11326 | E7: =IF(OR(OP!$D$53=1,$B7=""),"",N($E6)+N($D7)) -> 45304 | F7: =IF(OR(OP!$D$53=1,$B7="",ISERROR(VLOOKUP(OP!$C$55,SRV,$B7+1,0))),"",ROUND(VLOOKUP(OP!$C$55,SRV,$B7+1,0)*OP!$C$28,0)) | G7: =IF(OR(OP!$D$53=1,$B7="",ISERROR(VLOOKUP(OP!$C$55,SRV,$B7+1,0))),"",N($G6)+N($F7)) | H7: =IF(OR(OP!$D$53=1,$B7=""),"",ROUND(VLOOKUP(OP!$C$55,DIE,$B7+1,0)*OP!$C$28,0)) -> #N/A | I7: =IF(OR(OP!$D$53=1,$B7=""),"",ROUND(VLOOKUP(OP!$C$55,CV,$B7+1,0)*OP!$C$28,0)) -> #N/A | J7: =IF(OR(OP!$D$53=1,$B7=""),"",ROUND(VLOOKUP(OP!$C$55,PA,$B7+1,0)*OP!$C$28,0)) -> #N/A | S7: =IF(OR(OP!$D$53=1,$B7=""),"",N($F7)+N($O7)) -> 0 | T7: =IF(OR(OP!$D$53=1,$B7=""),0,N($T6)+N($S7)) -> 0 | U7: =IF(OR(OP!$D$53=1,$B7=""),"",ROUND($S7/12,0)) -> 0 | V7: =IF(OR(OP!$D$53=1,$B7=""),0,N($V6)+(N($U7)*12)) -> 0 | Y7: =IF(OR(OP!$D$53=1,$B7=""),"",ROUND(($H7+$Q7)*IF(OR($C7<16,$Z7=0,$Z7=""),1,PYO),0)) -> #N/A | Z7: =IF(OR(OP!$D$53=1,$B7=""),"",ROUND(($H7+Q7)*IF(OR($C7<16,($H7+$Q7)*PY!$C$4<PY!$D$5,($H7+$Q7)*PY!$C$4*PYR<PY!$C$5),0,PYY)*PYR,0)) -> #N/A | AA7: =IF(OR(OP!$D$53=1,AND(B7>OP!$C$24)),"",OP!$C$52) -> 11326 | AB7: =IF(OR(OP!$D$53=1,$B7=""),"",N($AB6)+N($AA7)) -> 45304 | AH7: =IF(OR(OP!$D$53=1,$B7=""),"",ROUND(VLOOKUP(OP!$C$55,HL_1,$B7+1,0)*OP!$C$28,0)) -> #N/A | AI7: =IF(OR(OP!$D$53=1,$B7=""),"",ROUND(VLOOKUP(OP!$C$55,HL_2,$B7+1,0)*OP!$C$28,0)) -> #N/A
