Workbook
Name BD: 輸入頁!$E$7
Name BGP: OP!$C$30
Name CV: P_DATA!$Q$427:$DX$844
Name DIE: P_DATA!$ED$2:$IK$420
Name EXP: P_DATA!$Q$2:$DX$420
Name GP: P_DATA!$J:$K
Name HL_1: P_DATA!$Q$850:$DX$1267
Name HL_2: P_DATA!$ED$850:$IK$1267
Name HL_3: P_DATA!$Q$1276:$DX$1693
Name IN: 輸入頁!$E$5
Name MGP: OP!$C$35
Name PA: P_DATA!$ED$426:$IK$844
Name PI: OP!$AK$4:$AL$90
Name PM: 輸入頁!$E$17
Name PYO: PY!$D$4
Name PYR: PY!$C$11
Name PYY: PY!$C$4
Name SEX: 輸入頁!$K$5
Name WORDING: OP!$P$2:$Q$20
Name WORDINGP: OP!$AD$2:$AE$41
Name YPN: 輸入頁!$D$35
Name 主約1: OP!$H$43:$H$45
Name 保額倍數: OP!$B$87:$C$197
Name 繳: OP!$H$17:$H$21
Name 繳別首: OP!$L$31:$L$35
Name 繳別續: OP!$M$31:$M$35
Name 關係: OP!$B$143:$B$147

Sheet 揭露
B1: =OP!$C$56 -> SDH10 | C1: ←帶OP | D1: =IF(OP!$E$16=1,"足歲",IF(OP!$E$16=2,"保險年齡","錯誤")) -> 保險年齡 | E1: ←帶OP | Q1: 6 | R1: 7 | S1: 8 | T1: 9 | U1: 10 | V1: 11 | W1: 12
L2: 以下3欄要注意最下方要和右側揭露拉齊 | O2: 以下COPY-DB | Q2: 109
C3: 代表年齡第?小→ | D3: 1 | E3: 2 | F3: 3 | G3: 1 | H3: 2 | I3: 3 | K3: 年齡代號轉換 | L3: KEY | M3: 年齡 | N3: 年度 | O3: 險種大類 | P3: 年期險種 | Q3: 性別 | R3: 年齡 | S3: 繳費方式 | T3: 宣告利率 | U3: 繳費金額 | V3: 保單年度 | W3: 揭露利率
C4: 性別男=1，女=2→ | D4: 1 | E4: 1 | F4: 1 | G4: 2 | H4: 2 | I4: 2 | K4: =IF($D$1="足歲","15足歲","") | L4: =IF(P4<>$B$1,"",P4&Q4&R4&V4) -> SDH10151 | M4: =IF(L4="","-",IF(ISERROR($R4*1),LEFT($R4,2)*1,$R4*1)) -> 5 | N4: =IF(L4="","",V4*1) -> 1 | P4: SDH10 | Q4: 1 | R4: 5 | S4: 0 | T4: 0 | U4: 0 | V4: 1 | W4: 42.57%
B5: 取第?欄→ | C5: 12 | D5: =IF(SMALL($M:$M,D$3)=15,$K$4,SMALL($M:$M,D$3)) -> 5 | E5: =IF(SMALL($M:$M,E$3)=15,$K$4,SMALL($M:$M,E$3)) -> 35 | F5: =IF(SMALL($M:$M,F$3)=15,$K$4,SMALL($M:$M,F$3)) -> 60 | G5: =IF(SMALL($M:$M,G$3)=15,$K$4,SMALL($M:$M,G$3)) -> 5 | H5: =IF(SMALL($M:$M,H$3)=15,$K$4,SMALL($M:$M,H$3)) -> 35 | I5: =IF(SMALL($M:$M,I$3)=15,$K$4,SMALL($M:$M,I$3)) -> 60 | L5: =IF(P5<>$B$1,"",P5&Q5&R5&V5) -> SDH10152 | M5: =IF(OR(L5="",COUNTIF($M$4:M4,IF(ISERROR($R5*1),LEFT($R5,2)*1,$R5*1))>=1),"-",IF(ISERROR($R5*1),LEFT($R5,2)*1,$R5*1)) -> - | N5: =IF(OR(L5="",COUNTIF($N$4:N4,V5*1)>=1),"-",V5*1) -> 2 | P5: SDH10 | Q5: 1 | R5: 5 | S5: 0 | T5: 0 | U5: 0 | V5: 2 | W5: 48.88%
B6: 第?小↓ | C6: 保單年度 | D6: =IF(OR(ISERROR($D5)),"",IF(N(D$5)=0,D$5&IF(D$4=1,"男性",IF(D$4=2,"女性","")),D$5&"歲"&IF(D$4=1,"男性",IF(D$4=2,"女性","")))) -> 5歲男性 | E6: =IF(OR(ISERROR($D5)),"",IF(N(E$5)=0,E$5&IF(E$4=1,"男性",IF(E$4=2,"女性","")),E$5&"歲"&IF(E$4=1,"男性",IF(E$4=2,"女性","")))) -> 35歲男性 | F6: =IF(OR(ISERROR($D5)),"",IF(N(F$5)=0,F$5&IF(F$4=1,"男性",IF(F$4=2,"女性","")),F$5&"歲"&IF(F$4=1,"男性",IF(F$4=2,"女性","")))) -> 60歲男性 | G6: =IF(OR(ISERROR($D5)),"",IF(N(G$5)=0,G$5&IF(G$4=1,"男性",IF(G$4=2,"女性","")),G$5&"歲"&IF(G$4=1,"男性",IF(G$4=2,"女性","")))) -> 5歲女性 | H6: =IF(OR(ISERROR($D5)),"",IF(N(H$5)=0,H$5&IF(H$4=1,"男性",IF(H$4=2,"女性","")),H$5&"歲"&IF(H$4=1,"男性",IF(H$4=2,"女性","")))) -> 35歲女性 | I6: =IF(OR(ISERROR($D5)),"",IF(N(I$5)=0,I$5&IF(I$4=1,"男性",IF(I$4=2,"女性","")),I$5&"歲"&IF(I$4=1,"男性",IF(I$4=2,"女性","")))) -> 60歲女性 | L6: =IF(P6<>$B$1,"",P6&Q6&R6&V6) -> SDH10153 | M6: =IF(OR(L6="",COUNTIF($M$4:M5,IF(ISERROR($R6*1),LEFT($R6,2)*1,$R6*1))>=1),"-",IF(ISERROR($R6*1),LEFT($R6,2)*1,$R6*1)) -> - | N6: =IF(OR(L6="",COUNTIF($N$4:N5,V6*1)>=1),"-",V6*1) -> 3 | P6: SDH10 | Q6: 1 | R6: 5 | S6: 0 | T6: 0 | U6: 0 | V6: 3 | W6: 51.07%
B7: 1 | C7: =IF(ISERROR(SMALL($N:$N,$B7)),"",SMALL($N:$N,$B7)) -> 1 | D7: =IF(ISERROR(VLOOKUP($B$1&D$4&D$5&$C7,$L:$W,$C$5,0)),"",VLOOKUP($B$1&D$4&D$5&$C7,$L:$W,$C$5,0)) -> 42.57% | E7: =IF(ISERROR(VLOOKUP($B$1&E$4&E$5&$C7,$L:$W,$C$5,0)),"",VLOOKUP($B$1&E$4&E$5&$C7,$L:$W,$C$5,0)) -> 17.48% | F7: =IF(ISERROR(VLOOKUP($B$1&F$4&F$5&$C7,$L:$W,$C$5,0)),"",VLOOKUP($B$1&F$4&F$5&$C7,$L:$W,$C$5,0)) -> 0.00% | G7: =IF(ISERROR(VLOOKUP($B$1&G$4&G$5&$C7,$L:$W,$C$5,0)),"",VLOOKUP($B$1&G$4&G$5&$C7,$L:$W,$C$5,0)) -> 43.92% | H7: =IF(ISERROR(VLOOKUP($B$1&H$4&H$5&$C7,$L:$W,$C$5,0)),"",VLOOKUP($B$1&H$4&H$5&$C7,$L:$W,$C$5,0)) -> 20.41% | I7: =IF(ISERROR(VLOOKUP($B$1&I$4&I$5&$C7,$L:$W,$C$5,0)),"",VLOOKUP($B$1&I$4&I$5&$C7,$L:$W,$C$5,0)) -> 0.00% | L7: =IF(P7<>$B$1,"",P7&Q7&R7&V7) -> SDH10154 | M7: =IF(OR(L7="",COUNTIF($M$4:M6,IF(ISERROR($R7*1),LEFT($R7,2)*1,$R7*1))>=1),"-",IF(ISERROR($R7*1),LEFT($R7,2)*1,$R7*1)) -> - | N7: =IF(OR(L7="",COUNTIF($N$4:N6,V7*1)>=1),"-",V7*1) -> 4 | P7: SDH10 | Q7: 1 | R7: 5 | S7: 0 | T7: 0 | U7: 0 | V7: 4 | W7: 52.25%
B8: 2 | C8: =IF(ISERROR(SMALL($N:$N,$B8)),"",SMALL($N:$N,$B8)) -> 2 | D8: =IF(ISERROR(VLOOKUP($B$1&D$4&D$5&$C8,$L:$W,$C$5,0)),"",VLOOKUP($B$1&D$4&D$5&$C8,$L:$W,$C$5,0)) -> 48.88% | E8: =IF(ISERROR(VLOOKUP($B$1&E$4&E$5&$C8,$L:$W,$C$5,0)),"",VLOOKUP($B$1&E$4&E$5&$C8,$L:$W,$C$5,0)) -> 28.53% | F8: =IF(ISERROR(VLOOKUP($B$1&F$4&F$5&$C8,$L:$W,$C$5,0)),"",VLOOKUP($B$1&F$4&F$5&$C8,$L:$W,$C$5,0)) -> 7.66% | G8: =IF(ISERROR(VLOOKUP($B$1&G$4&G$5&$C8,$L:$W,$C$5,0)),"",VLOOKUP($B$1&G$4&G$5&$C8,$L:$W,$C$5,0)) -> 49.49% | H8: =IF(ISERROR(VLOOKUP($B$1&H$4&H$5&$C8,$L:$W,$C$5,0)),"",VLOOKUP($B$1&H$4&H$5&$C8,$L:$W,$C$5,0)) -> 30.30% | I8: =IF(ISERROR(VLOOKUP($B$1&I$4&I$5&$C8,$L:$W,$C$5,0)),"",VLOOKUP($B$1&I$4&I$5&$C8,$L:$W,$C$5,0)) -> 9.61% | L8: =IF(P8<>$B$1,"",P8&Q8&R8&V8) -> SDH10155 | M8: =IF(OR(L8="",COUNTIF($M$4:M7,IF(ISERROR($R8*1),LEFT($R8,2)*1,$R8*1))>=1),"-",IF(ISERROR($R8*1),LEFT($R8,2)*1,$R8*1)) -> - | N8: =IF(OR(L8="",COUNTIF($N$4:N7,V8*1)>=1),"-",V8*1) -> 5 | P8: SDH10 | Q8: 1 | R8: 5 | S8: 0 | T8: 0 | U8: 0 | V8: 5 | W8: 52.95%
B9: 3 | C9: =IF(ISERROR(SMALL($N:$N,$B9)),"",SMALL($N:$N,$B9)) -> 3 | D9: =IF(ISERROR(VLOOKUP($B$1&D$4&D$5&$C9,$L:$W,$C$5,0)),"",VLOOKUP($B$1&D$4&D$5&$C9,$L:$W,$C$5,0)) -> 51.07% | E9: =IF(ISERROR(VLOOKUP($B$1&E$4&E$5&$C9,$L:$W,$C$5,0)),"",VLOOKUP($B$1&E$4&E$5&$C9,$L:$W,$C$5,0)) -> 32.30% | F9: =IF(ISERROR(VLOOKUP($B$1&F$4&F$5&$C9,$L:$W,$C$5,0)),"",VLOOKUP($B$1&F$4&F$5&$C9,$L:$W,$C$5,0)) -> 10.43% | G9: =IF(ISERROR(VLOOKUP($B$1&G$4&G$5&$C9,$L:$W,$C$5,0)),"",VLOOKUP($B$1&G$4&G$5&$C9,$L:$W,$C$5,0)) -> 51.40% | H9: =IF(ISERROR(VLOOKUP($B$1&H$4&H$5&$C9,$L:$W,$C$5,0)),"",VLOOKUP($B$1&H$4&H$5&$C9,$L:$W,$C$5,0)) -> 33.71% | I9: =IF(ISERROR(VLOOKUP($B$1&I$4&I$5&$C9,$L:$W,$C$5,0)),"",VLOOKUP($B$1&I$4&I$5&$C9,$L:$W,$C$5,0)) -> 12.98% | L9: =IF(P9<>$B$1,"",P9&Q9&R9&V9) -> SDH101510 | M9: =IF(OR(L9="",COUNTIF($M$4:M8,IF(ISERROR($R9*1),LEFT($R9,2)*1,$R9*1))>=1),"-",IF(ISERROR($R9*1),LEFT($R9,2)*1,$R9*1)) -> - | N9: =IF(OR(L9="",COUNTIF($N$4:N8,V9*1)>=1),"-",V9*1) -> 10 | P9: SDH10 | Q9: 1 | R9: 5 | S9: 0 | T9: 0 | U9: 0 | V9: 10 | W9: 73.10%
B10: 4 | C10: =IF(ISERROR(SMALL($N:$N,$B10)),"",SMALL($N:$N,$B10)) -> 4 | D10: =IF(ISERROR(VLOOKUP($B$1&D$4&D$5&$C10,$L:$W,$C$5,0)),"",VLOOKUP($B$1&D$4&D$5&$C10,$L:$W,$C$5,0)) -> 52.25% | E10: =IF(ISERROR(VLOOKUP($B$1&E$4&E$5&$C10,$L:$W,$C$5,0)),"",VLOOKUP($B$1&E$4&E$5&$C10,$L:$W,$C$5,0)) -> 34.33% | F10: =IF(ISERROR(VLOOKUP($B$1&F$4&F$5&$C10,$L:$W,$C$5,0)),"",VLOOKUP($B$1&F$4&F$5&$C10,$L:$W,$C$5,0)) -> 11.99% | G10: =IF(ISERROR(VLOOKUP($B$1&G$4&G$5&$C10,$L:$W,$C$5,0)),"",VLOOKUP($B$1&G$4&G$5&$C10,$L:$W,$C$5,0)) -> 52.44% | H10: =IF(ISERROR(VLOOKUP($B$1&H$4&H$5&$C10,$L:$W,$C$5,0)),"",VLOOKUP($B$1&H$4&H$5&$C10,$L:$W,$C$5,0)) -> 35.56% | I10: =IF(ISERROR(VLOOKUP($B$1&I$4&I$5&$C10,$L:$W,$C$5,0)),"",VLOOKUP($B$1&I$4&I$5&$C10,$L:$W,$C$5,0)) -> 14.83% | L10: =IF(P10<>$B$1,"",P10&Q10&R10&V10) -> SDH101515 | M10: =IF(OR(L10="",COUNTIF($M$4:M9,IF(ISERROR($R10*1),LEFT($R10,2)*1,$R10*1))>=1),"-",IF(ISERROR($R10*1),LEFT($R10,2)*1,$R10*1)) -> - | N10: =IF(OR(L10="",COUNTIF($N$4:N9,V10*1)>=1),"-",V10*1) -> 15 | P10: SDH10 | Q10: 1 | R10: 5 | S10: 0 | T10: 0 | U10: 0 | V10: 15 | W10: 75.08%
B11: 5 | C11: =IF(ISERROR(SMALL($N:$N,$B11)),"",SMALL($N:$N,$B11)) -> 5 | D11: =IF(ISERROR(VLOOKUP($B$1&D$4&D$5&$C11,$L:$W,$C$5,0)),"",VLOOKUP($B$1&D$4&D$5&$C11,$L:$W,$C$5,0)) -> 52.95% | E11: =IF(ISERROR(VLOOKUP($B$1&E$4&E$5&$C11,$L:$W,$C$5,0)),"",VLOOKUP($B$1&E$4&E$5&$C11,$L:$W,$C$5,0)) -> 35.59% | F11: =IF(ISERROR(VLOOKUP($B$1&F$4&F$5&$C11,$L:$W,$C$5,0)),"",VLOOKUP($B$1&F$4&F$5&$C11,$L:$W,$C$5,0)) -> 13.02% | G11: =IF(ISERROR(VLOOKUP($B$1&G$4&G$5&$C11,$L:$W,$C$5,0)),"",VLOOKUP($B$1&G$4&G$5&$C11,$L:$W,$C$5,0)) -> 53.08% | H11: =IF(ISERROR(VLOOKUP($B$1&H$4&H$5&$C11,$L:$W,$C$5,0)),"",VLOOKUP($B$1&H$4&H$5&$C11,$L:$W,$C$5,0)) -> 36.75% | I11: =IF(ISERROR(VLOOKUP($B$1&I$4&I$5&$C11,$L:$W,$C$5,0)),"",VLOOKUP($B$1&I$4&I$5&$C11,$L:$W,$C$5,0)) -> 16.08% | L11: =IF(P11<>$B$1,"",P11&Q11&R11&V11) -> SDH101520 | M11: =IF(OR(L11="",COUNTIF($M$4:M10,IF(ISERROR($R11*1),LEFT($R11,2)*1,$R11*1))>=1),"-",IF(ISERROR($R11*1),LEFT($R11,2)*1,$R11*1)) -> - | N11: =IF(OR(L11="",COUNTIF($N$4:N10,V11*1)>=1),"-",V11*1) -> 20 | P11: SDH10 | Q11: 1 | R11: 5 | S11: 0 | T11: 0 | U11: 0 | V11: 20 | W11: 77.44%
B12: 6 | C12: =IF(ISERROR(SMALL($N:$N,$B12)),"",SMALL($N:$N,$B12)) -> 10 | D12: =IF(ISERROR(VLOOKUP($B$1&D$4&D$5&$C12,$L:$W,$C$5,0)),"",VLOOKUP($B$1&D$4&D$5&$C12,$L:$W,$C$5,0)) -> 73.10% | E12: =IF(ISERROR(VLOOKUP($B$1&E$4&E$5&$C12,$L:$W,$C$5,0)),"",VLOOKUP($B$1&E$4&E$5&$C12,$L:$W,$C$5,0)) -> 52.20% | F12: =IF(ISERROR(VLOOKUP($B$1&F$4&F$5&$C12,$L:$W,$C$5,0)),"",VLOOKUP($B$1&F$4&F$5&$C12,$L:$W,$C$5,0)) -> 21.68% | G12: =IF(ISERROR(VLOOKUP($B$1&G$4&G$5&$C12,$L:$W,$C$5,0)),"",VLOOKUP($B$1&G$4&G$5&$C12,$L:$W,$C$5,0)) -> 73.09% | H12: =IF(ISERROR(VLOOKUP($B$1&H$4&H$5&$C12,$L:$W,$C$5,0)),"",VLOOKUP($B$1&H$4&H$5&$C12,$L:$W,$C$5,0)) -> 53.79% | I12: =IF(ISERROR(VLOOKUP($B$1&I$4&I$5&$C12,$L:$W,$C$5,0)),"",VLOOKUP($B$1&I$4&I$5&$C12,$L:$W,$C$5,0)) -> 26.51% | L12: =IF(P12<>$B$1,"",P12&Q12&R12&V12) -> SDH101351 | M12: =IF(OR(L12="",COUNTIF($M$4:M11,IF(ISERROR($R12*1),LEFT($R12,2)*1,$R12*1))>=1),"-",IF(ISERROR($R12*1),LEFT($R12,2)*1,$R12*1)) -> 35 | N12: =IF(OR(L12="",COUNTIF($N$4:N11,V12*1)>=1),"-",V12*1) -> - | P12: SDH10 | Q12: 1 | R12: 35 | S12: 0 | T12: 0 | U12: 0 | V12: 1 | W12: 17.48%
B13: 7 | C13: =IF(ISERROR(SMALL($N:$N,$B13)),"",SMALL($N:$N,$B13)) -> 15 | D13: =IF(ISERROR(VLOOKUP($B$1&D$4&D$5&$C13,$L:$W,$C$5,0)),"",VLOOKUP($B$1&D$4&D$5&$C13,$L:$W,$C$5,0)) -> 75.08% | E13: =IF(ISERROR(VLOOKUP($B$1&E$4&E$5&$C13,$L:$W,$C$5,0)),"",VLOOKUP($B$1&E$4&E$5&$C13,$L:$W,$C$5,0)) -> 56.52% | F13: =IF(ISERROR(VLOOKUP($B$1&F$4&F$5&$C13,$L:$W,$C$5,0)),"",VLOOKUP($B$1&F$4&F$5&$C13,$L:$W,$C$5,0)) -> 27.28% | G13: =IF(ISERROR(VLOOKUP($B$1&G$4&G$5&$C13,$L:$W,$C$5,0)),"",VLOOKUP($B$1&G$4&G$5&$C13,$L:$W,$C$5,0)) -> 74.99% | H13: =IF(ISERROR(VLOOKUP($B$1&H$4&H$5&$C13,$L:$W,$C$5,0)),"",VLOOKUP($B$1&H$4&H$5&$C13,$L:$W,$C$5,0)) -> 58.90% | I13: =IF(ISERROR(VLOOKUP($B$1&I$4&I$5&$C13,$L:$W,$C$5,0)),"",VLOOKUP($B$1&I$4&I$5&$C13,$L:$W,$C$5,0)) -> 32.61% | L13: =IF(P13<>$B$1,"",P13&Q13&R13&V13) -> SDH101352 | M13: =IF(OR(L13="",COUNTIF($M$4:M12,IF(ISERROR($R13*1),LEFT($R13,2)*1,$R13*1))>=1),"-",IF(ISERROR($R13*1),LEFT($R13,2)*1,$R13*1)) -> - | N13: =IF(OR(L13="",COUNTIF($N$4:N12,V13*1)>=1),"-",V13*1) -> - | P13: SDH10 | Q13: 1 | R13: 35 | S13: 0 | T13: 0 | U13: 0 | V13: 2 | W13: 28.53%
B14: 8 | C14: =IF(ISERROR(SMALL($N:$N,$B14)),"",SMALL($N:$N,$B14)) -> 20 | D14: =IF(ISERROR(VLOOKUP($B$1&D$4&D$5&$C14,$L:$W,$C$5,0)),"",VLOOKUP($B$1&D$4&D$5&$C14,$L:$W,$C$5,0)) -> 77.44% | E14: =IF(ISERROR(VLOOKUP($B$1&E$4&E$5&$C14,$L:$W,$C$5,0)),"",VLOOKUP($B$1&E$4&E$5&$C14,$L:$W,$C$5,0)) -> 64.00% | F14: =IF(ISERROR(VLOOKUP($B$1&F$4&F$5&$C14,$L:$W,$C$5,0)),"",VLOOKUP($B$1&F$4&F$5&$C14,$L:$W,$C$5,0)) -> 40.38% | G14: =IF(ISERROR(VLOOKUP($B$1&G$4&G$5&$C14,$L:$W,$C$5,0)),"",VLOOKUP($B$1&G$4&G$5&$C14,$L:$W,$C$5,0)) -> 77.22% | H14: =IF(ISERROR(VLOOKUP($B$1&H$4&H$5&$C14,$L:$W,$C$5,0)),"",VLOOKUP($B$1&H$4&H$5&$C14,$L:$W,$C$5,0)) -> 66.24% | I14: =IF(ISERROR(VLOOKUP($B$1&I$4&I$5&$C14,$L:$W,$C$5,0)),"",VLOOKUP($B$1&I$4&I$5&$C14,$L:$W,$C$5,0)) -> 45.13% | L14: =IF(P14<>$B$1,"",P14&Q14&R14&V14) -> SDH101353 | M14: =IF(OR(L14="",COUNTIF($M$4:M13,IF(ISERROR($R14*1),LEFT($R14,2)*1,$R14*1))>=1),"-",IF(ISERROR($R14*1),LEFT($R14,2)*1,$R14*1)) -> - | N14: =IF(OR(L14="",COUNTIF($N$4:N13,V14*1)>=1),"-",V14*1) -> - | P14: SDH10 | Q14: 1 | R14: 35 | S14: 0 | T14: 0 | U14: 0 | V14: 3 | W14: 32.30%
C15: 以上區域為帶入列印頁範圍 | L15: =IF(P15<>$B$1,"",P15&Q15&R15&V15) -> SDH101354 | M15: =IF(OR(L15="",COUNTIF($M$4:M14,IF(ISERROR($R15*1),LEFT($R15,2)*1,$R15*1))>=1),"-",IF(ISERROR($R15*1),LEFT($R15,2)*1,$R15*1)) -> - | N15: =IF(OR(L15="",COUNTIF($N$4:N14,V15*1)>=1),"-",V15*1) -> - | P15: SDH10 | Q15: 1 | R15: 35 | S15: 0 | T15: 0 | U15: 0 | V15: 4 | W15: 34.33%
L16: =IF(P16<>$B$1,"",P16&Q16&R16&V16) -> SDH101355 | M16: =IF(OR(L16="",COUNTIF($M$4:M15,IF(ISERROR($R16*1),LEFT($R16,2)*1,$R16*1))>=1),"-",IF(ISERROR($R16*1),LEFT($R16,2)*1,$R16*1)) -> - | N16: =IF(OR(L16="",COUNTIF($N$4:N15,V16*1)>=1),"-",V16*1) -> - | P16: SDH10 | Q16: 1 | R16: 35 | S16: 0 | T16: 0 | U16: 0 | V16: 5 | W16: 35.59%
L17: =IF(P17<>$B$1,"",P17&Q17&R17&V17) -> SDH1013510 | M17: =IF(OR(L17="",COUNTIF($M$4:M16,IF(ISERROR($R17*1),LEFT($R17,2)*1,$R17*1))>=1),"-",IF(ISERROR($R17*1),LEFT($R17,2)*1,$R17*1)) -> - | N17: =IF(OR(L17="",COUNTIF($N$4:N16,V17*1)>=1),"-",V17*1) -> - | P17: SDH10 | Q17: 1 | R17: 35 | S17: 0 | T17: 0 | U17: 0 | V17: 10 | W17: 52.20%
L18: =IF(P18<>$B$1,"",P18&Q18&R18&V18) -> SDH1013515 | M18: =IF(OR(L18="",COUNTIF($M$4:M17,IF(ISERROR($R18*1),LEFT($R18,2)*1,$R18*1))>=1),"-",IF(ISERROR($R18*1),LEFT($R18,2)*1,$R18*1)) -> - | N18: =IF(OR(L18="",COUNTIF($N$4:N17,V18*1)>=1),"-",V18*1) -> - | P18: SDH10 | Q18: 1 | R18: 35 | S18: 0 | T18: 0 | U18: 0 | V18: 15 | W18: 56.52%
L19: =IF(P19<>$B$1,"",P19&Q19&R19&V19) -> SDH1013520 | M19: =IF(OR(L19="",COUNTIF($M$4:M18,IF(ISERROR($R19*1),LEFT($R19,2)*1,$R19*1))>=1),"-",IF(ISERROR($R19*1),LEFT($R19,2)*1,$R19*1)) -> - | N19: =IF(OR(L19="",COUNTIF($N$4:N18,V19*1)>=1),"-",V19*1) -> - | P19: SDH10 | Q19: 1 | R19: 35 | S19: 0 | T19: 0 | U19: 0 | V19: 20 | W19: 64.00%
L20: =IF(P20<>$B$1,"",P20&Q20&R20&V20) -> SDH101601 | M20: =IF(OR(L20="",COUNTIF($M$4:M19,IF(ISERROR($R20*1),LEFT($R20,2)*1,$R20*1))>=1),"-",IF(ISERROR($R20*1),LEFT($R20,2)*1,$R20*1)) -> 60 | N20: =IF(OR(L20="",COUNTIF($N$4:N19,V20*1)>=1),"-",V20*1) -> - | P20: SDH10 | Q20: 1 | R20: 60 | S20: 0 | T20: 0 | U20: 0 | V20: 1 | W20: 0.00%
L21: =IF(P21<>$B$1,"",P21&Q21&R21&V21) -> SDH101602 | M21: =IF(OR(L21="",COUNTIF($M$4:M20,IF(ISERROR($R21*1),LEFT($R21,2)*1,$R21*1))>=1),"-",IF(ISERROR($R21*1),LEFT($R21,2)*1,$R21*1)) -> - | N21: =IF(OR(L21="",COUNTIF($N$4:N20,V21*1)>=1),"-",V21*1) -> - | P21: SDH10 | Q21: 1 | R21: 60 | S21: 0 | T21: 0 | U21: 0 | V21: 2 | W21: 7.66%
L22: =IF(P22<>$B$1,"",P22&Q22&R22&V22) -> SDH101603 | M22: =IF(OR(L22="",COUNTIF($M$4:M21,IF(ISERROR($R22*1),LEFT($R22,2)*1,$R22*1))>=1),"-",IF(ISERROR($R22*1),LEFT($R22,2)*1,$R22*1)) -> - | N22: =IF(OR(L22="",COUNTIF($N$4:N21,V22*1)>=1),"-",V22*1) -> - | P22: SDH10 | Q22: 1 | R22: 60 | S22: 0 | T22: 0 | U22: 0 | V22: 3 | W22: 10.43%
L23: =IF(P23<>$B$1,"",P23&Q23&R23&V23) -> SDH101604 | M23: =IF(OR(L23="",COUNTIF($M$4:M22,IF(ISERROR($R23*1),LEFT($R23,2)*1,$R23*1))>=1),"-",IF(ISERROR($R23*1),LEFT($R23,2)*1,$R23*1)) -> - | N23: =IF(OR(L23="",COUNTIF($N$4:N22,V23*1)>=1),"-",V23*1) -> - | P23: SDH10 | Q23: 1 | R23: 60 | S23: 0 | T23: 0 | U23: 0 | V23: 4 | W23: 11.99%
L24: =IF(P24<>$B$1,"",P24&Q24&R24&V24) -> SDH101605 | M24: =IF(OR(L24="",COUNTIF($M$4:M23,IF(ISERROR($R24*1),LEFT($R24,2)*1,$R24*1))>=1),"-",IF(ISERROR($R24*1),LEFT($R24,2)*1,$R24*1)) -> - | N24: =IF(OR(L24="",COUNTIF($N$4:N23,V24*1)>=1),"-",V24*1) -> - | P24: SDH10 | Q24: 1 | R24: 60 | S24: 0 | T24: 0 | U24: 0 | V24: 5 | W24: 13.02%
L25: =IF(P25<>$B$1,"",P25&Q25&R25&V25) -> SDH1016010 | M25: =IF(OR(L25="",COUNTIF($M$4:M24,IF(ISERROR($R25*1),LEFT($R25,2)*1,$R25*1))>=1),"-",IF(ISERROR($R25*1),LEFT($R25,2)*1,$R25*1)) -> - | N25: =IF(OR(L25="",COUNTIF($N$4:N24,V25*1)>=1),"-",V25*1) -> - | P25: SDH10 | Q25: 1 | R25: 60 | S25: 0 | T25: 0 | U25: 0 | V25: 10 | W25: 21.68%
L26: =IF(P26<>$B$1,"",P26&Q26&R26&V26) -> SDH1016015 | M26: =IF(OR(L26="",COUNTIF($M$4:M25,IF(ISERROR($R26*1),LEFT($R26,2)*1,$R26*1))>=1),"-",IF(ISERROR($R26*1),LEFT($R26,2)*1,$R26*1)) -> - | N26: =IF(OR(L26="",COUNTIF($N$4:N25,V26*1)>=1),"-",V26*1) -> - | P26: SDH10 | Q26: 1 | R26: 60 | S26: 0 | T26: 0 | U26: 0 | V26: 15 | W26: 27.28%
L27: =IF(P27<>$B$1,"",P27&Q27&R27&V27) -> SDH1016020 | M27: =IF(OR(L27="",COUNTIF($M$4:M26,IF(ISERROR($R27*1),LEFT($R27,2)*1,$R27*1))>=1),"-",IF(ISERROR($R27*1),LEFT($R27,2)*1,$R27*1)) -> - | N27: =IF(OR(L27="",COUNTIF($N$4:N26,V27*1)>=1),"-",V27*1) -> - | P27: SDH10 | Q27: 1 | R27: 60 | S27: 0 | T27: 0 | U27: 0 | V27: 20 | W27: 40.38%
... L195: =IF(P195<>$B$1,"",P195&Q195&R195&V195) | M195: =IF(OR(L195="",COUNTIF($M$4:M194,IF(ISERROR($R195*1),LEFT($R195,2)*1,$R195*1))>=1),"-",IF(ISERROR($R195*1),LEFT($R195,2)*1,$R195*1)) -> - | N195: =IF(OR(L195="",COUNTIF($N$4:N194,V195*1)>=1),"-",V195*1) -> - | P195: SDH30 | Q195: 2 | R195: 40 | S195: 0 | T195: 0 | U195: 0 | V195: 20 | W195: 15.55%
L196: =IF(P196<>$B$1,"",P196&Q196&R196&V196) | M196: =IF(OR(L196="",COUNTIF($M$4:M195,IF(ISERROR($R196*1),LEFT($R196,2)*1,$R196*1))>=1),"-",IF(ISERROR($R196*1),LEFT($R196,2)*1,$R196*1)) -> - | N196: =IF(OR(L196="",COUNTIF($N$4:N195,V196*1)>=1),"-",V196*1) -> -
L197: =IF(P197<>$B$1,"",P197&Q197&R197&V197) | M197: =IF(OR(L197="",COUNTIF($M$4:M196,IF(ISERROR($R197*1),LEFT($R197,2)*1,$R197*1))>=1),"-",IF(ISERROR($R197*1),LEFT($R197,2)*1,$R197*1)) -> - | N197: =IF(OR(L197="",COUNTIF($N$4:N196,V197*1)>=1),"-",V197*1) -> -
L198: =IF(P198<>$B$1,"",P198&Q198&R198&V198) | M198: =IF(OR(L198="",COUNTIF($M$4:M197,IF(ISERROR($R198*1),LEFT($R198,2)*1,$R198*1))>=1),"-",IF(ISERROR($R198*1),LEFT($R198,2)*1,$R198*1)) -> - | N198: =IF(OR(L198="",COUNTIF($N$4:N197,V198*1)>=1),"-",V198*1) -> -
L199: =IF(P199<>$B$1,"",P199&Q199&R199&V199) | M199: =IF(OR(L199="",COUNTIF($M$4:M198,IF(ISERROR($R199*1),LEFT($R199,2)*1,$R199*1))>=1),"-",IF(ISERROR($R199*1),LEFT($R199,2)*1,$R199*1)) -> - | N199: =IF(OR(L199="",COUNTIF($N$4:N198,V199*1)>=1),"-",V199*1) -> -
L200: =IF(P200<>$B$1,"",P200&Q200&R200&V200) | M200: =IF(OR(L200="",COUNTIF($M$4:M199,IF(ISERROR($R200*1),LEFT($R200,2)*1,$R200*1))>=1),"-",IF(ISERROR($R200*1),LEFT($R200,2)*1,$R200*1)) -> - | N200: =IF(OR(L200="",COUNTIF($N$4:N199,V200*1)>=1),"-",V200*1) -> -
L201: =IF(P201<>$B$1,"",P201&Q201&R201&V201) | M201: =IF(OR(L201="",COUNTIF($M$4:M200,IF(ISERROR($R201*1),LEFT($R201,2)*1,$R201*1))>=1),"-",IF(ISERROR($R201*1),LEFT($R201,2)*1,$R201*1)) -> - | N201: =IF(OR(L201="",COUNTIF($N$4:N200,V201*1)>=1),"-",V201*1) -> -
L202: =IF(P202<>$B$1,"",P202&Q202&R202&V202) | M202: =IF(OR(L202="",COUNTIF($M$4:M201,IF(ISERROR($R202*1),LEFT($R202,2)*1,$R202*1))>=1),"-",IF(ISERROR($R202*1),LEFT($R202,2)*1,$R202*1)) -> - | N202: =IF(OR(L202="",COUNTIF($N$4:N201,V202*1)>=1),"-",V202*1) -> -
L203: =IF(P203<>$B$1,"",P203&Q203&R203&V203) | M203: =IF(OR(L203="",COUNTIF($M$4:M202,IF(ISERROR($R203*1),LEFT($R203,2)*1,$R203*1))>=1),"-",IF(ISERROR($R203*1),LEFT($R203,2)*1,$R203*1)) -> - | N203: =IF(OR(L203="",COUNTIF($N$4:N202,V203*1)>=1),"-",V203*1) -> -
L204: =IF(P204<>$B$1,"",P204&Q204&R204&V204) | M204: =IF(OR(L204="",COUNTIF($M$4:M203,IF(ISERROR($R204*1),LEFT($R204,2)*1,$R204*1))>=1),"-",IF(ISERROR($R204*1),LEFT($R204,2)*1,$R204*1)) -> - | N204: =IF(OR(L204="",COUNTIF($N$4:N203,V204*1)>=1),"-",V204*1) -> -
L205: =IF(P205<>$B$1,"",P205&Q205&R205&V205) | M205: =IF(OR(L205="",COUNTIF($M$4:M204,IF(ISERROR($R205*1),LEFT($R205,2)*1,$R205*1))>=1),"-",IF(ISERROR($R205*1),LEFT($R205,2)*1,$R205*1)) -> - | N205: =IF(OR(L205="",COUNTIF($N$4:N204,V205*1)>=1),"-",V205*1) -> -
L206: =IF(P206<>$B$1,"",P206&Q206&R206&V206) | M206: =IF(OR(L206="",COUNTIF($M$4:M205,IF(ISERROR($R206*1),LEFT($R206,2)*1,$R206*1))>=1),"-",IF(ISERROR($R206*1),LEFT($R206,2)*1,$R206*1)) -> - | N206: =IF(OR(L206="",COUNTIF($N$4:N205,V206*1)>=1),"-",V206*1) -> -
L207: =IF(P207<>$B$1,"",P207&Q207&R207&V207) | M207: =IF(OR(L207="",COUNTIF($M$4:M206,IF(ISERROR($R207*1),LEFT($R207,2)*1,$R207*1))>=1),"-",IF(ISERROR($R207*1),LEFT($R207,2)*1,$R207*1)) -> - | N207: =IF(OR(L207="",COUNTIF($N$4:N206,V207*1)>=1),"-",V207*1) -> -
...

Sheet P_DATA
A1: GP | B1: SDH | J1: =B1&TEXT(F1,"00")&TEXT(H1,"00") -> SDH0000 | M1: EXP | Q1: =N1&TEXT(O1,"00")&TEXT(P1,"00") -> 0000 | DZ1: DIE | ED1: =EA1&TEXT(EB1,"00")&TEXT(EC1,"00") -> 0000
A2: 版次 | B2: 商品代號 | C2: 職業等級 | D2: 年期 | E2: 保額代碼 | F2: 性別 | G2: 投保金額 | H2: 年齡 | I2: 繳費年度 | J2: =B2&TEXT(F2,"00")&TEXT(H2,"00") -> 商品代號性別年齡 | K2: 保費 | M2: 版次 | N2: 商品代號 | O2: 性別 | P2: 年齡 | Q2: =N2&TEXT(O2,"00")&TEXT(P2,"00") -> 商品代號性別年齡 | R2: 第1年滿期保險金 | S2: 第2年滿期保險金 | T2: 第3年滿期保險金 | U2: 第4年滿期保險金 | V2: 第5年滿期保險金 | W2: 第6年滿期保險金 | X2: 第7年滿期保險金 | Y2: 第8年滿期保險金 | Z2: 第9年滿期保險金 | AA2: 第10年滿期保險金 | AB2: 第11年滿期保險金 | AC2: 第12年滿期保險金 | AD2: 第13年滿期保險金 | AE2: 第14年滿期保險金 | AF2: 第15年滿期保險金 | AG2: 第16年滿期保險金 | AH2: 第17年滿期保險金 | AI2: 第18年滿期保險金 | AJ2: 第19年滿期保險金 | AK2: 第20年滿期保險金 | AL2: 第21年滿期保險金 | AM2: 第22年滿期保險金 | AN2: 第23年滿期保險金 | AO2: 第24年滿期保險金 | AP2: 第25年滿期保險金 | AQ2: 第26年滿期保險金 | AR2: 第27年滿期保險金 | AS2: 第28年滿期保險金 | AT2: 第29年滿期保險金 | AU2: 第30年滿期保險金 | AV2: 第31年滿期保險金 | AW2: 第32年滿期保險金 | AX2: 第33年滿期保險金 | AY2: 第34年滿期保險金 | AZ2: 第35年滿期保險金 | BA2: 第36年滿期保險金 | BB2: 第37年滿期保險金 | BC2: 第38年滿期保險金 | BD2: 第39年滿期保險金 | BE2: 第40年滿期保險金 | BF2: 第41年滿期保險金 | BG2: 第42年滿期保險金 | BH2: 第43年滿期保險金 | BI2: 第44年滿期保險金 | BJ2: 第45年滿期保險金 | BK2: 第46年滿期保險金 | BL2: 第47年滿期保險金 | BM2: 第48年滿期保險金 | BN2: 第49年滿期保險金 | BO2: 第50年滿期保險金 | BP2: 第51年滿期保險金 | BQ2: 第52年滿期保險金 | BR2: 第53年滿期保險金 | BS2: 第54年滿期保險金 | BT2: 第55年滿期保險金 | BU2: 第56年滿期保險金 | BV2: 第57年滿期保險金 | BW2: 第58年滿期保險金 | BX2: 第59年滿期保險金 | BY2: 第60年滿期保險金 | BZ2: 第61年滿期保險金 | CA2: 第62年滿期保險金 | CB2: 第63年滿期保險金 | CC2: 第64年滿期保險金 | CD2: 第65年滿期保險金 | CE2: 第66年滿期保險金 | CF2: 第67年滿期保險金 | CG2: 第68年滿期保險金 | CH2: 第69年滿期保險金 | CI2: 第70年滿期保險金 | CJ2: 第71年滿期保險金 | CK2: 第72年滿期保險金 | CL2: 第73年滿期保險金 | CM2: 第74年滿期保險金 | CN2: 第75年滿期保險金 | CO2: 第76年滿期保險金 | CP2: 第77年滿期保險金 | CQ2: 第78年滿期保險金 | CR2: 第79年滿期保險金 | CS2: 第80年滿期保險金 | CT2: 第81年滿期保險金 | CU2: 第82年滿期保險金 | CV2: 第83年滿期保險金 | CW2: 第84年滿期保險金 | CX2: 第85年滿期保險金 | CY2: 第86年滿期保險金 | CZ2: 第87年滿期保險金 | DA2: 第88年滿期保險金 | DB2: 第89年滿期保險金 | DC2: 第90年滿期保險金 | DD2: 第91年滿期保險金 | DE2: 第92年滿期保險金 | DF2: 第93年滿期保險金 | DG2: 第94年滿期保險金 | DH2: 第95年滿期保險金 | DI2: 第96年滿期保險金 | DJ2: 第97年滿期保險金 | DK2: 第98年滿期保險金 | DL2: 第99年滿期保險金 | DM2: 第100年滿期保險金 | DN2: 第101年滿期保險金 | DO2: 第102年滿期保險金 | DP2: 第103年滿期保險金 | DQ2: 第104年滿期保險金 | DR2: 第105年滿期保險金 | DS2: 第106年滿期保險金 | DT2: 第107年滿期保險金 | DU2: 第108年滿期保險金 | DV2: 第109年滿期保險金 | DW2: 第110年滿期保險金 | DX2: 第111年滿期保險金 | DZ2: 版次 | EA2: 商品代號 | EB2: 性別 | EC2: 年齡 | ED2: =EA2&TEXT(EB2,"00")&TEXT(EC2,"00") -> 商品代號性別年齡 | EE2: 第1年身故保險金 | EF2: 第2年身故保險金 | EG2: 第3年身故保險金 | EH2: 第4年身故保險金 | EI2: 第5年身故保險金 | EJ2: 第6年身故保險金 | EK2: 第7年身故保險金 | EL2: 第8年身故保險金 | EM2: 第9年身故保險金 | EN2: 第10年身故保險金 | EO2: 第11年身故保險金 | EP2: 第12年身故保險金 | EQ2: 第13年身故保險金 | ER2: 第14年身故保險金 | ES2: 第15年身故保險金 | ET2: 第16年身故保險金 | EU2: 第17年身故保險金 | EV2: 第18年身故保險金 | EW2: 第19年身故保險金 | EX2: 第20年身故保險金 | EY2: 第21年身故保險金 | EZ2: 第22年身故保險金 | FA2: 第23年身故保險金 | FB2: 第24年身故保險金 | FC2: 第25年身故保險金 | FD2: 第26年身故保險金 | FE2: 第27年身故保險金 | FF2: 第28年身故保險金 | FG2: 第29年身故保險金 | FH2: 第30年身故保險金 | FI2: 第31年身故保險金 | FJ2: 第32年身故保險金 | FK2: 第33年身故保險金 | FL2: 第34年身故保險金 | FM2: 第35年身故保險金 | FN2: 第36年身故保險金 | FO2: 第37年身故保險金 | FP2: 第38年身故保險金 | FQ2: 第39年身故保險金 | FR2: 第40年身故保險金 | FS2: 第41年身故保險金 | FT2: 第42年身故保險金 | FU2: 第43年身故保險金 | FV2: 第44年身故保險金 | FW2: 第45年身故保險金 | FX2: 第46年身故保險金 | FY2: 第47年身故保險金 | FZ2: 第48年身故保險金 | GA2: 第49年身故保險金 | GB2: 第50年身故保險金 | GC2: 第51年身故保險金 | GD2: 第52年身故保險金 | GE2: 第53年身故保險金 | GF2: 第54年身故保險金 | GG2: 第55年身故保險金 | GH2: 第56年身故保險金 | GI2: 第57年身故保險金 | GJ2: 第58年身故保險金 | GK2: 第59年身故保險金 | GL2: 第60年身故保險金 | GM2: 第61年身故保險金 | GN2: 第62年身故保險金 | GO2: 第63年身故保險金 | GP2: 第64年身故保險金 | GQ2: 第65年身故保險金 | GR2: 第66年身故保險金 | GS2: 第67年身故保險金 | GT2: 第68年身故保險金 | GU2: 第69年身故保險金 | GV2: 第70年身故保險金 | GW2: 第71年身故保險金 | GX2: 第72年身故保險金 | GY2: 第73年身故保險金 | GZ2: 第74年身故保險金額 | HA2: 第75年身故保險金 | HB2: 第76年身故保險金 | HC2: 第77年身故保險金 | HD2: 第78年身故保險金 | HE2: 第79年身故保險金 | HF2: 第80年身故保險金 | HG2: 第81年身故保險金 | HH2: 第82年身故保險金 | HI2: 第83年身故保險金 | HJ2: 第84年身故保險金 | HK2: 第85年身故保險金 | HL2: 第86年身故保險金 | HM2: 第87年身故保險金 | HN2: 第88年身故保險金 | HO2: 第89年身故保險金 | HP2: 第90年身故保險金 | HQ2: 第91年身故保險金 | HR2: 第92年身故保險金 | HS2: 第93年身故保險金 | HT2: 第94年身故保險金 | HU2: 第95年身故保險金 | HV2: 第96年身故保險金 | HW2: 第97年身故保險金 | HX2: 第98年身故保險金 | HY2: 第99年身故保險金 | HZ2: 第100年身故保險金 | IA2: 第101年身故保險金 | IB2: 第102年身故保險金 | IC2: 第103年身故保險金 | ID2: 第104年身故保險金 | IE2: 第105年身故保險金 | IF2: 第106年身故保險金 | IG2: 第107年身故保險金 | IH2: 第108年身故保險金 | II2: 第109年身故保險金 | IJ2: 第110年身故保險金 | IK2: 第111年身故保險金
A3: 56 | B3: SDH10 | F3: 1 | H3: 0 | J3: =B3&TEXT(F3,"00")&TEXT(H3,"00") -> SDH100100 | K3: 875 | M3: 56 | N3: SDH10 | O3: 1 | P3: 0 | Q3: =N3&TEXT(O3,"00")&TEXT(P3,"00") -> SDH100100 | R3: 0 | S3: 0 | T3: 0 | U3: 0 | V3: 0 | W3: 0 | X3: 0 | Y3: 0 | Z3: 0 | AA3: 0 | AB3: 0 | AC3: 0 | AD3: 0 | AE3: 0 | AF3: 0 | AG3: 0 | AH3: 0 | AI3: 0 | AJ3: 0 | AK3: 0 | AL3: 0 | AM3: 0 | AN3: 0 | AO3: 0 | AP3: 10000 | AQ3: 0 | AR3: 0 | AS3: 0 | AT3: 0 | AU3: 0 | AV3: 0 | AW3: 0 | AX3: 0 | AY3: 0 | AZ3: 0 | BA3: 0 | BB3: 0 | BC3: 0 | BD3: 0 | BE3: 0 | BF3: 0 | BG3: 0 | BH3: 0 | BI3: 0 | BJ3: 0 | BK3: 0 | BL3: 0 | BM3: 0 | BN3: 0 | BO3: 0 | BP3: 0 | BQ3: 0 | BR3: 0 | BS3: 0 | BT3: 0 | BU3: 0 | BV3: 0 | BW3: 0 | BX3: 0 | BY3: 0 | BZ3: 0 | CA3: 0 | CB3: 0 | CC3: 0 | CD3: 0 | CE3: 0 | CF3: 0 | CG3: 0 | CH3: 0 | CI3: 0 | CJ3: 0 | CK3: 0 | CL3: 0 | CM3: 0 | CN3: 0 | CO3: 0 | CP3: 0 | CQ3: 0 | CR3: 0 | CS3: 0 | CT3: 0 | CU3: 0 | CV3: 0 | CW3: 0 | CX3: 0 | CY3: 0 | CZ3: 0 | DA3: 0 | DB3: 0 | DC3: 0 | DD3: 0 | DE3: 0 | DF3: 0 | DG3: 0 | DH3: 0 | DI3: 0 | DJ3: 0 | DK3: 0 | DL3: 0 | DM3: 0 | DN3: 0 | DO3: 0 | DP3: 0 | DQ3: 0 | DR3: 0 | DS3: 0 | DT3: 0 | DU3: 0 | DV3: 0 | DW3: 0 | DX3: 0 | DZ3: 56 | EA3: SDH10 | EB3: 1 | EC3: 0 | ED3: =EA3&TEXT(EB3,"00")&TEXT(EC3,"00") -> SDH100100 | EE3: 10000 | EF3: 10000 | EG3: 10000 | EH3: 10000 | EI3: 10000 | EJ3: 10000 | EK3: 10000 | EL3: 10000 | EM3: 10000 | EN3: 10000 | EO3: 10000 | EP3: 10000 | EQ3: 10000 | ER3: 10000 | ES3: 10000 | ET3: 10000 | EU3: 10000 | EV3: 10000 | EW3: 10000 | EX3: 10000 | EY3: 10000 | EZ3: 10000 | FA3: 10000 | FB3: 10000 | FC3: 10000 | FD3: 0 | FE3: 0 | FF3: 0 | FG3: 0 | FH3: 0 | FI3: 0 | FJ3: 0 | FK3: 0 | FL3: 0 | FM3: 0 | FN3: 0 | FO3: 0 | FP3: 0 | FQ3: 0 | FR3: 0 | FS3: 0 | FT3: 0 | FU3: 0 | FV3: 0 | FW3: 0 | FX3: 0 | FY3: 0 | FZ3: 0 | GA3: 0 | GB3: 0 | GC3: 0 | GD3: 0 | GE3: 0 | GF3: 0 | GG3: 0 | GH3: 0 | GI3: 0 | GJ3: 0 | GK3: 0 | GL3: 0 | GM3: 0 | GN3: 0 | GO3: 0 | GP3: 0 | GQ3: 0 | GR3: 0 | GS3: 0 | GT3: 0 | GU3: 0 | GV3: 0 | GW3: 0 | GX3: 0 | GY3: 0 | GZ3: 0 | HA3: 0 | HB3: 0 | HC3: 0 | HD3: 0 | HE3: 0 | HF3: 0 | HG3: 0 | HH3: 0 | HI3: 0 | HJ3: 0 | HK3: 0 | HL3: 0 | HM3: 0 | HN3: 0 | HO3: 0 | HP3: 0 | HQ3: 0 | HR3: 0 | HS3: 0 | HT3: 0 | HU3: 0 | HV3: 0 | HW3: 0 | HX3: 0 | HY3: 0 | HZ3: 0 | IA3: 0 | IB3: 0 | IC3: 0 | ID3: 0 | IE3: 0 | IF3: 0 | IG3: 0 | IH3: 0 | II3: 0 | IJ3: 0 | IK3: 0
A4: 56 | B4: SDH10 | F4: 1 | H4: 1 | J4: =B4&TEXT(F4,"00")&TEXT(H4,"00") -> SDH100101 | K4: 875 | M4: 56 | N4: SDH10 | O4: 1 | P4: 1 | Q4: =N4&TEXT(O4,"00")&TEXT(P4,"00") -> SDH100101 | R4: 0 | S4: 0 | T4: 0 | U4: 0 | V4: 0 | W4: 0 | X4: 0 | Y4: 0 | Z4: 0 | AA4: 0 | AB4: 0 | AC4: 0 | AD4: 0 | AE4: 0 | AF4: 0 | AG4: 0 | AH4: 0 | AI4: 0 | AJ4: 0 | AK4: 0 | AL4: 0 | AM4: 0 | AN4: 0 | AO4: 0 | AP4: 10000 | AQ4: 0 | AR4: 0 | AS4: 0 | AT4: 0 | AU4: 0 | AV4: 0 | AW4: 0 | AX4: 0 | AY4: 0 | AZ4: 0 | BA4: 0 | BB4: 0 | BC4: 0 | BD4: 0 | BE4: 0 | BF4: 0 | BG4: 0 | BH4: 0 | BI4: 0 | BJ4: 0 | BK4: 0 | BL4: 0 | BM4: 0 | BN4: 0 | BO4: 0 | BP4: 0 | BQ4: 0 | BR4: 0 | BS4: 0 | BT4: 0 | BU4: 0 | BV4: 0 | BW4: 0 | BX4: 0 | BY4: 0 | BZ4: 0 | CA4: 0 | CB4: 0 | CC4: 0 | CD4: 0 | CE4: 0 | CF4: 0 | CG4: 0 | CH4: 0 | CI4: 0 | CJ4: 0 | CK4: 0 | CL4: 0 | CM4: 0 | CN4: 0 | CO4: 0 | CP4: 0 | CQ4: 0 | CR4: 0 | CS4: 0 | CT4: 0 | CU4: 0 | CV4: 0 | CW4: 0 | CX4: 0 | CY4: 0 | CZ4: 0 | DA4: 0 | DB4: 0 | DC4: 0 | DD4: 0 | DE4: 0 | DF4: 0 | DG4: 0 | DH4: 0 | DI4: 0 | DJ4: 0 | DK4: 0 | DL4: 0 | DM4: 0 | DN4: 0 | DO4: 0 | DP4: 0 | DQ4: 0 | DR4: 0 | DS4: 0 | DT4: 0 | DU4: 0 | DV4: 0 | DW4: 0 | DX4: 0 | DZ4: 56 | EA4: SDH10 | EB4: 1 | EC4: 1 | ED4: =EA4&TEXT(EB4,"00")&TEXT(EC4,"00") -> SDH100101 | EE4: 10000 | EF4: 10000 | EG4: 10000 | EH4: 10000 | EI4: 10000 | EJ4: 10000 | EK4: 10000 | EL4: 10000 | EM4: 10000 | EN4: 10000 | EO4: 10000 | EP4: 10000 | EQ4: 10000 | ER4: 10000 | ES4: 10000 | ET4: 10000 | EU4: 10000 | EV4: 10000 | EW4: 10000 | EX4: 10000 | EY4: 10000 | EZ4: 10000 | FA4: 10000 | FB4: 10000 | FC4: 10000 | FD4: 0 | FE4: 0 | FF4: 0 | FG4: 0 | FH4: 0 | FI4: 0 | FJ4: 0 | FK4: 0 | FL4: 0 | FM4: 0 | FN4: 0 | FO4: 0 | FP4: 0 | FQ4: 0 | FR4: 0 | FS4: 0 | FT4: 0 | FU4: 0 | FV4: 0 | FW4: 0 | FX4: 0 | FY4: 0 | FZ4: 0 | GA4: 0 | GB4: 0 | GC4: 0 | GD4: 0 | GE4: 0 | GF4: 0 | GG4: 0 | GH4: 0 | GI4: 0 | GJ4: 0 | GK4: 0 | GL4: 0 | GM4: 0 | GN4: 0 | GO4: 0 | GP4: 0 | GQ4: 0 | GR4: 0 | GS4: 0 | GT4: 0 | GU4: 0 | GV4: 0 | GW4: 0 | GX4: 0 | GY4: 0 | GZ4: 0 | HA4: 0 | HB4: 0 | HC4: 0 | HD4: 0 | HE4: 0 | HF4: 0 | HG4: 0 | HH4: 0 | HI4: 0 | HJ4: 0 | HK4: 0 | HL4: 0 | HM4: 0 | HN4: 0 | HO4: 0 | HP4: 0 | HQ4: 0 | HR4: 0 | HS4: 0 | HT4: 0 | HU4: 0 | HV4: 0 | HW4: 0 | HX4: 0 | HY4: 0 | HZ4: 0 | IA4: 0 | IB4: 0 | IC4: 0 | ID4: 0 | IE4: 0 | IF4: 0 | IG4: 0 | IH4: 0 | II4: 0 | IJ4: 0 | IK4: 0
A5: 56 | B5: SDH10 | F5: 1 | H5: 2 | J5: =B5&TEXT(F5,"00")&TEXT(H5,"00") -> SDH100102 | K5: 875 | M5: 56 | N5: SDH10 | O5: 1 | P5: 2 | Q5: =N5&TEXT(O5,"00")&TEXT(P5,"00") -> SDH100102 | R5: 0 | S5: 0 | T5: 0 | U5: 0 | V5: 0 | W5: 0 | X5: 0 | Y5: 0 | Z5: 0 | AA5: 0 | AB5: 0 | AC5: 0 | AD5: 0 | AE5: 0 | AF5: 0 | AG5: 0 | AH5: 0 | AI5: 0 | AJ5: 0 | AK5: 0 | AL5: 0 | AM5: 0 | AN5: 0 | AO5: 0 | AP5: 10000 | AQ5: 0 | AR5: 0 | AS5: 0 | AT5: 0 | AU5: 0 | AV5: 0 | AW5: 0 | AX5: 0 | AY5: 0 | AZ5: 0 | BA5: 0 | BB5: 0 | BC5: 0 | BD5: 0 | BE5: 0 | BF5: 0 | BG5: 0 | BH5: 0 | BI5: 0 | BJ5: 0 | BK5: 0 | BL5: 0 | BM5: 0 | BN5: 0 | BO5: 0 | BP5: 0 | BQ5: 0 | BR5: 0 | BS5: 0 | BT5: 0 | BU5: 0 | BV5: 0 | BW5: 0 | BX5: 0 | BY5: 0 | BZ5: 0 | CA5: 0 | CB5: 0 | CC5: 0 | CD5: 0 | CE5: 0 | CF5: 0 | CG5: 0 | CH5: 0 | CI5: 0 | CJ5: 0 | CK5: 0 | CL5: 0 | CM5: 0 | CN5: 0 | CO5: 0 | CP5: 0 | CQ5: 0 | CR5: 0 | CS5: 0 | CT5: 0 | CU5: 0 | CV5: 0 | CW5: 0 | CX5: 0 | CY5: 0 | CZ5: 0 | DA5: 0 | DB5: 0 | DC5: 0 | DD5: 0 | DE5: 0 | DF5: 0 | DG5: 0 | DH5: 0 | DI5: 0 | DJ5: 0 | DK5: 0 | DL5: 0 | DM5: 0 | DN5: 0 | DO5: 0 | DP5: 0 | DQ5: 0 | DR5: 0 | DS5: 0 | DT5: 0 | DU5: 0 | DV5: 0 | DW5: 0 | DX5: 0 | DZ5: 56 | EA5: SDH10 | EB5: 1 | EC5: 2 | ED5: =EA5&TEXT(EB5,"00")&TEXT(EC5,"00") -> SDH100102 | EE5: 10000 | EF5: 10000 | EG5: 10000 | EH5: 10000 | EI5: 10000 | EJ5: 10000 | EK5: 10000 | EL5: 10000 | EM5: 10000 | EN5: 10000 | EO5: 10000 | EP5: 10000 | EQ5: 10000 | ER5: 10000 | ES5: 10000 | ET5: 10000 | EU5: 10000 | EV5: 10000 | EW5: 10000 | EX5: 10000 | EY5: 10000 | EZ5: 10000 | FA5: 10000 | FB5: 10000 | FC5: 10000 | FD5: 0 | FE5: 0 | FF5: 0 | FG5: 0 | FH5: 0 | FI5: 0 | FJ5: 0 | FK5: 0 | FL5: 0 | FM5: 0 | FN5: 0 | FO5: 0 | FP5: 0 | FQ5: 0 | FR5: 0 | FS5: 0 | FT5: 0 | FU5: 0 | FV5: 0 | FW5: 0 | FX5: 0 | FY5: 0 | FZ5: 0 | GA5: 0 | GB5: 0 | GC5: 0 | GD5: 0 | GE5: 0 | GF5: 0 | GG5: 0 | GH5: 0 | GI5: 0 | GJ5: 0 | GK5: 0 | GL5: 0 | GM5: 0 | GN5: 0 | GO5: 0 | GP5: 0 | GQ5: 0 | GR5: 0 | GS5: 0 | GT5: 0 | GU5: 0 | GV5: 0 | GW5: 0 | GX5: 0 | GY5: 0 | GZ5: 0 | HA5: 0 | HB5: 0 | HC5: 0 | HD5: 0 | HE5: 0 | HF5: 0 | HG5: 0 | HH5: 0 | HI5: 0 | HJ5: 0 | HK5: 0 | HL5: 0 | HM5: 0 | HN5: 0 | HO5: 0 | HP5: 0 | HQ5: 0 | HR5: 0 | HS5: 0 | HT5: 0 | HU5: 0 | HV5: 0 | HW5: 0 | HX5: 0 | HY5: 0 | HZ5: 0 | IA5: 0 | IB5: 0 | IC5: 0 | ID5: 0 | IE5: 0 | IF5: 0 | IG5: 0 | IH5: 0 | II5: 0 | IJ5: 0 | IK5: 0
A6: 56 | B6: SDH10 | F6: 1 | H6: 3 | J6: =B6&TEXT(F6,"00")&TEXT(H6,"00") -> SDH100103 | K6: 875 | M6: 56 | N6: SDH10 | O6: 1 | P6: 3 | Q6: =N6&TEXT(O6,"00")&TEXT(P6,"00") -> SDH100103 | R6: 0 | S6: 0 | T6: 0 | U6: 0 | V6: 0 | W6: 0 | X6: 0 | Y6: 0 | Z6: 0 | AA6: 0 | AB6: 0 | AC6: 0 | AD6: 0 | AE6: 0 | AF6: 0 | AG6: 0 | AH6: 0 | AI6: 0 | AJ6: 0 | AK6: 0 | AL6: 0 | AM6: 0 | AN6: 0 | AO6: 0 | AP6: 10000 | AQ6: 0 | AR6: 0 | AS6: 0 | AT6: 0 | AU6: 0 | AV6: 0 | AW6: 0 | AX6: 0 | AY6: 0 | AZ6: 0 | BA6: 0 | BB6: 0 | BC6: 0 | BD6: 0 | BE6: 0 | BF6: 0 | BG6: 0 | BH6: 0 | BI6: 0 | BJ6: 0 | BK6: 0 | BL6: 0 | BM6: 0 | BN6: 0 | BO6: 0 | BP6: 0 | BQ6: 0 | BR6: 0 | BS6: 0 | BT6: 0 | BU6: 0 | BV6: 0 | BW6: 0 | BX6: 0 | BY6: 0 | BZ6: 0 | CA6: 0 | CB6: 0 | CC6: 0 | CD6: 0 | CE6: 0 | CF6: 0 | CG6: 0 | CH6: 0 | CI6: 0 | CJ6: 0 | CK6: 0 | CL6: 0 | CM6: 0 | CN6: 0 | CO6: 0 | CP6: 0 | CQ6: 0 | CR6: 0 | CS6: 0 | CT6: 0 | CU6: 0 | CV6: 0 | CW6: 0 | CX6: 0 | CY6: 0 | CZ6: 0 | DA6: 0 | DB6: 0 | DC6: 0 | DD6: 0 | DE6: 0 | DF6: 0 | DG6: 0 | DH6: 0 | DI6: 0 | DJ6: 0 | DK6: 0 | DL6: 0 | DM6: 0 | DN6: 0 | DO6: 0 | DP6: 0 | DQ6: 0 | DR6: 0 | DS6: 0 | DT6: 0 | DU6: 0 | DV6: 0 | DW6: 0 | DX6: 0 | DZ6: 56 | EA6: SDH10 | EB6: 1 | EC6: 3 | ED6: =EA6&TEXT(EB6,"00")&TEXT(EC6,"00") -> SDH100103 | EE6: 10000 | EF6: 10000 | EG6: 10000 | EH6: 10000 | EI6: 10000 | EJ6: 10000 | EK6: 10000 | EL6: 10000 | EM6: 10000 | EN6: 10000 | EO6: 10000 | EP6: 10000 | EQ6: 10000 | ER6: 10000 | ES6: 10000 | ET6: 10000 | EU6: 10000 | EV6: 10000 | EW6: 10000 | EX6: 10000 | EY6: 10000 | EZ6: 10000 | FA6: 10000 | FB6: 10000 | FC6: 10000 | FD6: 0 | FE6: 0 | FF6: 0 | FG6: 0 | FH6: 0 | FI6: 0 | FJ6: 0 | FK6: 0 | FL6: 0 | FM6: 0 | FN6: 0 | FO6: 0 | FP6: 0 | FQ6: 0 | FR6: 0 | FS6: 0 | FT6: 0 | FU6: 0 | FV6: 0 | FW6: 0 | FX6: 0 | FY6: 0 | FZ6: 0 | GA6: 0 | GB6: 0 | GC6: 0 | GD6: 0 | GE6: 0 | GF6: 0 | GG6: 0 | GH6: 0 | GI6: 0 | GJ6: 0 | GK6: 0 | GL6: 0 | GM6: 0 | GN6: 0 | GO6: 0 | GP6: 0 | GQ6: 0 | GR6: 0 | GS6: 0 | GT6: 0 | GU6: 0 | GV6: 0 | GW6: 0 | GX6: 0 | GY6: 0 | GZ6: 0 | HA6: 0 | HB6: 0 | HC6: 0 | HD6: 0 | HE6: 0 | HF6: 0 | HG6: 0 | HH6: 0 | HI6: 0 | HJ6: 0 | HK6: 0 | HL6: 0 | HM6: 0 | HN6: 0 | HO6: 0 | HP6: 0 | HQ6: 0 | HR6: 0 | HS6: 0 | HT6: 0 | HU6: 0 | HV6: 0 | HW6: 0 | HX6: 0 | HY6: 0 | HZ6: 0 | IA6: 0 | IB6: 0 | IC6: 0 | ID6: 0 | IE6: 0 | IF6: 0 | IG6: 0 | IH6: 0 | II6: 0 | IJ6: 0 | IK6: 0
A7: 56 | B7: SDH10 | F7: 1 | H7: 4 | J7: =B7&TEXT(F7,"00")&TEXT(H7,"00") -> SDH100104 | K7: 875 | M7: 56 | N7: SDH10 | O7: 1 | P7: 4 | Q7: =N7&TEXT(O7,"00")&TEXT(P7,"00") -> SDH100104 | R7: 0 | S7: 0 | T7: 0 | U7: 0 | V7: 0 | W7: 0 | X7: 0 | Y7: 0 | Z7: 0 | AA7: 0 | AB7: 0 | AC7: 0 | AD7: 0 | AE7: 0 | AF7: 0 | AG7: 0 | AH7: 0 | AI7: 0 | AJ7: 0 | AK7: 0 | AL7: 0 | AM7: 0 | AN7: 0 | AO7: 0 | AP7: 10000 | AQ7: 0 | AR7: 0 | AS7: 0 | AT7: 0 | AU7: 0 | AV7: 0 | AW7: 0 | AX7: 0 | AY7: 0 | AZ7: 0 | BA7: 0 | BB7: 0 | BC7: 0 | BD7: 0 | BE7: 0 | BF7: 0 | BG7: 0 | BH7: 0 | BI7: 0 | BJ7: 0 | BK7: 0 | BL7: 0 | BM7: 0 | BN7: 0 | BO7: 0 | BP7: 0 | BQ7: 0 | BR7: 0 | BS7: 0 | BT7: 0 | BU7: 0 | BV7: 0 | BW7: 0 | BX7: 0 | BY7: 0 | BZ7: 0 | CA7: 0 | CB7: 0 | CC7: 0 | CD7: 0 | CE7: 0 | CF7: 0 | CG7: 0 | CH7: 0 | CI7: 0 | CJ7: 0 | CK7: 0 | CL7: 0 | CM7: 0 | CN7: 0 | CO7: 0 | CP7: 0 | CQ7: 0 | CR7: 0 | CS7: 0 | CT7: 0 | CU7: 0 | CV7: 0 | CW7: 0 | CX7: 0 | CY7: 0 | CZ7: 0 | DA7: 0 | DB7: 0 | DC7: 0 | DD7: 0 | DE7: 0 | DF7: 0 | DG7: 0 | DH7: 0 | DI7: 0 | DJ7: 0 | DK7: 0 | DL7: 0 | DM7: 0 | DN7: 0 | DO7: 0 | DP7: 0 | DQ7: 0 | DR7: 0 | DS7: 0 | DT7: 0 | DU7: 0 | DV7: 0 | DW7: 0 | DX7: 0 | DZ7: 56 | EA7: SDH10 | EB7: 1 | EC7: 4 | ED7: =EA7&TEXT(EB7,"00")&TEXT(EC7,"00") -> SDH100104 | EE7: 10000 | EF7: 10000 | EG7: 10000 | EH7: 10000 | EI7: 10000 | EJ7: 10000 | EK7: 10000 | EL7: 10000 | EM7: 10000 | EN7: 10000 | EO7: 10000 | EP7: 10000 | EQ7: 10000 | ER7: 10000 | ES7: 10000 | ET7: 10000 | EU7: 10000 | EV7: 10000 | EW7: 10000 | EX7: 10000 | EY7: 10000 | EZ7: 10000 | FA7: 10000 | FB7: 10000 | FC7: 10000 | FD7: 0 | FE7: 0 | FF7: 0 | FG7: 0 | FH7: 0 | FI7: 0 | FJ7: 0 | FK7: 0 | FL7: 0 | FM7: 0 | FN7: 0 | FO7: 0 | FP7: 0 | FQ7: 0 | FR7: 0 | FS7: 0 | FT7: 0 | FU7: 0 | FV7: 0 | FW7: 0 | FX7: 0 | FY7: 0 | FZ7: 0 | GA7: 0 | GB7: 0 | GC7: 0 | GD7: 0 | GE7: 0 | GF7: 0 | GG7: 0 | GH7: 0 | GI7: 0 | GJ7: 0 | GK7: 0 | GL7: 0 | GM7: 0 | GN7: 0 | GO7: 0 | GP7: 0 | GQ7: 0 | GR7: 0 | GS7: 0 | GT7: 0 | GU7: 0 | GV7: 0 | GW7: 0 | GX7: 0 | GY7: 0 | GZ7: 0 | HA7: 0 | HB7: 0 | HC7: 0 | HD7: 0 | HE7: 0 | HF7: 0 | HG7: 0 | HH7: 0 | HI7: 0 | HJ7: 0 | HK7: 0 | HL7: 0 | HM7: 0 | HN7: 0 | HO7: 0 | HP7: 0 | HQ7: 0 | HR7: 0 | HS7: 0 | HT7: 0 | HU7: 0 | HV7: 0 | HW7: 0 | HX7: 0 | HY7: 0 | HZ7: 0 | IA7: 0 | IB7: 0 | IC7: 0 | ID7: 0 | IE7: 0 | IF7: 0 | IG7: 0 | IH7: 0 | II7: 0 | IJ7: 0 | IK7: 0
A8: 56 | B8: SDH10 | F8: 1 | H8: 5 | J8: =B8&TEXT(F8,"00")&TEXT(H8,"00") -> SDH100105 | K8: 875 | M8: 56 | N8: SDH10 | O8: 1 | P8: 5 | Q8: =N8&TEXT(O8,"00")&TEXT(P8,"00") -> SDH100105 | R8: 0 | S8: 0 | T8: 0 | U8: 0 | V8: 0 | W8: 0 | X8: 0 | Y8: 0 | Z8: 0 | AA8: 0 | AB8: 0 | AC8: 0 | AD8: 0 | AE8: 0 | AF8: 0 | AG8: 0 | AH8: 0 | AI8: 0 | AJ8: 0 | AK8: 0 | AL8: 0 | AM8: 0 | AN8: 0 | AO8: 0 | AP8: 10000 | AQ8: 0 | AR8: 0 | AS8: 0 | AT8: 0 | AU8: 0 | AV8: 0 | AW8: 0 | AX8: 0 | AY8: 0 | AZ8: 0 | BA8: 0 | BB8: 0 | BC8: 0 | BD8: 0 | BE8: 0 | BF8: 0 | BG8: 0 | BH8: 0 | BI8: 0 | BJ8: 0 | BK8: 0 | BL8: 0 | BM8: 0 | BN8: 0 | BO8: 0 | BP8: 0 | BQ8: 0 | BR8: 0 | BS8: 0 | BT8: 0 | BU8: 0 | BV8: 0 | BW8: 0 | BX8: 0 | BY8: 0 | BZ8: 0 | CA8: 0 | CB8: 0 | CC8: 0 | CD8: 0 | CE8: 0 | CF8: 0 | CG8: 0 | CH8: 0 | CI8: 0 | CJ8: 0 | CK8: 0 | CL8: 0 | CM8: 0 | CN8: 0 | CO8: 0 | CP8: 0 | CQ8: 0 | CR8: 0 | CS8: 0 | CT8: 0 | CU8: 0 | CV8: 0 | CW8: 0 | CX8: 0 | CY8: 0 | CZ8: 0 | DA8: 0 | DB8: 0 | DC8: 0 | DD8: 0 | DE8: 0 | DF8: 0 | DG8: 0 | DH8: 0 | DI8: 0 | DJ8: 0 | DK8: 0 | DL8: 0 | DM8: 0 | DN8: 0 | DO8: 0 | DP8: 0 | DQ8: 0 | DR8: 0 | DS8: 0 | DT8: 0 | DU8: 0 | DV8: 0 | DW8: 0 | DX8: 0 | DZ8: 56 | EA8: SDH10 | EB8: 1 | EC8: 5 | ED8: =EA8&TEXT(EB8,"00")&TEXT(EC8,"00") -> SDH100105 | EE8: 10000 | EF8: 10000 | EG8: 10000 | EH8: 10000 | EI8: 10000 | EJ8: 10000 | EK8: 10000 | EL8: 10000 | EM8: 10000 | EN8: 10000 | EO8: 10000 | EP8: 10000 | EQ8: 10000 | ER8: 10000 | ES8: 10000 | ET8: 10000 | EU8: 10000 | EV8: 10000 | EW8: 10000 | EX8: 10000 | EY8: 10000 | EZ8: 10000 | FA8: 10000 | FB8: 10000 | FC8: 10000 | FD8: 0 | FE8: 0 | FF8: 0 | FG8: 0 | FH8: 0 | FI8: 0 | FJ8: 0 | FK8: 0 | FL8: 0 | FM8: 0 | FN8: 0 | FO8: 0 | FP8: 0 | FQ8: 0 | FR8: 0 | FS8: 0 | FT8: 0 | FU8: 0 | FV8: 0 | FW8: 0 | FX8: 0 | FY8: 0 | FZ8: 0 | GA8: 0 | GB8: 0 | GC8: 0 | GD8: 0 | GE8: 0 | GF8: 0 | GG8: 0 | GH8: 0 | GI8: 0 | GJ8: 0 | GK8: 0 | GL8: 0 | GM8: 0 | GN8: 0 | GO8: 0 | GP8: 0 | GQ8: 0 | GR8: 0 | GS8: 0 | GT8: 0 | GU8: 0 | GV8: 0 | GW8: 0 | GX8: 0 | GY8: 0 | GZ8: 0 | HA8: 0 | HB8: 0 | HC8: 0 | HD8: 0 | HE8: 0 | HF8: 0 | HG8: 0 | HH8: 0 | HI8: 0 | HJ8: 0 | HK8: 0 | HL8: 0 | HM8: 0 | HN8: 0 | HO8: 0 | HP8: 0 | HQ8: 0 | HR8: 0 | HS8: 0 | HT8: 0 | HU8: 0 | HV8: 0 | HW8: 0 | HX8: 0 | HY8: 0 | HZ8: 0 | IA8: 0 | IB8: 0 | IC8: 0 | ID8: 0 | IE8: 0 | IF8: 0 | IG8: 0 | IH8: 0 | II8: 0 | IJ8: 0 | IK8: 0
A9: 56 | B9: SDH10 | F9: 1 | H9: 6 | J9: =B9&TEXT(F9,"00")&TEXT(H9,"00") -> SDH100106 | K9: 875 | M9: 56 | N9: SDH10 | O9: 1 | P9: 6 | Q9: =N9&TEXT(O9,"00")&TEXT(P9,"00") -> SDH100106 | R9: 0 | S9: 0 | T9: 0 | U9: 0 | V9: 0 | W9: 0 | X9: 0 | Y9: 0 | Z9: 0 | AA9: 0 | AB9: 0 | AC9: 0 | AD9: 0 | AE9: 0 | AF9: 0 | AG9: 0 | AH9: 0 | AI9: 0 | AJ9: 0 | AK9: 0 | AL9: 0 | AM9: 0 | AN9: 0 | AO9: 0 | AP9: 10000 | AQ9: 0 | AR9: 0 | AS9: 0 | AT9: 0 | AU9: 0 | AV9: 0 | AW9: 0 | AX9: 0 | AY9: 0 | AZ9: 0 | BA9: 0 | BB9: 0 | BC9: 0 | BD9: 0 | BE9: 0 | BF9: 0 | BG9: 0 | BH9: 0 | BI9: 0 | BJ9: 0 | BK9: 0 | BL9: 0 | BM9: 0 | BN9: 0 | BO9: 0 | BP9: 0 | BQ9: 0 | BR9: 0 | BS9: 0 | BT9: 0 | BU9: 0 | BV9: 0 | BW9: 0 | BX9: 0 | BY9: 0 | BZ9: 0 | CA9: 0 | CB9: 0 | CC9: 0 | CD9: 0 | CE9: 0 | CF9: 0 | CG9: 0 | CH9: 0 | CI9: 0 | CJ9: 0 | CK9: 0 | CL9: 0 | CM9: 0 | CN9: 0 | CO9: 0 | CP9: 0 | CQ9: 0 | CR9: 0 | CS9: 0 | CT9: 0 | CU9: 0 | CV9: 0 | CW9: 0 | CX9: 0 | CY9: 0 | CZ9: 0 | DA9: 0 | DB9: 0 | DC9: 0 | DD9: 0 | DE9: 0 | DF9: 0 | DG9: 0 | DH9: 0 | DI9: 0 | DJ9: 0 | DK9: 0 | DL9: 0 | DM9: 0 | DN9: 0 | DO9: 0 | DP9: 0 | DQ9: 0 | DR9: 0 | DS9: 0 | DT9: 0 | DU9: 0 | DV9: 0 | DW9: 0 | DX9: 0 | DZ9: 56 | EA9: SDH10 | EB9: 1 | EC9: 6 | ED9: =EA9&TEXT(EB9,"00")&TEXT(EC9,"00") -> SDH100106 | EE9: 10000 | EF9: 10000 | EG9: 10000 | EH9: 10000 | EI9: 10000 | EJ9: 10000 | EK9: 10000 | EL9: 10000 | EM9: 10000 | EN9: 10000 | EO9: 10000 | EP9: 10000 | EQ9: 10000 | ER9: 10000 | ES9: 10000 | ET9: 10000 | EU9: 10000 | EV9: 10000 | EW9: 10000 | EX9: 10000 | EY9: 10000 | EZ9: 10000 | FA9: 10000 | FB9: 10000 | FC9: 10000 | FD9: 0 | FE9: 0 | FF9: 0 | FG9: 0 | FH9: 0 | FI9: 0 | FJ9: 0 | FK9: 0 | FL9: 0 | FM9: 0 | FN9: 0 | FO9: 0 | FP9: 0 | FQ9: 0 | FR9: 0 | FS9: 0 | FT9: 0 | FU9: 0 | FV9: 0 | FW9: 0 | FX9: 0 | FY9: 0 | FZ9: 0 | GA9: 0 | GB9: 0 | GC9: 0 | GD9: 0 | GE9: 0 | GF9: 0 | GG9: 0 | GH9: 0 | GI9: 0 | GJ9: 0 | GK9: 0 | GL9: 0 | GM9: 0 | GN9: 0 | GO9: 0 | GP9: 0 | GQ9: 0 | GR9: 0 | GS9: 0 | GT9: 0 | GU9: 0 | GV9: 0 | GW9: 0 | GX9: 0 | GY9: 0 | GZ9: 0 | HA9: 0 | HB9: 0 | HC9: 0 | HD9: 0 | HE9: 0 | HF9: 0 | HG9: 0 | HH9: 0 | HI9: 0 | HJ9: 0 | HK9: 0 | HL9: 0 | HM9: 0 | HN9: 0 | HO9: 0 | HP9: 0 | HQ9: 0 | HR9: 0 | HS9: 0 | HT9: 0 | HU9: 0 | HV9: 0 | HW9: 0 | HX9: 0 | HY9: 0 | HZ9: 0 | IA9: 0 | IB9: 0 | IC9: 0 | ID9: 0 | IE9: 0 | IF9: 0 | IG9: 0 | IH9: 0 | II9: 0 | IJ9: 0 | IK9: 0
A10: 56 | B10: SDH10 | F10: 1 | H10: 7 | J10: =B10&TEXT(F10,"00")&TEXT(H10,"00") -> SDH100107 | K10: 875 | M10: 56 | N10: SDH10 | O10: 1 | P10: 7 | Q10: =N10&TEXT(O10,"00")&TEXT(P10,"00") -> SDH100107 | R10: 0 | S10: 0 | T10: 0 | U10: 0 | V10: 0 | W10: 0 | X10: 0 | Y10: 0 | Z10: 0 | AA10: 0 | AB10: 0 | AC10: 0 | AD10: 0 | AE10: 0 | AF10: 0 | AG10: 0 | AH10: 0 | AI10: 0 | AJ10: 0 | AK10: 0 | AL10: 0 | AM10: 0 | AN10: 0 | AO10: 0 | AP10: 10000 | AQ10: 0 | AR10: 0 | AS10: 0 | AT10: 0 | AU10: 0 | AV10: 0 | AW10: 0 | AX10: 0 | AY10: 0 | AZ10: 0 | BA10: 0 | BB10: 0 | BC10: 0 | BD10: 0 | BE10: 0 | BF10: 0 | BG10: 0 | BH10: 0 | BI10: 0 | BJ10: 0 | BK10: 0 | BL10: 0 | BM10: 0 | BN10: 0 | BO10: 0 | BP10: 0 | BQ10: 0 | BR10: 0 | BS10: 0 | BT10: 0 | BU10: 0 | BV10: 0 | BW10: 0 | BX10: 0 | BY10: 0 | BZ10: 0 | CA10: 0 | CB10: 0 | CC10: 0 | CD10: 0 | CE10: 0 | CF10: 0 | CG10: 0 | CH10: 0 | CI10: 0 | CJ10: 0 | CK10: 0 | CL10: 0 | CM10: 0 | CN10: 0 | CO10: 0 | CP10: 0 | CQ10: 0 | CR10: 0 | CS10: 0 | CT10: 0 | CU10: 0 | CV10: 0 | CW10: 0 | CX10: 0 | CY10: 0 | CZ10: 0 | DA10: 0 | DB10: 0 | DC10: 0 | DD10: 0 | DE10: 0 | DF10: 0 | DG10: 0 | DH10: 0 | DI10: 0 | DJ10: 0 | DK10: 0 | DL10: 0 | DM10: 0 | DN10: 0 | DO10: 0 | DP10: 0 | DQ10: 0 | DR10: 0 | DS10: 0 | DT10: 0 | DU10: 0 | DV10: 0 | DW10: 0 | DX10: 0 | DZ10: 56 | EA10: SDH10 | EB10: 1 | EC10: 7 | ED10: =EA10&TEXT(EB10,"00")&TEXT(EC10,"00") -> SDH100107 | EE10: 10000 | EF10: 10000 | EG10: 10000 | EH10: 10000 | EI10: 10000 | EJ10: 10000 | EK10: 10000 | EL10: 10000 | EM10: 10000 | EN10: 10000 | EO10: 10000 | EP10: 10000 | EQ10: 10000 | ER10: 10000 | ES10: 10000 | ET10: 10000 | EU10: 10000 | EV10: 10000 | EW10: 10000 | EX10: 10000 | EY10: 10000 | EZ10: 10000 | FA10: 10000 | FB10: 10000 | FC10: 10000 | FD10: 0 | FE10: 0 | FF10: 0 | FG10: 0 | FH10: 0 | FI10: 0 | FJ10: 0 | FK10: 0 | FL10: 0 | FM10: 0 | FN10: 0 | FO10: 0 | FP10: 0 | FQ10: 0 | FR10: 0 | FS10: 0 | FT10: 0 | FU10: 0 | FV10: 0 | FW10: 0 | FX10: 0 | FY10: 0 | FZ10: 0 | GA10: 0 | GB10: 0 | GC10: 0 | GD10: 0 | GE10: 0 | GF10: 0 | GG10: 0 | GH10: 0 | GI10: 0 | GJ10: 0 | GK10: 0 | GL10: 0 | GM10: 0 | GN10: 0 | GO10: 0 | GP10: 0 | GQ10: 0 | GR10: 0 | GS10: 0 | GT10: 0 | GU10: 0 | GV10: 0 | GW10: 0 | GX10: 0 | GY10: 0 | GZ10: 0 | HA10: 0 | HB10: 0 | HC10: 0 | HD10: 0 | HE10: 0 | HF10: 0 | HG10: 0 | HH10: 0 | HI10: 0 | HJ10: 0 | HK10: 0 | HL10: 0 | HM10: 0 | HN10: 0 | HO10: 0 | HP10: 0 | HQ10: 0 | HR10: 0 | HS10: 0 | HT10: 0 | HU10: 0 | HV10: 0 | HW10: 0 | HX10: 0 | HY10: 0 | HZ10: 0 | IA10: 0 | IB10: 0 | IC10: 0 | ID10: 0 | IE10: 0 | IF10: 0 | IG10: 0 | IH10: 0 | II10: 0 | IJ10: 0 | IK10: 0
A11: 56 | B11: SDH10 | F11: 1 | H11: 8 | J11: =B11&TEXT(F11,"00")&TEXT(H11,"00") -> SDH100108 | K11: 875 | M11: 56 | N11: SDH10 | O11: 1 | P11: 8 | Q11: =N11&TEXT(O11,"00")&TEXT(P11,"00") -> SDH100108 | R11: 0 | S11: 0 | T11: 0 | U11: 0 | V11: 0 | W11: 0 | X11: 0 | Y11: 0 | Z11: 0 | AA11: 0 | AB11: 0 | AC11: 0 | AD11: 0 | AE11: 0 | AF11: 0 | AG11: 0 | AH11: 0 | AI11: 0 | AJ11: 0 | AK11: 0 | AL11: 0 | AM11: 0 | AN11: 0 | AO11: 0 | AP11: 10000 | AQ11: 0 | AR11: 0 | AS11: 0 | AT11: 0 | AU11: 0 | AV11: 0 | AW11: 0 | AX11: 0 | AY11: 0 | AZ11: 0 | BA11: 0 | BB11: 0 | BC11: 0 | BD11: 0 | BE11: 0 | BF11: 0 | BG11: 0 | BH11: 0 | BI11: 0 | BJ11: 0 | BK11: 0 | BL11: 0 | BM11: 0 | BN11: 0 | BO11: 0 | BP11: 0 | BQ11: 0 | BR11: 0 | BS11: 0 | BT11: 0 | BU11: 0 | BV11: 0 | BW11: 0 | BX11: 0 | BY11: 0 | BZ11: 0 | CA11: 0 | CB11: 0 | CC11: 0 | CD11: 0 | CE11: 0 | CF11: 0 | CG11: 0 | CH11: 0 | CI11: 0 | CJ11: 0 | CK11: 0 | CL11: 0 | CM11: 0 | CN11: 0 | CO11: 0 | CP11: 0 | CQ11: 0 | CR11: 0 | CS11: 0 | CT11: 0 | CU11: 0 | CV11: 0 | CW11: 0 | CX11: 0 | CY11: 0 | CZ11: 0 | DA11: 0 | DB11: 0 | DC11: 0 | DD11: 0 | DE11: 0 | DF11: 0 | DG11: 0 | DH11: 0 | DI11: 0 | DJ11: 0 | DK11: 0 | DL11: 0 | DM11: 0 | DN11: 0 | DO11: 0 | DP11: 0 | DQ11: 0 | DR11: 0 | DS11: 0 | DT11: 0 | DU11: 0 | DV11: 0 | DW11: 0 | DX11: 0 | DZ11: 56 | EA11: SDH10 | EB11: 1 | EC11: 8 | ED11: =EA11&TEXT(EB11,"00")&TEXT(EC11,"00") -> SDH100108 | EE11: 10000 | EF11: 10000 | EG11: 10000 | EH11: 10000 | EI11: 10000 | EJ11: 10000 | EK11: 10000 | EL11: 10000 | EM11: 10000 | EN11: 10000 | EO11: 10000 | EP11: 10000 | EQ11: 10000 | ER11: 10000 | ES11: 10000 | ET11: 10000 | EU11: 10000 | EV11: 10000 | EW11: 10000 | EX11: 10000 | EY11: 10000 | EZ11: 10000 | FA11: 10000 | FB11: 10000 | FC11: 10000 | FD11: 0 | FE11: 0 | FF11: 0 | FG11: 0 | FH11: 0 | FI11: 0 | FJ11: 0 | FK11: 0 | FL11: 0 | FM11: 0 | FN11: 0 | FO11: 0 | FP11: 0 | FQ11: 0 | FR11: 0 | FS11: 0 | FT11: 0 | FU11: 0 | FV11: 0 | FW11: 0 | FX11: 0 | FY11: 0 | FZ11: 0 | GA11: 0 | GB11: 0 | GC11: 0 | GD11: 0 | GE11: 0 | GF11: 0 | GG11: 0 | GH11: 0 | GI11: 0 | GJ11: 0 | GK11: 0 | GL11: 0 | GM11: 0 | GN11: 0 | GO11: 0 | GP11: 0 | GQ11: 0 | GR11: 0 | GS11: 0 | GT11: 0 | GU11: 0 | GV11: 0 | GW11: 0 | GX11: 0 | GY11: 0 | GZ11: 0 | HA11: 0 | HB11: 0 | HC11: 0 | HD11: 0 | HE11: 0 | HF11: 0 | HG11: 0 | HH11: 0 | HI11: 0 | HJ11: 0 | HK11: 0 | HL11: 0 | HM11: 0 | HN11: 0 | HO11: 0 | HP11: 0 | HQ11: 0 | HR11: 0 | HS11: 0 | HT11: 0 | HU11: 0 | HV11: 0 | HW11: 0 | HX11: 0 | HY11: 0 | HZ11: 0 | IA11: 0 | IB11: 0 | IC11: 0 | ID11: 0 | IE11: 0 | IF11: 0 | IG11: 0 | IH11: 0 | II11: 0 | IJ11: 0 | IK11: 0
A12: 56 | B12: SDH10 | F12: 1 | H12: 9 | J12: =B12&TEXT(F12,"00")&TEXT(H12,"00") -> SDH100109 | K12: 875 | M12: 56 | N12: SDH10 | O12: 1 | P12: 9 | Q12: =N12&TEXT(O12,"00")&TEXT(P12,"00") -> SDH100109 | R12: 0 | S12: 0 | T12: 0 | U12: 0 | V12: 0 | W12: 0 | X12: 0 | Y12: 0 | Z12: 0 | AA12: 0 | AB12: 0 | AC12: 0 | AD12: 0 | AE12: 0 | AF12: 0 | AG12: 0 | AH12: 0 | AI12: 0 | AJ12: 0 | AK12: 0 | AL12: 0 | AM12: 0 | AN12: 0 | AO12: 0 | AP12: 10000 | AQ12: 0 | AR12: 0 | AS12: 0 | AT12: 0 | AU12: 0 | AV12: 0 | AW12: 0 | AX12: 0 | AY12: 0 | AZ12: 0 | BA12: 0 | BB12: 0 | BC12: 0 | BD12: 0 | BE12: 0 | BF12: 0 | BG12: 0 | BH12: 0 | BI12: 0 | BJ12: 0 | BK12: 0 | BL12: 0 | BM12: 0 | BN12: 0 | BO12: 0 | BP12: 0 | BQ12: 0 | BR12: 0 | BS12: 0 | BT12: 0 | BU12: 0 | BV12: 0 | BW12: 0 | BX12: 0 | BY12: 0 | BZ12: 0 | CA12: 0 | CB12: 0 | CC12: 0 | CD12: 0 | CE12: 0 | CF12: 0 | CG12: 0 | CH12: 0 | CI12: 0 | CJ12: 0 | CK12: 0 | CL12: 0 | CM12: 0 | CN12: 0 | CO12: 0 | CP12: 0 | CQ12: 0 | CR12: 0 | CS12: 0 | CT12: 0 | CU12: 0 | CV12: 0 | CW12: 0 | CX12: 0 | CY12: 0 | CZ12: 0 | DA12: 0 | DB12: 0 | DC12: 0 | DD12: 0 | DE12: 0 | DF12: 0 | DG12: 0 | DH12: 0 | DI12: 0 | DJ12: 0 | DK12: 0 | DL12: 0 | DM12: 0 | DN12: 0 | DO12: 0 | DP12: 0 | DQ12: 0 | DR12: 0 | DS12: 0 | DT12: 0 | DU12: 0 | DV12: 0 | DW12: 0 | DX12: 0 | DZ12: 56 | EA12: SDH10 | EB12: 1 | EC12: 9 | ED12: =EA12&TEXT(EB12,"00")&TEXT(EC12,"00") -> SDH100109 | EE12: 10000 | EF12: 10000 | EG12: 10000 | EH12: 10000 | EI12: 10000 | EJ12: 10000 | EK12: 10000 | EL12: 10000 | EM12: 10000 | EN12: 10000 | EO12: 10000 | EP12: 10000 | EQ12: 10000 | ER12: 10000 | ES12: 10000 | ET12: 10000 | EU12: 10000 | EV12: 10000 | EW12: 10000 | EX12: 10000 | EY12: 10000 | EZ12: 10000 | FA12: 10000 | FB12: 10000 | FC12: 10000 | FD12: 0 | FE12: 0 | FF12: 0 | FG12: 0 | FH12: 0 | FI12: 0 | FJ12: 0 | FK12: 0 | FL12: 0 | FM12: 0 | FN12: 0 | FO12: 0 | FP12: 0 | FQ12: 0 | FR12: 0 | FS12: 0 | FT12: 0 | FU12: 0 | FV12: 0 | FW12: 0 | FX12: 0 | FY12: 0 | FZ12: 0 | GA12: 0 | GB12: 0 | GC12: 0 | GD12: 0 | GE12: 0 | GF12: 0 | GG12: 0 | GH12: 0 | GI12: 0 | GJ12: 0 | GK12: 0 | GL12: 0 | GM12: 0 | GN12: 0 | GO12: 0 | GP12: 0 | GQ12: 0 | GR12: 0 | GS12: 0 | GT12: 0 | GU12: 0 | GV12: 0 | GW12: 0 | GX12: 0 | GY12: 0 | GZ12: 0 | HA12: 0 | HB12: 0 | HC12: 0 | HD12: 0 | HE12: 0 | HF12: 0 | HG12: 0 | HH12: 0 | HI12: 0 | HJ12: 0 | HK12: 0 | HL12: 0 | HM12: 0 | HN12: 0 | HO12: 0 | HP12: 0 | HQ12: 0 | HR12: 0 | HS12: 0 | HT12: 0 | HU12: 0 | HV12: 0 | HW12: 0 | HX12: 0 | HY12: 0 | HZ12: 0 | IA12: 0 | IB12: 0 | IC12: 0 | ID12: 0 | IE12: 0 | IF12: 0 | IG12: 0 | IH12: 0 | II12: 0 | IJ12: 0 | IK12: 0
A13: 56 | B13: SDH10 | F13: 1 | H13: 10 | J13: =B13&TEXT(F13,"00")&TEXT(H13,"00") -> SDH100110 | K13: 875 | M13: 56 | N13: SDH10 | O13: 1 | P13: 10 | Q13: =N13&TEXT(O13,"00")&TEXT(P13,"00") -> SDH100110 | R13: 0 | S13: 0 | T13: 0 | U13: 0 | V13: 0 | W13: 0 | X13: 0 | Y13: 0 | Z13: 0 | AA13: 0 | AB13: 0 | AC13: 0 | AD13: 0 | AE13: 0 | AF13: 0 | AG13: 0 | AH13: 0 | AI13: 0 | AJ13: 0 | AK13: 0 | AL13: 0 | AM13: 0 | AN13: 0 | AO13: 0 | AP13: 10000 | AQ13: 0 | AR13: 0 | AS13: 0 | AT13: 0 | AU13: 0 | AV13: 0 | AW13: 0 | AX13: 0 | AY13: 0 | AZ13: 0 | BA13: 0 | BB13: 0 | BC13: 0 | BD13: 0 | BE13: 0 | BF13: 0 | BG13: 0 | BH13: 0 | BI13: 0 | BJ13: 0 | BK13: 0 | BL13: 0 | BM13: 0 | BN13: 0 | BO13: 0 | BP13: 0 | BQ13: 0 | BR13: 0 | BS13: 0 | BT13: 0 | BU13: 0 | BV13: 0 | BW13: 0 | BX13: 0 | BY13: 0 | BZ13: 0 | CA13: 0 | CB13: 0 | CC13: 0 | CD13: 0 | CE13: 0 | CF13: 0 | CG13: 0 | CH13: 0 | CI13: 0 | CJ13: 0 | CK13: 0 | CL13: 0 | CM13: 0 | CN13: 0 | CO13: 0 | CP13: 0 | CQ13: 0 | CR13: 0 | CS13: 0 | CT13: 0 | CU13: 0 | CV13: 0 | CW13: 0 | CX13: 0 | CY13: 0 | CZ13: 0 | DA13: 0 | DB13: 0 | DC13: 0 | DD13: 0 | DE13: 0 | DF13: 0 | DG13: 0 | DH13: 0 | DI13: 0 | DJ13: 0 | DK13: 0 | DL13: 0 | DM13: 0 | DN13: 0 | DO13: 0 | DP13: 0 | DQ13: 0 | DR13: 0 | DS13: 0 | DT13: 0 | DU13: 0 | DV13: 0 | DW13: 0 | DX13: 0 | DZ13: 56 | EA13: SDH10 | EB13: 1 | EC13: 10 | ED13: =EA13&TEXT(EB13,"00")&TEXT(EC13,"00") -> SDH100110 | EE13: 10000 | EF13: 10000 | EG13: 10000 | EH13: 10000 | EI13: 10000 | EJ13: 10000 | EK13: 10000 | EL13: 10000 | EM13: 10000 | EN13: 10000 | EO13: 10000 | EP13: 10000 | EQ13: 10000 | ER13: 10000 | ES13: 10000 | ET13: 10000 | EU13: 10000 | EV13: 10000 | EW13: 10000 | EX13: 10000 | EY13: 10000 | EZ13: 10000 | FA13: 10000 | FB13: 10000 | FC13: 10000 | FD13: 0 | FE13: 0 | FF13: 0 | FG13: 0 | FH13: 0 | FI13: 0 | FJ13: 0 | FK13: 0 | FL13: 0 | FM13: 0 | FN13: 0 | FO13: 0 | FP13: 0 | FQ13: 0 | FR13: 0 | FS13: 0 | FT13: 0 | FU13: 0 | FV13: 0 | FW13: 0 | FX13: 0 | FY13: 0 | FZ13: 0 | GA13: 0 | GB13: 0 | GC13: 0 | GD13: 0 | GE13: 0 | GF13: 0 | GG13: 0 | GH13: 0 | GI13: 0 | GJ13: 0 | GK13: 0 | GL13: 0 | GM13: 0 | GN13: 0 | GO13: 0 | GP13: 0 | GQ13: 0 | GR13: 0 | GS13: 0 | GT13: 0 | GU13: 0 | GV13: 0 | GW13: 0 | GX13: 0 | GY13: 0 | GZ13: 0 | HA13: 0 | HB13: 0 | HC13: 0 | HD13: 0 | HE13: 0 | HF13: 0 | HG13: 0 | HH13: 0 | HI13: 0 | HJ13: 0 | HK13: 0 | HL13: 0 | HM13: 0 | HN13: 0 | HO13: 0 | HP13: 0 | HQ13: 0 | HR13: 0 | HS13: 0 | HT13: 0 | HU13: 0 | HV13: 0 | HW13: 0 | HX13: 0 | HY13: 0 | HZ13: 0 | IA13: 0 | IB13: 0 | IC13: 0 | ID13: 0 | IE13: 0 | IF13: 0 | IG13: 0 | IH13: 0 | II13: 0 | IJ13: 0 | IK13: 0
A14: 56 | B14: SDH10 | F14: 1 | H14: 11 | J14: =B14&TEXT(F14,"00")&TEXT(H14,"00") -> SDH100111 | K14: 880 | M14: 56 | N14: SDH10 | O14: 1 | P14: 11 | Q14: =N14&TEXT(O14,"00")&TEXT(P14,"00") -> SDH100111 | R14: 0 | S14: 0 | T14: 0 | U14: 0 | V14: 0 | W14: 0 | X14: 0 | Y14: 0 | Z14: 0 | AA14: 0 | AB14: 0 | AC14: 0 | AD14: 0 | AE14: 0 | AF14: 0 | AG14: 0 | AH14: 0 | AI14: 0 | AJ14: 0 | AK14: 0 | AL14: 0 | AM14: 0 | AN14: 0 | AO14: 0 | AP14: 10000 | AQ14: 0 | AR14: 0 | AS14: 0 | AT14: 0 | AU14: 0 | AV14: 0 | AW14: 0 | AX14: 0 | AY14: 0 | AZ14: 0 | BA14: 0 | BB14: 0 | BC14: 0 | BD14: 0 | BE14: 0 | BF14: 0 | BG14: 0 | BH14: 0 | BI14: 0 | BJ14: 0 | BK14: 0 | BL14: 0 | BM14: 0 | BN14: 0 | BO14: 0 | BP14: 0 | BQ14: 0 | BR14: 0 | BS14: 0 | BT14: 0 | BU14: 0 | BV14: 0 | BW14: 0 | BX14: 0 | BY14: 0 | BZ14: 0 | CA14: 0 | CB14: 0 | CC14: 0 | CD14: 0 | CE14: 0 | CF14: 0 | CG14: 0 | CH14: 0 | CI14: 0 | CJ14: 0 | CK14: 0 | CL14: 0 | CM14: 0 | CN14: 0 | CO14: 0 | CP14: 0 | CQ14: 0 | CR14: 0 | CS14: 0 | CT14: 0 | CU14: 0 | CV14: 0 | CW14: 0 | CX14: 0 | CY14: 0 | CZ14: 0 | DA14: 0 | DB14: 0 | DC14: 0 | DD14: 0 | DE14: 0 | DF14: 0 | DG14: 0 | DH14: 0 | DI14: 0 | DJ14: 0 | DK14: 0 | DL14: 0 | DM14: 0 | DN14: 0 | DO14: 0 | DP14: 0 | DQ14: 0 | DR14: 0 | DS14: 0 | DT14: 0 | DU14: 0 | DV14: 0 | DW14: 0 | DX14: 0 | DZ14: 56 | EA14: SDH10 | EB14: 1 | EC14: 11 | ED14: =EA14&TEXT(EB14,"00")&TEXT(EC14,"00") -> SDH100111 | EE14: 10000 | EF14: 10000 | EG14: 10000 | EH14: 10000 | EI14: 10000 | EJ14: 10000 | EK14: 10000 | EL14: 10000 | EM14: 10000 | EN14: 10000 | EO14: 10000 | EP14: 10000 | EQ14: 10000 | ER14: 10000 | ES14: 10000 | ET14: 10000 | EU14: 10000 | EV14: 10000 | EW14: 10000 | EX14: 10000 | EY14: 10000 | EZ14: 10000 | FA14: 10000 | FB14: 10000 | FC14: 10000 | FD14: 0 | FE14: 0 | FF14: 0 | FG14: 0 | FH14: 0 | FI14: 0 | FJ14: 0 | FK14: 0 | FL14: 0 | FM14: 0 | FN14: 0 | FO14: 0 | FP14: 0 | FQ14: 0 | FR14: 0 | FS14: 0 | FT14: 0 | FU14: 0 | FV14: 0 | FW14: 0 | FX14: 0 | FY14: 0 | FZ14: 0 | GA14: 0 | GB14: 0 | GC14: 0 | GD14: 0 | GE14: 0 | GF14: 0 | GG14: 0 | GH14: 0 | GI14: 0 | GJ14: 0 | GK14: 0 | GL14: 0 | GM14: 0 | GN14: 0 | GO14: 0 | GP14: 0 | GQ14: 0 | GR14: 0 | GS14: 0 | GT14: 0 | GU14: 0 | GV14: 0 | GW14: 0 | GX14: 0 | GY14: 0 | GZ14: 0 | HA14: 0 | HB14: 0 | HC14: 0 | HD14: 0 | HE14: 0 | HF14: 0 | HG14: 0 | HH14: 0 | HI14: 0 | HJ14: 0 | HK14: 0 | HL14: 0 | HM14: 0 | HN14: 0 | HO14: 0 | HP14: 0 | HQ14: 0 | HR14: 0 | HS14: 0 | HT14: 0 | HU14: 0 | HV14: 0 | HW14: 0 | HX14: 0 | HY14: 0 | HZ14: 0 | IA14: 0 | IB14: 0 | IC14: 0 | ID14: 0 | IE14: 0 | IF14: 0 | IG14: 0 | IH14: 0 | II14: 0 | IJ14: 0 | IK14: 0
... A103: 56 | B103: SDH10 | F103: 2 | H103: 39 | J103: =B103&TEXT(F103,"00")&TEXT(H103,"00") -> SDH100239 | K103: 915 | M103: 56 | N103: SDH10 | O103: 2 | P103: 39 | Q103: =N103&TEXT(O103,"00")&TEXT(P103,"00") -> SDH100239 | R103: 0 | S103: 0 | T103: 0 | U103: 0 | V103: 0 | W103: 0 | X103: 0 | Y103: 0 | Z103: 0 | AA103: 0 | AB103: 0 | AC103: 0 | AD103: 0 | AE103: 0 | AF103: 0 | AG103: 0 | AH103: 0 | AI103: 0 | AJ103: 0 | AK103: 0 | AL103: 0 | AM103: 0 | AN103: 0 | AO103: 0 | AP103: 10000 | AQ103: 0 | AR103: 0 | AS103: 0 | AT103: 0 | AU103: 0 | AV103: 0 | AW103: 0 | AX103: 0 | AY103: 0 | AZ103: 0 | BA103: 0 | BB103: 0 | BC103: 0 | BD103: 0 | BE103: 0 | BF103: 0 | BG103: 0 | BH103: 0 | BI103: 0 | BJ103: 0 | BK103: 0 | BL103: 0 | BM103: 0 | BN103: 0 | BO103: 0 | BP103: 0 | BQ103: 0 | BR103: 0 | BS103: 0 | BT103: 0 | BU103: 0 | BV103: 0 | BW103: 0 | BX103: 0 | BY103: 0 | BZ103: 0 | CA103: 0 | CB103: 0 | CC103: 0 | CD103: 0 | CE103: 0 | CF103: 0 | CG103: 0 | CH103: 0 | CI103: 0 | CJ103: 0 | CK103: 0 | CL103: 0 | CM103: 0 | CN103: 0 | CO103: 0 | CP103: 0 | CQ103: 0 | CR103: 0 | CS103: 0 | CT103: 0 | CU103: 0 | CV103: 0 | CW103: 0 | CX103: 0 | CY103: 0 | CZ103: 0 | DA103: 0 | DB103: 0 | DC103: 0 | DD103: 0 | DE103: 0 | DF103: 0 | DG103: 0 | DH103: 0 | DI103: 0 | DJ103: 0 | DK103: 0 | DL103: 0 | DM103: 0 | DN103: 0 | DO103: 0 | DP103: 0 | DQ103: 0 | DR103: 0 | DS103: 0 | DT103: 0 | DU103: 0 | DV103: 0 | DW103: 0 | DX103: 0 | DZ103: 56 | EA103: SDH10 | EB103: 2 | EC103: 39 | ED103: =EA103&TEXT(EB103,"00")&TEXT(EC103,"00") -> SDH100239 | EE103: 10000 | EF103: 10000 | EG103: 10000 | EH103: 10000 | EI103: 10000 | EJ103: 10000 | EK103: 10000 | EL103: 10000 | EM103: 10000 | EN103: 10000 | EO103: 10000 | EP103: 10000 | EQ103: 10000 | ER103: 10000 | ES103: 10000 | ET103: 10000 | EU103: 10000 | EV103: 10000 | EW103: 10000 | EX103: 10000 | EY103: 10000 | EZ103: 10000 | FA103: 10000 | FB103: 10000 | FC103: 10000 | FD103: 0 | FE103: 0 | FF103: 0 | FG103: 0 | FH103: 0 | FI103: 0 | FJ103: 0 | FK103: 0 | FL103: 0 | FM103: 0 | FN103: 0 | FO103: 0 | FP103: 0 | FQ103: 0 | FR103: 0 | FS103: 0 | FT103: 0 | FU103: 0 | FV103: 0 | FW103: 0 | FX103: 0 | FY103: 0 | FZ103: 0 | GA103: 0 | GB103: 0 | GC103: 0 | GD103: 0 | GE103: 0 | GF103: 0 | GG103: 0 | GH103: 0 | GI103: 0 | GJ103: 0 | GK103: 0 | GL103: 0 | GM103: 0 | GN103: 0 | GO103: 0 | GP103: 0 | GQ103: 0 | GR103: 0 | GS103: 0 | GT103: 0 | GU103: 0 | GV103: 0 | GW103: 0 | GX103: 0 | GY103: 0 | GZ103: 0 | HA103: 0 | HB103: 0 | HC103: 0 | HD103: 0 | HE103: 0 | HF103: 0 | HG103: 0 | HH103: 0 | HI103: 0 | HJ103: 0 | HK103: 0 | HL103: 0 | HM103: 0 | HN103: 0 | HO103: 0 | HP103: 0 | HQ103: 0 | HR103: 0 | HS103: 0 | HT103: 0 | HU103: 0 | HV103: 0 | HW103: 0 | HX103: 0 | HY103: 0 | HZ103: 0 | IA103: 0 | IB103: 0 | IC103: 0 | ID103: 0 | IE103: 0 | IF103: 0 | IG103: 0 | IH103: 0 | II103: 0 | IJ103: 0 | IK103: 0
B104: SDH10 | F104: 2 | H104: 40 | J104: =B104&TEXT(F104,"00")&TEXT(H104,"00") -> SDH100240 | K104: 920 | N104: SDH10 | O104: 2 | P104: 40 | Q104: =N104&TEXT(O104,"00")&TEXT(P104,"00") -> SDH100240 | R104: 0 | S104: 0 | T104: 0 | U104: 0 | V104: 0 | W104: 0 | X104: 0 | Y104: 0 | Z104: 0 | AA104: 0 | AB104: 0 | AC104: 0 | AD104: 0 | AE104: 0 | AF104: 0 | AG104: 0 | AH104: 0 | AI104: 0 | AJ104: 0 | AK104: 0 | AL104: 0 | AM104: 0 | AN104: 0 | AO104: 0 | AP104: 10000 | AQ104: 0 | AR104: 0 | AS104: 0 | AT104: 0 | AU104: 0 | AV104: 0 | AW104: 0 | AX104: 0 | AY104: 0 | AZ104: 0 | BA104: 0 | BB104: 0 | BC104: 0 | BD104: 0 | BE104: 0 | BF104: 0 | BG104: 0 | BH104: 0 | BI104: 0 | BJ104: 0 | BK104: 0 | BL104: 0 | BM104: 0 | BN104: 0 | BO104: 0 | BP104: 0 | BQ104: 0 | BR104: 0 | BS104: 0 | BT104: 0 | BU104: 0 | BV104: 0 | BW104: 0 | BX104: 0 | BY104: 0 | BZ104: 0 | CA104: 0 | CB104: 0 | CC104: 0 | CD104: 0 | CE104: 0 | CF104: 0 | CG104: 0 | CH104: 0 | CI104: 0 | CJ104: 0 | CK104: 0 | CL104: 0 | CM104: 0 | CN104: 0 | CO104: 0 | CP104: 0 | CQ104: 0 | CR104: 0 | CS104: 0 | CT104: 0 | CU104: 0 | CV104: 0 | CW104: 0 | CX104: 0 | CY104: 0 | CZ104: 0 | DA104: 0 | DB104: 0 | DC104: 0 | DD104: 0 | DE104: 0 | DF104: 0 | DG104: 0 | DH104: 0 | DI104: 0 | DJ104: 0 | DK104: 0 | DL104: 0 | DM104: 0 | DN104: 0 | DO104: 0 | DP104: 0 | DQ104: 0 | DR104: 0 | DS104: 0 | DT104: 0 | DU104: 0 | DV104: 0 | DW104: 0 | DX104: 0 | EA104: SDH10 | EB104: 2 | EC104: 40 | ED104: =EA104&TEXT(EB104,"00")&TEXT(EC104,"00") -> SDH100240 | EE104: 10000 | EF104: 10000 | EG104: 10000 | EH104: 10000 | EI104: 10000 | EJ104: 10000 | EK104: 10000 | EL104: 10000 | EM104: 10000 | EN104: 10000 | EO104: 10000 | EP104: 10000 | EQ104: 10000 | ER104: 10000 | ES104: 10000 | ET104: 10000 | EU104: 10000 | EV104: 10000 | EW104: 10000 | EX104: 10000 | EY104: 10000 | EZ104: 10000 | FA104: 10000 | FB104: 10000 | FC104: 10000 | FD104: 0 | FE104: 0 | FF104: 0 | FG104: 0 | FH104: 0 | FI104: 0 | FJ104: 0 | FK104: 0 | FL104: 0 | FM104: 0 | FN104: 0 | FO104: 0 | FP104: 0 | FQ104: 0 | FR104: 0 | FS104: 0 | FT104: 0 | FU104: 0 | FV104: 0 | FW104: 0 | FX104: 0 | FY104: 0 | FZ104: 0 | GA104: 0 | GB104: 0 | GC104: 0 | GD104: 0 | GE104: 0 | GF104: 0 | GG104: 0 | GH104: 0 | GI104: 0 | GJ104: 0 | GK104: 0 | GL104: 0 | GM104: 0 | GN104: 0 | GO104: 0 | GP104: 0 | GQ104: 0 | GR104: 0 | GS104: 0 | GT104: 0 | GU104: 0 | GV104: 0 | GW104: 0 | GX104: 0 | GY104: 0 | GZ104: 0 | HA104: 0 | HB104: 0 | HC104: 0 | HD104: 0 | HE104: 0 | HF104: 0 | HG104: 0 | HH104: 0 | HI104: 0 | HJ104: 0 | HK104: 0 | HL104: 0 | HM104: 0 | HN104: 0 | HO104: 0 | HP104: 0 | HQ104: 0 | HR104: 0 | HS104: 0 | HT104: 0 | HU104: 0 | HV104: 0 | HW104: 0 | HX104: 0 | HY104: 0 | HZ104: 0 | IA104: 0 | IB104: 0 | IC104: 0 | ID104: 0 | IE104: 0 | IF104: 0 | IG104: 0 | IH104: 0 | II104: 0 | IJ104: 0 | IK104: 0
